Workbook

Sheet Instructions
B3: Instructions
B4: Fill in Purple fields with market values based off the GTN
B7: Info
B8: Author: | C8: Mads Onsberg
B9: Email: | C9: onsberg@gmail.com
B10: Current version: | C10: 1.2
B11: Released: | C11: 40924
B14: Version history
B15: Version 1 | C15: Corrected GTN successful sale cut % in profit calculation
C16: Released: 11/01/2012
B17: Version 1.1 | C17: Removed Exotect schematics
C18: Added more space for custom schematics
C19: Added Implants sheet
C20: Added instructions sheet
C21: Moved Grade 1 to 4 materials to apear inactive
C22: Minor changes to framing layout
C23: Released: 15/01/2012
B24: Version 1.2 | C24: Corrected mislabled fields
C25: Added Implants by stat sheet
C26: Renamed Impants sheet to Implants by bonus
C27: Released: 16/01/2012

Sheet Materials
D2: Material | E2: Value | I2: Material | J2: Value | N2: Material | O2: Value
B3: Grade 5 | D3: Parasitic Microorganism | G3: Vendor Mats | I3: Hypo-syringe | J3: 10 | L3: Grade 1 | N3: Dielectric Cell Fiber
D4: Quick-Growth Agent | I4: First Aid Kit | J4: 10 | N4: Bacterial Strain
D5: Red Goo | I5: Single-Pulse Implant Processor | J5: 10 | N5: Green Goo
D6: Psychoactive Compound | I6: Double-Pulse Implant Processor | J6: 200 | N6: Biochemical Bonding Agent
D7: Nutrient Gel | I7: D-Package Implant Processor | J7: 50 | N7: Alien Blood Sample
D8: Experimental Serum | I8: Advanced Power Implant Processor | J8: 400 | L8: Grade 2 | N8: Toxic Extract
D9: Iridescent Goo | N9: Microscopic Symbiote
B10: Grade 6 | D10: Mutagenic Paste | N10: Genetic Anomaly
D11: Neurochemical Extract | N11: Luminescent Cell Culture
D12: Immunity Cell Culture | N12: Molecular Programmer
D13: Smart Cells | N13: Mechanical Symbiote
D14: Radioactive Paste | L14: Grade 3 | N14: Unknown Microorganism
N15: Bio-Energy Cell Sample
N16: Blue Goo
N17: Medicinal Fluid
N18: Hallucinogenic Compound
N19: Neuro-Stimulator
N20: Bioelectric Toxin
L21: Grade 4 | N21: Alien Bacteria
N22: Inert Virus
N23: Nerve-Damaging Chemical
N24: Cosmic Trace Particle
N25: Synthetic Blood
N26: Miracle Fluid

Sheet Adrenals & Stims
H2: Hypo-syringe | I2: First Aid Kit | J2: Single-Pulse Implant Processor | K2: Double-Pulse Implant Processor | L2: D-Package Implant Processor | M2: Advanced Power Implant Processor | N2: Mutagenic Paste | O2: Neurochemical Extract | P2: Immunity Cell Culture | Q2: Smart Cells | R2: Radioactive Paste | S2: Parasitic Microorganism | T2: Quick-Growth Agent | U2: Red Goo | V2: Psychoactive Compound | W2: Nutrient Gel | X2: Experimental Serum | Y2: Iridescent Goo
D15: Price | E15: Value | F15: Profit | G15: ROI | H15: Vendor Mats | N15: Grade 6 | S15: Grade 5
B16: Adrenals | C16: Hyper-Battle Absorb Adrenal | E16: =$S16*Materials!$E$3+$T16*Materials!$E$4+$U16*Materials!$E$5+$V16*Materials!$E$6+$W16*Materials!$E$7+$X16*Materials!$E$8+$Y16*Materials!$E$9+$N16*Materials!$E$10+$O16*Materials!$E$11+$P16*Materials!$E$12+$Q16*Materials!$E$13+$R16*Materials!$E$14+$H16*Materials!$J$3+$I16*Materials!$J$4+$J16*Materials!$J$5+$K16*Materials!$J$6+$L16*Materials!$J$7+$M16*Materials!$J$8 -> 10 | F16: =(D16-E16)-(D16)*0.03 -> -10 | G16: =IF(E16>0,F16/E16,"N/A") -> -1 | H16: 1 | N16: 4 | O16: 4 | Q16: 4 | U16: 4
C17: Hyper-Battle Attack Adrenal | E17: =$S17*Materials!$E$3+$T17*Materials!$E$4+$U17*Materials!$E$5+$V17*Materials!$E$6+$W17*Materials!$E$7+$X17*Materials!$E$8+$Y17*Materials!$E$9+$N17*Materials!$E$10+$O17*Materials!$E$11+$P17*Materials!$E$12+$Q17*Materials!$E$13+$R17*Materials!$E$14+$H17*Materials!$J$3+$I17*Materials!$J$4+$J17*Materials!$J$5+$K17*Materials!$J$6+$L17*Materials!$J$7+$M17*Materials!$J$8 -> 10 | F17: =(D17-E17)-(D17)*0.03 -> -10 | G17: =IF(E17>0,F17/E17,"N/A") -> -1 | H17: 1 | P17: 4 | T17: 4 | V17: 4 | X17: 4
C18: Hyper-Battle Critical Adrenal | E18: =$S18*Materials!$E$3+$T18*Materials!$E$4+$U18*Materials!$E$5+$V18*Materials!$E$6+$W18*Materials!$E$7+$X18*Materials!$E$8+$Y18*Materials!$E$9+$N18*Materials!$E$10+$O18*Materials!$E$11+$P18*Materials!$E$12+$Q18*Materials!$E$13+$R18*Materials!$E$14+$H18*Materials!$J$3+$I18*Materials!$J$4+$J18*Materials!$J$5+$K18*Materials!$J$6+$L18*Materials!$J$7+$M18*Materials!$J$8 -> 10 | F18: =(D18-E18)-(D18)*0.03 -> -10 | G18: =IF(E18>0,F18/E18,"N/A") -> -1 | H18: 1 | P18: 4 | T18: 4 | V18: 4 | X18: 4
C19: Hyper-Battle Efficacy Adrenal | E19: =$S19*Materials!$E$3+$T19*Materials!$E$4+$U19*Materials!$E$5+$V19*Materials!$E$6+$W19*Materials!$E$7+$X19*Materials!$E$8+$Y19*Materials!$E$9+$N19*Materials!$E$10+$O19*Materials!$E$11+$P19*Materials!$E$12+$Q19*Materials!$E$13+$R19*Materials!$E$14+$H19*Materials!$J$3+$I19*Materials!$J$4+$J19*Materials!$J$5+$K19*Materials!$J$6+$L19*Materials!$J$7+$M19*Materials!$J$8 -> 10 | F19: =(D19-E19)-(D19)*0.03 -> -10 | G19: =IF(E19>0,F19/E19,"N/A") -> -1 | H19: 1 | N19: 4 | O19: 4 | Q19: 4 | U19: 4
C20: Hyper-Battle Force Adrenal | E20: =$S20*Materials!$E$3+$T20*Materials!$E$4+$U20*Materials!$E$5+$V20*Materials!$E$6+$W20*Materials!$E$7+$X20*Materials!$E$8+$Y20*Materials!$E$9+$N20*Materials!$E$10+$O20*Materials!$E$11+$P20*Materials!$E$12+$Q20*Materials!$E$13+$R20*Materials!$E$14+$H20*Materials!$J$3+$I20*Materials!$J$4+$J20*Materials!$J$5+$K20*Materials!$J$6+$L20*Materials!$J$7+$M20*Materials!$J$8 -> 10 | F20: =(D20-E20)-(D20)*0.03 -> -10 | G20: =IF(E20>0,F20/E20,"N/A") -> -1 | H20: 1 | P20: 4 | T20: 4 | V20: 4 | X20: 4
C21: Hyper-Battle Tech Adrenal | E21: =$S21*Materials!$E$3+$T21*Materials!$E$4+$U21*Materials!$E$5+$V21*Materials!$E$6+$W21*Materials!$E$7+$X21*Materials!$E$8+$Y21*Materials!$E$9+$N21*Materials!$E$10+$O21*Materials!$E$11+$P21*Materials!$E$12+$Q21*Materials!$E$13+$R21*Materials!$E$14+$H21*Materials!$J$3+$I21*Materials!$J$4+$J21*Materials!$J$5+$K21*Materials!$J$6+$L21*Materials!$J$7+$M21*Materials!$J$8 -> 10 | F21: =(D21-E21)-(D21)*0.03 -> -10 | G21: =IF(E21>0,F21/E21,"N/A") -> -1 | H21: 1 | P21: 4 | T21: 4 | V21: 4 | X21: 4
C22: Hyper-Battle Triage Adrenal | E22: =$S22*Materials!$E$3+$T22*Materials!$E$4+$U22*Materials!$E$5+$V22*Materials!$E$6+$W22*Materials!$E$7+$X22*Materials!$E$8+$Y22*Materials!$E$9+$N22*Materials!$E$10+$O22*Materials!$E$11+$P22*Materials!$E$12+$Q22*Materials!$E$13+$R22*Materials!$E$14+$H22*Materials!$J$3+$I22*Materials!$J$4+$J22*Materials!$J$5+$K22*Materials!$J$6+$L22*Materials!$J$7+$M22*Materials!$J$8 -> 10 | F22: =(D22-E22)-(D22)*0.03 -> -10 | G22: =IF(E22>0,F22/E22,"N/A") -> -1 | H22: 1 | N22: 4 | O22: 4 | Q22: 4 | U22: 4
B23: Stims | C23: Prototype Hyper-Battle Command Stim | E23: =$S23*Materials!$E$3+$T23*Materials!$E$4+$U23*Materials!$E$5+$V23*Materials!$E$6+$W23*Materials!$E$7+$X23*Materials!$E$8+$Y23*Materials!$E$9+$N23*Materials!$E$10+$O23*Materials!$E$11+$P23*Materials!$E$12+$Q23*Materials!$E$13+$R23*Materials!$E$14+$H23*Materials!$J$3+$I23*Materials!$J$4+$J23*Materials!$J$5+$K23*Materials!$J$6+$L23*Materials!$J$7+$M23*Materials!$J$8 -> 10 | F23: =(D23-E23)-(D23)*0.03 -> -10 | G23: =IF(E23>0,F23/E23,"N/A") -> -1 | H23: 1 | N23: 4 | O23: 6 | P23: 4 | Q23: 4
C24: Prototype Hyper-Battle Fortitude Stim | E24: =$S24*Materials!$E$3+$T24*Materials!$E$4+$U24*Materials!$E$5+$V24*Materials!$E$6+$W24*Materials!$E$7+$X24*Materials!$E$8+$Y24*Materials!$E$9+$N24*Materials!$E$10+$O24*Materials!$E$11+$P24*Materials!$E$12+$Q24*Materials!$E$13+$R24*Materials!$E$14+$H24*Materials!$J$3+$I24*Materials!$J$4+$J24*Materials!$J$5+$K24*Materials!$J$6+$L24*Materials!$J$7+$M24*Materials!$J$8 -> 10 | F24: =(D24-E24)-(D24)*0.03 -> -10 | G24: =IF(E24>0,F24/E24,"N/A") -> -1 | H24: 1 | N24: 4 | O24: 6 | P24: 4 | Q24: 4
C25: Prototype Hyper-Battle Might Stim | E25: =$S25*Materials!$E$3+$T25*Materials!$E$4+$U25*Materials!$E$5+$V25*Materials!$E$6+$W25*Materials!$E$7+$X25*Materials!$E$8+$Y25*Materials!$E$9+$N25*Materials!$E$10+$O25*Materials!$E$11+$P25*Materials!$E$12+$Q25*Materials!$E$13+$R25*Materials!$E$14+$H25*Materials!$J$3+$I25*Materials!$J$4+$J25*Materials!$J$5+$K25*Materials!$J$6+$L25*Materials!$J$7+$M25*Materials!$J$8 -> 10 | F25: =(D25-E25)-(D25)*0.03 -> -10 | G25: =IF(E25>0,F25/E25,"N/A") -> -1 | H25: 1 | T25: 6 | U25: 4 | V25: 4 | X25: 4
C26: Prototype Hyper-Battle Reflex Stim | E26: =$S26*Materials!$E$3+$T26*Materials!$E$4+$U26*Materials!$E$5+$V26*Materials!$E$6+$W26*Materials!$E$7+$X26*Materials!$E$8+$Y26*Materials!$E$9+$N26*Materials!$E$10+$O26*Materials!$E$11+$P26*Materials!$E$12+$Q26*Materials!$E$13+$R26*Materials!$E$14+$H26*Materials!$J$3+$I26*Materials!$J$4+$J26*Materials!$J$5+$K26*Materials!$J$6+$L26*Materials!$J$7+$M26*Materials!$J$8 -> 10 | F26: =(D26-E26)-(D26)*0.03 -> -10 | G26: =IF(E26>0,F26/E26,"N/A") -> -1 | H26: 1 | T26: 6 | U26: 4 | V26: 4 | X26: 4
C27: Prototype Hyper-Battle Resolve Stim | E27: =$S27*Materials!$E$3+$T27*Materials!$E$4+$U27*Materials!$E$5+$V27*Materials!$E$6+$W27*Materials!$E$7+$X27*Materials!$E$8+$Y27*Materials!$E$9+$N27*Materials!$E$10+$O27*Materials!$E$11+$P27*Materials!$E$12+$Q27*Materials!$E$13+$R27*Materials!$E$14+$H27*Materials!$J$3+$I27*Materials!$J$4+$J27*Materials!$J$5+$K27*Materials!$J$6+$L27*Materials!$J$7+$M27*Materials!$J$8 -> 10 | F27: =(D27-E27)-(D27)*0.03 -> -10 | G27: =IF(E27>0,F27/E27,"N/A") -> -1 | H27: 1 | T27: 6 | U27: 4 | V27: 4 | X27: 4
C28: Prototype Hyper-Battle Skill Stim | E28: =$S28*Materials!$E$3+$T28*Materials!$E$4+$U28*Materials!$E$5+$V28*Materials!$E$6+$W28*Materials!$E$7+$X28*Materials!$E$8+$Y28*Materials!$E$9+$N28*Materials!$E$10+$O28*Materials!$E$11+$P28*Materials!$E$12+$Q28*Materials!$E$13+$R28*Materials!$E$14+$H28*Materials!$J$3+$I28*Materials!$J$4+$J28*Materials!$J$5+$K28*Materials!$J$6+$L28*Materials!$J$7+$M28*Materials!$J$8 -> 10 | F28: =(D28-E28)-(D28)*0.03 -> -10 | G28: =IF(E28>0,F28/E28,"N/A") -> -1 | H28: 1 | T28: 6 | U28: 4 | V28: 4 | X28: 4
B29: Custom | E29: =$S29*Materials!$E$3+$T29*Materials!$E$4+$U29*Materials!$E$5+$V29*Materials!$E$6+$W29*Materials!$E$7+$X29*Materials!$E$8+$Y29*Materials!$E$9+$N29*Materials!$E$10+$O29*Materials!$E$11+$P29*Materials!$E$12+$Q29*Materials!$E$13+$R29*Materials!$E$14+$H29*Materials!$J$3+$I29*Materials!$J$4+$J29*Materials!$J$5+$K29*Materials!$J$6+$L29*Materials!$J$7+$M29*Materials!$J$8 -> 0 | F29: =(D29-E29)-(D29)*0.03 -> 0 | G29: =IF(E29>0,F29/E29,"N/A") -> N/A
E30: =$S30*Materials!$E$3+$T30*Materials!$E$4+$U30*Materials!$E$5+$V30*Materials!$E$6+$W30*Materials!$E$7+$X30*Materials!$E$8+$Y30*Materials!$E$9+$N30*Materials!$E$10+$O30*Materials!$E$11+$P30*Materials!$E$12+$Q30*Materials!$E$13+$R30*Materials!$E$14+$H30*Materials!$J$3+$I30*Materials!$J$4+$J30*Materials!$J$5+$K30*Materials!$J$6+$L30*Materials!$J$7+$M30*Materials!$J$8 -> 0 | F30: =(D30-E30)-(D30)*0.03 -> 0 | G30: =IF(E30>0,F30/E30,"N/A") -> N/A
E31: =$S31*Materials!$E$3+$T31*Materials!$E$4+$U31*Materials!$E$5+$V31*Materials!$E$6+$W31*Materials!$E$7+$X31*Materials!$E$8+$Y31*Materials!$E$9+$N31*Materials!$E$10+$O31*Materials!$E$11+$P31*Materials!$E$12+$Q31*Materials!$E$13+$R31*Materials!$E$14+$H31*Materials!$J$3+$I31*Materials!$J$4+$J31*Materials!$J$5+$K31*Materials!$J$6+$L31*Materials!$J$7+$M31*Materials!$J$8 -> 0 | F31: =(D31-E31)-(D31)*0.03 -> 0 | G31: =IF(E31>0,F31/E31,"N/A") -> N/A
E32: =$S32*Materials!$E$3+$T32*Materials!$E$4+$U32*Materials!$E$5+$V32*Materials!$E$6+$W32*Materials!$E$7+$X32*Materials!$E$8+$Y32*Materials!$E$9+$N32*Materials!$E$10+$O32*Materials!$E$11+$P32*Materials!$E$12+$Q32*Materials!$E$13+$R32*Materials!$E$14+$H32*Materials!$J$3+$I32*Materials!$J$4+$J32*Materials!$J$5+$K32*Materials!$J$6+$L32*Materials!$J$7+$M32*Materials!$J$8 -> 0 | F32: =(D32-E32)-(D32)*0.03 -> 0 | G32: =IF(E32>0,F32/E32,"N/A") -> N/A
E33: =$S33*Materials!$E$3+$T33*Materials!$E$4+$U33*Materials!$E$5+$V33*Materials!$E$6+$W33*Materials!$E$7+$X33*Materials!$E$8+$Y33*Materials!$E$9+$N33*Materials!$E$10+$O33*Materials!$E$11+$P33*Materials!$E$12+$Q33*Materials!$E$13+$R33*Materials!$E$14+$H33*Materials!$J$3+$I33*Materials!$J$4+$J33*Materials!$J$5+$K33*Materials!$J$6+$L33*Materials!$J$7+$M33*Materials!$J$8 -> 0 | F33: =(D33-E33)-(D33)*0.03 -> 0 | G33: =IF(E33>0,F33/E33,"N/A") -> N/A
E34: =$S34*Materials!$E$3+$T34*Materials!$E$4+$U34*Materials!$E$5+$V34*Materials!$E$6+$W34*Materials!$E$7+$X34*Materials!$E$8+$Y34*Materials!$E$9+$N34*Materials!$E$10+$O34*Materials!$E$11+$P34*Materials!$E$12+$Q34*Materials!$E$13+$R34*Materials!$E$14+$H34*Materials!$J$3+$I34*Materials!$J$4+$J34*Materials!$J$5+$K34*Materials!$J$6+$L34*Materials!$J$7+$M34*Materials!$J$8 -> 0 | F34: =(D34-E34)-(D34)*0.03 -> 0 | G34: =IF(E34>0,F34/E34,"N/A") -> N/A
E35: =$S35*Materials!$E$3+$T35*Materials!$E$4+$U35*Materials!$E$5+$V35*Materials!$E$6+$W35*Materials!$E$7+$X35*Materials!$E$8+$Y35*Materials!$E$9+$N35*Materials!$E$10+$O35*Materials!$E$11+$P35*Materials!$E$12+$Q35*Materials!$E$13+$R35*Materials!$E$14+$H35*Materials!$J$3+$I35*Materials!$J$4+$J35*Materials!$J$5+$K35*Materials!$J$6+$L35*Materials!$J$7+$M35*Materials!$J$8 -> 0 | F35: =(D35-E35)-(D35)*0.03 -> 0 | G35: =IF(E35>0,F35/E35,"N/A") -> N/A
E36: =$S36*Materials!$E$3+$T36*Materials!$E$4+$U36*Materials!$E$5+$V36*Materials!$E$6+$W36*Materials!$E$7+$X36*Materials!$E$8+$Y36*Materials!$E$9+$N36*Materials!$E$10+$O36*Materials!$E$11+$P36*Materials!$E$12+$Q36*Materials!$E$13+$R36*Materials!$E$14+$H36*Materials!$J$3+$I36*Materials!$J$4+$J36*Materials!$J$5+$K36*Materials!$J$6+$L36*Materials!$J$7+$M36*Materials!$J$8 -> 0 | F36: =(D36-E36)-(D36)*0.03 -> 0 | G36: =IF(E36>0,F36/E36,"N/A") -> N/A
E37: =$S37*Materials!$E$3+$T37*Materials!$E$4+$U37*Materials!$E$5+$V37*Materials!$E$6+$W37*Materials!$E$7+$X37*Materials!$E$8+$Y37*Materials!$E$9+$N37*Materials!$E$10+$O37*Materials!$E$11+$P37*Materials!$E$12+$Q37*Materials!$E$13+$R37*Materials!$E$14+$H37*Materials!$J$3+$I37*Materials!$J$4+$J37*Materials!$J$5+$K37*Materials!$J$6+$L37*Materials!$J$7+$M37*Materials!$J$8 -> 0 | F37: =(D37-E37)-(D37)*0.03 -> 0 | G37: =IF(E37>0,F37/E37,"N/A") -> N/A
E38: =$S38*Materials!$E$3+$T38*Materials!$E$4+$U38*Materials!$E$5+$V38*Materials!$E$6+$W38*Materials!$E$7+$X38*Materials!$E$8+$Y38*Materials!$E$9+$N38*Materials!$E$10+$O38*Materials!$E$11+$P38*Materials!$E$12+$Q38*Materials!$E$13+$R38*Materials!$E$14+$H38*Materials!$J$3+$I38*Materials!$J$4+$J38*Materials!$J$5+$K38*Materials!$J$6+$L38*Materials!$J$7+$M38*Materials!$J$8 -> 0 | F38: =(D38-E38)-(D38)*0.03 -> 0 | G38: =IF(E38>0,F38/E38,"N/A") -> N/A
E39: =$S39*Materials!$E$3+$T39*Materials!$E$4+$U39*Materials!$E$5+$V39*Materials!$E$6+$W39*Materials!$E$7+$X39*Materials!$E$8+$Y39*Materials!$E$9+$N39*Materials!$E$10+$O39*Materials!$E$11+$P39*Materials!$E$12+$Q39*Materials!$E$13+$R39*Materials!$E$14+$H39*Materials!$J$3+$I39*Materials!$J$4+$J39*Materials!$J$5+$K39*Materials!$J$6+$L39*Materials!$J$7+$M39*Materials!$J$8 -> 0 | F39: =(D39-E39)-(D39)*0.03 -> 0 | G39: =IF(E39>0,F39/E39,"N/A") -> N/A
E40: =$S40*Materials!$E$3+$T40*Materials!$E$4+$U40*Materials!$E$5+$V40*Materials!$E$6+$W40*Materials!$E$7+$X40*Materials!$E$8+$Y40*Materials!$E$9+$N40*Materials!$E$10+$O40*Materials!$E$11+$P40*Materials!$E$12+$Q40*Materials!$E$13+$R40*Materials!$E$14+$H40*Materials!$J$3+$I40*Materials!$J$4+$J40*Materials!$J$5+$K40*Materials!$J$6+$L40*Materials!$J$7+$M40*Materials!$J$8 -> 0 | F40: =(D40-E40)-(D40)*0.03 -> 0 | G40: =IF(E40>0,F40/E40,"N/A") -> N/A
E41: =$S41*Materials!$E$3+$T41*Materials!$E$4+$U41*Materials!$E$5+$V41*Materials!$E$6+$W41*Materials!$E$7+$X41*Materials!$E$8+$Y41*Materials!$E$9+$N41*Materials!$E$10+$O41*Materials!$E$11+$P41*Materials!$E$12+$Q41*Materials!$E$13+$R41*Materials!$E$14+$H41*Materials!$J$3+$I41*Materials!$J$4+$J41*Materials!$J$5+$K41*Materials!$J$6+$L41*Materials!$J$7+$M41*Materials!$J$8 -> 0 | F41: =(D41-E41)-(D41)*0.03 -> 0 | G41: =IF(E41>0,F41/E41,"N/A") -> N/A
... E62: =$S62*Materials!$E$3+$T62*Materials!$E$4+$U62*Materials!$E$5+$V62*Materials!$E$6+$W62*Materials!$E$7+$X62*Materials!$E$8+$Y62*Materials!$E$9+$N62*Materials!$E$10+$O62*Materials!$E$11+$P62*Materials!$E$12+$Q62*Materials!$E$13+$R62*Materials!$E$14+$H62*Materials!$J$3+$I62*Materials!$J$4+$J62*Materials!$J$5+$K62*Materials!$J$6+$L62*Materials!$J$7+$M62*Materials!$J$8 -> 0 | F62: =(D62-E62)-(D62)*0.03 -> 0 | G62: =IF(E62>0,F62/E62,"N/A") -> N/A

Sheet Implants by stat
B2: Awareness | I2: Resolve | P2: Resistance
E3: Primary: | F3: Endurance, Willpower | L3: Primary: | M3: Willpower, Endurance | S3: Primary: | T3: Endurance, Willpower
E4: Secondary: | F4: Accuracy, Critical | L4: Secondary: | M4: Alacrity, Critical | S4: Secondary: | T4: Accuracy, Defense
B6: Prefix | C6: Schematic | D6: Price | E6: Value | F6: Profit | G6: ROI | I6: Prefix | J6: Schematic | K6: Price | L6: Value | M6: Profit | N6: ROI | P6: Prefix | Q6: Schematic | R6: Price | S6: Value | T6: Profit | U6: ROI
C7: Nano-Optic Awareness Motivator | E7: =2*Materials!$E$5+4*Materials!$E$10+2*Materials!$E$11+1*Materials!$J$8 -> 400 | F7: =(D7-E7)-(D7)*0.03 -> -400 | G7: =IF(E7>0,F7/E7,"N/A") -> -1 | J7: Nano-Optic Resolve System | L7: =2*Materials!$E$5+4*Materials!$E$10+2*Materials!$E$11+1*Materials!$J$8 -> 400 | M7: =(K7-L7)-(K7)*0.03 -> -400 | N7: =IF(L7>0,M7/L7,"N/A") -> -1 | Q7: Nano-Optic Resistance System | S7: =2*Materials!$E$10+4*Materials!$E$11+2*Materials!$E$12+1*Materials!$J$8 -> 400 | T7: =(R7-S7)-(R7)*0.03 -> -400 | U7: =IF(S7>0,T7/S7,"N/A") -> -1
B8: Critical | C8: Nano-Optic Awareness System | E8: =2*Materials!$E$5+4*Materials!$E$10+2*Materials!$E$11+2*Materials!$E$13+1*Materials!$J$8 -> 400 | F8: =(D8-E8)-(D8)*0.03 -> -400 | G8: =IF(E8>0,F8/E8,"N/A") -> -1 | I8: Critical | J8: Nano-Optic Resolve System | L8: =2*Materials!$E$5+4*Materials!$E$10+2*Materials!$E$11+2*Materials!$E$13+1*Materials!$J$8 -> 400 | M8: =(K8-L8)-(K8)*0.03 -> -400 | N8: =IF(L8>0,M8/L8,"N/A") -> -1 | P8: Critical | Q8: Nano-Optic Resistance System | S8: =2*Materials!$E$10+4*Materials!$E$11+2*Materials!$E$12+2*Materials!$E$13+1*Materials!$J$8 -> 400 | T8: =(R8-S8)-(R8)*0.03 -> -400 | U8: =IF(S8>0,T8/S8,"N/A") -> -1
B9: Fervor | C9: Nano-Optic Awareness System | E9: =2*Materials!$E$5+4*Materials!$E$10+2*Materials!$E$11+2*Materials!$E$14+1*Materials!$J$8 -> 400 | F9: =(D9-E9)-(D9)*0.03 -> -400 | G9: =IF(E9>0,F9/E9,"N/A") -> -1 | I9: Fervor | J9: Nano-Optic Resolve System | L9: =2*Materials!$E$5+4*Materials!$E$10+2*Materials!$E$11+2*Materials!$E$14+1*Materials!$J$8 -> 400 | M9: =(K9-L9)-(K9)*0.03 -> -400 | N9: =IF(L9>0,M9/L9,"N/A") -> -1 | P9: Fervor | Q9: Nano-Optic Resistance System | S9: =2*Materials!$E$10+4*Materials!$E$11+2*Materials!$E$12+2*Materials!$E$14+1*Materials!$J$8 -> 400 | T9: =(R9-S9)-(R9)*0.03 -> -400 | U9: =IF(S9>0,T9/S9,"N/A") -> -1
B10: Supremacy | C10: Nano-Optic Awareness System | E10: =2*Materials!$E$5+4*Materials!$E$10+2*Materials!$E$11+2*Materials!$E$14+1*Materials!$J$8 -> 400 | F10: =(D10-E10)-(D10)*0.03 -> -400 | G10: =IF(E10>0,F10/E10,"N/A") -> -1 | I10: Supremacy | J10: Nano-Optic Resolve System | L10: =2*Materials!$E$5+4*Materials!$E$10+2*Materials!$E$11+2*Materials!$E$14+1*Materials!$J$8 -> 400 | M10: =(K10-L10)-(K10)*0.03 -> -400 | N10: =IF(L10>0,M10/L10,"N/A") -> -1 | P10: Supremacy | Q10: Nano-Optic Resistance System | S10: =2*Materials!$E$10+4*Materials!$E$11+2*Materials!$E$12+2*Materials!$E$14+1*Materials!$J$8 -> 400 | T10: =(R10-S10)-(R10)*0.03 -> -400 | U10: =IF(S10>0,T10/S10,"N/A") -> -1
B11: Leadership | C11: Nano-Optic Awareness System | E11: =2*Materials!$E$5+4*Materials!$E$10+2*Materials!$E$11+2*Materials!$E$14+1*Materials!$J$8 -> 400 | F11: =(D11-E11)-(D11)*0.03 -> -400 | G11: =IF(E11>0,F11/E11,"N/A") -> -1 | I11: Leadership | J11: Nano-Optic Resolve System | L11: =2*Materials!$E$5+4*Materials!$E$10+2*Materials!$E$11+2*Materials!$E$14+1*Materials!$J$8 -> 400 | M11: =(K11-L11)-(K11)*0.03 -> -400 | N11: =IF(L11>0,M11/L11,"N/A") -> -1 | P11: Leadership | Q11: Nano-Optic Resistance System | S11: =2*Materials!$E$10+4*Materials!$E$11+2*Materials!$E$12+2*Materials!$E$14+1*Materials!$J$8 -> 400 | T11: =(R11-S11)-(R11)*0.03 -> -400 | U11: =IF(S11>0,T11/S11,"N/A") -> -1
B12: Endowment | C12: Nano-Optic Awareness System | E12: =2*Materials!$E$5+4*Materials!$E$10+2*Materials!$E$11+2*Materials!$E$14+1*Materials!$J$8 -> 400 | F12: =(D12-E12)-(D12)*0.03 -> -400 | G12: =IF(E12>0,F12/E12,"N/A") -> -1 | I12: Endowment | J12: Nano-Optic Resolve System | L12: =2*Materials!$E$5+4*Materials!$E$10+2*Materials!$E$11+2*Materials!$E$14+1*Materials!$J$8 -> 400 | M12: =(K12-L12)-(K12)*0.03 -> -400 | N12: =IF(L12>0,M12/L12,"N/A") -> -1 | P12: Endowment | Q12: Nano-Optic Resistance System | S12: =2*Materials!$E$10+4*Materials!$E$11+2*Materials!$E$12+2*Materials!$E$14+1*Materials!$J$8 -> 400 | T12: =(R12-S12)-(R12)*0.03 -> -400 | U12: =IF(S12>0,T12/S12,"N/A") -> -1
B13: Tempest | C13: Nano-Optic Awareness System | E13: =2*Materials!$E$5+4*Materials!$E$10+2*Materials!$E$11+2*Materials!$E$14+1*Materials!$J$8 -> 400 | F13: =(D13-E13)-(D13)*0.03 -> -400 | G13: =IF(E13>0,F13/E13,"N/A") -> -1 | I13: Tempest | J13: Nano-Optic Resolve System | L13: =2*Materials!$E$5+4*Materials!$E$10+2*Materials!$E$11+2*Materials!$E$14+1*Materials!$J$8 -> 400 | M13: =(K13-L13)-(K13)*0.03 -> -400 | N13: =IF(L13>0,M13/L13,"N/A") -> -1 | P13: Tempest | Q13: Nano-Optic Resistance System | S13: =2*Materials!$E$10+4*Materials!$E$11+2*Materials!$E$12+2*Materials!$E$14+1*Materials!$J$8 -> 400 | T13: =(R13-S13)-(R13)*0.03 -> -400 | U13: =IF(S13>0,T13/S13,"N/A") -> -1
B14: Overkill | C14: Nano-Optic Awareness System | E14: =2*Materials!$E$5+4*Materials!$E$10+2*Materials!$E$11+2*Materials!$E$13+1*Materials!$J$8 -> 400 | F14: =(D14-E14)-(D14)*0.03 -> -400 | G14: =IF(E14>0,F14/E14,"N/A") -> -1 | I14: Overkill | J14: Nano-Optic Resolve System | L14: =2*Materials!$E$5+4*Materials!$E$10+2*Materials!$E$11+2*Materials!$E$13+1*Materials!$J$8 -> 400 | M14: =(K14-L14)-(K14)*0.03 -> -400 | N14: =IF(L14>0,M14/L14,"N/A") -> -1 | P14: Overkill | Q14: Nano-Optic Resistance System | S14: =2*Materials!$E$10+4*Materials!$E$11+2*Materials!$E$12+2*Materials!$E$13+1*Materials!$J$8 -> 400 | T14: =(R14-S14)-(R14)*0.03 -> -400 | U14: =IF(S14>0,T14/S14,"N/A") -> -1
B15: Hawkeye | C15: Nano-Optic Awareness System | E15: =2*Materials!$E$5+4*Materials!$E$10+2*Materials!$E$11+2*Materials!$E$14+1*Materials!$J$8 -> 400 | F15: =(D15-E15)-(D15)*0.03 -> -400 | G15: =IF(E15>0,F15/E15,"N/A") -> -1 | I15: Hawkeye | J15: Nano-Optic Resolve System | L15: =2*Materials!$E$5+4*Materials!$E$10+2*Materials!$E$11+2*Materials!$E$14+1*Materials!$J$8 -> 400 | M15: =(K15-L15)-(K15)*0.03 -> -400 | N15: =IF(L15>0,M15/L15,"N/A") -> -1 | P15: Hawkeye | Q15: Nano-Optic Resistance System | S15: =2*Materials!$E$10+4*Materials!$E$11+2*Materials!$E$12+2*Materials!$E$14+1*Materials!$J$8 -> 400 | T15: =(R15-S15)-(R15)*0.03 -> -400 | U15: =IF(S15>0,T15/S15,"N/A") -> -1
B16: Vehemance | C16: Nano-Optic Awareness System | E16: =2*Materials!$E$5+4*Materials!$E$10+2*Materials!$E$11+2*Materials!$E$14+1*Materials!$J$8 -> 400 | F16: =(D16-E16)-(D16)*0.03 -> -400 | G16: =IF(E16>0,F16/E16,"N/A") -> -1 | I16: Vehemance | J16: Nano-Optic Resolve System | L16: =2*Materials!$E$5+4*Materials!$E$10+2*Materials!$E$11+2*Materials!$E$14+1*Materials!$J$8 -> 400 | M16: =(K16-L16)-(K16)*0.03 -> -400 | N16: =IF(L16>0,M16/L16,"N/A") -> -1 | P16: Vehemance | Q16: Nano-Optic Resistance System | S16: =2*Materials!$E$10+4*Materials!$E$11+2*Materials!$E$12+2*Materials!$E$14+1*Materials!$J$8 -> 400 | T16: =(R16-S16)-(R16)*0.03 -> -400 | U16: =IF(S16>0,T16/S16,"N/A") -> -1
B17: Commander | C17: Nano-Optic Awareness System | E17: =2*Materials!$E$5+4*Materials!$E$10+2*Materials!$E$11+2*Materials!$E$14+1*Materials!$J$8 -> 400 | F17: =(D17-E17)-(D17)*0.03 -> -400 | G17: =IF(E17>0,F17/E17,"N/A") -> -1 | I17: Commander | J17: Nano-Optic Resolve System | L17: =2*Materials!$E$5+4*Materials!$E$10+2*Materials!$E$11+2*Materials!$E$14+1*Materials!$J$8 -> 400 | M17: =(K17-L17)-(K17)*0.03 -> -400 | N17: =IF(L17>0,M17/L17,"N/A") -> -1 | P17: Commander | Q17: Nano-Optic Resistance System | S17: =2*Materials!$E$10+4*Materials!$E$11+2*Materials!$E$12+2*Materials!$E$14+1*Materials!$J$8 -> 400 | T17: =(R17-S17)-(R17)*0.03 -> -400 | U17: =IF(S17>0,T17/S17,"N/A") -> -1
B18: Expert | C18: Nano-Optic Awareness System | E18: =2*Materials!$E$5+4*Materials!$E$10+2*Materials!$E$11+2*Materials!$E$14+1*Materials!$J$8 -> 400 | F18: =(D18-E18)-(D18)*0.03 -> -400 | G18: =IF(E18>0,F18/E18,"N/A") -> -1 | I18: Expert | J18: Nano-Optic Resolve System | L18: =2*Materials!$E$5+4*Materials!$E$10+2*Materials!$E$11+2*Materials!$E$14+1*Materials!$J$8 -> 400 | M18: =(K18-L18)-(K18)*0.03 -> -400 | N18: =IF(L18>0,M18/L18,"N/A") -> -1 | P18: Expert | Q18: Nano-Optic Resistance System | S18: =2*Materials!$E$10+4*Materials!$E$11+2*Materials!$E$12+2*Materials!$E$14+1*Materials!$J$8 -> 400 | T18: =(R18-S18)-(R18)*0.03 -> -400 | U18: =IF(S18>0,T18/S18,"N/A") -> -1
B19: Rampart | C19: Nano-Optic Awareness System | E19: =2*Materials!$E$5+4*Materials!$E$10+2*Materials!$E$11+2*Materials!$E$14+1*Materials!$J$8 -> 400 | F19: =(D19-E19)-(D19)*0.03 -> -400 | G19: =IF(E19>0,F19/E19,"N/A") -> -1 | I19: Rampart | J19: Nano-Optic Resolve System | L19: =2*Materials!$E$5+4*Materials!$E$10+2*Materials!$E$11+2*Materials!$E$14+1*Materials!$J$8 -> 400 | M19: =(K19-L19)-(K19)*0.03 -> -400 | N19: =IF(L19>0,M19/L19,"N/A") -> -1 | P19: Rampart | Q19: Nano-Optic Resistance System | S19: =2*Materials!$E$10+4*Materials!$E$11+2*Materials!$E$12+2*Materials!$E$14+1*Materials!$J$8 -> 400 | T19: =(R19-S19)-(R19)*0.03 -> -400 | U19: =IF(S19>0,T19/S19,"N/A") -> -1
B20: Redoubt | C20: Nano-Optic Awareness System | E20: =2*Materials!$E$5+4*Materials!$E$10+2*Materials!$E$11+2*Materials!$E$13+1*Materials!$J$8 -> 400 | F20: =(D20-E20)-(D20)*0.03 -> -400 | G20: =IF(E20>0,F20/E20,"N/A") -> -1 | I20: Redoubt | J20: Nano-Optic Resolve System | L20: =2*Materials!$E$5+4*Materials!$E$10+2*Materials!$E$11+2*Materials!$E$13+1*Materials!$J$8 -> 400 | M20: =(K20-L20)-(K20)*0.03 -> -400 | N20: =IF(L20>0,M20/L20,"N/A") -> -1 | P20: Redoubt | Q20: Nano-Optic Resistance System | S20: =2*Materials!$E$10+4*Materials!$E$11+2*Materials!$E$12+2*Materials!$E$13+1*Materials!$J$8 -> 400 | T20: =(R20-S20)-(R20)*0.03 -> -400 | U20: =IF(S20>0,T20/S20,"N/A") -> -1
B21: Exactitude | C21: Nano-Optic Awareness System | E21: =2*Materials!$E$5+4*Materials!$E$10+2*Materials!$E$11+2*Materials!$E$14+1*Materials!$J$8 -> 400 | F21: =(D21-E21)-(D21)*0.03 -> -400 | G21: =IF(E21>0,F21/E21,"N/A") -> -1 | I21: Exactitude | J21: Nano-Optic Resolve System | L21: =2*Materials!$E$5+4*Materials!$E$10+2*Materials!$E$11+2*Materials!$E$14+1*Materials!$J$8 -> 400 | M21: =(K21-L21)-(K21)*0.03 -> -400 | N21: =IF(L21>0,M21/L21,"N/A") -> -1 | P21: Exactitude | Q21: Nano-Optic Resistance System | S21: =2*Materials!$E$10+4*Materials!$E$11+2*Materials!$E$12+2*Materials!$E$14+1*Materials!$J$8 -> 400 | T21: =(R21-S21)-(R21)*0.03 -> -400 | U21: =IF(S21>0,T21/S21,"N/A") -> -1
B22: General | C22: Nano-Optic Awareness System | E22: =2*Materials!$E$5+4*Materials!$E$10+2*Materials!$E$11+2*Materials!$E$14+1*Materials!$J$8 -> 400 | F22: =(D22-E22)-(D22)*0.03 -> -400 | G22: =IF(E22>0,F22/E22,"N/A") -> -1 | I22: General | J22: Nano-Optic Resolve System | L22: =2*Materials!$E$5+4*Materials!$E$10+2*Materials!$E$11+2*Materials!$E$14+1*Materials!$J$8 -> 400 | M22: =(K22-L22)-(K22)*0.03 -> -400 | N22: =IF(L22>0,M22/L22,"N/A") -> -1 | P22: General | Q22: Nano-Optic Resistance System | S22: =2*Materials!$E$10+4*Materials!$E$11+2*Materials!$E$12+2*Materials!$E$14+1*Materials!$J$8 -> 400 | T22: =(R22-S22)-(R22)*0.03 -> -400 | U22: =IF(S22>0,T22/S22,"N/A") -> -1
B23: Anti-Armor | C23: Nano-Optic Awareness System | E23: =2*Materials!$E$5+4*Materials!$E$10+2*Materials!$E$11+2*Materials!$E$14+1*Materials!$J$8 -> 400 | F23: =(D23-E23)-(D23)*0.03 -> -400 | G23: =IF(E23>0,F23/E23,"N/A") -> -1 | I23: Anti-Armor | J23: Nano-Optic Resolve System | L23: =2*Materials!$E$5+4*Materials!$E$10+2*Materials!$E$11+2*Materials!$E$14+1*Materials!$J$8 -> 400 | M23: =(K23-L23)-(K23)*0.03 -> -400 | N23: =IF(L23>0,M23/L23,"N/A") -> -1 | P23: Anti-Armor | Q23: Nano-Optic Resistance System | S23: =2*Materials!$E$10+4*Materials!$E$11+2*Materials!$E$12+2*Materials!$E$14+1*Materials!$J$8 -> 400 | T23: =(R23-S23)-(R23)*0.03 -> -400 | U23: =IF(S23>0,T23/S23,"N/A") -> -1
B24: Veracity | C24: Nano-Optic Awareness System | E24: =2*Materials!$E$5+4*Materials!$E$10+2*Materials!$E$11+2*Materials!$E$14+1*Materials!$J$8 -> 400 | F24: =(D24-E24)-(D24)*0.03 -> -400 | G24: =IF(E24>0,F24/E24,"N/A") -> -1 | I24: Veracity | J24: Nano-Optic Resolve System | L24: =2*Materials!$E$5+4*Materials!$E$10+2*Materials!$E$11+2*Materials!$E$14+1*Materials!$J$8 -> 400 | M24: =(K24-L24)-(K24)*0.03 -> -400 | N24: =IF(L24>0,M24/L24,"N/A") -> -1 | P24: Veracity | Q24: Nano-Optic Resistance System | S24: =2*Materials!$E$10+4*Materials!$E$11+2*Materials!$E$12+2*Materials!$E$14+1*Materials!$J$8 -> 400 | T24: =(R24-S24)-(R24)*0.03 -> -400 | U24: =IF(S24>0,T24/S24,"N/A") -> -1
B27: Reflex | I27: Response | P27: Rejuvenation
E28: Primary: | F28: Endurance, Aim | L28: Primary: | M28: Endurance, Aim | S28: Primary: | T28: Endurance, Aim
E29: Secondary: | F29: Accuracy, Critical | L29: Secondary: | M29: Accuracy, Defense | S29: Secondary: | T29: Alacrity, Critical
B31: Prefix | C31: Schematic | D31: Price | E31: Value | F31: Profit | G31: ROI | I31: Prefix | J31: Schematic | K31: Price | L31: Value | M31: Profit | N31: ROI | P31: Prefix | Q31: Schematic | R31: Price | S31: Value | T31: Profit | U31: ROI
C32: Nano-Optic Reflex Enhancer | E32: =2*Materials!$E$5+4*Materials!$E$10+2*Materials!$E$11+1*Materials!$J$8 -> 400 | F32: =(D32-E32)-(D32)*0.03 -> -400 | G32: =IF(E32>0,F32/E32,"N/A") -> -1 | J32: Nano-Optic Response Implant | L32: =2*Materials!$E$10+4*Materials!$E$11+2*Materials!$E$12+1*Materials!$J$8 -> 400 | M32: =(K32-L32)-(K32)*0.03 -> -400 | N32: =IF(L32>0,M32/L32,"N/A") -> -1 | Q32: Nano-Optic Rejuvenation System | S32: =2*Materials!$E$10+4*Materials!$E$11+2*Materials!$E$12+1*Materials!$J$8 -> 400 | T32: =(R32-S32)-(R32)*0.03 -> -400 | U32: =IF(S32>0,T32/S32,"N/A") -> -1
B33: Critical | C33: Nano-Optic Reflex Enhancer | E33: =2*Materials!$E$5+4*Materials!$E$10+2*Materials!$E$11+2*Materials!$E$13+1*Materials!$J$8 -> 400 | F33: =(D33-E33)-(D33)*0.03 -> -400 | G33: =IF(E33>0,F33/E33,"N/A") -> -1 | I33: Critical | J33: Nano-Optic Response Implant | L33: =2*Materials!$E$10+4*Materials!$E$11+2*Materials!$E$12+2*Materials!$E$13+1*Materials!$J$8 -> 400 | M33: =(K33-L33)-(K33)*0.03 -> -400 | N33: =IF(L33>0,M33/L33,"N/A") -> -1 | P33: Critical | Q33: Nano-Optic Rejuvenation System | S33: =2*Materials!$E$10+4*Materials!$E$11+2*Materials!$E$12+2*Materials!$E$13+1*Materials!$J$8 -> 400 | T33: =(R33-S33)-(R33)*0.03 -> -400 | U33: =IF(S33>0,T33/S33,"N/A") -> -1
B34: Fervor | C34: Nano-Optic Reflex Enhancer | E34: =2*Materials!$E$5+4*Materials!$E$10+2*Materials!$E$11+2*Materials!$E$14+1*Materials!$J$8 -> 400 | F34: =(D34-E34)-(D34)*0.03 -> -400 | G34: =IF(E34>0,F34/E34,"N/A") -> -1 | I34: Fervor | J34: Nano-Optic Response Implant | L34: =2*Materials!$E$10+4*Materials!$E$11+2*Materials!$E$12+2*Materials!$E$14+1*Materials!$J$8 -> 400 | M34: =(K34-L34)-(K34)*0.03 -> -400 | N34: =IF(L34>0,M34/L34,"N/A") -> -1 | P34: Fervor | Q34: Nano-Optic Rejuvenation System | S34: =2*Materials!$E$10+4*Materials!$E$11+2*Materials!$E$12+2*Materials!$E$14+1*Materials!$J$8 -> 400 | T34: =(R34-S34)-(R34)*0.03 -> -400 | U34: =IF(S34>0,T34/S34,"N/A") -> -1
B35: Supremacy | C35: Nano-Optic Reflex Enhancer | E35: =2*Materials!$E$5+4*Materials!$E$10+2*Materials!$E$11+2*Materials!$E$14+1*Materials!$J$8 -> 400 | F35: =(D35-E35)-(D35)*0.03 -> -400 | G35: =IF(E35>0,F35/E35,"N/A") -> -1 | I35: Supremacy | J35: Nano-Optic Response Implant | L35: =2*Materials!$E$10+4*Materials!$E$11+2*Materials!$E$12+2*Materials!$E$14+1*Materials!$J$8 -> 400 | M35: =(K35-L35)-(K35)*0.03 -> -400 | N35: =IF(L35>0,M35/L35,"N/A") -> -1 | P35: Supremacy | Q35: Nano-Optic Rejuvenation System | S35: =2*Materials!$E$10+4*Materials!$E$11+2*Materials!$E$12+2*Materials!$E$14+1*Materials!$J$8 -> 400 | T35: =(R35-S35)-(R35)*0.03 -> -400 | U35: =IF(S35>0,T35/S35,"N/A") -> -1
B36: Leadership | C36: Nano-Optic Reflex Enhancer | E36: =2*Materials!$E$5+4*Materials!$E$10+2*Materials!$E$11+2*Materials!$E$14+1*Materials!$J$8 -> 400 | F36: =(D36-E36)-(D36)*0.03 -> -400 | G36: =IF(E36>0,F36/E36,"N/A") -> -1 | I36: Leadership | J36: Nano-Optic Response Implant | L36: =2*Materials!$E$10+4*Materials!$E$11+2*Materials!$E$12+2*Materials!$E$14+1*Materials!$J$8 -> 400 | M36: =(K36-L36)-(K36)*0.03 -> -400 | N36: =IF(L36>0,M36/L36,"N/A") -> -1 | P36: Leadership | Q36: Nano-Optic Rejuvenation System | S36: =2*Materials!$E$10+4*Materials!$E$11+2*Materials!$E$12+2*Materials!$E$14+1*Materials!$J$8 -> 400 | T36: =(R36-S36)-(R36)*0.03 -> -400 | U36: =IF(S36>0,T36/S36,"N/A") -> -1
B37: Endowment | C37: Nano-Optic Reflex Enhancer | E37: =2*Materials!$E$5+4*Materials!$E$10+2*Materials!$E$11+2*Materials!$E$14+1*Materials!$J$8 -> 400 | F37: =(D37-E37)-(D37)*0.03 -> -400 | G37: =IF(E37>0,F37/E37,"N/A") -> -1 | I37: Endowment | J37: Nano-Optic Response Implant | L37: =2*Materials!$E$10+4*Materials!$E$11+2*Materials!$E$12+2*Materials!$E$14+1*Materials!$J$8 -> 400 | M37: =(K37-L37)-(K37)*0.03 -> -400 | N37: =IF(L37>0,M37/L37,"N/A") -> -1 | P37: Endowment | Q37: Nano-Optic Rejuvenation System | S37: =2*Materials!$E$10+4*Materials!$E$11+2*Materials!$E$12+2*Materials!$E$14+1*Materials!$J$8 -> 400 | T37: =(R37-S37)-(R37)*0.03 -> -400 | U37: =IF(S37>0,T37/S37,"N/A") -> -1
B38: Tempest | C38: Nano-Optic Reflex Enhancer | E38: =2*Materials!$E$5+4*Materials!$E$10+2*Materials!$E$11+2*Materials!$E$14+1*Materials!$J$8 -> 400 | F38: =(D38-E38)-(D38)*0.03 -> -400 | G38: =IF(E38>0,F38/E38,"N/A") -> -1 | I38: Tempest | J38: Nano-Optic Response Implant | L38: =2*Materials!$E$10+4*Materials!$E$11+2*Materials!$E$12+2*Materials!$E$14+1*Materials!$J$8 -> 400 | M38: =(K38-L38)-(K38)*0.03 -> -400 | N38: =IF(L38>0,M38/L38,"N/A") -> -1 | P38: Tempest | Q38: Nano-Optic Rejuvenation System | S38: =2*Materials!$E$10+4*Materials!$E$11+2*Materials!$E$12+2*Materials!$E$14+1*Materials!$J$8 -> 400 | T38: =(R38-S38)-(R38)*0.03 -> -400 | U38: =IF(S38>0,T38/S38,"N/A") -> -1
B39: Overkill | C39: Nano-Optic Reflex Enhancer | E39: =2*Materials!$E$5+4*Materials!$E$10+2*Materials!$E$11+2*Materials!$E$13+1*Materials!$J$8 -> 400 | F39: =(D39-E39)-(D39)*0.03 -> -400 | G39: =IF(E39>0,F39/E39,"N/A") -> -1 | I39: Overkill | J39: Nano-Optic Response Implant | L39: =2*Materials!$E$10+4*Materials!$E$11+2*Materials!$E$12+2*Materials!$E$13+1*Materials!$J$8 -> 400 | M39: =(K39-L39)-(K39)*0.03 -> -400 | N39: =IF(L39>0,M39/L39,"N/A") -> -1 | P39: Overkill | Q39: Nano-Optic Rejuvenation System | S39: =2*Materials!$E$10+4*Materials!$E$11+2*Materials!$E$12+2*Materials!$E$13+1*Materials!$J$8 -> 400 | T39: =(R39-S39)-(R39)*0.03 -> -400 | U39: =IF(S39>0,T39/S39,"N/A") -> -1
B40: Hawkeye | C40: Nano-Optic Reflex Enhancer | E40: =2*Materials!$E$5+4*Materials!$E$10+2*Materials!$E$11+2*Materials!$E$14+1*Materials!$J$8 -> 400 | F40: =(D40-E40)-(D40)*0.03 -> -400 | G40: =IF(E40>0,F40/E40,"N/A") -> -1 | I40: Hawkeye | J40: Nano-Optic Response Implant | L40: =2*Materials!$E$10+4*Materials!$E$11+2*Materials!$E$12+2*Materials!$E$14+1*Materials!$J$8 -> 400 | M40: =(K40-L40)-(K40)*0.03 -> -400 | N40: =IF(L40>0,M40/L40,"N/A") -> -1 | P40: Hawkeye | Q40: Nano-Optic Rejuvenation System | S40: =2*Materials!$E$10+4*Materials!$E$11+2*Materials!$E$12+2*Materials!$E$14+1*Materials!$J$8 -> 400 | T40: =(R40-S40)-(R40)*0.03 -> -400 | U40: =IF(S40>0,T40/S40,"N/A") -> -1
B41: Vehemance | C41: Nano-Optic Reflex Enhancer | E41: =2*Materials!$E$5+4*Materials!$E$10+2*Materials!$E$11+2*Materials!$E$14+1*Materials!$J$8 -> 400 | F41: =(D41-E41)-(D41)*0.03 -> -400 | G41: =IF(E41>0,F41/E41,"N/A") -> -1 | I41: Vehemance | J41: Nano-Optic Response Implant | L41: =2*Materials!$E$10+4*Materials!$E$11+2*Materials!$E$12+2*Materials!$E$14+1*Materials!$J$8 -> 400 | M41: =(K41-L41)-(K41)*0.03 -> -400 | N41: =IF(L41>0,M41/L41,"N/A") -> -1 | P41: Vehemance | Q41: Nano-Optic Rejuvenation System | S41: =2*Materials!$E$10+4*Materials!$E$11+2*Materials!$E$12+2*Materials!$E$14+1*Materials!$J$8 -> 400 | T41: =(R41-S41)-(R41)*0.03 -> -400 | U41: =IF(S41>0,T41/S41,"N/A") -> -1
B42: Commander | C42: Nano-Optic Reflex Enhancer | E42: =2*Materials!$E$5+4*Materials!$E$10+2*Materials!$E$11+2*Materials!$E$14+1*Materials!$J$8 -> 400 | F42: =(D42-E42)-(D42)*0.03 -> -400 | G42: =IF(E42>0,F42/E42,"N/A") -> -1 | I42: Commander | J42: Nano-Optic Response Implant | L42: =2*Materials!$E$10+4*Materials!$E$11+2*Materials!$E$12+2*Materials!$E$14+1*Materials!$J$8 -> 400 | M42: =(K42-L42)-(K42)*0.03 -> -400 | N42: =IF(L42>0,M42/L42,"N/A") -> -1 | P42: Commander | Q42: Nano-Optic Rejuvenation System | S42: =2*Materials!$E$10+4*Materials!$E$11+2*Materials!$E$12+2*Materials!$E$14+1*Materials!$J$8 -> 400 | T42: =(R42-S42)-(R42)*0.03 -> -400 | U42: =IF(S42>0,T42/S42,"N/A") -> -1
B43: Expert | C43: Nano-Optic Reflex Enhancer | E43: =2*Materials!$E$5+4*Materials!$E$10+2*Materials!$E$11+2*Materials!$E$14+1*Materials!$J$8 -> 400 | F43: =(D43-E43)-(D43)*0.03 -> -400 | G43: =IF(E43>0,F43/E43,"N/A") -> -1 | I43: Expert | J43: Nano-Optic Response Implant | L43: =2*Materials!$E$10+4*Materials!$E$11+2*Materials!$E$12+2*Materials!$E$14+1*Materials!$J$8 -> 400 | M43: =(K43-L43)-(K43)*0.03 -> -400 | N43: =IF(L43>0,M43/L43,"N/A") -> -1 | P43: Expert | Q43: Nano-Optic Rejuvenation System | S43: =2*Materials!$E$10+4*Materials!$E$11+2*Materials!$E$12+2*Materials!$E$14+1*Materials!$J$8 -> 400 | T43: =(R43-S43)-(R43)*0.03 -> -400 | U43: =IF(S43>0,T43/S43,"N/A") -> -1
B44: Rampart | C44: Nano-Optic Reflex Enhancer | E44: =2*Materials!$E$5+4*Materials!$E$10+2*Materials!$E$11+2*Materials!$E$14+1*Materials!$J$8 -> 400 | F44: =(D44-E44)-(D44)*0.03 -> -400 | G44: =IF(E44>0,F44/E44,"N/A") -> -1 | I44: Rampart | J44: Nano-Optic Response Implant | L44: =2*Materials!$E$10+4*Materials!$E$11+2*Materials!$E$12+2*Materials!$E$14+1*Materials!$J$8 -> 400 | M44: =(K44-L44)-(K44)*0.03 -> -400 | N44: =IF(L44>0,M44/L44,"N/A") -> -1 | P44: Rampart | Q44: Nano-Optic Rejuvenation System | S44: =2*Materials!$E$10+4*Materials!$E$11+2*Materials!$E$12+2*Materials!$E$14+1*Materials!$J$8 -> 400 | T44: =(R44-S44)-(R44)*0.03 -> -400 | U44: =IF(S44>0,T44/S44,"N/A") -> -1
B45: Redoubt | C45: Nano-Optic Reflex Enhancer | E45: =2*Materials!$E$5+4*Materials!$E$10+2*Materials!$E$11+2*Materials!$E$13+1*Materials!$J$8 -> 400 | F45: =(D45-E45)-(D45)*0.03 -> -400 | G45: =IF(E45>0,F45/E45,"N/A") -> -1 | I45: Redoubt | J45: Nano-Optic Response Implant | L45: =2*Materials!$E$10+4*Materials!$E$11+2*Materials!$E$12+2*Materials!$E$13+1*Materials!$J$8 -> 400 | M45: =(K45-L45)-(K45)*0.03 -> -400 | N45: =IF(L45>0,M45/L45,"N/A") -> -1 | P45: Redoubt | Q45: Nano-Optic Rejuvenation System | S45: =2*Materials!$E$10+4*Materials!$E$11+2*Materials!$E$12+2*Materials!$E$13+1*Materials!$J$8 -> 400 | T45: =(R45-S45)-(R45)*0.03 -> -400 | U45: =IF(S45>0,T45/S45,"N/A") -> -1
...

Sheet Implants by bonus
B2: Critical | J2: Overkill | R2: Redoubt
D5: Price | E5: Value | F5: Profit | G5: ROI | L5: Price | M5: Value | N5: Profit | O5: ROI | T5: Price | U5: Value | V5: Profit | W5: ROI
B6: Fervor | C6: Nano-Optic Awareness System | E6: =2*Materials!$E$5+4*Materials!$E$10+2*Materials!$E$11+2*Materials!$E$14+1*Materials!$J$8 -> 400 | F6: =(D6-E6)-(D6)*0.03 -> -400 | G6: =IF(E6>0,F6/E6,"N/A") -> -1 | J6: Hawkeye | K6: Nano-Optic Awareness System | M6: =2*Materials!$E$5+4*Materials!$E$10+2*Materials!$E$11+2*Materials!$E$14+1*Materials!$J$8 -> 400 | N6: =(L6-M6)-(L6)*0.03 -> -400 | O6: =IF(M6>0,N6/M6,"N/A") -> -1 | R6: Exactitude | S6: Nano-Optic Awareness System | U6: =2*Materials!$E$5+4*Materials!$E$10+2*Materials!$E$11+2*Materials!$E$14+1*Materials!$J$8 -> 400 | V6: =(T6-U6)-(T6)*0.03 -> -400 | W6: =IF(U6>0,V6/U6,"N/A") -> -1
C7: Nano-Optic Cardio System | E7: =2*Materials!$E$10+4*Materials!$E$11+2*Materials!$E$12+2*Materials!$E$14+1*Materials!$J$8 -> 400 | F7: =(D7-E7)-(D7)*0.03 -> -400 | G7: =IF(E7>0,F7/E7,"N/A") -> -1 | K7: Nano-Optic Cardio System | M7: =2*Materials!$E$10+4*Materials!$E$11+2*Materials!$E$12+2*Materials!$E$14+1*Materials!$J$8 -> 400 | N7: =(L7-M7)-(L7)*0.03 -> -400 | O7: =IF(M7>0,N7/M7,"N/A") -> -1 | S7: Nano-Optic Cardio System | U7: =2*Materials!$E$10+4*Materials!$E$11+2*Materials!$E$12+2*Materials!$E$14+1*Materials!$J$8 -> 400 | V7: =(T7-U7)-(T7)*0.03 -> -400 | W7: =IF(U7>0,V7/U7,"N/A") -> -1
C8: Nano-Optic Might Package | E8: =2*Materials!$E$5+4*Materials!$E$10+2*Materials!$E$11+2*Materials!$E$14+1*Materials!$J$8 -> 400 | F8: =(D8-E8)-(D8)*0.03 -> -400 | G8: =IF(E8>0,F8/E8,"N/A") -> -1 | K8: Nano-Optic Might Package | M8: =2*Materials!$E$5+4*Materials!$E$10+2*Materials!$E$11+2*Materials!$E$14+1*Materials!$J$8 -> 400 | N8: =(L8-M8)-(L8)*0.03 -> -400 | O8: =IF(M8>0,N8/M8,"N/A") -> -1 | S8: Nano-Optic Might Package | U8: =2*Materials!$E$5+4*Materials!$E$10+2*Materials!$E$11+2*Materials!$E$14+1*Materials!$J$8 -> 400 | V8: =(T8-U8)-(T8)*0.03 -> -400 | W8: =IF(U8>0,V8/U8,"N/A") -> -1
C9: Nano-Optic Reaction Implant | E9: =2*Materials!$E$10+4*Materials!$E$11+2*Materials!$E$12+2*Materials!$E$14+1*Materials!$J$8 -> 400 | F9: =(D9-E9)-(D9)*0.03 -> -400 | G9: =IF(E9>0,F9/E9,"N/A") -> -1 | K9: Nano-Optic Reaction Implant | M9: =2*Materials!$E$10+4*Materials!$E$11+2*Materials!$E$12+2*Materials!$E$14+1*Materials!$J$8 -> 400 | N9: =(L9-M9)-(L9)*0.03 -> -400 | O9: =IF(M9>0,N9/M9,"N/A") -> -1 | S9: Nano-Optic Reaction Implant | U9: =2*Materials!$E$10+4*Materials!$E$11+2*Materials!$E$12+2*Materials!$E$14+1*Materials!$J$8 -> 400 | V9: =(T9-U9)-(T9)*0.03 -> -400 | W9: =IF(U9>0,V9/U9,"N/A") -> -1
C10: Nano-Optic Reflex Enxhancer | E10: =2*Materials!$E$5+4*Materials!$E$10+2*Materials!$E$11+2*Materials!$E$14+1*Materials!$J$8 -> 400 | F10: =(D10-E10)-(D10)*0.03 -> -400 | G10: =IF(E10>0,F10/E10,"N/A") -> -1 | K10: Nano-Optic Reflex Enxhancer | M10: =2*Materials!$E$5+4*Materials!$E$10+2*Materials!$E$11+2*Materials!$E$14+1*Materials!$J$8 -> 400 | N10: =(L10-M10)-(L10)*0.03 -> -400 | O10: =IF(M10>0,N10/M10,"N/A") -> -1 | S10: Nano-Optic Reflex Enxhancer | U10: =2*Materials!$E$5+4*Materials!$E$10+2*Materials!$E$11+2*Materials!$E$14+1*Materials!$J$8 -> 400 | V10: =(T10-U10)-(T10)*0.03 -> -400 | W10: =IF(U10>0,V10/U10,"N/A") -> -1
C11: Nano-Optic Rejuvenation System | E11: =2*Materials!$E$10+4*Materials!$E$11+2*Materials!$E$12+2*Materials!$E$14+1*Materials!$J$8 -> 400 | F11: =(D11-E11)-(D11)*0.03 -> -400 | G11: =IF(E11>0,F11/E11,"N/A") -> -1 | K11: Nano-Optic Rejuvenation System | M11: =2*Materials!$E$10+4*Materials!$E$11+2*Materials!$E$12+2*Materials!$E$14+1*Materials!$J$8 -> 400 | N11: =(L11-M11)-(L11)*0.03 -> -400 | O11: =IF(M11>0,N11/M11,"N/A") -> -1 | S11: Nano-Optic Rejuvenation System | U11: =2*Materials!$E$10+4*Materials!$E$11+2*Materials!$E$12+2*Materials!$E$14+1*Materials!$J$8 -> 400 | V11: =(T11-U11)-(T11)*0.03 -> -400 | W11: =IF(U11>0,V11/U11,"N/A") -> -1
C12: Nano-Optic Resistance Implant | E12: =2*Materials!$E$10+4*Materials!$E$11+2*Materials!$E$12+2*Materials!$E$14+1*Materials!$J$8 -> 400 | F12: =(D12-E12)-(D12)*0.03 -> -400 | G12: =IF(E12>0,F12/E12,"N/A") -> -1 | K12: Nano-Optic Resistance Implant | M12: =2*Materials!$E$10+4*Materials!$E$11+2*Materials!$E$12+2*Materials!$E$14+1*Materials!$J$8 -> 400 | N12: =(L12-M12)-(L12)*0.03 -> -400 | O12: =IF(M12>0,N12/M12,"N/A") -> -1 | S12: Nano-Optic Resistance Implant | U12: =2*Materials!$E$10+4*Materials!$E$11+2*Materials!$E$12+2*Materials!$E$14+1*Materials!$J$8 -> 400 | V12: =(T12-U12)-(T12)*0.03 -> -400 | W12: =IF(U12>0,V12/U12,"N/A") -> -1
C13: Nano-Optic Resolve System | E13: =2*Materials!$E$5+4*Materials!$E$10+2*Materials!$E$11+2*Materials!$E$14+1*Materials!$J$8 -> 400 | F13: =(D13-E13)-(D13)*0.03 -> -400 | G13: =IF(E13>0,F13/E13,"N/A") -> -1 | K13: Nano-Optic Resolve System | M13: =2*Materials!$E$5+4*Materials!$E$10+2*Materials!$E$11+2*Materials!$E$14+1*Materials!$J$8 -> 400 | N13: =(L13-M13)-(L13)*0.03 -> -400 | O13: =IF(M13>0,N13/M13,"N/A") -> -1 | S13: Nano-Optic Resolve System | U13: =2*Materials!$E$5+4*Materials!$E$10+2*Materials!$E$11+2*Materials!$E$14+1*Materials!$J$8 -> 400 | V13: =(T13-U13)-(T13)*0.03 -> -400 | W13: =IF(U13>0,V13/U13,"N/A") -> -1
C14: Nano-Optic Response System | E14: =2*Materials!$E$10+4*Materials!$E$11+2*Materials!$E$12+2*Materials!$E$14+1*Materials!$J$8 -> 400 | F14: =(D14-E14)-(D14)*0.03 -> -400 | G14: =IF(E14>0,F14/E14,"N/A") -> -1 | K14: Nano-Optic Response System | M14: =2*Materials!$E$10+4*Materials!$E$11+2*Materials!$E$12+2*Materials!$E$14+1*Materials!$J$8 -> 400 | N14: =(L14-M14)-(L14)*0.03 -> -400 | O14: =IF(M14>0,N14/M14,"N/A") -> -1 | S14: Nano-Optic Response System | U14: =2*Materials!$E$10+4*Materials!$E$11+2*Materials!$E$12+2*Materials!$E$14+1*Materials!$J$8 -> 400 | V14: =(T14-U14)-(T14)*0.03 -> -400 | W14: =IF(U14>0,V14/U14,"N/A") -> -1
C15: Nano-Optic Skill Package | E15: =2*Materials!$E$5+4*Materials!$E$10+2*Materials!$E$11+2*Materials!$E$14+1*Materials!$J$8 -> 400 | F15: =(D15-E15)-(D15)*0.03 -> -400 | G15: =IF(E15>0,F15/E15,"N/A") -> -1 | K15: Nano-Optic Skill Package | M15: =2*Materials!$E$5+4*Materials!$E$10+2*Materials!$E$11+2*Materials!$E$14+1*Materials!$J$8 -> 400 | N15: =(L15-M15)-(L15)*0.03 -> -400 | O15: =IF(M15>0,N15/M15,"N/A") -> -1 | S15: Nano-Optic Skill Package | U15: =2*Materials!$E$5+4*Materials!$E$10+2*Materials!$E$11+2*Materials!$E$14+1*Materials!$J$8 -> 400 | V15: =(T15-U15)-(T15)*0.03 -> -400 | W15: =IF(U15>0,V15/U15,"N/A") -> -1
B16: Supremacy | C16: Nano-Optic Awareness System | E16: =2*Materials!$E$5+4*Materials!$E$10+2*Materials!$E$11+2*Materials!$E$14+1*Materials!$J$8 -> 400 | F16: =(D16-E16)-(D16)*0.03 -> -400 | G16: =IF(E16>0,F16/E16,"N/A") -> -1 | J16: Vehemance | K16: Nano-Optic Awareness System | M16: =2*Materials!$E$5+4*Materials!$E$10+2*Materials!$E$11+2*Materials!$E$14+1*Materials!$J$8 -> 400 | N16: =(L16-M16)-(L16)*0.03 -> -400 | O16: =IF(M16>0,N16/M16,"N/A") -> -1 | R16: General | S16: Nano-Optic Awareness System | U16: =2*Materials!$E$5+4*Materials!$E$10+2*Materials!$E$11+2*Materials!$E$14+1*Materials!$J$8 -> 400 | V16: =(T16-U16)-(T16)*0.03 -> -400 | W16: =IF(U16>0,V16/U16,"N/A") -> -1
C17: Nano-Optic Cardio System | E17: =2*Materials!$E$10+4*Materials!$E$11+2*Materials!$E$12+2*Materials!$E$14+1*Materials!$J$8 -> 400 | F17: =(D17-E17)-(D17)*0.03 -> -400 | G17: =IF(E17>0,F17/E17,"N/A") -> -1 | K17: Nano-Optic Cardio System | M17: =2*Materials!$E$10+4*Materials!$E$11+2*Materials!$E$12+2*Materials!$E$14+1*Materials!$J$8 -> 400 | N17: =(L17-M17)-(L17)*0.03 -> -400 | O17: =IF(M17>0,N17/M17,"N/A") -> -1 | S17: Nano-Optic Cardio System | U17: =2*Materials!$E$10+4*Materials!$E$11+2*Materials!$E$12+2*Materials!$E$14+1*Materials!$J$8 -> 400 | V17: =(T17-U17)-(T17)*0.03 -> -400 | W17: =IF(U17>0,V17/U17,"N/A") -> -1
C18: Nano-Optic Might Package | E18: =2*Materials!$E$5+4*Materials!$E$10+2*Materials!$E$11+2*Materials!$E$14+1*Materials!$J$8 -> 400 | F18: =(D18-E18)-(D18)*0.03 -> -400 | G18: =IF(E18>0,F18/E18,"N/A") -> -1 | K18: Nano-Optic Might Package | M18: =2*Materials!$E$5+4*Materials!$E$10+2*Materials!$E$11+2*Materials!$E$14+1*Materials!$J$8 -> 400 | N18: =(L18-M18)-(L18)*0.03 -> -400 | O18: =IF(M18>0,N18/M18,"N/A") -> -1 | S18: Nano-Optic Might Package | U18: =2*Materials!$E$5+4*Materials!$E$10+2*Materials!$E$11+2*Materials!$E$14+1*Materials!$J$8 -> 400 | V18: =(T18-U18)-(T18)*0.03 -> -400 | W18: =IF(U18>0,V18/U18,"N/A") -> -1
C19: Nano-Optic Reaction Implant | E19: =2*Materials!$E$10+4*Materials!$E$11+2*Materials!$E$12+2*Materials!$E$14+1*Materials!$J$8 -> 400 | F19: =(D19-E19)-(D19)*0.03 -> -400 | G19: =IF(E19>0,F19/E19,"N/A") -> -1 | K19: Nano-Optic Reaction Implant | M19: =2*Materials!$E$10+4*Materials!$E$11+2*Materials!$E$12+2*Materials!$E$14+1*Materials!$J$8 -> 400 | N19: =(L19-M19)-(L19)*0.03 -> -400 | O19: =IF(M19>0,N19/M19,"N/A") -> -1 | S19: Nano-Optic Reaction Implant | U19: =2*Materials!$E$10+4*Materials!$E$11+2*Materials!$E$12+2*Materials!$E$14+1*Materials!$J$8 -> 400 | V19: =(T19-U19)-(T19)*0.03 -> -400 | W19: =IF(U19>0,V19/U19,"N/A") -> -1
C20: Nano-Optic Reflex Enxhancer | E20: =2*Materials!$E$5+4*Materials!$E$10+2*Materials!$E$11+2*Materials!$E$14+1*Materials!$J$8 -> 400 | F20: =(D20-E20)-(D20)*0.03 -> -400 | G20: =IF(E20>0,F20/E20,"N/A") -> -1 | K20: Nano-Optic Reflex Enxhancer | M20: =2*Materials!$E$5+4*Materials!$E$10+2*Materials!$E$11+2*Materials!$E$14+1*Materials!$J$8 -> 400 | N20: =(L20-M20)-(L20)*0.03 -> -400 | O20: =IF(M20>0,N20/M20,"N/A") -> -1 | S20: Nano-Optic Reflex Enxhancer | U20: =2*Materials!$E$5+4*Materials!$E$10+2*Materials!$E$11+2*Materials!$E$14+1*Materials!$J$8 -> 400 | V20: =(T20-U20)-(T20)*0.03 -> -400 | W20: =IF(U20>0,V20/U20,"N/A") -> -1
C21: Nano-Optic Rejuvenation System | E21: =2*Materials!$E$10+4*Materials!$E$11+2*Materials!$E$12+2*Materials!$E$14+1*Materials!$J$8 -> 400 | F21: =(D21-E21)-(D21)*0.03 -> -400 | G21: =IF(E21>0,F21/E21,"N/A") -> -1 | K21: Nano-Optic Rejuvenation System | M21: =2*Materials!$E$10+4*Materials!$E$11+2*Materials!$E$12+2*Materials!$E$14+1*Materials!$J$8 -> 400 | N21: =(L21-M21)-(L21)*0.03 -> -400 | O21: =IF(M21>0,N21/M21,"N/A") -> -1 | S21: Nano-Optic Rejuvenation System | U21: =2*Materials!$E$10+4*Materials!$E$11+2*Materials!$E$12+2*Materials!$E$14+1*Materials!$J$8 -> 400 | V21: =(T21-U21)-(T21)*0.03 -> -400 | W21: =IF(U21>0,V21/U21,"N/A") -> -1
C22: Nano-Optic Resistance Implant | E22: =2*Materials!$E$10+4*Materials!$E$11+2*Materials!$E$12+2*Materials!$E$14+1*Materials!$J$8 -> 400 | F22: =(D22-E22)-(D22)*0.03 -> -400 | G22: =IF(E22>0,F22/E22,"N/A") -> -1 | K22: Nano-Optic Resistance Implant | M22: =2*Materials!$E$10+4*Materials!$E$11+2*Materials!$E$12+2*Materials!$E$14+1*Materials!$J$8 -> 400 | N22: =(L22-M22)-(L22)*0.03 -> -400 | O22: =IF(M22>0,N22/M22,"N/A") -> -1 | S22: Nano-Optic Resistance Implant | U22: =2*Materials!$E$10+4*Materials!$E$11+2*Materials!$E$12+2*Materials!$E$14+1*Materials!$J$8 -> 400 | V22: =(T22-U22)-(T22)*0.03 -> -400 | W22: =IF(U22>0,V22/U22,"N/A") -> -1
C23: Nano-Optic Resolve System | E23: =2*Materials!$E$5+4*Materials!$E$10+2*Materials!$E$11+2*Materials!$E$14+1*Materials!$J$8 -> 400 | F23: =(D23-E23)-(D23)*0.03 -> -400 | G23: =IF(E23>0,F23/E23,"N/A") -> -1 | K23: Nano-Optic Resolve System | M23: =2*Materials!$E$5+4*Materials!$E$10+2*Materials!$E$11+2*Materials!$E$14+1*Materials!$J$8 -> 400 | N23: =(L23-M23)-(L23)*0.03 -> -400 | O23: =IF(M23>0,N23/M23,"N/A") -> -1 | S23: Nano-Optic Resolve System | U23: =2*Materials!$E$5+4*Materials!$E$10+2*Materials!$E$11+2*Materials!$E$14+1*Materials!$J$8 -> 400 | V23: =(T23-U23)-(T23)*0.03 -> -400 | W23: =IF(U23>0,V23/U23,"N/A") -> -1
C24: Nano-Optic Response System | E24: =2*Materials!$E$10+4*Materials!$E$11+2*Materials!$E$12+2*Materials!$E$14+1*Materials!$J$8 -> 400 | F24: =(D24-E24)-(D24)*0.03 -> -400 | G24: =IF(E24>0,F24/E24,"N/A") -> -1 | K24: Nano-Optic Response System | M24: =2*Materials!$E$10+4*Materials!$E$11+2*Materials!$E$12+2*Materials!$E$14+1*Materials!$J$8 -> 400 | N24: =(L24-M24)-(L24)*0.03 -> -400 | O24: =IF(M24>0,N24/M24,"N/A") -> -1 | S24: Nano-Optic Response System | U24: =2*Materials!$E$10+4*Materials!$E$11+2*Materials!$E$12+2*Materials!$E$14+1*Materials!$J$8 -> 400 | V24: =(T24-U24)-(T24)*0.03 -> -400 | W24: =IF(U24>0,V24/U24,"N/A") -> -1
C25: Nano-Optic Skill Package | E25: =2*Materials!$E$5+4*Materials!$E$10+2*Materials!$E$11+2*Materials!$E$14+1*Materials!$J$8 -> 400 | F25: =(D25-E25)-(D25)*0.03 -> -400 | G25: =IF(E25>0,F25/E25,"N/A") -> -1 | K25: Nano-Optic Skill Package | M25: =2*Materials!$E$5+4*Materials!$E$10+2*Materials!$E$11+2*Materials!$E$14+1*Materials!$J$8 -> 400 | N25: =(L25-M25)-(L25)*0.03 -> -400 | O25: =IF(M25>0,N25/M25,"N/A") -> -1 | S25: Nano-Optic Skill Package | U25: =2*Materials!$E$5+4*Materials!$E$10+2*Materials!$E$11+2*Materials!$E$14+1*Materials!$J$8 -> 400 | V25: =(T25-U25)-(T25)*0.03 -> -400 | W25: =IF(U25>0,V25/U25,"N/A") -> -1
B26: Leadership | C26: Nano-Optic Awareness System | E26: =2*Materials!$E$5+4*Materials!$E$10+2*Materials!$E$11+2*Materials!$E$14+1*Materials!$J$8 -> 400 | F26: =(D26-E26)-(D26)*0.03 -> -400 | G26: =IF(E26>0,F26/E26,"N/A") -> -1 | J26: Commander | K26: Nano-Optic Awareness System | M26: =2*Materials!$E$5+4*Materials!$E$10+2*Materials!$E$11+2*Materials!$E$14+1*Materials!$J$8 -> 400 | N26: =(L26-M26)-(L26)*0.03 -> -400 | O26: =IF(M26>0,N26/M26,"N/A") -> -1 | R26: Anti-Armor | S26: Nano-Optic Awareness System | U26: =2*Materials!$E$5+4*Materials!$E$10+2*Materials!$E$11+2*Materials!$E$14+1*Materials!$J$8 -> 400 | V26: =(T26-U26)-(T26)*0.03 -> -400 | W26: =IF(U26>0,V26/U26,"N/A") -> -1
C27: Nano-Optic Cardio System | E27: =2*Materials!$E$10+4*Materials!$E$11+2*Materials!$E$12+2*Materials!$E$14+1*Materials!$J$8 -> 400 | F27: =(D27-E27)-(D27)*0.03 -> -400 | G27: =IF(E27>0,F27/E27,"N/A") -> -1 | K27: Nano-Optic Cardio System | M27: =2*Materials!$E$10+4*Materials!$E$11+2*Materials!$E$12+2*Materials!$E$14+1*Materials!$J$8 -> 400 | N27: =(L27-M27)-(L27)*0.03 -> -400 | O27: =IF(M27>0,N27/M27,"N/A") -> -1 | S27: Nano-Optic Cardio System | U27: =2*Materials!$E$10+4*Materials!$E$11+2*Materials!$E$12+2*Materials!$E$14+1*Materials!$J$8 -> 400 | V27: =(T27-U27)-(T27)*0.03 -> -400 | W27: =IF(U27>0,V27/U27,"N/A") -> -1
C28: Nano-Optic Might Package | E28: =2*Materials!$E$5+4*Materials!$E$10+2*Materials!$E$11+2*Materials!$E$14+1*Materials!$J$8 -> 400 | F28: =(D28-E28)-(D28)*0.03 -> -400 | G28: =IF(E28>0,F28/E28,"N/A") -> -1 | K28: Nano-Optic Might Package | M28: =2*Materials!$E$5+4*Materials!$E$10+2*Materials!$E$11+2*Materials!$E$14+1*Materials!$J$8 -> 400 | N28: =(L28-M28)-(L28)*0.03 -> -400 | O28: =IF(M28>0,N28/M28,"N/A") -> -1 | S28: Nano-Optic Might Package | U28: =2*Materials!$E$5+4*Materials!$E$10+2*Materials!$E$11+2*Materials!$E$14+1*Materials!$J$8 -> 400 | V28: =(T28-U28)-(T28)*0.03 -> -400 | W28: =IF(U28>0,V28/U28,"N/A") -> -1
C29: Nano-Optic Reaction Implant | E29: =2*Materials!$E$10+4*Materials!$E$11+2*Materials!$E$12+2*Materials!$E$14+1*Materials!$J$8 -> 400 | F29: =(D29-E29)-(D29)*0.03 -> -400 | G29: =IF(E29>0,F29/E29,"N/A") -> -1 | K29: Nano-Optic Reaction Implant | M29: =2*Materials!$E$10+4*Materials!$E$11+2*Materials!$E$12+2*Materials!$E$14+1*Materials!$J$8 -> 400 | N29: =(L29-M29)-(L29)*0.03 -> -400 | O29: =IF(M29>0,N29/M29,"N/A") -> -1 | S29: Nano-Optic Reaction Implant | U29: =2*Materials!$E$10+4*Materials!$E$11+2*Materials!$E$12+2*Materials!$E$14+1*Materials!$J$8 -> 400 | V29: =(T29-U29)-(T29)*0.03 -> -400 | W29: =IF(U29>0,V29/U29,"N/A") -> -1
C30: Nano-Optic Reflex Enxhancer | E30: =2*Materials!$E$5+4*Materials!$E$10+2*Materials!$E$11+2*Materials!$E$14+1*Materials!$J$8 -> 400 | F30: =(D30-E30)-(D30)*0.03 -> -400 | G30: =IF(E30>0,F30/E30,"N/A") -> -1 | K30: Nano-Optic Reflex Enxhancer | M30: =2*Materials!$E$5+4*Materials!$E$10+2*Materials!$E$11+2*Materials!$E$14+1*Materials!$J$8 -> 400 | N30: =(L30-M30)-(L30)*0.03 -> -400 | O30: =IF(M30>0,N30/M30,"N/A") -> -1 | S30: Nano-Optic Reflex Enxhancer | U30: =2*Materials!$E$5+4*Materials!$E$10+2*Materials!$E$11+2*Materials!$E$14+1*Materials!$J$8 -> 400 | V30: =(T30-U30)-(T30)*0.03 -> -400 | W30: =IF(U30>0,V30/U30,"N/A") -> -1
C31: Nano-Optic Rejuvenation System | E31: =2*Materials!$E$10+4*Materials!$E$11+2*Materials!$E$12+2*Materials!$E$14+1*Materials!$J$8 -> 400 | F31: =(D31-E31)-(D31)*0.03 -> -400 | G31: =IF(E31>0,F31/E31,"N/A") -> -1 | K31: Nano-Optic Rejuvenation System | M31: =2*Materials!$E$10+4*Materials!$E$11+2*Materials!$E$12+2*Materials!$E$14+1*Materials!$J$8 -> 400 | N31: =(L31-M31)-(L31)*0.03 -> -400 | O31: =IF(M31>0,N31/M31,"N/A") -> -1 | S31: Nano-Optic Rejuvenation System | U31: =2*Materials!$E$10+4*Materials!$E$11+2*Materials!$E$12+2*Materials!$E$14+1*Materials!$J$8 -> 400 | V31: =(T31-U31)-(T31)*0.03 -> -400 | W31: =IF(U31>0,V31/U31,"N/A") -> -1
C32: Nano-Optic Resistance Implant | E32: =2*Materials!$E$10+4*Materials!$E$11+2*Materials!$E$12+2*Materials!$E$14+1*Materials!$J$8 -> 400 | F32: =(D32-E32)-(D32)*0.03 -> -400 | G32: =IF(E32>0,F32/E32,"N/A") -> -1 | K32: Nano-Optic Resistance Implant | M32: =2*Materials!$E$10+4*Materials!$E$11+2*Materials!$E$12+2*Materials!$E$14+1*Materials!$J$8 -> 400 | N32: =(L32-M32)-(L32)*0.03 -> -400 | O32: =IF(M32>0,N32/M32,"N/A") -> -1 | S32: Nano-Optic Resistance Implant | U32: =2*Materials!$E$10+4*Materials!$E$11+2*Materials!$E$12+2*Materials!$E$14+1*Materials!$J$8 -> 400 | V32: =(T32-U32)-(T32)*0.03 -> -400 | W32: =IF(U32>0,V32/U32,"N/A") -> -1
C33: Nano-Optic Resolve System | E33: =2*Materials!$E$5+4*Materials!$E$10+2*Materials!$E$11+2*Materials!$E$14+1*Materials!$J$8 -> 400 | F33: =(D33-E33)-(D33)*0.03 -> -400 | G33: =IF(E33>0,F33/E33,"N/A") -> -1 | K33: Nano-Optic Resolve System | M33: =2*Materials!$E$5+4*Materials!$E$10+2*Materials!$E$11+2*Materials!$E$14+1*Materials!$J$8 -> 400 | N33: =(L33-M33)-(L33)*0.03 -> -400 | O33: =IF(M33>0,N33/M33,"N/A") -> -1 | S33: Nano-Optic Resolve System | U33: =2*Materials!$E$5+4*Materials!$E$10+2*Materials!$E$11+2*Materials!$E$14+1*Materials!$J$8 -> 400 | V33: =(T33-U33)-(T33)*0.03 -> -400 | W33: =IF(U33>0,V33/U33,"N/A") -> -1
C34: Nano-Optic Response System | E34: =2*Materials!$E$10+4*Materials!$E$11+2*Materials!$E$12+2*Materials!$E$14+1*Materials!$J$8 -> 400 | F34: =(D34-E34)-(D34)*0.03 -> -400 | G34: =IF(E34>0,F34/E34,"N/A") -> -1 | K34: Nano-Optic Response System | M34: =2*Materials!$E$10+4*Materials!$E$11+2*Materials!$E$12+2*Materials!$E$14+1*Materials!$J$8 -> 400 | N34: =(L34-M34)-(L34)*0.03 -> -400 | O34: =IF(M34>0,N34/M34,"N/A") -> -1 | S34: Nano-Optic Response System | U34: =2*Materials!$E$10+4*Materials!$E$11+2*Materials!$E$12+2*Materials!$E$14+1*Materials!$J$8 -> 400 | V34: =(T34-U34)-(T34)*0.03 -> -400 | W34: =IF(U34>0,V34/U34,"N/A") -> -1
C35: Nano-Optic Skill Package | E35: =2*Materials!$E$5+4*Materials!$E$10+2*Materials!$E$11+2*Materials!$E$14+1*Materials!$J$8 -> 400 | F35: =(D35-E35)-(D35)*0.03 -> -400 | G35: =IF(E35>0,F35/E35,"N/A") -> -1 | K35: Nano-Optic Skill Package | M35: =2*Materials!$E$5+4*Materials!$E$10+2*Materials!$E$11+2*Materials!$E$14+1*Materials!$J$8 -> 400 | N35: =(L35-M35)-(L35)*0.03 -> -400 | O35: =IF(M35>0,N35/M35,"N/A") -> -1 | S35: Nano-Optic Skill Package | U35: =2*Materials!$E$5+4*Materials!$E$10+2*Materials!$E$11+2*Materials!$E$14+1*Materials!$J$8 -> 400 | V35: =(T35-U35)-(T35)*0.03 -> -400 | W35: =IF(U35>0,V35/U35,"N/A") -> -1
B36: Endowment | C36: Nano-Optic Awareness System | E36: =2*Materials!$E$5+4*Materials!$E$10+2*Materials!$E$11+2*Materials!$E$14+1*Materials!$J$8 -> 400 | F36: =(D36-E36)-(D36)*0.03 -> -400 | G36: =IF(E36>0,F36/E36,"N/A") -> -1 | J36: Expert | K36: Nano-Optic Awareness System | M36: =2*Materials!$E$5+4*Materials!$E$10+2*Materials!$E$11+2*Materials!$E$14+1*Materials!$J$8 -> 400 | N36: =(L36-M36)-(L36)*0.03 -> -400 | O36: =IF(M36>0,N36/M36,"N/A") -> -1 | R36: Veracity | S36: Nano-Optic Awareness System | U36: =2*Materials!$E$5+4*Materials!$E$10+2*Materials!$E$11+2*Materials!$E$14+1*Materials!$J$8 -> 400 | V36: =(T36-U36)-(T36)*0.03 -> -400 | W36: =IF(U36>0,V36/U36,"N/A") -> -1
C37: Nano-Optic Cardio System | E37: =2*Materials!$E$10+4*Materials!$E$11+2*Materials!$E$12+2*Materials!$E$14+1*Materials!$J$8 -> 400 | F37: =(D37-E37)-(D37)*0.03 -> -400 | G37: =IF(E37>0,F37/E37,"N/A") -> -1 | K37: Nano-Optic Cardio System | M37: =2*Materials!$E$10+4*Materials!$E$11+2*Materials!$E$12+2*Materials!$E$14+1*Materials!$J$8 -> 400 | N37: =(L37-M37)-(L37)*0.03 -> -400 | O37: =IF(M37>0,N37/M37,"N/A") -> -1 | S37: Nano-Optic Cardio System | U37: =2*Materials!$E$10+4*Materials!$E$11+2*Materials!$E$12+2*Materials!$E$14+1*Materials!$J$8 -> 400 | V37: =(T37-U37)-(T37)*0.03 -> -400 | W37: =IF(U37>0,V37/U37,"N/A") -> -1
C38: Nano-Optic Might Package | E38: =2*Materials!$E$5+4*Materials!$E$10+2*Materials!$E$11+2*Materials!$E$14+1*Materials!$J$8 -> 400 | F38: =(D38-E38)-(D38)*0.03 -> -400 | G38: =IF(E38>0,F38/E38,"N/A") -> -1 | K38: Nano-Optic Might Package | M38: =2*Materials!$E$5+4*Materials!$E$10+2*Materials!$E$11+2*Materials!$E$14+1*Materials!$J$8 -> 400 | N38: =(L38-M38)-(L38)*0.03 -> -400 | O38: =IF(M38>0,N38/M38,"N/A") -> -1 | S38: Nano-Optic Might Package | U38: =2*Materials!$E$5+4*Materials!$E$10+2*Materials!$E$11+2*Materials!$E$14+1*Materials!$J$8 -> 400 | V38: =(T38-U38)-(T38)*0.03 -> -400 | W38: =IF(U38>0,V38/U38,"N/A") -> -1
