Workbook

Sheet Par équipe
E4: Conférence Nord-Est
E5: Cross-country
E6: Saison 2012
E7: FÉMININ
C8: 88 | E8: 89 | G8: 97
B9: Établissement | C9: 8 septembre 2012 | E9: 23 septembre 2012 | G9: 6 octobre 2012 | I9: Total | J9: Rang
C10: Trois-Rivières - 4 km - | E10: Victoriaville - 4 km - | G10: U. Laval - x km -
C11: RÉSULTATS CUMULÉS FÉMININ | E11: RÉSULTATS CUMULÉS FÉMININ | G11: RÉSULTATS CUMULÉS FÉMININ
B12: Ste-Foy | C12: =+Féminin!F10+Féminin!F11+Féminin!F12+Féminin!F16 -> 13 | I12: =C12+E12+G12 -> 13 | J12: 1
B13: Cégep Garneau | C13: =+Féminin!F19+Féminin!F20+Féminin!F25+Féminin!F32 -> 60 | I13: =C13+E13+G13 -> 60 | J13: 2
B14: Victoriaville | C14: =+Féminin!F21+Féminin!F28+Féminin!F31+Féminin!F35 -> 79 | I14: =C14+E14+G14 -> 79 | J14: 3
B15: Trois-Rivières | C15: =+Féminin!F17+Féminin!F18+Féminin!F36+Féminin!F46 -> 81 | I15: =C15+E15+G15 -> 81 | J15: 4
B16: Champlain-Lennoxville | C16: =+Féminin!F27+Féminin!F39+Féminin!F41+Féminin!F42 -> 113 | I16: =C16+E16+G16 -> 113 | J16: 5
B17: Mérici | C17: =+Féminin!F23+Féminin!F34+Féminin!F44+Féminin!F69 -> 134 | I17: =C17+E17+G17 -> 134 | J17: 6
B18: Lévis-Lauzon | C18: =+Féminin!F33+Féminin!F37+Féminin!F43+Féminin!F65 -> 142 | I18: =C18+E18+G18 -> 142 | J18: 7
B19: Shawinigan | C19: =+Féminin!F22+Féminin!F45+Féminin!F63+Féminin!F71 -> 165 | I19: =C19+E19+G19 -> 165 | J19: 8
B20: Notre-Dame-de-Foy | C20: =+Féminin!F29+Féminin!F59+Féminin!F60+Féminin!F62 -> 174 | I20: =C20+E20+G20 -> 174 | J20: 9
B21: Rivière-du-Loup | C21: =+Féminin!F13+Féminin!F57+Féminin!F84+'Par équipe'!C8:D8 -> 215 | I21: =C21+E21+G21 -> 215 | J21: 10
B22: Baie-Comeau | C22: =+Féminin!F14+Féminin!F56+Féminin!F91+'Par équipe'!C8:D8 -> 222 | I22: =C22+E22+G22 -> 222 | J22: 11
B23: Alma | C23: =+Féminin!F15+'Par équipe'!C8:D8+'Par équipe'!C8:D8+'Par équipe'!C8:D8 -> 270 | I23: =C23+E23+G23 -> 270 | J23: 12
B24: St-Hyacinthe | C24: =+Féminin!F49+Féminin!F74+Féminin!F90+'Par équipe'!C8:D8 -> 274 | I24: =C24+E24+G24 -> 274 | J24: 13
B25: St.Lawrence | C25: =+Féminin!F26+'Par équipe'!C8:D8+'Par équipe'!C8:D8+'Par équipe'!C8:D8 -> 281 | I25: =C25+E25+G25 -> 281 | J25: 14
B26: ITA et La Pocatière | C26: =+Féminin!F73+Féminin!F93+Féminin!F94+'Par équipe'!C8:D8 -> 321 | I26: =C26+E26+G26 -> 321 | J26: 15
B27: Chicoutimi | C27: ABS | I27: DIS | J27: DIS
B28: Jonquière | C28: ABS | I28: DIS | J28: DIS
E34: Conférence Nord-Est
E35: Cross-country
E36: Saison 2012
E37: MASCULIN
C38: 99 | F38: 102 | G38: 114
B39: Établissement | C39: 8 septembre 2012 | E39: 23 septembre 2012 | G39: 8 octobre 2012 | I39: Total | J39: Rang
C40: Trois-Rivières - 6 km - | E40: Victoriaville - 8 km - | G40: U. Laval - x km -
C41: RÉSULTATS CUMULÉS MASCULIN | E41: RÉSULTATS CUMULÉS MASCULIN | G41: RÉSULTATS CUMULÉS MASCULIN
B42: Ste-Foy | C42: =+Masculin!F12+Masculin!F14+Masculin!F19+Masculin!F29 -> 38 | I42: =+C42+E42+G42 -> 38 | J42: 1
B43: Trois-Rivières | C43: =+Masculin!F15+Masculin!F20+Masculin!F22+Masculin!F23 -> 44 | I43: =+C43+E43+G43 -> 44 | J43: 2
B44: Victoriaville | C44: =+Masculin!F13+Masculin!F27+Masculin!F32+Masculin!F42 -> 78 | I44: =+C44+E44+G44 -> 78 | J44: 3
B45: Lévis-Lauzon | C45: =+Masculin!F11+Masculin!F28+Masculin!F38+Masculin!F41 -> 82 | I45: =+C45+E45+G45 -> 82 | J45: 4
B46: Alma | C46: =+Masculin!F17+Masculin!F33+Masculin!F36+Masculin!F39 -> 89 | I46: =+C46+E46+G46 -> 89 | J46: 5
B47: Shawinigan | C47: =+Masculin!F21+Masculin!F35+Masculin!F40+Masculin!F48 -> 108 | I47: =+C47+E47+G47 -> 108 | J47: 6
B48: Notre-Dame-de-Foy | C48: =+Masculin!F10+Masculin!F26+Masculin!F37+Masculin!F81 -> 118 | I48: =+C48+E48+G48 -> 118 | J48: 7
...

Sheet Féminin
E2: Conférence Nord-Est
E3: Cross-country
E4: Saison 2012
D6: Référence F : | E6: 0.80416667 | G6: Référence F : | H6: 0
B7: Prénom | C7: Nom | D7: Établissement | E7: 8 septembre 2012 | G7: 23 septembre 2012 | I7: 6 octobre 2012 | K7: Rangs | L7: Rang | M7: Section | N7: Sexe | O7: Éligibilité | P7: Membre | Q7: Commentaires
E8: Trois-Rivières - 4F - | G8: Victoriaville - 4F - | I8: U. Laval - x km - | K8: Cumulés | L8: Final | O8: championnat
E9: Temps | F9: Position | G9: Temps | H9: Position | I9: Temps | J9: Position | O9: provincial | P9: ACSC
B10: Frédérique | C10: Latraverse | D10: CSF | E10: 0.67013889 | F10: 1 | M10: 1 | N10: F | P10: Oui
B11: Caroline | C11: Pomerleau | D11: CSF | E11: 0.73541667 | F11: 2 | M11: 1 | N11: F | P11: Oui
B12: Gabrielle | C12: Saint-Pierre | D12: CSF | E12: 0.7375 | F12: 3 | M12: 1 | N12: F | P12: Oui
B13: Ouellet | C13: Béatrice | D13: RDL | E13: 0.73819444 | F13: 4 | M13: 1 | N13: F | P13: Oui
B14: Turcotte | C14: Isabelle | D14: BCO | E14: 0.76736111 | F14: 5 | M14: 1 | N14: F | P14: Non
B15: Fleury | C15: Catherine | D15: ALM | E15: 0.77152778 | F15: 6 | M15: 1 | N15: F | P15: Oui
B16: Vicky | C16: Tremblay | D16: CSF | E16: 0.77986111 | F16: 7 | M16: 1 | N16: F | P16: Oui
B17: Chloé | C17: Perreault | D17: TRV | E17: 0.78611111 | F17: 8 | M17: 1 | N17: F | P17: Oui
B18: Catherine | C18: Vaillancourt | D18: TRV | E18: 0.78958333 | F18: 9 | M18: 1 | N18: F | P18: Oui
B19: Anne-Marie | C19: Gauthier | D19: FXG | E19: 0.79305556 | F19: 10 | M19: 1 | N19: F | P19: Oui
B20: Vanessa | C20: Charron | D20: FXG | E20: 0.79722222 | F20: 11 | M20: 1 | N20: F | P20: Oui
B21: Richard | C21: Gabrielle | D21: VIC | E21: 0.80208333 | F21: 12 | M21: 1 | N21: F | P21: Oui
... B96: Corine | C96: Béliveau | D96: SHA | E96: 1.1618056 | F96: 87 | M96: 2 | N96: F | P96: Oui
B97: Patricia | C97: Boisvert | D97: STH | E97: ABS | F97: ABS | M97: N/A | N97: F | P97: Non
B98: Florence | C98: Croteau | D98: STH | E98: ABS | F98: ABS | M98: N/A | N98: F | P98: Non
B99: Geneviève | C99: Robidoux (ITA) | D99: STH | E99: ABS | F99: ABS | M99: N/A | N99: F | P99: Non
B100: Julie | C100: Savard | D100: STH | E100: ABS | F100: ABS | M100: N/A | N100: F | P100: Non
B101: Cormier | C101: Sophie | D101: VIC | E101: ABS | F101: ABS | M101: N/A | N101: F | P101: Oui
B102: Wendie | C102: Gervais | D102: SHA | E102: ABS | F102: ABS | M102: N/A | N102: F | P102: Oui
B103: Claudia | C103: Simard | D103: SHA | E103: ABS | F103: ABS | M103: N/A | N103: F | P103: Oui
B104: Adélie | C104: Lebel | D104: SHA | E104: ABS | F104: ABS | M104: N/A | N104: F | P104: Oui
B105: Laurence | C105: Dontigny | D105: SLC | E105: ABS | F105: ABS | M105: N/A | N105: F | P105: Oui
B106: Patricia | C106: Turcotte | D106: SLC | E106: ABS | F106: ABS | M106: N/A | N106: F | P106: Oui
B107: Catherine | C107: Wang | D107: SLC | E107: ABS | F107: ABS | M107: N/A | N107: F | P107: Oui
B108: Larochelle | C108: Virginie | D108: CLL | E108: ABS | F108: ABS | M108: N/A | N108: F | P108: Oui
... B119: Joanie | C119: Langevin | D119: SHA | E119: ABS | F119: ABS | M119: N/A | N119: F | P119: Oui

Sheet Masculin
E2: Conférence Nord-Est
E3: Cross-country
E4: Saison 2012
D5: Référence M : | E5: 1.0847222 | G5: Référence M : | H5: 0
B7: Prénom | C7: Nom | D7: Établissement | E7: 8 septembre 2012 | G7: 23 septembre 2012 | I7: 6 octobre 2012 | K7: Rangs | L7: Rang | M7: Section | N7: Sexe | O7: Éligibilité | P7: Membre | Q7: Commentaires
E8: Trois-Rivières - 6M - | G8: Victoriaville - 8M - | I8: U. Laval - x km - | K8: Cumulés | L8: Final | O8: championnat
E9: Temps | F9: Position | G9: Temps | H9: Position | I9: Temps | J9: Position | O9: provincial | P9: ACSC
B10: Stéphan | C10: St-Martin | D10: NDF | E10: 0.90416667 | F10: 1 | M10: 1 | N10: M | P10: Oui
B11: Keven | C11: Bédard | D11: CLL | E11: 0.93611111 | F11: 2 | M11: 1 | N11: M | P11: Oui
B12: Audet | C12: Nicolas | D12: CSF | E12: 0.93958333 | F12: 3 | M12: 1 | N12: M | P12: Oui
B13: Guillaume | C13: Ouellet | D13: VIC | E13: 0.95416667 | F13: 4 | M13: 1 | N13: M | P13: Oui
B14: Philippe | C14: Brochu | D14: CSF | E14: 0.97083333 | F14: 5 | M14: 1 | N14: M | P14: Oui
B15: Perreault | C15: Dominic | D15: TRV | E15: 0.97222222 | F15: 6 | M15: 1 | N15: M | P15: Oui
B16: Duhamel | C16: Ilrick | D16: FXG | E16: 0.98263889 | F16: 7 | M16: 1 | N16: M | P16: Oui
B17: Samuel | C17: Gaudreault | D17: ALM | E17: 1.0006944 | F17: 8 | M17: 1 | N17: M | P17: Oui
B18: Jason | C18: Argouin | D18: LEN | E18: 1.0041667 | F18: 9 | M18: 1 | N18: M | P18: Non
B19: Jason | C19: Lévesque | D19: CSF | E19: 1.00625 | F19: 10 | M19: 1 | N19: M | P19: Oui
B20: Asselin | C20: Charles | D20: TRV | E20: 1.0083333 | F20: 11 | M20: 1 | N20: M | P20: Oui
B21: Robitaille-Beaumier | C21: Maxim | D21: SHA | E21: 1.0125 | F21: 12 | M21: 1 | N21: M | P21: Oui
... B107: Chandonnet | C107: Samuel | D107: SHA | E107: 1.575 | F107: 98 | M107: 2 | N107: M | P107: Oui
B108: William | C108: Bourney | D108: LEN | E108: ABS | F108: ABS | M108: N/A | N108: M | P108: Non
B109: Carl-Philippe | C109: Rousse | D109: LEN | E109: ABS | F109: ABS | M109: N/A | N109: M | P109: Non
B110: François | C110: Morin | D110: MER | E110: ABS | F110: ABS | M110: N/A | N110: M | P110: Non
B111: Karl | C111: Tucker | D111: MER | E111: ABS | F111: ABS | M111: N/A | N111: M | P111: Non
B112: P. Cormier (ITA) | C112: Alexis | D112: STH | E112: ABS | F112: ABS | M112: N/A | N112: M | P112: Non
B113: Alexandre | C113: Lavigne | D113: CSF | E113: ABS | F113: ABS | M113: N/A | N113: M | P113: Oui
B114: Alexandre | C114: Bussière | D114: CSF | E114: ABS | F114: ABS | M114: N/A | N114: M | P114: Oui
B115: Fecteau | C115: Jean-Christophe | D115: CSF | E115: ABS | F115: ABS | M115: N/A | N115: M | P115: Oui
B116: Croteau Dontigny | C116: Raphael | D116: SHA | E116: ABS | F116: ABS | M116: N/A | N116: M | P116: Oui
B117: Giguère | C117: Marc-Antoine | D117: SHA | E117: ABS | F117: ABS | M117: N/A | N117: M | P117: Oui
B118: Nicolas | C118: Bourgoin | D118: RDL | E118: ABS | F118: ABS | M118: N/A | N118: M | P118: Oui
B119: Beland | C119: Marc-Antoine | D119: SLC | E119: ABS | F119: ABS | M119: N/A | N119: M | P119: Oui
... B132: Auger | C132: Guillaume | D132: TRV | E132: ABS | F132: ABS | M132: N/A | N132: M | P132: Oui
