Workbook

Sheet 1. Start Here
A1: This cost-estimating detector tool has two primary objectives:
A2: 1. Provide an overview of the key issues/considerations and cost elements one needs to consider for a given detector technology to obtain a real-time data feed,
A3: 2. Provide a range of costs for each cost element, as well as overall costs (including Year 1, 5-year life cycle, 10-year life cycle) per mile and for a given segment length.
A5: Development of such a tool requires a myriad of assumptions, clarifications, and user-inputs. These are highlighted throughout the spreadsheet tabs.
A7: The following detector technologies/methods are included in this spreadsheet (names in parentheses refer to worksheet name):
A8: Bluetooth probes ("2A. Bluetooth Probe")
A9: Private-sector GPS fleets ("2B. Private Sector")
A10: Toll tags ("2C. Toll Tags")
A11: Radar point detectors ("2D. Radar")
A12: Dual loop point detectors ("2E. Dual Loops")
A13: Magnetometer point detectors ("2F. Magnetometer")
A14: Video point detectors ("2G. Video")
... A18: These costs are broken out as Year 1 costs, 5-year costs, and 10-year costs.
B19: = yellow cells for all user-entered values
B20: = blue cells for all computed values
A22: The worksheet "3. Summary" provides a table comparison and charts of the results.
A23: The worksheet "4. References" provides a listing of the references (literature and persons) consulted for this detector cost-estimating tool.
A25: Bill Eisele
A26: Texas Transportation Institute
A27: 979-845-8550
A28: bill-eisele@tamu.edu
A29: May 2011
A31: Project Sponsor: Mobility Measures in Urban Transportation FHWA Pooled Fund Study
A32: Pooled Fund Study sponsors include 12 state departments of transportation (California, Colorado, Florida, Kentucky, Maryland, Minnesota, New York, Ohio, Oregon, Texas,
A33: Virginia, Washington) and 2 metropolitan planning organizations (Houston-Galveston Area Council, Maricopa Association of Governments).
A34: This spreadsheet is available at http://mobility.tamu.edu/resources (under "Data Collection and Management")

Sheet 2A. Bluetooth Probe
A1: Bluetooth Cost Estimates
A3: Detector and Corridor Characteristics | D3: Description/notes/assumptions on values:
A4: Segment Length (miles)
A5: Miles= | B5: 20 | D5: Enter the roadway segment length
A6: Detector Spacing (miles)
A7: Low= | B7: 1 | D7: Enter the lower estimate of the detector spacing
A8: High= | B8: 2 | D8: Enter the higher estimate of the detector spacing
A10: Required number of detectors
A11: Low= | B11: =(B5/B8)+1 -> 11 | D11: Computed low estimate of the number of detectors for the segment
A12: High= | B12: =(B5/B7)+1 -> 21 | D12: Computed high estimate of the number of detectors for the segment
A13: Cost Elements
A14: One-time Initial Costs
A15: Initial Capital Cost Per Unit (One-time cost)
A16: Low= | B16: 3500 | D16: Roadside reader (modem, antenna) and software, and traffic data calculation software; assumes available pole for mounting, else have installation cost. Captures both directions of travel.
A17: High= | B17: 5000 | D17: Roadside reader (modem, antenna) and software, and traffic data calculation software; assumes available pole for mounting, else have installation cost. Captures both directions of travel.
A19: Installation Cost Per Unit (One-time cost)
A20: Low= | B20: 200 | D20: 2 hours @ $100/hour.
A21: High= | B21: 400 | D21: 4 hours @ $100/hour.
A23: Integration to Real-Time Map (One-time cost) | D23: This is the cost of taking the incoming data stream and working with a systems integrator to create a real-time map.
A24: Low= | B24: 0 | D24: Default is that this is not included. Low estimate = 450 hours @ $150/hour = $67,500.
A25: High= | B25: 0 | D25: Default is that this is not included. High estimate = 500 hours @ $200/hour (including profit) = $100,000.
A27: Initial Cost Subtotal
A28: Low (per unit) = | B28: =B16+B20+B24 -> 3700
A29: High (per unit) = | B29: =B17+B21+B25 -> 5400
A31: Low (per mile) = | B31: =(B28*B11)/B5 -> 2035
A32: High (per mile) = | B32: =(B29*B12)/B5 -> 5670
A34: Low (for given segment length) = | B34: =B31*B5 -> 40700
A35: High (for given segment length) = | B35: =B32*B5 -> 113400
A37: Yearly On-going Operations and Maintenance Costs
A38: Communication Cost Per Unit Per Year
A39: Low= | B39: 480 | D39: Cellular at about $40/month per unit. Could tie into existing fiber/WiMAX for no cost.
A40: High= | B40: 600 | D40: Cellular at about $50/month per unit. Could tie into existing fiber/WiMAX for no cost.
A42: Power Cost Per Unit Per Year
A43: Low= | B43: 0 | D43: Assumed negligible. Tie into existing power (lighting, signal cabinet or ITS infrastructure). Else solar cost is approximately $800.
A44: High= | B44: 0 | D44: Assumed negligible. Tie into existing power (lighting, signal cabinet or ITS infrastructure). Else solar cost is approximately $800.
A46: Maintenance Cost Per Unit Per Year
A47: Low= | B47: 0 | D47: Includes trouble-shooting power outages. Assumed negligible; else perhaps 2-3 hours/year to check the unit @ $100/hour.
A48: High= | B48: 0 | D48: Includes trouble-shooting power outages. Assumed negligible; else perhaps 4-6 hours/year to check the unit @ $100/hour.
A50: Real-Time Map Maintenance Per Year
A51: Low= | B51: 0 | D51: On-call systems integrator. Perhaps $20,000 on low end.
...

Sheet 2B. Private Sector
A1: Private-Sector Data Cost Estimates
A3: Detector and Corridor Characteristics | D3: Description/notes/assumptions on values:
A4: Segment Length (miles)
A5: Value= | B5: 20 | D5: Enter the roadway segment length
A7: Cost Elements
A8: One-time Initial Costs
A9: Per-mile Cost for Initial Set-up (Year 1 cost only)
A10: Low= | B10: 150 | D10: Cost for private sector to set up TMCs for roadways of interest.
A11: High= | B11: 200 | D11: Cost for private sector to set up TMCs for roadways of interest.
A13: Per-mile Cost to Provide the Data Per Year
A14: Low= | B14: 700 | D14: Cost per mile to obtain data feed.
A15: High= | B15: 800 | D15: Cost per mile to obtain data feed.
A17: Integration to Real-Time Map (One-time Cost) | D17: This is the cost of taking the incoming data stream and working with a systems integrator to create a real-time map.
A18: Low= | B18: 0 | D18: Default is that this is not included. Low estimate = 450 hours @ $150/hour = $67,500.
A19: High= | B19: 0 | D19: Default is that this is not included. High estimate = 500 hours @ $200/hour (including profit) = $100,000.
A21: Real-Time Map Maintenance Per Year
A22: Low= | B22: 0 | D22: On-call systems integrator. Perhaps $20,000 on low end.
A23: High= | B23: 0 | D23: On-call systems integrator. Perhaps $40,000 on high end.
A25: Estimated Total Costs
A26: Year 1 Costs
A27: Low (per mile) = | B27: =B30/B5 -> 850 | D27: Includes initial costs and 1st year O&M.
A28: High (per mile) = | B28: =B31/B5 -> 1000 | D28: Includes initial costs and 1st year O&M.
A30: Low (for given segment length) = | B30: =((B10+B14)*B5)+B18+B22 -> 17000 | D30: Includes initial costs and 1st year O&M.
A31: High (for given segment length) = | B31: =((B11+B15)*B5)+B19+B23 -> 20000 | D31: Includes initial costs and 1st year O&M.
A33: 5-Year Estimated Cost
A34: Low (per mile) = | B34: =B37/B5 -> 3650 | D34: Includes Year 1 cost plus 4 additional years of the data feed.
A35: High (per mile) = | B35: =B38/B5 -> 4200 | D35: Includes Year 1 cost plus 4 additional years of the data feed.
A37: Low (for given segment length) = | B37: =B30+(4*B14*B5) -> 73000 | D37: Includes Year 1 cost plus 4 additional years of the data feed.
A38: High (for given segment length) = | B38: =B31+(4*B15*B5) -> 84000 | D38: Includes Year 1 cost plus 4 additional years of the data feed.
A40: 10-Year Estimated Cost
A41: Low (per mile) = | B41: =B44/B5 -> 7150 | D41: Includes Year 1 cost plus 9 additional years of the data feed.
A42: High (per mile) = | B42: =B45/B5 -> 8200 | D42: Includes Year 1 cost plus 9 additional years of the data feed.
A44: Low (for given segment length) = | B44: =B30+(9*B14*B5) -> 143000 | D44: Includes Year 1 cost plus 9 additional years of the data feed.
A45: High (for given segment length) = | B45: =B31+(9*B15*B5) -> 164000 | D45: Includes Year 1 cost plus 9 additional years of the data feed.
A47: Additional Notes, Assumptions, and Considerations
A48: -Data you have with private sector: 15-minute period average speeds (averaged across 365 days) by traffic message channel (TMC), and sample size; data are not lane-by-lane.
A49: -Will require some verification/monitoring with another technology (e.g., Bluetooth).
A50: -Note: can currently get a basic traveler information map (red-yellow-green) free from Navteq or Inrix [see "4. References" worksheet for websites].

Sheet 2C. Toll Tags
A1: Toll Tag Detector Cost Estimates
A3: Detector and Corridor Characteristics | D3: Description/notes/assumptions on values:
A4: Segment Length (miles)
A5: Value= | B5: 20 | D5: Enter the roadway segment length
A6: Detector Spacing (miles)
A7: Low= | B7: 2 | D7: Enter the lower estimate of the detector spacing
A8: High= | B8: 3 | D8: Enter the higher estimate of the detector spacing
A10: Required number of detectors
A11: Low= | B11: =(B5/B8)+1 -> 7.6666667 | D11: Computed low estimate of the number of detectors for the segment
A12: High= | B12: =(B5/B7)+1 -> 11 | D12: Computed high estimate of the number of detectors for the segment
A13: Cost Elements
A14: One-time Initial Costs
A15: Initial Capital Cost Per Station (One-time Cost)
A16: Low= | B16: 70000 | D16: Includes antenna and field hardware at a station (includes equipment for both directions).
A17: High= | B17: 80000 | D17: Includes antenna and field hardware at a station (includes equipment for both directions).
A19: Installation Cost Per Station (One-time Cost)
A20: Low= | B20: 1600 | D20: 2 persons x 2 directions x 4 hours @ $100/hour. Assume public agency has a bucket truck and commercial license driver so no cost.
A21: High= | B21: 3200 | D21: 2 persons x 2 directions x 8 hours @ $100/hour. Assume public agency has a bucket truck and commercial license driver so no cost.
A23: Traffic Control Cost for Installation (One-time Cost)
A24: Low= | B24: 4000 | D24: $1,000 per lane. Assume 2 lanes closed x 2 directions.
A25: High= | B25: 4000 | D25: $1,000 per lane. Assume 2 lanes closed x 2 directions.
A27: Integration to Real-Time Map (One-time Cost) | D27: This is the cost of taking the incoming data stream and working with a systems integrator to create a real-time map.
A28: Low= | B28: 0 | D28: Default is that this is not included. Low estimate = 450 hours @ $150/hour = $67,500.
A29: High= | B29: 0 | D29: Default is that this is not included. High estimate = 500 hours @ $200/hour (including profit) = $100,000.
A31: Initial Cost Subtotal
A32: Low (per station) = | B32: =B16+B20+B24+B28 -> 75600 | D32: Note: Station includes an antenna/equipment for each direction.
A33: High (per station) = | B33: =B17+B21+B25+B29 -> 87200 | D33: Note: Station includes an antenna/equipment for each direction.
A35: Low (per mile) = | B35: =B38/B5 -> 28980
A36: High (per mile) = | B36: =B39/B5 -> 47960
A38: Low (for given segment length) = | B38: =B32*B11 -> 579600
A39: High (for given segment length) = | B39: =B33*B12 -> 959200
A41: Yearly On-going Operations and Maintenance Costs
A42: Communication Cost Per Station Per Year
A43: Low= | B43: 0 | D43: Tie into existing fiber/landline assumed here.
A44: High= | B44: 0 | D44: Tie into existing fiber/landline assumed here.
A46: Power Cost Per Station Per Year
A47: Low= | B47: 0 | D47: Assumed negligible. Tie into existing power (lighting, signal cabinet or ITS infrastructure).
A48: High= | B48: 0 | D48: Assumed negligible. Tie into existing power (lighting, signal cabinet or ITS infrastructure).
A50: Maintenance Cost for Entire Corridor Length
A51: Low= | B51: =200*2*B5 -> 8000 | D51: Assume contract with private company. $200/directional mile assumed as default for "low". (Rates could be higher for a relatively short corridor like the default here.)
...

Sheet 2D. Radar
A1: Radar Cost Estimates
A3: Detector and Corridor Characteristics | D3: Description/notes/assumptions on values:
A4: Segment Length (miles)
A5: Value= | B5: 20 | D5: Enter the roadway segment length
A6: Detector Spacing (miles)
A7: Low= | B7: 1 | D7: Enter the lower estimate of the detector spacing
A8: High= | B8: 2 | D8: Enter the higher estimate of the detector spacing
A10: Required number of detectors
A11: Low= | B11: =(B5/B8)+1 -> 11 | D11: Computed low estimate of the number of detectors for the segment
A12: High= | B12: =(B5/B7)+1 -> 21 | D12: Computed high estimate of the number of detectors for the segment
A13: Cost Elements
A14: One-time Initial Costs
A15: Initial Capital Cost Per Unit (One-time Cost)
A16: Low= | B16: 5000 | D16: Side-fire hardware that captures both directions of travel.
A17: High= | B17: 8000 | D17: Side-fire hardware that captures both directions of travel.
A19: Pole Installation and Foundation (One-time Cost)
A20: Low= | B20: 0 | D20: If no adequate pole present. Default assumes pole is present so cost is negligible. Else, costs could range from $3,000-$6,000 for 25'-30' pole.
A21: High= | B21: 0 | D21: If no adequate pole present. Default assumes pole is present so cost is negligible. Else, costs could range from $3,000-$6,000 for 25'-30' pole.
A23: Cabinet (One-time Cost)
A24: Low= | B24: 0 | D24: Assume one is present. Else cost could range from $5,000 to $6,000 to install.
A25: High= | B25: 0 | D25: Assume one is present. Else cost could range from $5,000 to $6,000 to install.
A27: Conduit/Cable/Trenching (One-time Cost)
A28: Low= | B28: =(200*7.5)+(150*10) -> 3000 | D28: Wire/coaxial cable (power and communications) @ $7.50/foot. Conduit/trenching at $10/foot for 150'. Assume 200' for pole height to cabinet for wire/cable. Note: any necessary boring would cost $15-$20/foot and none included here.
A29: High= | B29: =(7.5*300)+(10*250) -> 4750 | D29: Wire/coaxial cable (power and communications) @ $7.50/foot. Conduit/trenching at $10/foot for 250'. Assume 300' for pole height to cabinet for wire/cable. Note: any necessary boring would cost $15-$20/foot and none included here.
A31: Installation Cost Per Unit (One-time Cost)
A32: Low= | B32: 400 | D32: 2 people (for safety with bucket truck) for 2 hours @ $100/hour. Assume public agency has a bucket truck and commercial license driver so no cost.
A33: High= | B33: 800 | D33: 2 people (for safety with bucket truck) for 4 hours @ $100/hour. Assume public agency has a bucket truck and commercial license driver so no cost.
A35: Integration to Real-Time Map (One-time Cost) | D35: This is the cost of taking the incoming data stream and working with a systems integrator to create a real-time map.
A36: Low= | B36: 0 | D36: Default is that this is not included. Low estimate = 450 hours @ $150/hour = $67,500.
A37: High= | B37: 0 | D37: Default is that this is not included. High estimate = 500 hours @ $200/hour (including profit) = $100,000.
A39: Initial Cost Subtotal
A40: Low (per unit) = | B40: =B16+B20+B24+B28+B32+B36 -> 8400
A41: High (per unit) = | B41: =B17+B21+B25+B29+B33+B37 -> 13550
A43: Low (per mile) = | B43: =(B40*B11)/B5 -> 4620
A44: High (per mile) = | B44: =(B41*B12)/B5 -> 14227.5
A46: Low (for given segment length) = | B46: =B43*B5 -> 92400
A47: High (for given segment length) = | B47: =B44*B5 -> 284550
A49: Yearly On-going Operations and Maintenance Costs
A50: Communication Cost Per Unit Per Year
A51: Low= | B51: 480 | D51: Tie into existing fiber/landline. Else cellular is about $40/month per unit (assumed in default here).
...

Sheet 2E. Dual Loops
A1: Dual Loop Detectors Cost Estimates
A2: Cost for 12 Loops (6 Lanes)
A4: Detector and Corridor Characteristics | D4: Description/notes/assumptions on default values:
A5: Segment Length (miles)
A6: Value= | B6: 20 | D6: Enter the roadway segment length
A7: Detector Spacing (miles)
A8: Low= | B8: 0.5 | D8: Enter the lower estimate of the detector spacing
A9: High= | B9: 1 | D9: Enter the higher estimate of the detector spacing
A11: Required number of detector stations (includes 12 loops)
A12: Low= | B12: =(B6/B9)+1 -> 21 | D12: Computed low estimate of the number of detectors for the segment
A13: High= | B13: =(B6/B8)+1 -> 41 | D13: Computed high estimate of the number of detectors for the segment
A14: Cost Elements
A15: One-time Initial Costs
A16: Capital and Installation Cost for One Station (One-time Cost)
A17: Saw cut = | B17: 4200 | D17: 50 feet x 12 loops x $7.00/foot (includes wire for loop and to the first pull-box, includes loop sealant)
A18: Conduit from lead-in to pull-box = | B18: 240 | D18: 24 feet x $10.00/foot
A19: Road bore (from pull-box to cabinet) = | B19: 2400 | D19: 160 feet x $15.00/foot
A20: 4 Pull boxes--2 on each side of the road = | B20: 3200 | D20: $800 each x 4
A21: Conduit from pull-box to pull-box = | B21: 3200 | D21: 160 feet x 2 sides of the road x $10.00/foot
A22: Wire (2 conductor shielded) from pull-box to pull-box = | B22: 288 | D22: 160 feet x 12 loops x $0.15/foot
A23: Wire (pull-box to the cabinet) = | B23: 27 | D23: 15 feet x 12 loops x $0.15/foot
A24: Electronics in the cabinet = | B24: 1200 | D24: $200/lane
A25: Traffic control = | B25: 6000 | D25: $1000/lane x 6 lanes
A27: Total Capital and Installation Cost = | B27: =SUM(B17:B25) -> 20755
A29: Margin of error in capital and installation cost = | B29: 0.1 | D29: Assumed 10% margin of error in capital cost estimates.
A31: Low= | B31: =B27 - (B27*B29) -> 18679.5 | D31: = (Total Capital and Installation Cost) - margin of error
A32: High= | B32: =B27+(B27*B29) -> 22830.5 | D32: = (Total Capital and Installation Cost) + margin of error
A34: Installation Cost (Labor) for 12-Loop Station (One-time Cost)
A35: Low= | B35: 800 | D35: 2 people for 4 hours @ $100/hour. Assumes cabinet is present and does not require installation.
A36: High= | B36: 1600 | D36: 2 people for 8 hours @ $100/hour. Assumes cabinet is present and does not require installation.
A38: Integration to Real-Time Map (One-time Cost) | D38: This is the cost of taking the incoming data stream and working with a systems integrator to create a real-time map.
A39: Low= | B39: 0 | D39: Default is that this is not included. Low estimate = 450 hours @ $150/hour = $67,500.
A40: High= | B40: 0 | D40: Default is that this is not included. High estimate = 500 hours @ $200/hour (including profit) = $100,000.
A42: Initial Cost Subtotal
A43: Low (per station) = | B43: =B31+B35+B39 -> 19479.5
A44: High (per station) = | B44: =B32+B36+B40 -> 24430.5
A46: Low (per mile) = | B46: =(B43*B12)/B6 -> 20453.475
A47: High (per mile) = | B47: =(B44*B13)/B6 -> 50082.525
A49: Low (for given segment length) = | B49: =B46*B6 -> 409069.5
A50: High (for given segment length) = | B50: =B47*B6 -> 1001650.5
...

Sheet 2F. Magnetometer
A1: Magnetometer Detector Cost Estimates
A2: (Assumed 6-Lane Facility)
A4: Detector and Corridor Characteristics | D4: Description/notes/assumptions on values:
A5: Segment Length (miles)
A6: Value= | B6: 20 | D6: Enter the roadway segment length
A7: Detector Spacing (miles)
A8: Low= | B8: 0.5 | D8: Enter the lower estimate of the detector spacing
A9: High= | B9: 1 | D9: Enter the higher estimate of the detector spacing
A11: Required number of detector stations
A12: Low= | B12: =(B6/B9)+1 -> 21 | D12: Computed low estimate of the number of detector stations for the segment. Each "station" includes 12 magnetometers.
A13: High= | B13: =(B6/B8)+1 -> 41 | D13: Computed high estimate of the number of detector stations for the segment. Each "station" includes 12 magnetometers.
A14: Cost Elements
A15: One-time Initial Costs
A16: Initial Capital Cost Per Unit (One-time Cost)
A17: Low= | B17: 8800 | D17: [($400 each x 2 per lane) x 6 lanes ] + [1 Access Point (AP) communication device that "listens" to detectors ($3,000)] + [$1,000 for data store]
A18: High= | B18: 10000 | D18: [($500 each x 2 per lane) x 6 lanes ] + [1 Access Point (AP) communication device that "listens" to detectors ($3,000)] + [$1,000 for data store]
A20: Cabinet (One-time Cost)
A21: Low= | B21: 0 | D21: Assume one is present. Else cost could range from $5,000 to $6,000 to install.
A22: High= | B22: 0 | D22: Assume one is present. Else cost could range from $5,000 to $6,000 to install.
A24: Installation Cost Per Unit (One-time Cost)
A25: Low= | B25: 700 | D25: 2 persons x 3 hours @ $100/hour. Core, place, epoxy ($100) in place.
A26: High= | B26: 1300 | D26: 2 persons x 6 hours @ $100/hour. Core, place, epoxy ($100) in place.
A28: Traffic Control Per Unit for Installation (One-time Cost)
A29: Low= | B29: 6000 | D29: $1,000/lane x 6 lanes
A30: High= | B30: 6000 | D30: $1,000/lane x 6 lanes
A32: Integration to Real-Time Map (One-time Cost) | D32: This is the cost of taking the incoming data stream and working with a systems integrator to create a real-time map.
A33: Low= | B33: 0 | D33: Default is that this is not included. Low estimate = 450 hours @ $150/hour = $67,500.
A34: High= | B34: 0 | D34: Default is that this is not included. High estimate = 500 hours @ $200/hour (including profit) = $100,000.
A36: Initial Cost Subtotal
A37: Low (per station) = | B37: =B17+B21+B25+B29+B33 -> 15500 | D37: Note: Each "station" includes 12 magnetometers.
A38: High (per station) = | B38: =B18+B22+B26+B30+B34 -> 17300 | D38: Note: Each "station" includes 12 magnetometers.
A40: Low (per mile) = | B40: =B43/B6 -> 16275
A41: High (per mile) = | B41: =B44/B6 -> 35465
A43: Low (for given segment length) = | B43: =B37*B12 -> 325500
A44: High (for given segment length) = | B44: =B38*B13 -> 709300
A46: Yearly On-going Operations and Maintenance Costs
A47: Communication Cost Per Station Per Year
A48: Low= | B48: 480 | D48: Tie into existing fiber/landline. Else cellular is about $40/month per unit (assumed in default here).
A49: High= | B49: 600 | D49: Tie into existing fiber/landline. Else cellular is about $50/month per unit (assumed in default here).
A51: Power Cost Per Station Per Year
...

Sheet 2G. Video
A1: Video Detectors Cost Estimates
A2: (Assumed 6-Lane Facility)
A4: Detector and Corridor Characteristics | D4: Description/notes/assumptions on values:
A5: Segment Length (miles)
A6: Value= | B6: 20 | D6: Enter the roadway segment length
A7: Detector Spacing (miles)
A8: Low= | B8: 1 | D8: Enter the lower estimate of the detector spacing
A9: High= | B9: 2 | D9: Enter the higher estimate of the detector spacing
A11: Required number of stations (points with camera each dir)
A12: Low= | B12: =(B6/B9)+1 -> 11 | D12: Computed low estimate of the number of stations for the segment
A13: High= | B13: =(B6/B8)+1 -> 21 | D13: Computed high estimate of the number of stations for the segment
A14: Cost Elements
A15: One-time Initial Costs
A16: Initial Capital Cost Per Station (One-time Cost)
A17: Low= | B17: 15000 | D17: $7,500 x 2 cameras (need a camera for each direction); Cost is for a "station" defined as having a camera for both directions.
A18: High= | B18: 16000 | D18: $8,000 x 2 cameras (need a camera for each direction); Cost is for a "station" defined as having a camera for both directions.
A20: Pole Installation and Foundation (One-time Cost)
A21: Low= | B21: 0 | D21: If no adequate pole present. Default assumes pole is present so cost is negligible. Else, costs could range from $3,000-$6,000 for 25'-30' pole.
A22: High= | B22: 0 | D22: If no adequate pole present. Default assumes pole is present so cost is negligible. Else, costs could range from $3,000-$6,000 for 25'-30' pole.
A24: Cabinet (One-time Cost)
A25: Low= | B25: 0 | D25: Assume one is present. Else cost could range from $5,000 to $6,000 to install.
A26: High= | B26: 0 | D26: Assume one is present. Else cost could range from $5,000 to $6,000 to install.
A28: Conduit/Cable/Trenching Per Station (One-time Cost)
A29: Low= | B29: =2*((200*7.5)+(150*10)) -> 6000 | D29: Wire/coaxial cable (power and communications) @ $7.50/foot. Conduit/trenching at $10/foot for 150'. Assume 200' for pole height to cabinet for wire/cable. Note: any necessary boring would cost $15-$20/foot and none included here. Note: need this on both sides of the road so it is doubled.
A30: High= | B30: =2*((7.5*300)+(10*250)) -> 9500 | D30: Wire/coaxial cable (power and communications) @ $7.50/foot. Conduit/trenching at $10/foot for 150'. Assume 200' for pole height to cabinet for wire/cable. Note: any necessary boring would cost $15-$20/foot and none included here. Note: need this on both sides of the road so it is doubled.
A32: Installation Cost Per Unit (One-time Cost)
A33: Low= | B33: 400 | D33: 2 people (for safety with bucket truck) for 2 hours @ $100/hour. Assume public agency has a bucket truck--no cost.
A34: High= | B34: 800 | D34: 2 people (for safety with bucket truck) for 4 hours @ $100/hour. Assume public agency has a bucket truck--no cost.
A36: Integration to Real-Time Map (One-time Cost) | D36: This is the cost of taking the incoming data stream and working with a systems integrator to create a real-time map.
A37: Low= | B37: 0 | D37: Default is that this is not included. Low estimate = 450 hours @ $150/hour = $67,500.
A38: High= | B38: 0 | D38: Default is that this is not included. High estimate = 500 hours @ $200/hour (including profit) = $100,000.
A40: Initial Cost Subtotal
A41: Low (per station) = | B41: =B17+B21+B25+B29+B33+B37 -> 21400 | D41: Note: "station" terminology used because 2 cameras are used--one for each side of the road.
A42: High (per station) = | B42: =B18+B22+B26+B30+B34+B38 -> 26300 | D42: Note: "station" terminology used because 2 cameras are used--one for each side of the road.
A44: Low (per mile) = | B44: =B47/B6 -> 11770
A45: High (per mile) = | B45: =B48/B6 -> 27615
A47: Low (for given segment length) = | B47: =B41*B12 -> 235400
A48: High (for given segment length) = | B48: =B42*B13 -> 552300
A50: Yearly On-going Operations and Maintenance Costs
A51: Communication Cost Per Unit Per Year
...

Sheet 3. Summary
A1: Summary of Life-cycle Costs
E2: Bluetooth | F2: Private Sector | G2: Toll Tags | H2: Radar | I2: Dual Loops | J2: Magnetometer | K2: Video
D3: Segment Length= | E3: ='2A. Bluetooth Probe'!B5 -> 20 | F3: ='2B. Private Sector'!B5 -> 20 | G3: ='2C. Toll Tags'!B5 -> 20 | H3: ='2D. Radar'!B5 -> 20 | I3: ='2E. Dual Loops'!B6 -> 20 | J3: ='2F. Magnetometer'!B6 -> 20 | K3: ='2G. Video'!B6 -> 20
D5: Detector Spacing (miles): | E5: ='2A. Bluetooth Probe'!B7 -> 1 | F5: 0.5 | G5: ='2C. Toll Tags'!B7 -> 2 | H5: ='2D. Radar'!B7 -> 1 | I5: ='2E. Dual Loops'!B8 -> 0.5 | J5: ='2F. Magnetometer'!B8 -> 0.5 | K5: ='2G. Video'!B8 -> 1
E6: ='2A. Bluetooth Probe'!B8 -> 2 | F6: 1 | G6: ='2C. Toll Tags'!B8 -> 3 | H6: ='2D. Radar'!B8 -> 2 | I6: ='2E. Dual Loops'!B9 -> 1 | J6: ='2F. Magnetometer'!B9 -> 1 | K6: ='2G. Video'!B9 -> 2
F7: -For private sector, spacing is based on average urban area Traffic Message Channel (TMC) length.
D8: Required Number of Detectors for Total Segment Length Above:
D9: Low= | E9: ='2A. Bluetooth Probe'!B11 -> 11 | F9: =(F3/F6)+1 -> 21 | G9: ='2C. Toll Tags'!B11 -> 7.6666667 | H9: ='2D. Radar'!B11 -> 11 | I9: ='2E. Dual Loops'!B12 -> 21 | J9: ='2F. Magnetometer'!B12 -> 21 | K9: ='2G. Video'!B12 -> 11
D10: High= | E10: ='2A. Bluetooth Probe'!B12 -> 21 | F10: =(F3/F5)+1 -> 41 | G10: ='2C. Toll Tags'!B12 -> 11 | H10: ='2D. Radar'!B12 -> 21 | I10: ='2E. Dual Loops'!B13 -> 41 | J10: ='2F. Magnetometer'!B13 -> 41 | K10: ='2G. Video'!B13 -> 21
B12: Cost Time-frame | D12: High or Low Value and Units | E12: Total Cost (No Systems Integration for Real-time Map)
E13: Probes | H13: Point Detectors
E14: Bluetooth | F14: Private Sector | G14: Toll Tags | H14: Radar | I14: Dual Loops | J14: Magnetometer | K14: Video
B15: Year 1 Costs | D15: Low (per mile) = | E15: =ROUND('2A. Bluetooth Probe'!B85, -3) -> 2000 | F15: =ROUND('2B. Private Sector'!B27,-2) -> 900 | G15: =ROUND('2C. Toll Tags'!B67,-3) -> 29000 | H15: =ROUND('2D. Radar'!B97,-3) -> 5000 | I15: =ROUND('2E. Dual Loops'!B94,-3) -> 21000 | J15: =ROUND('2F. Magnetometer'!B94,-3) -> 17000 | K15: =ROUND('2G. Video'!B98,-3) -> 12000
D16: High (per mile) = | E16: =ROUND('2A. Bluetooth Probe'!B86,-3) -> 6000 | F16: =ROUND('2B. Private Sector'!B28,-2) -> 1000 | G16: =ROUND('2C. Toll Tags'!B68,-3) -> 49000 | H16: =ROUND('2D. Radar'!B98,-3) -> 15000 | I16: =ROUND('2E. Dual Loops'!B95,-3) -> 51000 | J16: =ROUND('2F. Magnetometer'!B95,-3) -> 38000 | K16: =ROUND('2G. Video'!B99,-3) -> 28000
D17: Average (per mile) = | E17: =AVERAGE(E15:E16) -> 4000 | F17: =AVERAGE(F15:F16) -> 950 | G17: =AVERAGE(G15:G16) -> 39000 | H17: =AVERAGE(H15:H16) -> 10000 | I17: =AVERAGE(I15:I16) -> 36000 | J17: =AVERAGE(J15:J16) -> 27500 | K17: =AVERAGE(K15:K16) -> 20000
D18: Low (for given segment length) = | E18: =ROUND('2A. Bluetooth Probe'!B88,-3) -> 46000 | F18: =ROUND('2B. Private Sector'!B30,-2) -> 17000 | G18: =ROUND('2C. Toll Tags'!B70,-3) -> 588000 | H18: =ROUND('2D. Radar'!B100,-3) -> 98000 | I18: =ROUND('2E. Dual Loops'!B97,-3) -> 419000 | J18: =ROUND('2F. Magnetometer'!B97,-3) -> 342000 | K18: =ROUND('2G. Video'!B101,-3) -> 239000
D19: High (for given segment length) = | E19: =ROUND('2A. Bluetooth Probe'!B89,-3) -> 126000 | F19: =ROUND('2B. Private Sector'!B31,-2) -> 20000 | G19: =ROUND('2C. Toll Tags'!B71,-3) -> 979000 | H19: =ROUND('2D. Radar'!B101,-3) -> 297000 | I19: =ROUND('2E. Dual Loops'!B98,-3) -> 1026000 | J19: =ROUND('2F. Magnetometer'!B98,-3) -> 754000 | K19: =ROUND('2G. Video'!B102,-3) -> 566000
D20: Average (for given segment length) = | E20: =AVERAGE(E18:E19) -> 86000 | F20: =AVERAGE(F18:F19) -> 18500 | G20: =AVERAGE(G18:G19) -> 783500 | H20: =AVERAGE(H18:H19) -> 197500 | I20: =AVERAGE(I18:I19) -> 722500 | J20: =AVERAGE(J18:J19) -> 548000 | K20: =AVERAGE(K18:K19) -> 402500
B21: 5-Year Estimated Cost | D21: Low (per mile) = | E21: =ROUND('2A. Bluetooth Probe'!B92,-3) -> 5000 | F21: =ROUND('2B. Private Sector'!B34,-2) -> 3700 | G21: =ROUND('2C. Toll Tags'!B74,-3) -> 31000 | H21: =ROUND('2D. Radar'!B104,-3) -> 9000 | I21: =ROUND('2E. Dual Loops'!B113,-3) -> 29000 | J21: =ROUND('2F. Magnetometer'!B101,-3) -> 20000 | K21: =ROUND('2G. Video'!B105,-3) -> 29000
D22: High (per mile) = | E22: =ROUND('2A. Bluetooth Probe'!B93,-3) -> 14000 | F22: =ROUND('2B. Private Sector'!B35,-2) -> 4200 | G22: =ROUND('2C. Toll Tags'!B75,-3) -> 53000 | H22: =ROUND('2D. Radar'!B105,-3) -> 26000 | I22: =ROUND('2E. Dual Loops'!B114,-3) -> 103000 | J22: =ROUND('2F. Magnetometer'!B102,-3) -> 47000 | K22: =ROUND('2G. Video'!B106,-3) -> 65000
D23: Average (per mile) = | E23: =AVERAGE(E21:E22) -> 9500 | F23: =AVERAGE(F21:F22) -> 3950 | G23: =AVERAGE(G21:G22) -> 42000 | H23: =AVERAGE(H21:H22) -> 17500 | I23: =AVERAGE(I21:I22) -> 66000 | J23: =AVERAGE(J21:J22) -> 33500 | K23: =AVERAGE(K21:K22) -> 47000
D24: Low (for given segment length) = | E24: =ROUND('2A. Bluetooth Probe'!B95,-3) -> 106000 | F24: =ROUND('2B. Private Sector'!B37,-2) -> 73000 | G24: =ROUND('2C. Toll Tags'!B77,-3) -> 620000 | H24: =ROUND('2D. Radar'!B107,-3) -> 179000 | I24: =ROUND('2E. Dual Loops'!B116,-3) -> 586000 | J24: =ROUND('2F. Magnetometer'!B104,-3) -> 410000 | K24: =ROUND('2G. Video'!B108,-3) -> 583000
D25: High (for given segment length) = | E25: =ROUND('2A. Bluetooth Probe'!B96,-3) -> 281000 | F25: =ROUND('2B. Private Sector'!B38,-2) -> 84000 | G25: =ROUND('2C. Toll Tags'!B78,-3) -> 1059000 | H25: =ROUND('2D. Radar'!B108,-3) -> 526000 | I25: =ROUND('2E. Dual Loops'!B117,-3) -> 2055000 | J25: =ROUND('2F. Magnetometer'!B105,-3) -> 931000 | K25: =ROUND('2G. Video'!B109,-3) -> 1292000
D26: Average (for given segment length) = | E26: =AVERAGE(E24:E25) -> 193500 | F26: =AVERAGE(F24:F25) -> 78500 | G26: =AVERAGE(G24:G25) -> 839500 | H26: =AVERAGE(H24:H25) -> 352500 | I26: =AVERAGE(I24:I25) -> 1320500 | J26: =AVERAGE(J24:J25) -> 670500 | K26: =AVERAGE(K24:K25) -> 937500
B27: 10-Year Estimated Cost | D27: Low (per mile) = | E27: =ROUND('2A. Bluetooth Probe'!B99,-3) -> 9000 | F27: =ROUND('2B. Private Sector'!B41,-2) -> 7200 | G27: =ROUND('2C. Toll Tags'!B81,-3) -> 33000 | H27: =ROUND('2D. Radar'!B111,-3) -> 13000 | I27: =ROUND('2E. Dual Loops'!B132,-3) -> 48000 | J27: =ROUND('2F. Magnetometer'!B108,-3) -> 36000 | K27: =ROUND('2G. Video'!B112,-3) -> 47000
D28: High (per mile) = | E28: =ROUND('2A. Bluetooth Probe'!B100,-3) -> 22000 | F28: =ROUND('2B. Private Sector'!B42,-2) -> 8200 | G28: =ROUND('2C. Toll Tags'!B82,-3) -> 58000 | H28: =ROUND('2D. Radar'!B112,-3) -> 38000 | I28: =ROUND('2E. Dual Loops'!B133,-3) -> 146000 | J28: =ROUND('2F. Magnetometer'!B109,-3) -> 84000 | K28: =ROUND('2G. Video'!B113,-3) -> 102000
D29: Average (per mile) = | E29: =AVERAGE(E27:E28) -> 15500 | F29: =AVERAGE(F27:F28) -> 7700 | G29: =AVERAGE(G27:G28) -> 45500 | H29: =AVERAGE(H27:H28) -> 25500 | I29: =AVERAGE(I27:I28) -> 97000 | J29: =AVERAGE(J27:J28) -> 60000 | K29: =AVERAGE(K27:K28) -> 74500
D30: Low (for given segment length) = | E30: =ROUND('2A. Bluetooth Probe'!B102,-3) -> 171000 | F30: =ROUND('2B. Private Sector'!B44,-2) -> 143000 | G30: =ROUND('2C. Toll Tags'!B84,-3) -> 660000 | H30: =ROUND('2D. Radar'!B114,-3) -> 266000 | I30: =ROUND('2E. Dual Loops'!B135,-3) -> 954000 | J30: =ROUND('2F. Magnetometer'!B111,-3) -> 729000 | K30: =ROUND('2G. Video'!B115,-3) -> 931000
D31: High (for given segment length) = | E31: =ROUND('2A. Bluetooth Probe'!B103,-3) -> 449000 | F31: =ROUND('2B. Private Sector'!B45,-2) -> 164000 | G31: =ROUND('2C. Toll Tags'!B85,-3) -> 1159000 | H31: =ROUND('2D. Radar'!B115,-3) -> 768000 | I31: =ROUND('2E. Dual Loops'!B136,-3) -> 2921000 | J31: =ROUND('2F. Magnetometer'!B112,-3) -> 1677000 | K31: =ROUND('2G. Video'!B116,-3) -> 2031000
D32: Average (for given segment length) = | E32: =AVERAGE(E30:E31) -> 310000 | F32: =AVERAGE(F30:F31) -> 153500 | G32: =AVERAGE(G30:G31) -> 909500 | H32: =AVERAGE(H30:H31) -> 517000 | I32: =AVERAGE(I30:I31) -> 1937500 | J32: =AVERAGE(J30:J31) -> 1203000 | K32: =AVERAGE(K30:K31) -> 1481000
B33: Notes: Only includes cost to get the data. It does not include data integration to a map.
B34: Review prior worksheets for each detector technology for more information/assumptions.
B37: Graphic of estimated costs per mile for year 1, 5-year life cycle, and 10-year life cycle. | M37: Graphic of estimated costs for user-input segment length for year 1, 5-year life cycle, and 10-year life cycle.

Sheet 4. References
A1: A number of resources and/or persons provided information used to develop this spreadsheet. They are listed here.
A3: Dan Middleton, Texas Transportation Institute, College Station, Texas
A4: Mike Vickich, Texas Transportation Institute, Houston, Texas
A5: Darrell Borchardt, Texas Transportation Institute, Houston, Texas
A6: Darrell Puckett, Texas Transportation Institute, Houston, Texas
A7: Tony Voigt, Texas Transportation Institute, Houston, Texas
A8: Stan Young, University of Maryland, Center for Advanced Transportation Technology, College Park, Maryland
A10: Additional resources:
A11: ITS Benefits, Costs and Lessons Learned Database, US DOT, Available: http://www.benefitcost.its.dot.gov/
A12: Efforts to Address Highway Congestion through Real-time Traffic Information Systems are Expanding but Face Implementation Challenges, US GAO, GAO-10-121R, November 2009.
A13: Young, Stan, Bluetooth Traffic Monitoring, presented at Bluetooth Summit, Houston, Texas, February 18, 2010.
A14: Guide to Benchmarking Operations Performance Measures, Draft Final Report, National Cooperative Highway Research Program, Washington, D.C., January 2008.
... A24: Terri Johnson, Navteq, 214-634-8141, costs for point sensors and Navteq
