Workbook

Sheet BoostToolkitClipBoard2010

Sheet ReadMe
A1: Startup Model Template
A2: © 2012 by OpSpark, Inc.
A3: www.opspark.com
A4: http://blog.opspark.com
A6: Licensed under the MIT License:
A7: Permission is hereby granted, free of charge, to any person obtaining a copy of this software and associated documentation files (the "Software"), to deal in the Software without restriction, including without limitation the rights to use, copy, modify, merge, publish, distribute, sublicense, and/or sell copies of the Software, and to permit persons to whom the Software is furnished to do so, subject to the following conditions: The above copyright notice and this permission notice shall be included in all copies or substantial portions of the Software. THE SOFTWARE IS PROVIDED "AS IS", WITHOUT WARRANTY OF ANY KIND, EXPRESS OR IMPLIED, INCLUDING BUT NOT LIMITED TO THE WARRANTIES OF MERCHANTABILITY, FITNESS FOR A PARTICULAR PURPOSE AND NONINFRINGEMENT. IN NO EVENT SHALL THE AUTHORS OR COPYRIGHT HOLDERS BE LIABLE FOR ANY CLAIM, DAMAGES OR OTHER LIABILITY, WHETHER IN AN ACTION OF CONTRACT, TORT OR OTHERWISE, ARISING FROM, OUT OF OR IN CONNECTION WITH THE SOFTWARE OR THE USE OR OTHER DEALINGS IN THE SOFTWARE.

Sheet IS
A1: Simple Tech Startup
A2: Income Statement
A3: ($ in 000s)
B4: =IF(B6=1,"Mo.",IF(B6=3,"Qtr.",IF(B6=12,"Year",IF(B6="","Founded","ERROR")))) -> Founded | C4: =IF(C6=1,"Mo.",IF(C6=3,"Qtr.",IF(C6=12,"Year",IF(C6="","Founded","ERROR")))) -> Mo. | D4: =IF(D6=1,"Mo.",IF(D6=3,"Qtr.",IF(D6=12,"Year",IF(D6="","Founded","ERROR")))) -> Mo. | E4: =IF(E6=1,"Mo.",IF(E6=3,"Qtr.",IF(E6=12,"Year",IF(E6="","Founded","ERROR")))) -> Mo. | F4: =IF(F6=1,"Mo.",IF(F6=3,"Qtr.",IF(F6=12,"Year",IF(F6="","Founded","ERROR")))) -> Mo. | G4: =IF(G6=1,"Mo.",IF(G6=3,"Qtr.",IF(G6=12,"Year",IF(G6="","Founded","ERROR")))) -> Mo. | H4: =IF(H6=1,"Mo.",IF(H6=3,"Qtr.",IF(H6=12,"Year",IF(H6="","Founded","ERROR")))) -> Mo. | I4: =IF(I6=1,"Mo.",IF(I6=3,"Qtr.",IF(I6=12,"Year",IF(I6="","Founded","ERROR")))) -> Mo. | ... U4: =IF(U6=1,"Mo.",IF(U6=3,"Qtr.",IF(U6=12,"Year",IF(U6="","Founded","ERROR")))) -> Year
A5: Pd. End | B5: 40908 | C5: =B5+C6*30 -> 40938 | D5: =C5+D6*30 -> 40968 | E5: =D5+E6*30 -> 40998 | F5: =E5+F6*30 -> 41028 | G5: =F5+G6*30 -> 41058 | H5: =G5+H6*30 -> 41088 | I5: =H5+I6*30 -> 41118 | J5: =I5+J6*30 -> 41148 | ... U5: =T5+U6*30 -> 42708
A6: Mos in Pd | C6: 1 | D6: 1 | E6: 1 | F6: 1 | G6: 1 | H6: 1 | I6: 1 | J6: 1 | K6: 1 | L6: 1 | M6: 1 | N6: 1 | O6: 3 | P6: 3 | Q6: 3 | R6: 3 | S6: 12 | T6: 12 | U6: 12
A8: Revenue
A9: =Scen!A14 -> Consulting | C9: =Scen!C14 -> 20 | D9: =Scen!D14 -> 21 | E9: =Scen!E14 -> 22 | F9: =Scen!F14 -> 23 | G9: =Scen!G14 -> 24 | H9: =Scen!H14 -> 25 | I9: =Scen!I14 -> 26 | J9: =Scen!J14 -> 27 | ... U9: =Scen!U14 -> 303
A10: =Scen!A21 -> Client Sales | C10: =Scen!C21 -> 20 | D10: =Scen!D21 -> 21 | E10: =Scen!E21 -> 22 | F10: =Scen!F21 -> 23 | G10: =Scen!G21 -> 24 | H10: =Scen!H21 -> 25 | I10: =Scen!I21 -> 26 | J10: =Scen!J21 -> 27 | ... U10: =Scen!U21 -> 303
A11: Client Monthly | C11: 5 | D11: 6 | E11: 7.2 | F11: 8.64 | G11: 10.368 | H11: 12.4416 | I11: 14.92992 | J11: 17.915904 | K11: 21.499085 | L11: 25.798902 | M11: 30.958682 | N11: 37.150419 | O11: 133.74151 | P11: 160.48981 | Q11: 192.58777 | R11: 231.10532 | S11: 1109.3056 | T11: 1331.1667 | U11: 1597.4
A12: Client Licenses | C12: 4 | D12: 4.8 | E12: 5.76 | F12: 6.912 | G12: 8.2944 | H12: 9.95328 | I12: 11.943936 | J12: 14.332723 | K12: 17.199268 | L12: 20.639121 | M12: 24.766946 | N12: 29.720335 | O12: 106.99321 | P12: 128.39185 | Q12: 154.07022 | R12: 184.88426 | S12: 887.44444 | T12: 1064.9333 | U12: 1277.92
A13: Internet Sales | C13: 3 | D13: 3.6 | E13: 4.32 | F13: 5.184 | G13: 6.2208 | H13: 7.46496 | I13: 8.957952 | J13: 10.749542 | K13: 12.899451 | L13: 15.479341 | M13: 18.575209 | N13: 22.290251 | O13: 80.244904 | P13: 96.293885 | Q13: 115.55266 | R13: 138.66319 | S13: 665.58333 | T13: 798.7 | U13: 958.44
A14: Internet Monthly | C14: 2 | D14: 2.4 | E14: 2.88 | F14: 3.456 | G14: 4.1472 | H14: 4.97664 | I14: 5.971968 | J14: 7.1663616 | K14: 8.5996339 | L14: 10.319561 | M14: 12.383473 | N14: 14.860167 | O14: 53.496603 | P14: 64.195923 | Q14: 77.035108 | R14: 92.442129 | S14: 443.72222 | T14: 532.46667 | U14: 638.96
A15: Other Revenue | C15: 0 | D15: 0 | E15: 0 | F15: 0 | G15: 0 | H15: 0 | I15: 0 | J15: 0 | K15: 0 | L15: 0 | M15: 0 | N15: 0 | O15: 0 | P15: 0 | Q15: 0 | R15: 0 | S15: 0 | T15: 0 | U15: 0
A16: Other Revenue | C16: 0 | D16: 0 | E16: 0 | F16: 0 | G16: 0 | H16: 0 | I16: 0 | J16: 0 | K16: 0 | L16: 0 | M16: 0 | N16: 0 | O16: 0 | P16: 0 | Q16: 0 | R16: 0 | S16: 0 | T16: 0 | U16: 0
A17: Other Revenue | C17: 0 | D17: 0 | E17: 0 | F17: 0 | G17: 0 | H17: 0 | I17: 0 | J17: 0 | K17: 0 | L17: 0 | M17: 0 | N17: 0 | O17: 0 | P17: 0 | Q17: 0 | R17: 0 | S17: 0 | T17: 0 | U17: 0
A18: Other Revenue | C18: 0 | D18: 0 | E18: 0 | F18: 0 | G18: 0 | H18: 0 | I18: 0 | J18: 0 | K18: 0 | L18: 0 | M18: 0 | N18: 0 | O18: 0 | P18: 0 | Q18: 0 | R18: 0 | S18: 0 | T18: 0 | U18: 0
A20: =A8 -> Revenue | C20: =SUM(C8:C19) -> 54 | D20: =SUM(D8:D19) -> 58.8 | E20: =SUM(E8:E19) -> 64.16 | F20: =SUM(F8:F19) -> 70.192 | G20: =SUM(G8:G19) -> 77.0304 | H20: =SUM(H8:H19) -> 84.83648 | I20: =SUM(I8:I19) -> 93.803776 | J20: =SUM(J8:J19) -> 104.16453 | ... U20: =SUM(U8:U19) -> 5078.72
A22: Expenses
A23: Payroll | C23: =HC!C32 -> 12.5 | D23: =HC!D32 -> 12.5 | E23: =HC!E32 -> 25 | F23: =HC!F32 -> 25 | G23: =HC!G32 -> 25 | H23: =HC!H32 -> 31.25 | I23: =HC!I32 -> 31.25 | J23: =HC!J32 -> 31.25 | ... U23: =HC!U32 -> 750
A24: Payroll Tax | C24: =HC!C33 -> 0.9375 | D24: =HC!D33 -> 0.9375 | E24: =HC!E33 -> 1.875 | F24: =HC!F33 -> 1.875 | G24: =HC!G33 -> 1.875 | H24: =HC!H33 -> 2.34375 | I24: =HC!I33 -> 2.34375 | J24: =HC!J33 -> 2.34375 | ... U24: =HC!U33 -> 56.25
A25: Outsourced Dev | C25: 1 | D25: 1 | E25: 1 | F25: 1 | G25: 1 | H25: 1 | I25: 1 | J25: 1 | K25: 1 | L25: 1 | M25: 1 | N25: 1 | O25: 3 | P25: 3 | Q25: 3 | R25: 3 | S25: 10 | T25: 10 | U25: 10
A26: Legal | C26: 20 | D26: 1 | E26: 1 | F26: 1 | G26: 1 | H26: 1 | I26: 1 | J26: 1 | K26: 1 | L26: 1 | M26: 1 | N26: 1 | O26: 3 | P26: 3 | Q26: 3 | R26: 3 | S26: 10 | T26: 10 | U26: 10
A27: Rent/Occupancy | C27: 1 | D27: 1 | E27: 1 | F27: 1 | G27: 1 | H27: 1 | I27: 1 | J27: 1 | K27: 1 | L27: 1 | M27: 1 | N27: 1 | O27: 3 | P27: 3 | Q27: 3 | R27: 3 | S27: 10 | T27: 10 | U27: 10
A28: Cloud Computing | C28: 1 | D28: 1 | E28: 1 | F28: 1 | G28: 1 | H28: 1 | I28: 1 | J28: 1 | K28: 1 | L28: 1 | M28: 1 | N28: 1 | O28: 3 | P28: 3 | Q28: 3 | R28: 3 | S28: 10 | T28: 10 | U28: 10
A29: T&E | C29: 1 | D29: 1 | E29: 1 | F29: 1 | G29: 1 | H29: 1 | I29: 1 | J29: 1 | K29: 1 | L29: 1 | M29: 1 | N29: 1 | O29: 3 | P29: 3 | Q29: 3 | R29: 3 | S29: 10 | T29: 10 | U29: 10
A30: Designers | C30: 10 | D30: 0 | E30: 0 | F30: 0 | G30: 0 | H30: 0 | I30: 0 | J30: 0 | K30: 0 | L30: 0 | M30: 0 | N30: 0 | O30: 0 | P30: 0 | Q30: 0 | R30: 0 | S30: 0 | T30: 0 | U30: 0
A31: Telecomm. | C31: 0 | D31: 1 | E31: 1 | F31: 1 | G31: 1 | H31: 1 | I31: 1 | J31: 1 | K31: 1 | L31: 1 | M31: 1 | N31: 1 | O31: 3 | P31: 3 | Q31: 3 | R31: 3 | S31: 10 | T31: 10 | U31: 10
A32: Insurance | C32: 0 | D32: 0 | E32: 0 | F32: 0 | G32: 0 | H32: 0 | I32: 0 | J32: 0 | K32: 0 | L32: 0 | M32: 0 | N32: 0 | O32: 0 | P32: 0 | Q32: 0 | R32: 0 | S32: 0 | T32: 0 | U32: 0
A33: Office Supplies | C33: 0 | D33: 1 | E33: 1 | F33: 1 | G33: 1 | H33: 1 | I33: 1 | J33: 1 | K33: 1 | L33: 1 | M33: 1 | N33: 1 | O33: 3 | P33: 3 | Q33: 3 | R33: 3 | S33: 10 | T33: 10 | U33: 10
A34: Miscellaneous | C34: 0 | D34: 0 | E34: 0 | F34: 0 | G34: 0 | H34: 0 | I34: 0 | J34: 0 | K34: 0 | L34: 0 | M34: 0 | N34: 0 | O34: 0 | P34: 0 | Q34: 0 | R34: 0 | S34: 0 | T34: 0 | U34: 0
A35: Miscellaneous | C35: 0 | D35: 0 | E35: 0 | F35: 0 | G35: 0 | H35: 0 | I35: 0 | J35: 0 | K35: 0 | L35: 0 | M35: 0 | N35: 0 | O35: 0 | P35: 0 | Q35: 0 | R35: 0 | S35: 0 | T35: 0 | U35: 0
A36: Miscellaneous | C36: 0 | D36: 0 | E36: 0 | F36: 0 | G36: 0 | H36: 0 | I36: 0 | J36: 0 | K36: 0 | L36: 0 | M36: 0 | N36: 0 | O36: 0 | P36: 0 | Q36: 0 | R36: 0 | S36: 0 | T36: 0 | U36: 0
... A44: Miscellaneous | C44: 0 | D44: 0 | E44: 0 | F44: 0 | G44: 0 | H44: 0 | I44: 0 | J44: 0 | K44: 0 | L44: 0 | M44: 0 | N44: 0 | O44: 0 | P44: 0 | Q44: 0 | R44: 0 | S44: 0 | T44: 0 | U44: 0
A46: Subtotal | C46: =SUM(C22:C45) -> 47.4375 | D46: =SUM(D22:D45) -> 20.4375 | E46: =SUM(E22:E45) -> 33.875 | F46: =SUM(F22:F45) -> 33.875 | G46: =SUM(G22:G45) -> 33.875 | H46: =SUM(H22:H45) -> 40.59375 | I46: =SUM(I22:I45) -> 40.59375 | J46: =SUM(J22:J45) -> 40.59375 | ... U46: =SUM(U22:U45) -> 876.25
A47: Depreciation | B47: 5 | C47: =BS!B19*IS!C$6/(12*IS!$B47) -> 0 | D47: =BS!C19*IS!D$6/(12*IS!$B47) -> 0 | E47: =BS!D19*IS!E$6/(12*IS!$B47) -> 0 | F47: =BS!E19*IS!F$6/(12*IS!$B47) -> 0 | G47: =BS!F19*IS!G$6/(12*IS!$B47) -> 0 | H47: =BS!G19*IS!H$6/(12*IS!$B47) -> 0 | I47: =BS!H19*IS!I$6/(12*IS!$B47) -> 0 | J47: =BS!I19*IS!J$6/(12*IS!$B47) -> 0 | ... U47: =BS!T19*IS!U$6/(12*IS!$B47) -> 0
A49: Operating Ep. | C49: =SUM(C46:C48) -> 47.4375 | D49: =SUM(D46:D48) -> 20.4375 | E49: =SUM(E46:E48) -> 33.875 | F49: =SUM(F46:F48) -> 33.875 | G49: =SUM(G46:G48) -> 33.875 | H49: =SUM(H46:H48) -> 40.59375 | I49: =SUM(I46:I48) -> 40.59375 | J49: =SUM(J46:J48) -> 40.59375 | ... U49: =SUM(U46:U48) -> 876.25
A50: =BS!A39&" Interest" -> Loan 1 Interest | B50: 0.07 | C50: =$B50*BS!B39*C$6/12 -> 0 | D50: =$B50*BS!C39*D$6/12 -> 0 | E50: =$B50*BS!D39*E$6/12 -> 0 | F50: =$B50*BS!E39*F$6/12 -> 0 | G50: =$B50*BS!F39*G$6/12 -> 0 | H50: =$B50*BS!G39*H$6/12 -> 0 | I50: =$B50*BS!H39*I$6/12 -> 0 | J50: =$B50*BS!I39*J$6/12 -> 0 | ... U50: =$B50*BS!T39*U$6/12 -> 0
A51: =BS!A40&" Interest" -> Loan 2 Interest | B51: 0.08 | C51: =$B51*BS!B40*C$6/12 -> 0 | D51: =$B51*BS!C40*D$6/12 -> 0 | E51: =$B51*BS!D40*E$6/12 -> 0 | F51: =$B51*BS!E40*F$6/12 -> 0 | G51: =$B51*BS!F40*G$6/12 -> 0 | H51: =$B51*BS!G40*H$6/12 -> 0 | I51: =$B51*BS!H40*I$6/12 -> 0 | J51: =$B51*BS!I40*J$6/12 -> 0 | ... U51: =$B51*BS!T40*U$6/12 -> 0
A53: =A22 -> Expenses | C53: =SUM(C49:C52) -> 47.4375 | D53: =SUM(D49:D52) -> 20.4375 | E53: =SUM(E49:E52) -> 33.875 | F53: =SUM(F49:F52) -> 33.875 | G53: =SUM(G49:G52) -> 33.875 | H53: =SUM(H49:H52) -> 40.59375 | I53: =SUM(I49:I52) -> 40.59375 | J53: =SUM(J49:J52) -> 40.59375 | ... U53: =SUM(U49:U52) -> 876.25
...

Sheet BS
A1: =IS!A1 -> Simple Tech Startup
A2: Balance Sheet
A3: =IS!A3 -> ($ in 000s)
B4: =IS!B4 -> Founded | C4: =IS!C4 -> Mo. | D4: =IS!D4 -> Mo. | E4: =IS!E4 -> Mo. | F4: =IS!F4 -> Mo. | G4: =IS!G4 -> Mo. | H4: =IS!H4 -> Mo. | I4: =IS!I4 -> Mo. | ... U4: =IS!U4 -> Year
A5: Pd. End | B5: =IS!B5 -> 40908 | C5: =IS!C5 -> 40938 | D5: =IS!D5 -> 40968 | E5: =IS!E5 -> 40998 | F5: =IS!F5 -> 41028 | G5: =IS!G5 -> 41058 | H5: =IS!H5 -> 41088 | I5: =IS!I5 -> 41118 | ... U5: =IS!U5 -> 42708
A6: Mos in Pd | B6: =IS!B6 -> 0 | C6: =IS!C6 -> 1 | D6: =IS!D6 -> 1 | E6: =IS!E6 -> 1 | F6: =IS!F6 -> 1 | G6: =IS!G6 -> 1 | H6: =IS!H6 -> 1 | I6: =IS!I6 -> 1 | ... U6: =IS!U6 -> 12
A8: ASSETS
A9: Current Assets
A10: Cash | B10: 100 | C10: =B10+CF!C42 -> 549.9375 | D10: =C10+CF!D42 -> 568.155 | E10: =D10+CF!E42 -> 580.966 | F10: =E10+CF!F42 -> 596.7242 | G10: =F10+CF!G42 -> 615.77904 | H10: =G10+CF!H42 -> 634.5186 | I10: =H10+CF!I42 -> 657.47732 | J10: =I10+CF!J42 -> 685.25903 | ... U10: =T10+CF!U42 -> 7971.7004
A11: Accounts Receivable | B11: 0 | C11: =30/360*IS!C$20*12/IS!C$6 -> 54 | D11: =30/360*IS!D$20*12/IS!D$6 -> 58.8 | E11: =30/360*IS!E$20*12/IS!E$6 -> 64.16 | F11: =30/360*IS!F$20*12/IS!F$6 -> 70.192 | G11: =30/360*IS!G$20*12/IS!G$6 -> 77.0304 | H11: =30/360*IS!H$20*12/IS!H$6 -> 84.83648 | I11: =30/360*IS!I$20*12/IS!I$6 -> 93.803776 | J11: =30/360*IS!J$20*12/IS!J$6 -> 104.16453 | ... U11: =30/360*IS!U$20*12/IS!U$6 -> 423.22667
A12: Inventory | B12: 0 | C12: 0 | D12: 0 | E12: 0 | F12: 0 | G12: 0 | H12: 0 | I12: 0 | J12: 0 | K12: 0 | L12: 0 | M12: 0 | N12: 0 | O12: 0 | P12: 0 | Q12: 0 | R12: 0 | S12: 0 | T12: 0 | U12: 0
A13: Prepaid Expenses | B13: 0 | C13: 0 | D13: 0 | E13: 0 | F13: 0 | G13: 0 | H13: 0 | I13: 0 | J13: 0 | K13: 0 | L13: 0 | M13: 0 | N13: 0 | O13: 0 | P13: 0 | Q13: 0 | R13: 0 | S13: 0 | T13: 0 | U13: 0
A14: Other Current Assets | B14: 0 | C14: 0 | D14: 0 | E14: 0 | F14: 0 | G14: 0 | H14: 0 | I14: 0 | J14: 0 | K14: 0 | L14: 0 | M14: 0 | N14: 0 | O14: 0 | P14: 0 | Q14: 0 | R14: 0 | S14: 0 | T14: 0 | U14: 0
A16: =A9 -> Current Assets | B16: =SUM(B9:B15) -> 100 | C16: =SUM(C9:C15) -> 603.9375 | D16: =SUM(D9:D15) -> 626.955 | E16: =SUM(E9:E15) -> 645.126 | F16: =SUM(F9:F15) -> 666.9162 | G16: =SUM(G9:G15) -> 692.80944 | H16: =SUM(H9:H15) -> 719.35508 | I16: =SUM(I9:I15) -> 751.28109 | ... U16: =SUM(U9:U15) -> 8394.927
A18: PP&E
A19: PP&E Gross | B19: 0 | C19: =B19-CF!C26 -> 0 | D19: =C19-CF!D26 -> 0 | E19: =D19-CF!E26 -> 0 | F19: =E19-CF!F26 -> 0 | G19: =F19-CF!G26 -> 0 | H19: =G19-CF!H26 -> 0 | I19: =H19-CF!I26 -> 0 | J19: =I19-CF!J26 -> 0 | ... U19: =T19-CF!U26 -> 0
A20: Less: Accumlated Depn. | B20: 0 | C20: =B20-IS!C47 -> 0 | D20: =C20-IS!D47 -> 0 | E20: =D20-IS!E47 -> 0 | F20: =E20-IS!F47 -> 0 | G20: =F20-IS!G47 -> 0 | H20: =G20-IS!H47 -> 0 | I20: =H20-IS!I47 -> 0 | J20: =I20-IS!J47 -> 0 | ... U20: =T20-IS!U47 -> 0
A22: Net PP&E | B22: =SUM(B18:B21) -> 0 | C22: =SUM(C18:C21) -> 0 | D22: =SUM(D18:D21) -> 0 | E22: =SUM(E18:E21) -> 0 | F22: =SUM(F18:F21) -> 0 | G22: =SUM(G18:G21) -> 0 | H22: =SUM(H18:H21) -> 0 | I22: =SUM(I18:I21) -> 0 | ... U22: =SUM(U18:U21) -> 0
A24: Deferred Tax (NOL) | B24: 0 | C24: =B24-CF!C11 -> 0 | D24: =C24-CF!D11 -> 0 | E24: =D24-CF!E11 -> 0 | F24: =E24-CF!F11 -> 0 | G24: =F24-CF!G11 -> 0 | H24: =G24-CF!H11 -> 0 | I24: =H24-CF!I11 -> 0 | J24: =I24-CF!J11 -> 0 | ... U24: =T24-CF!U11 -> 0
A25: Other N.C. Assets | B25: 0 | C25: 0 | D25: 0 | E25: 0 | F25: 0 | G25: 0 | H25: 0 | I25: 0 | J25: 0 | K25: 0 | L25: 0 | M25: 0 | N25: 0 | O25: 0 | P25: 0 | Q25: 0 | R25: 0 | S25: 0 | T25: 0 | U25: 0
A27: Total Assets | B27: =B22+B24+B25+B16 -> 100 | C27: =C22+C24+C25+C16 -> 603.9375 | D27: =D22+D24+D25+D16 -> 626.955 | E27: =E22+E24+E25+E16 -> 645.126 | F27: =F22+F24+F25+F16 -> 666.9162 | G27: =G22+G24+G25+G16 -> 692.80944 | H27: =H22+H24+H25+H16 -> 719.35508 | I27: =I22+I24+I25+I16 -> 751.28109 | ... U27: =U22+U24+U25+U16 -> 8394.927
A29: LIABILITIES & EQUITY
A30: Current Liabilities
A31: Accounts Payable | B31: 0 | C31: 0 | D31: 0 | E31: 0 | F31: 0 | G31: 0 | H31: 0 | I31: 0 | J31: 0 | K31: 0 | L31: 0 | M31: 0 | N31: 0 | O31: 0 | P31: 0 | Q31: 0 | R31: 0 | S31: 0 | T31: 0 | U31: 0
A32: Accrued Expenses | B32: 0 | C32: 0 | D32: 0 | E32: 0 | F32: 0 | G32: 0 | H32: 0 | I32: 0 | J32: 0 | K32: 0 | L32: 0 | M32: 0 | N32: 0 | O32: 0 | P32: 0 | Q32: 0 | R32: 0 | S32: 0 | T32: 0 | U32: 0
A33: Deferred Revenue | B33: 0 | C33: 0 | D33: 0 | E33: 0 | F33: 0 | G33: 0 | H33: 0 | I33: 0 | J33: 0 | K33: 0 | L33: 0 | M33: 0 | N33: 0 | O33: 0 | P33: 0 | Q33: 0 | R33: 0 | S33: 0 | T33: 0 | U33: 0
A34: Other Current Liabs. | B34: 0 | C34: 0 | D34: 0 | E34: 0 | F34: 0 | G34: 0 | H34: 0 | I34: 0 | J34: 0 | K34: 0 | L34: 0 | M34: 0 | N34: 0 | O34: 0 | P34: 0 | Q34: 0 | R34: 0 | S34: 0 | T34: 0 | U34: 0
A36: =A30 -> Current Liabilities | B36: =SUM(B30:B35) -> 0 | C36: =SUM(C30:C35) -> 0 | D36: =SUM(D30:D35) -> 0 | E36: =SUM(E30:E35) -> 0 | F36: =SUM(F30:F35) -> 0 | G36: =SUM(G30:G35) -> 0 | H36: =SUM(H30:H35) -> 0 | I36: =SUM(I30:I35) -> 0 | ... U36: =SUM(U30:U35) -> 0
A38: Non-Current Liabs
A39: Loan 1 | B39: 0 | C39: =B39+CF!C34 -> 0 | D39: =C39+CF!D34 -> 0 | E39: =D39+CF!E34 -> 0 | F39: =E39+CF!F34 -> 0 | G39: =F39+CF!G34 -> 0 | H39: =G39+CF!H34 -> 0 | I39: =H39+CF!I34 -> 0 | J39: =I39+CF!J34 -> 0 | ... U39: =T39+CF!U34 -> 0
A40: Loan 2 | B40: 0 | C40: =B40+CF!C35 -> 0 | D40: =C40+CF!D35 -> 0 | E40: =D40+CF!E35 -> 0 | F40: =E40+CF!F35 -> 0 | G40: =F40+CF!G35 -> 0 | H40: =G40+CF!H35 -> 0 | I40: =H40+CF!I35 -> 0 | J40: =I40+CF!J35 -> 0 | ... U40: =T40+CF!U35 -> 0
A42: =A38 -> Non-Current Liabs | B42: =SUM(B38:B41) -> 0 | C42: =SUM(C38:C41) -> 0 | D42: =SUM(D38:D41) -> 0 | E42: =SUM(E38:E41) -> 0 | F42: =SUM(F38:F41) -> 0 | G42: =SUM(G38:G41) -> 0 | H42: =SUM(H38:H41) -> 0 | I42: =SUM(I38:I41) -> 0 | ... U42: =SUM(U38:U41) -> 0
A44: Equity
A45: Preferred A | B45: 0 | C45: =B45+CF!C36 -> 500 | D45: =C45+CF!D36 -> 500 | E45: =D45+CF!E36 -> 500 | F45: =E45+CF!F36 -> 500 | G45: =F45+CF!G36 -> 500 | H45: =G45+CF!H36 -> 500 | I45: =H45+CF!I36 -> 500 | J45: =I45+CF!J36 -> 500 | ... U45: =T45+CF!U36 -> 500
A46: Preferred B | B46: 0 | C46: =B46+CF!C37 -> 0 | D46: =C46+CF!D37 -> 0 | E46: =D46+CF!E37 -> 0 | F46: =E46+CF!F37 -> 0 | G46: =F46+CF!G37 -> 0 | H46: =G46+CF!H37 -> 0 | I46: =H46+CF!I37 -> 0 | J46: =I46+CF!J37 -> 0 | ... U46: =T46+CF!U37 -> 0
A47: Common | B47: 100 | C47: =B47+CF!C38 -> 100 | D47: =C47+CF!D38 -> 100 | E47: =D47+CF!E38 -> 100 | F47: =E47+CF!F38 -> 100 | G47: =F47+CF!G38 -> 100 | H47: =G47+CF!H38 -> 100 | I47: =H47+CF!I38 -> 100 | J47: =I47+CF!J38 -> 100 | ... U47: =T47+CF!U38 -> 100
A48: Retained Earnings | B48: 0 | C48: =B48+CF!C9 -> 3.9375 | D48: =C48+CF!D9 -> 26.955 | E48: =D48+CF!E9 -> 45.126 | F48: =E48+CF!F9 -> 66.9162 | G48: =F48+CF!G9 -> 92.80944 | H48: =G48+CF!H9 -> 119.35508 | I48: =H48+CF!I9 -> 151.28109 | J48: =I48+CF!J9 -> 189.42356 | ... U48: =T48+CF!U9 -> 7794.927
A50: =A44 -> Equity | B50: =SUM(B44:B49) -> 100 | C50: =SUM(C44:C49) -> 603.9375 | D50: =SUM(D44:D49) -> 626.955 | E50: =SUM(E44:E49) -> 645.126 | F50: =SUM(F44:F49) -> 666.9162 | G50: =SUM(G44:G49) -> 692.80944 | H50: =SUM(H44:H49) -> 719.35508 | I50: =SUM(I44:I49) -> 751.28109 | ... U50: =SUM(U44:U49) -> 8394.927
A52: Liabilities & Equity | B52: =B50+B42+B36 -> 100 | C52: =C50+C42+C36 -> 603.9375 | D52: =D50+D42+D36 -> 626.955 | E52: =E50+E42+E36 -> 645.126 | F52: =F50+F42+F36 -> 666.9162 | G52: =G50+G42+G36 -> 692.80944 | H52: =H50+H42+H36 -> 719.35508 | I52: =I50+I42+I36 -> 751.28109 | ... U52: =U50+U42+U36 -> 8394.927
A54: Check | B54: =ABS(B27-B52) -> 0 | C54: =ABS(C27-C52) -> 0 | D54: =ABS(D27-D52) -> 1.1368684e-13 | E54: =ABS(E27-E52) -> 0 | F54: =ABS(F27-F52) -> 0 | G54: =ABS(G27-G52) -> 0 | H54: =ABS(H27-H52) -> 0 | I54: =ABS(I27-I52) -> 0 | ... U54: =ABS(U27-U52) -> 1.8189894e-12

Sheet CF
A1: =IS!A1 -> Simple Tech Startup
A2: Cash Flow Statement
A3: =IS!A3 -> ($ in 000s)
C4: =IS!C4 -> Mo. | D4: =IS!D4 -> Mo. | E4: =IS!E4 -> Mo. | F4: =IS!F4 -> Mo. | G4: =IS!G4 -> Mo. | H4: =IS!H4 -> Mo. | I4: =IS!I4 -> Mo. | J4: =IS!J4 -> Mo. | ... U4: =IS!U4 -> Year
A5: Pd. End | C5: =IS!C5 -> 40938 | D5: =IS!D5 -> 40968 | E5: =IS!E5 -> 40998 | F5: =IS!F5 -> 41028 | G5: =IS!G5 -> 41058 | H5: =IS!H5 -> 41088 | I5: =IS!I5 -> 41118 | J5: =IS!J5 -> 41148 | ... U5: =IS!U5 -> 42708
A6: Mos in Pd | C6: =IS!C6 -> 1 | D6: =IS!D6 -> 1 | E6: =IS!E6 -> 1 | F6: =IS!F6 -> 1 | G6: =IS!G6 -> 1 | H6: =IS!H6 -> 1 | I6: =IS!I6 -> 1 | J6: =IS!J6 -> 1 | ... U6: =IS!U6 -> 12
A8: Cash from Operations
A9: Net Income | C9: =IS!C63 -> 3.9375 | D9: =IS!D63 -> 23.0175 | E9: =IS!E63 -> 18.171 | F9: =IS!F63 -> 21.7902 | G9: =IS!G63 -> 25.89324 | H9: =IS!H63 -> 26.545638 | I9: =IS!I63 -> 31.926016 | J9: =IS!J63 -> 38.142469 | ... U9: =IS!U63 -> 2521.482
A10: Plus: Depreciation | C10: =IS!C47 -> 0 | D10: =IS!D47 -> 0 | E10: =IS!E47 -> 0 | F10: =IS!F47 -> 0 | G10: =IS!G47 -> 0 | H10: =IS!H47 -> 0 | I10: =IS!I47 -> 0 | J10: =IS!J47 -> 0 | ... U10: =IS!U47 -> 0
A11: Deferred Taxes | C11: =IS!C59 -> 0 | D11: =IS!D59 -> 0 | E11: =IS!E59 -> 0 | F11: =IS!F59 -> 0 | G11: =IS!G59 -> 0 | H11: =IS!H59 -> 0 | I11: =IS!I59 -> 0 | J11: =IS!J59 -> 0 | ... U11: =IS!U59 -> 0
A12: Less: Increase in Non-Cash Current Assets
A13: =BS!A11 -> Accounts Receivable | C13: =-(BS!C11-BS!B11) -> -54 | D13: =-(BS!D11-BS!C11) -> -4.8 | E13: =-(BS!E11-BS!D11) -> -5.36 | F13: =-(BS!F11-BS!E11) -> -6.032 | G13: =-(BS!G11-BS!F11) -> -6.8384 | H13: =-(BS!H11-BS!G11) -> -7.80608 | I13: =-(BS!I11-BS!H11) -> -8.967296 | J13: =-(BS!J11-BS!I11) -> -10.360755 | ... U13: =-(BS!U11-BS!T11) -> -70.454444
A14: =BS!A12 -> Inventory | C14: =-(BS!C12-BS!B12) -> 0 | D14: =-(BS!D12-BS!C12) -> 0 | E14: =-(BS!E12-BS!D12) -> 0 | F14: =-(BS!F12-BS!E12) -> 0 | G14: =-(BS!G12-BS!F12) -> 0 | H14: =-(BS!H12-BS!G12) -> 0 | I14: =-(BS!I12-BS!H12) -> 0 | J14: =-(BS!J12-BS!I12) -> 0 | ... U14: =-(BS!U12-BS!T12) -> 0
A15: =BS!A13 -> Prepaid Expenses | C15: =-(BS!C13-BS!B13) -> 0 | D15: =-(BS!D13-BS!C13) -> 0 | E15: =-(BS!E13-BS!D13) -> 0 | F15: =-(BS!F13-BS!E13) -> 0 | G15: =-(BS!G13-BS!F13) -> 0 | H15: =-(BS!H13-BS!G13) -> 0 | I15: =-(BS!I13-BS!H13) -> 0 | J15: =-(BS!J13-BS!I13) -> 0 | ... U15: =-(BS!U13-BS!T13) -> 0
A16: =BS!A14 -> Other Current Assets | C16: =-(BS!C14-BS!B14) -> 0 | D16: =-(BS!D14-BS!C14) -> 0 | E16: =-(BS!E14-BS!D14) -> 0 | F16: =-(BS!F14-BS!E14) -> 0 | G16: =-(BS!G14-BS!F14) -> 0 | H16: =-(BS!H14-BS!G14) -> 0 | I16: =-(BS!I14-BS!H14) -> 0 | J16: =-(BS!J14-BS!I14) -> 0 | ... U16: =-(BS!U14-BS!T14) -> 0
A17: Plus: Increase in Non-Cash Current Liabilities
A18: =BS!A31 -> Accounts Payable | C18: =BS!C31-BS!B31 -> 0 | D18: =BS!D31-BS!C31 -> 0 | E18: =BS!E31-BS!D31 -> 0 | F18: =BS!F31-BS!E31 -> 0 | G18: =BS!G31-BS!F31 -> 0 | H18: =BS!H31-BS!G31 -> 0 | I18: =BS!I31-BS!H31 -> 0 | J18: =BS!J31-BS!I31 -> 0 | ... U18: =BS!U31-BS!T31 -> 0
A19: =BS!A32 -> Accrued Expenses | C19: =BS!C32-BS!B32 -> 0 | D19: =BS!D32-BS!C32 -> 0 | E19: =BS!E32-BS!D32 -> 0 | F19: =BS!F32-BS!E32 -> 0 | G19: =BS!G32-BS!F32 -> 0 | H19: =BS!H32-BS!G32 -> 0 | I19: =BS!I32-BS!H32 -> 0 | J19: =BS!J32-BS!I32 -> 0 | ... U19: =BS!U32-BS!T32 -> 0
A20: =BS!A33 -> Deferred Revenue | C20: =BS!C33-BS!B33 -> 0 | D20: =BS!D33-BS!C33 -> 0 | E20: =BS!E33-BS!D33 -> 0 | F20: =BS!F33-BS!E33 -> 0 | G20: =BS!G33-BS!F33 -> 0 | H20: =BS!H33-BS!G33 -> 0 | I20: =BS!I33-BS!H33 -> 0 | J20: =BS!J33-BS!I33 -> 0 | ... U20: =BS!U33-BS!T33 -> 0
A21: =BS!A34 -> Other Current Liabs. | C21: =BS!C34-BS!B34 -> 0 | D21: =BS!D34-BS!C34 -> 0 | E21: =BS!E34-BS!D34 -> 0 | F21: =BS!F34-BS!E34 -> 0 | G21: =BS!G34-BS!F34 -> 0 | H21: =BS!H34-BS!G34 -> 0 | I21: =BS!I34-BS!H34 -> 0 | J21: =BS!J34-BS!I34 -> 0 | ... U21: =BS!U34-BS!T34 -> 0
A23: =A8 -> Cash from Operations | C23: =SUM(C8:C22) -> -50.0625 | D23: =SUM(D8:D22) -> 18.2175 | E23: =SUM(E8:E22) -> 12.811 | F23: =SUM(F8:F22) -> 15.7582 | G23: =SUM(G8:G22) -> 19.05484 | H23: =SUM(H8:H22) -> 18.739558 | I23: =SUM(I8:I22) -> 22.95872 | J23: =SUM(J8:J22) -> 27.781714 | ... U23: =SUM(U8:U22) -> 2451.0276
A25: Cash from Investing
A26: Less: Capex | C26: 0 | D26: 0 | E26: 0 | F26: 0 | G26: 0 | H26: 0 | I26: 0 | J26: 0 | K26: 0 | L26: 0 | M26: 0 | N26: 0 | O26: 0 | P26: 0 | Q26: 0 | R26: 0 | S26: 0 | T26: 0 | U26: 0
A28: =A25 -> Cash from Investing | C28: =SUM(C25:C27) -> 0 | D28: =SUM(D25:D27) -> 0 | E28: =SUM(E25:E27) -> 0 | F28: =SUM(F25:F27) -> 0 | G28: =SUM(G25:G27) -> 0 | H28: =SUM(H25:H27) -> 0 | I28: =SUM(I25:I27) -> 0 | J28: =SUM(J25:J27) -> 0 | ... U28: =SUM(U25:U27) -> 0
A30: Subtotal | C30: =C23+C28 -> -50.0625 | D30: =D23+D28 -> 18.2175 | E30: =E23+E28 -> 12.811 | F30: =F23+F28 -> 15.7582 | G30: =G23+G28 -> 19.05484 | H30: =H23+H28 -> 18.739558 | I30: =I23+I28 -> 22.95872 | J30: =J23+J28 -> 27.781714 | ... U30: =U23+U28 -> 2451.0276
A32: Financing Activities
A33: Plus Borrowing & Investment, Net
A34: =BS!A39 -> Loan 1 | C34: 0 | D34: 0 | E34: 0 | F34: 0 | G34: 0 | H34: 0 | I34: 0 | J34: 0 | K34: 0 | L34: 0 | M34: 0 | N34: 0 | O34: 0 | P34: 0 | Q34: 0 | R34: 0 | S34: 0 | T34: 0 | U34: 0
A35: =BS!A40 -> Loan 2 | C35: 0 | D35: 0 | E35: 0 | F35: 0 | G35: 0 | H35: 0 | I35: 0 | J35: 0 | K35: 0 | L35: 0 | M35: 0 | N35: 0 | O35: 0 | P35: 0 | Q35: 0 | R35: 0 | S35: 0 | T35: 0 | U35: 0
A36: =BS!A45 -> Preferred A | C36: 500 | D36: 0 | E36: 0 | F36: 0 | G36: 0 | H36: 0 | I36: 0 | J36: 0 | K36: 0 | L36: 0 | M36: 0 | N36: 0 | O36: 0 | P36: 0 | Q36: 0 | R36: 0 | S36: 0 | T36: 0 | U36: 0
A37: =BS!A46 -> Preferred B | C37: 0 | D37: 0 | E37: 0 | F37: 0 | G37: 0 | H37: 0 | I37: 0 | J37: 0 | K37: 0 | L37: 0 | M37: 0 | N37: 0 | O37: 0 | P37: 0 | Q37: 0 | R37: 0 | S37: 0 | T37: 0 | U37: 0
A38: =BS!A47 -> Common | C38: 0 | D38: 0 | E38: 0 | F38: 0 | G38: 0 | H38: 0 | I38: 0 | J38: 0 | K38: 0 | L38: 0 | M38: 0 | N38: 0 | O38: 0 | P38: 0 | Q38: 0 | R38: 0 | S38: 0 | T38: 0 | U38: 0
A40: =A32 -> Financing Activities | C40: =SUM(C32:C39) -> 500 | D40: =SUM(D32:D39) -> 0 | E40: =SUM(E32:E39) -> 0 | F40: =SUM(F32:F39) -> 0 | G40: =SUM(G32:G39) -> 0 | H40: =SUM(H32:H39) -> 0 | I40: =SUM(I32:I39) -> 0 | J40: =SUM(J32:J39) -> 0 | ... U40: =SUM(U32:U39) -> 0
A42: Change in Cash | C42: =C30+C40 -> 449.9375 | D42: =D30+D40 -> 18.2175 | E42: =E30+E40 -> 12.811 | F42: =F30+F40 -> 15.7582 | G42: =G30+G40 -> 19.05484 | H42: =H30+H40 -> 18.739558 | I42: =I30+I40 -> 22.95872 | J42: =J30+J40 -> 27.781714 | ... U42: =U30+U40 -> 2451.0276

Sheet Scen
A1: =IS!A1 -> Simple Tech Startup
A2: Scenarios Ex. | B2: Case | C2: 2 | D2: =OFFSET($B$9,$C$2-1,0) -> Case B
A3: =IS!A3 -> ($ in 000s)
C4: =IS!C4 -> Mo. | D4: =IS!D4 -> Mo. | E4: =IS!E4 -> Mo. | F4: =IS!F4 -> Mo. | G4: =IS!G4 -> Mo. | H4: =IS!H4 -> Mo. | I4: =IS!I4 -> Mo. | J4: =IS!J4 -> Mo. | ... U4: =IS!U4 -> Year
A5: Pd. End | C5: =IS!C5 -> 40938 | D5: =IS!D5 -> 40968 | E5: =IS!E5 -> 40998 | F5: =IS!F5 -> 41028 | G5: =IS!G5 -> 41058 | H5: =IS!H5 -> 41088 | I5: =IS!I5 -> 41118 | J5: =IS!J5 -> 41148 | ... U5: =IS!U5 -> 42708
A6: Mos in Pd | C6: =IS!C6 -> 1 | D6: =IS!D6 -> 1 | E6: =IS!E6 -> 1 | F6: =IS!F6 -> 1 | G6: =IS!G6 -> 1 | H6: =IS!H6 -> 1 | I6: =IS!I6 -> 1 | J6: =IS!J6 -> 1 | ... U6: =IS!U6 -> 12
A9: 1 | B9: Case A | C9: 10 | D9: 11 | E9: 12 | F9: 13 | G9: 14 | H9: 15 | I9: 16 | J9: 17 | K9: 18 | L9: 19 | M9: 20 | N9: 21 | O9: 63 | P9: 83 | Q9: 103 | R9: 123 | S9: =R9+50 -> 173 | T9: =S9+50 -> 223 | U9: =T9+50 -> 273
A10: =A9+1 -> 2 | B10: Case B | C10: 20 | D10: 21 | E10: 22 | F10: 23 | G10: 24 | H10: 25 | I10: 26 | J10: 27 | K10: 28 | L10: 29 | M10: 30 | N10: 31 | O10: 93 | P10: 113 | Q10: 133 | R10: 153 | S10: =R10+50 -> 203 | T10: =S10+50 -> 253 | U10: =T10+50 -> 303
A11: =A10+1 -> 3 | B11: Case C | C11: 30 | D11: 31 | E11: 32 | F11: 33 | G11: 34 | H11: 35 | I11: 36 | J11: 37 | K11: 38 | L11: 39 | M11: 40 | N11: 41 | O11: 123 | P11: 143 | Q11: 163 | R11: 183 | S11: =R11+50 -> 233 | T11: =S11+50 -> 283 | U11: =T11+50 -> 333
A12: =A11+1 -> 4 | B12: Case D | C12: 40 | D12: 41 | E12: 42 | F12: 43 | G12: 44 | H12: 45 | I12: 46 | J12: 47 | K12: 48 | L12: 49 | M12: 50 | N12: 51 | O12: 153 | P12: 173 | Q12: 193 | R12: 213 | S12: =R12+50 -> 263 | T12: =S12+50 -> 313 | U12: =T12+50 -> 363
A13: =A12+1 -> 5 | B13: Case E | C13: 50 | D13: 51 | E13: 52 | F13: 53 | G13: 54 | H13: 55 | I13: 56 | J13: 57 | K13: 58 | L13: 59 | M13: 60 | N13: 61 | O13: 183 | P13: 203 | Q13: 223 | R13: 243 | S13: =R13+50 -> 293 | T13: =S13+50 -> 343 | U13: =T13+50 -> 393
A14: Consulting | C14: =OFFSET(C9,$C$2-1,0) -> 20 | D14: =OFFSET(D9,$C$2-1,0) -> 21 | E14: =OFFSET(E9,$C$2-1,0) -> 22 | F14: =OFFSET(F9,$C$2-1,0) -> 23 | G14: =OFFSET(G9,$C$2-1,0) -> 24 | H14: =OFFSET(H9,$C$2-1,0) -> 25 | I14: =OFFSET(I9,$C$2-1,0) -> 26 | J14: =OFFSET(J9,$C$2-1,0) -> 27 | ... U14: =OFFSET(U9,$C$2-1,0) -> 303
A16: 1 | B16: Case A | C16: 10 | D16: 11 | E16: 12 | F16: 13 | G16: 14 | H16: 15 | I16: 16 | J16: 17 | K16: 18 | L16: 19 | M16: 20 | N16: 21 | O16: 63 | P16: 83 | Q16: 103 | R16: 123 | S16: 173 | T16: 223 | U16: 273
A17: =A16+1 -> 2 | B17: Case B | C17: 20 | D17: 21 | E17: 22 | F17: 23 | G17: 24 | H17: 25 | I17: 26 | J17: 27 | K17: 28 | L17: 29 | M17: 30 | N17: 31 | O17: 93 | P17: 113 | Q17: 133 | R17: 153 | S17: 203 | T17: 253 | U17: 303
A18: =A17+1 -> 3 | B18: Case C | C18: 30 | D18: 31 | E18: 32 | F18: 33 | G18: 34 | H18: 35 | I18: 36 | J18: 37 | K18: 38 | L18: 39 | M18: 40 | N18: 41 | O18: 123 | P18: 143 | Q18: 163 | R18: 183 | S18: 233 | T18: 283 | U18: 333
A19: =A18+1 -> 4 | B19: Case D | C19: 40 | D19: 41 | E19: 42 | F19: 43 | G19: 44 | H19: 45 | I19: 46 | J19: 47 | K19: 48 | L19: 49 | M19: 50 | N19: 51 | O19: 153 | P19: 173 | Q19: 193 | R19: 213 | S19: 263 | T19: 313 | U19: 363
A20: =A19+1 -> 5 | B20: Case E | C20: 50 | D20: 51 | E20: 52 | F20: 53 | G20: 54 | H20: 55 | I20: 56 | J20: 57 | K20: 58 | L20: 59 | M20: 60 | N20: 61 | O20: 183 | P20: 203 | Q20: 223 | R20: 243 | S20: 293 | T20: 343 | U20: 393
A21: Client Sales | C21: =OFFSET(C16,$C$2-1,0) -> 20 | D21: =OFFSET(D16,$C$2-1,0) -> 21 | E21: =OFFSET(E16,$C$2-1,0) -> 22 | F21: =OFFSET(F16,$C$2-1,0) -> 23 | G21: =OFFSET(G16,$C$2-1,0) -> 24 | H21: =OFFSET(H16,$C$2-1,0) -> 25 | I21: =OFFSET(I16,$C$2-1,0) -> 26 | J21: =OFFSET(J16,$C$2-1,0) -> 27 | ... U21: =OFFSET(U16,$C$2-1,0) -> 303

Sheet HC
A1: =IS!A1 -> Simple Tech Startup
A2: Headcount
A3: =IS!A3 -> ($ in 000s)
C4: =IS!C4 -> Mo. | D4: =IS!D4 -> Mo. | E4: =IS!E4 -> Mo. | F4: =IS!F4 -> Mo. | G4: =IS!G4 -> Mo. | H4: =IS!H4 -> Mo. | I4: =IS!I4 -> Mo. | J4: =IS!J4 -> Mo. | ... U4: =IS!U4 -> Year
A5: Pd. End | C5: =IS!C5 -> 40938 | D5: =IS!D5 -> 40968 | E5: =IS!E5 -> 40998 | F5: =IS!F5 -> 41028 | G5: =IS!G5 -> 41058 | H5: =IS!H5 -> 41088 | I5: =IS!I5 -> 41118 | J5: =IS!J5 -> 41148 | ... U5: =IS!U5 -> 42708
A6: Mos in Pd | C6: =IS!C6 -> 1 | D6: =IS!D6 -> 1 | E6: =IS!E6 -> 1 | F6: =IS!F6 -> 1 | G6: =IS!G6 -> 1 | H6: =IS!H6 -> 1 | I6: =IS!I6 -> 1 | J6: =IS!J6 -> 1 | ... U6: =IS!U6 -> 12
A8: Name/Role | C8: % of Period
A9: Employee 1 | C9: 1 | D9: 1 | E9: 1 | F9: 1 | G9: 1 | H9: 1 | I9: 1 | J9: 1 | K9: 1 | L9: 1 | M9: 1 | N9: 1 | O9: 1 | P9: 1 | Q9: 1 | R9: 1 | S9: 1 | T9: 1 | U9: 1
A10: Employee 2 | C10: 1 | D10: 1 | E10: 1 | F10: 1 | G10: 1 | H10: 1 | I10: 1 | J10: 1 | K10: 1 | L10: 1 | M10: 1 | N10: 1 | O10: 1 | P10: 1 | Q10: 1 | R10: 1 | S10: 1 | T10: 1 | U10: 1
A11: Employee 3 | C11: 0 | D11: 0 | E11: 1 | F11: 1 | G11: 1 | H11: 1 | I11: 1 | J11: 1 | K11: 1 | L11: 1 | M11: 1 | N11: 1 | O11: 1 | P11: 1 | Q11: 1 | R11: 1 | S11: 1 | T11: 1 | U11: 1
A12: Employee 4 | C12: 0 | D12: 0 | E12: 1 | F12: 1 | G12: 1 | H12: 1 | I12: 1 | J12: 1 | K12: 1 | L12: 1 | M12: 1 | N12: 1 | O12: 1 | P12: 1 | Q12: 1 | R12: 1 | S12: 1 | T12: 1 | U12: 1
A13: Employee 5 | C13: 0 | D13: 0 | E13: 0 | F13: 0 | G13: 0 | H13: 1 | I13: 1 | J13: 1 | K13: 1 | L13: 1 | M13: 1 | N13: 1 | O13: 1 | P13: 1 | Q13: 1 | R13: 1 | S13: 1 | T13: 1 | U13: 1
A14: Employee 6 | C14: 0 | D14: 0 | E14: 0 | F14: 0 | G14: 0 | H14: 0 | I14: 0 | J14: 0 | K14: 0 | L14: 1 | M14: 1 | N14: 1 | O14: 1 | P14: 1 | Q14: 1 | R14: 1 | S14: 1 | T14: 1 | U14: 1
A15: Employee 7 | C15: 0 | D15: 0 | E15: 0 | F15: 0 | G15: 0 | H15: 0 | I15: 0 | J15: 0 | K15: 0 | L15: 0 | M15: 0 | N15: 0 | O15: 1 | P15: 1 | Q15: 1 | R15: 1 | S15: 1 | T15: 1 | U15: 1
A16: Employee 8 | C16: 0 | D16: 0 | E16: 0 | F16: 0 | G16: 0 | H16: 0 | I16: 0 | J16: 0 | K16: 0 | L16: 0 | M16: 0 | N16: 0 | O16: 1 | P16: 1 | Q16: 1 | R16: 1 | S16: 1 | T16: 1 | U16: 1
A17: Employee 9 | C17: 0 | D17: 0 | E17: 0 | F17: 0 | G17: 0 | H17: 0 | I17: 0 | J17: 0 | K17: 0 | L17: 0 | M17: 0 | N17: 0 | O17: 1 | P17: 1 | Q17: 1 | R17: 1 | S17: 1 | T17: 1 | U17: 1
A18: Employee 10 | C18: 0 | D18: 0 | E18: 0 | F18: 0 | G18: 0 | H18: 0 | I18: 0 | J18: 0 | K18: 0 | L18: 0 | M18: 0 | N18: 0 | O18: 1 | P18: 1 | Q18: 1 | R18: 1 | S18: 1 | T18: 1 | U18: 1
A20: Name/Role | B20: $/yr | C20: $ Impact
A21: =A9 -> Employee 1 | B21: 75 | C21: =$B21*C$6/12*C9 -> 6.25 | D21: =$B21*D$6/12*D9 -> 6.25 | E21: =$B21*E$6/12*E9 -> 6.25 | F21: =$B21*F$6/12*F9 -> 6.25 | G21: =$B21*G$6/12*G9 -> 6.25 | H21: =$B21*H$6/12*H9 -> 6.25 | I21: =$B21*I$6/12*I9 -> 6.25 | J21: =$B21*J$6/12*J9 -> 6.25 | ... U21: =$B21*U$6/12*U9 -> 75
A22: =A10 -> Employee 2 | B22: 75 | C22: =$B22*C$6/12*C10 -> 6.25 | D22: =$B22*D$6/12*D10 -> 6.25 | E22: =$B22*E$6/12*E10 -> 6.25 | F22: =$B22*F$6/12*F10 -> 6.25 | G22: =$B22*G$6/12*G10 -> 6.25 | H22: =$B22*H$6/12*H10 -> 6.25 | I22: =$B22*I$6/12*I10 -> 6.25 | J22: =$B22*J$6/12*J10 -> 6.25 | ... U22: =$B22*U$6/12*U10 -> 75
A23: =A11 -> Employee 3 | B23: 75 | C23: =$B23*C$6/12*C11 -> 0 | D23: =$B23*D$6/12*D11 -> 0 | E23: =$B23*E$6/12*E11 -> 6.25 | F23: =$B23*F$6/12*F11 -> 6.25 | G23: =$B23*G$6/12*G11 -> 6.25 | H23: =$B23*H$6/12*H11 -> 6.25 | I23: =$B23*I$6/12*I11 -> 6.25 | J23: =$B23*J$6/12*J11 -> 6.25 | ... U23: =$B23*U$6/12*U11 -> 75
A24: =A12 -> Employee 4 | B24: 75 | C24: =$B24*C$6/12*C12 -> 0 | D24: =$B24*D$6/12*D12 -> 0 | E24: =$B24*E$6/12*E12 -> 6.25 | F24: =$B24*F$6/12*F12 -> 6.25 | G24: =$B24*G$6/12*G12 -> 6.25 | H24: =$B24*H$6/12*H12 -> 6.25 | I24: =$B24*I$6/12*I12 -> 6.25 | J24: =$B24*J$6/12*J12 -> 6.25 | ... U24: =$B24*U$6/12*U12 -> 75
A25: =A13 -> Employee 5 | B25: 75 | C25: =$B25*C$6/12*C13 -> 0 | D25: =$B25*D$6/12*D13 -> 0 | E25: =$B25*E$6/12*E13 -> 0 | F25: =$B25*F$6/12*F13 -> 0 | G25: =$B25*G$6/12*G13 -> 0 | H25: =$B25*H$6/12*H13 -> 6.25 | I25: =$B25*I$6/12*I13 -> 6.25 | J25: =$B25*J$6/12*J13 -> 6.25 | ... U25: =$B25*U$6/12*U13 -> 75
A26: =A14 -> Employee 6 | B26: 75 | C26: =$B26*C$6/12*C14 -> 0 | D26: =$B26*D$6/12*D14 -> 0 | E26: =$B26*E$6/12*E14 -> 0 | F26: =$B26*F$6/12*F14 -> 0 | G26: =$B26*G$6/12*G14 -> 0 | H26: =$B26*H$6/12*H14 -> 0 | I26: =$B26*I$6/12*I14 -> 0 | J26: =$B26*J$6/12*J14 -> 0 | ... U26: =$B26*U$6/12*U14 -> 75
A27: =A15 -> Employee 7 | B27: 75 | C27: =$B27*C$6/12*C15 -> 0 | D27: =$B27*D$6/12*D15 -> 0 | E27: =$B27*E$6/12*E15 -> 0 | F27: =$B27*F$6/12*F15 -> 0 | G27: =$B27*G$6/12*G15 -> 0 | H27: =$B27*H$6/12*H15 -> 0 | I27: =$B27*I$6/12*I15 -> 0 | J27: =$B27*J$6/12*J15 -> 0 | ... U27: =$B27*U$6/12*U15 -> 75
A28: =A16 -> Employee 8 | B28: 75 | C28: =$B28*C$6/12*C16 -> 0 | D28: =$B28*D$6/12*D16 -> 0 | E28: =$B28*E$6/12*E16 -> 0 | F28: =$B28*F$6/12*F16 -> 0 | G28: =$B28*G$6/12*G16 -> 0 | H28: =$B28*H$6/12*H16 -> 0 | I28: =$B28*I$6/12*I16 -> 0 | J28: =$B28*J$6/12*J16 -> 0 | ... U28: =$B28*U$6/12*U16 -> 75
A29: =A17 -> Employee 9 | B29: 75 | C29: =$B29*C$6/12*C17 -> 0 | D29: =$B29*D$6/12*D17 -> 0 | E29: =$B29*E$6/12*E17 -> 0 | F29: =$B29*F$6/12*F17 -> 0 | G29: =$B29*G$6/12*G17 -> 0 | H29: =$B29*H$6/12*H17 -> 0 | I29: =$B29*I$6/12*I17 -> 0 | J29: =$B29*J$6/12*J17 -> 0 | ... U29: =$B29*U$6/12*U17 -> 75
A30: =A18 -> Employee 10 | B30: 75 | C30: =$B30*C$6/12*C18 -> 0 | D30: =$B30*D$6/12*D18 -> 0 | E30: =$B30*E$6/12*E18 -> 0 | F30: =$B30*F$6/12*F18 -> 0 | G30: =$B30*G$6/12*G18 -> 0 | H30: =$B30*H$6/12*H18 -> 0 | I30: =$B30*I$6/12*I18 -> 0 | J30: =$B30*J$6/12*J18 -> 0 | ... U30: =$B30*U$6/12*U18 -> 75
A32: Payroll | C32: =SUM(C20:C31) -> 12.5 | D32: =SUM(D20:D31) -> 12.5 | E32: =SUM(E20:E31) -> 25 | F32: =SUM(F20:F31) -> 25 | G32: =SUM(G20:G31) -> 25 | H32: =SUM(H20:H31) -> 31.25 | I32: =SUM(I20:I31) -> 31.25 | J32: =SUM(J20:J31) -> 31.25 | ... U32: =SUM(U20:U31) -> 750
A33: Payroll Tax | B33: 0.075 | C33: =C32*$B33 -> 0.9375 | D33: =D32*$B33 -> 0.9375 | E33: =E32*$B33 -> 1.875 | F33: =F32*$B33 -> 1.875 | G33: =G32*$B33 -> 1.875 | H33: =H32*$B33 -> 2.34375 | I33: =I32*$B33 -> 2.34375 | J33: =J32*$B33 -> 2.34375 | ... U33: =U32*$B33 -> 56.25
