Workbook
Name AcctDesc: Choices!$B$2:$B$18
Name Address: Choices!$I$2:$I$6
Name HarlemMiddle: Choices!#REF!
Name Period: Choices!#REF!
Name SchoolChart: Choices!$A$2:$A$18
Name SchoolEntity: Choices!$F$2:$F$8
Name VANChart: Choices!#REF!
Name VANEntity: Choices!#REF!

Sheet Policy & Directions
A1: [INSERT ORGANIZATION NAME] PETTY CASH POLICY
B3: When to use: Petty cash is NOT intended to pay for everyday expenses. Instead it is intended to be used for things that can only be funded in cash, emergency items or very small dollar amount items. Some examples would be a tip for a delivery person, food for a student test day, or a $3.50 purchase from the local hardware store. Petty cash should not be used for large purchases. Special approval is needed for items over $200. Under no circumstances shall petty cash monies be used for non-business related items or to pay compensation.
B5: Amount on hand: Under normal circumstances, the petty cash fund should contain between $200-$500 at any given time. At certain times of the year, the schools tend to have above average cash needs. At such times a request can be made by the petty cash custodian to have more than this amount on hand. This request will be considered by the finance group and approved if it is reasonable.
B7: Control: Each petty cash fund has a custodian assigned to it that is responsible for ensuring that all funds are stored securely, spent on appropriate items and all receipts/documentation are maintained. The petty cash custodian is typically the school operations person. Petty cash funds should be stored in a secure, locked location. Only the petty cash custodian and Principal (for emergencies if the petty cash custodian is not available) shall have access to petty cash when not being used for an approved purchase.
B9: Petty cash use: Ideally petty cash is only given out when a receipt is being provided to the petty cash custodian. For things that are delivered to the petty cash custodian, this is simple as the petty cash custodian pays the requested amount and immediately receives the receipt from the vendor. In cases where the petty cash custodian is not the direct payer, the preferred method of payment would be for the employee to make the direct payment to the store/vendor and then provide the receipt to the petty cash custodian for reimbursement. This procedure ensures that all receipts are maintained. If this is not possible, the petty cash custodian may give cash to an employee with the assurance that all change and the related receipt will be returned to the petty cash custodian after the purchase. In such a case, the petty cash custodian shall fill out a Petty Cash Voucher (see "Voucher" tab) and have the employee sign. The voucher includes the name of the employee receiving the funds, the amount of funds provided, the date, the general purpose and a signed acknowledgement from the employee. This voucher shall be provided to the employee once the cash/receipts have been returned.
B11: Receipt/Document Retention: The petty cash custodian is responsible for the retention of all original receipts and documentation. At all time the sum of the receipts, petty cash vouchers and cash on hand should be equal to the amount given to the petty cash custodian.
B13: Tips/Gratuities: All tips should be indicated on the related receipt. If a tip is funded out of petty cash, but the original purchase is not, a copy of the related receipt / documentation should be kept with the petty cash fund with a note indicating that only the tip (and the amount) is included in petty cash. Tips should be provided in a manner consistent with how one would tip if they were using their own funds.
B15: Replenishment: In order for petty cash to be replenished, the petty cash custodian must fill out and submit a petty cash request. The petty cash request form includes the coding for all petty cash expenditures, a reconciliation between actual cash on hand and amounts provided, and a request for new funds. The petty cash custodian should follow the directions included in this file when submitting requests and must submit all related receipts with the request. Receipts should be taped to a piece of paper (fax copies are acceptable) in the order listed on the petty cash request form. Custodians should make requests a few weeks before they would run out to ensure that they have sufficient petty cash on hand.
B17: Thefts: From time to time, there are thefts at the school. If during such theft some petty cash funds are stolen, any related police report should be included with the next petty cash replenishment request along with the amount stolen. If there is no police report, the principal shall acknowledge in writing that a theft has occurred, the date, basic circumstances and how much was stolen.
A19: [INSERT ORGANIZATION NAME] PETTY CASH FORM DIRECTIONS
B21: All cell references are for the Petty Cash tab unless indicated otherwise. The Petty Cash tab is the only tab that needs to be submitted. A Sample Completed Form is included in the School Sample tab
A23: 1 | B23: In cell C3, type the name of the requester, which should be the petty cash custodian
A25: 2 | B25: In cell G3, type in the date (it is currently set to the current date)
A27: 3 | B27: In cell H8, enter the cash on hand at the time of the previous submission
A29: 4 | B29: In cell H9, enter any amounts received for petty cash since the last submission
A31: 5 | B31: In cell D5, using the pull down menu, pick the school that the petty cash request is for
A33: 6 | B33: In cell B11, using the pull down menu, pick the account description that best matches the items purchased in your first receipt. If you are unsure about what the account descriptions mean, there are more detailed descriptions included on the Choices tab in cells A2-C16. For example, if you purchased math workbooks, you should select Consummables
B35: Note: Column C will automatically fill itself - Please do not enter information in this column
A37: 7 | B37: In cell D11, enter the date of the receipt corresponding to the information inputted in cell B11. If there is no date on the receipt, estimate the approximate date.
A39: 8 | B39: In cell E11, enter the vendor (company) that the purchase was made from that corresponds to the information inputted in cell B11
A41: 9 | B41: In cell F11, enter a brief description of the goods purchased corresponding to the information inputted in cell B11. If the receipt is for travel, indicate where the trip was to. If the receipt was for food, list all names of the people that ate. If the receipt is for client entertainment, include the date, purpose and client (donor) names
A43: 10 | B43: In cell H11 enter the amount of the receipt corresponding to the information inputted in cell B11. Include amounts for tips or delivery charges in the amount entered.
B45: Note: If you have a receipt that should be split between multiple account descriptions, you can use multiple lines to indicate this. In each description, indicate the amount of the total receipt.
A47: [INSERT ORGANIZATION NAME] PETTY CASH FORM DIRECTIONS - CONTINUED
A49: 11 | B49: Mark the receipt corresponding to the information inputted in cell B11 with the number in cell A11. For example, if you were submitting the reimbursement on the School Sample tab, you would put a "1" on the receipt from Downtown Seafood
B51: Note: If petty cash was used to give a tip on an item that you have a receipt for, simply write the amount of the tip on the receipt and the total and circle the total. If you just gave a tip (on an order that you bought through a vendor that gets a check, for example), write the amount of the tip on the paper with the other receipts, put a small explanation, the date and the vendor and put a box around it.
A53: 12 | B53: Repeat steps 6-11 for each receipt
B55: Note: If you need more lines, please let the finance staff know and they can add more lines. Please do not add lines using another methodology as the formulas may not work.
A57: 13 | B57: Look at cell F71. It should say OK TO SEND. If it indicates that there is an error, look at column J for information on the error and fix the error before sending in for processing
A59: 14 | B59: Enter the budget manager's name in cell E76. The respective Principals are the budget managers for the schools.
A61: 15 | B61: Tape all receipts to standard pieces of paper (8 1/2 x 11 inch; please stay within the borders of the paper)
A63: 16 | B63: Sign & date the form where it says Requester's Signature (Cell B75) and Date (Cell B79). Then have your budget manager sign and date the form (Cells G76 and F79).
A65: 17 | B65: If submitting electronically, email the fully approved form and receipts (scanned) to the Senior Accountant in the 4th Sector Solutions office. Processing will begin once we receive the emailed form & receipts, your approval and the budget manager's approval. However, you still need to send the originals of the signed form and original receipts to the 4th Sector Solutions office. Please keep a copy of all submitted items in case there is a problem during processing.
A67: 18 | B67: If submitting directly by hard copy send the original signed form and original receipts to the 4th Sector Solutions office. Please keep a copy of all submitted items in case there is a problem during processing.
B69: FINAL CHECK: Before submitting, please make sure that cell F71 does not indicate any errors, it is approved by both yourself and the budget manager and that all receipts are included.
A71: [INSERT ORGANIZATION NAME] PETTY CASH VOUCHER DIRECTIONS
B73: The petty cash voucher is meant to be a temporary solution when cash needs to leave the petty cash box before the receipt is available. For example, if a teacher needs to purchase food in the 500 wing of the school, but the petty cash box is in the 100 wing of the school, then the teacher may need to get the cash prior to actually making the purchase. At all times, the sum of the petty cash vouchers, receipts and cash on hand should equal the amount of petty cash provided.
A75: 1 | B75: Date the petty cash voucher with the date the cash is provided to the staff member
A77: 2 | B77: Write the amount provided to the staff member
A79: 3 | B79: Write a brief description of the intended purpose of the amount requested by the staff member
...

Sheet Petty Cash Request
A1: [INSERT ORGANIZATION NAME] | F1: PETTY CASH REQUEST
B3: Person Requesting Funds | F3: Ending Date | G3: =TODAY() -> 40434 | J3: =IF(C3="Enter Requester","Need to Enter Requester",IF(G3="Enter Date","Need to Enter Date",IF(D5="Enter Entity","Need to Enter Entity",IF(H64>10,IF(F65="","Need to Enter Explanation for Shortfall",""),"")))) -> Need to Enter Entity
B5: Entity | C5: =VLOOKUP(D5,Choices!F2:G8,2,FALSE) -> 0 | D5: Enter Entity
B7: Account Description | C7: Acct # | D7: Date | E7: Vendor | F7: Description of Goods | H7: Amount
B8: Previous Balance | H8: 0
B9: Cash Received
A11: 1 | B11: Enter Account Title | C11: =IF(B11="Enter Account Title","",$C$5*1000000+VLOOKUP(B11,Choices!$A$3:$C$18,3,FALSE)) | J11: =IF(H11=0,"",IF(C11="","Error",""))
A12: 2 | B12: Enter Account Title | C12: =IF(B12="Enter Account Title","",$C$5*1000000+VLOOKUP(B12,Choices!$A$3:$C$18,3,FALSE)) | J12: =IF(H12=0,"",IF(C12="","Error",""))
A13: 3 | B13: Enter Account Title | C13: =IF(B13="Enter Account Title","",$C$5*1000000+VLOOKUP(B13,Choices!$A$3:$C$18,3,FALSE)) | J13: =IF(H13=0,"",IF(C13="","Error",""))
A14: 4 | B14: Enter Account Title | C14: =IF(B14="Enter Account Title","",$C$5*1000000+VLOOKUP(B14,Choices!$A$3:$C$18,3,FALSE)) | J14: =IF(H14=0,"",IF(C14="","Error",""))
A15: 5 | B15: Enter Account Title | C15: =IF(B15="Enter Account Title","",$C$5*1000000+VLOOKUP(B15,Choices!$A$3:$C$18,3,FALSE)) | J15: =IF(H15=0,"",IF(C15="","Error",""))
A16: 6 | B16: Enter Account Title | C16: =IF(B16="Enter Account Title","",$C$5*1000000+VLOOKUP(B16,Choices!$A$3:$C$18,3,FALSE)) | J16: =IF(H16=0,"",IF(C16="","Error",""))
A17: 7 | B17: Enter Account Title | C17: =IF(B17="Enter Account Title","",$C$5*1000000+VLOOKUP(B17,Choices!$A$3:$C$18,3,FALSE)) | J17: =IF(H17=0,"",IF(C17="","Error",""))
A18: 8 | B18: Enter Account Title | C18: =IF(B18="Enter Account Title","",$C$5*1000000+VLOOKUP(B18,Choices!$A$3:$C$18,3,FALSE)) | J18: =IF(H18=0,"",IF(C18="","Error",""))
A19: 9 | B19: Enter Account Title | C19: =IF(B19="Enter Account Title","",$C$5*1000000+VLOOKUP(B19,Choices!$A$3:$C$18,3,FALSE)) | J19: =IF(H19=0,"",IF(C19="","Error",""))
A20: 10 | B20: Enter Account Title | C20: =IF(B20="Enter Account Title","",$C$5*1000000+VLOOKUP(B20,Choices!$A$3:$C$18,3,FALSE)) | J20: =IF(H20=0,"",IF(C20="","Error",""))
A21: 11 | B21: Enter Account Title | C21: =IF(B21="Enter Account Title","",$C$5*1000000+VLOOKUP(B21,Choices!$A$3:$C$18,3,FALSE)) | J21: =IF(H21=0,"",IF(C21="","Error",""))
A22: 12 | B22: Enter Account Title | C22: =IF(B22="Enter Account Title","",$C$5*1000000+VLOOKUP(B22,Choices!$A$3:$C$18,3,FALSE)) | J22: =IF(H22=0,"",IF(C22="","Error",""))
... A60: 50 | B60: Enter Account Title | C60: =IF(B60="Enter Account Title","",$C$5*1000000+VLOOKUP(B60,Choices!$A$3:$C$18,3,FALSE)) | J60: =IF(H60=0,"",IF(C60="","Error",""))
B61: Total Expensed | H61: =SUM(H11:H60) -> 0
B62: Implied Ending Balance | H62: =H8+H9-H61 -> 0
B63: Actual Cash On Hand (Counted from the petty cash box)
B64: Difference | H64: =H62-H63 -> 0
B65: Explanation of Any Difference
B67: Amount Requested | H67: =ROUND(H61,0) -> 0
B69: All Expenses Require Original Receipts
B70: Descriptions for travel are required to include city & state going to as well as purpose
B71: Descriptions for meals are required to include the names of all people eating | F71: =IF(COUNTIF(J11:J60,"ERROR")>0,"ERROR - NOT READY TO SEND IN",IF(J3="","OK TO SEND","ERROR - NOT READY TO SEND IN")) -> ERROR - NOT READY TO SEND IN
B72: Descriptions for client entertainment are required to include date, purpose and client (donor) names
B77: Requester's Signature | E77: Approver's Name | G77: Approver's Signature
B80: Date | G80: Date
B85: FINAL CHECK
B86: Please make sure to submit all of the items below
B87: 1) This form with no Error Messages
B88: 2) Employee signature or electonic approval if emailing
B89: 3) Approver signature or electronic approval from the manager
B90: 4) All receipts taped to a standard sheet of paper with the receipts labeled to match the numbers in column A
A92: * Last updated June 22, 2010

Sheet Voucher
A1: Petty Cash Voucher | F1: Petty Cash Voucher
A3: Date: | B3: _________________________ | F3: Date: | G3: _________________________
A5: Amount Provided: $ | B5: _________________________ | F5: Amount Provided: $ | G5: _________________________
A8: Expected Use: | B8: _________________________ | F8: Expected Use: | G8: _________________________
A10: Name of Borrower: | B10: _________________________ | F10: Name of Borrower: | G10: _________________________
A12: I understand that I am being provided the amount above, which will solely be used for school related purposes. I understand that I am responsible for providing a receipt for the good/servies received for this money and returning any change (at which point this voucher will be disposed of). I understand that if I fail to provide the receipt, that I am personally responsible for returning the full amount listed on this voucher to the school. | F12: I understand that I am being provided the amount above, which will solely be used for school related purposes. I understand that I am responsible for providing a receipt for the good/servies received for this money and returning any change (at which point this voucher will be disposed of). I understand that if I fail to provide the receipt, that I am personally responsible for returning the full amount listed on this voucher to the school.
A16: Signature of Borrower: | B16: _________________________ | F16: Signature of Borrower: | G16: _________________________
A22: Petty Cash Voucher | F22: Petty Cash Voucher
A24: Date: | B24: _________________________ | F24: Date: | G24: _________________________
A26: Amount Provided: $ | B26: _________________________ | F26: Amount Provided: $ | G26: _________________________
A29: Expected Use: | B29: _________________________ | F29: Expected Use: | G29: _________________________
A31: Name of Borrower: | B31: _________________________ | F31: Name of Borrower: | G31: _________________________
A33: I understand that I am being provided the amount above, which will solely be used for school related purposes. I understand that I am responsible for providing a receipt for the good/servies received for this money and returning any change (at which point this voucher will be disposed of). I understand that if I fail to provide the receipt, that I am personally responsible for returning the full amount listed on this voucher to the school. | F33: I understand that I am being provided the amount above, which will solely be used for school related purposes. I understand that I am responsible for providing a receipt for the good/servies received for this money and returning any change (at which point this voucher will be disposed of). I understand that if I fail to provide the receipt, that I am personally responsible for returning the full amount listed on this voucher to the school.
A37: Signature of Borrower: | B37: _________________________ | F37: Signature of Borrower: | G37: _________________________

Sheet School Sample
A1: [INSERT ORGANIZATION NAME] | F1: PETTY CASH REQUEST
B3: Person Requesting Funds | F3: Ending Date | G3: 39805 | J3: =IF(C3="Enter Requester","Need to Enter Requester",IF(G3="Enter Date","Need to Enter Date",IF(D5="Enter Entity","Need to Enter Entity",IF(H64>10,IF(F65="","Need to Enter Explanation for Shortfall",""),""))))
B5: Entity | C5: =VLOOKUP(D5,Choices!F2:G6,2,FALSE) -> 3 | D5: School Name 1
B7: Account Description | C7: Acct # | D7: Date | E7: Vendor | F7: Description of Goods | H7: Amount
B8: Previous Balance | H8: 202.64
B9: Cash Received | H9: 297
A11: 1 | B11: Classroom Supplies | C11: =IF(B11="Enter Account Title","",$C$5*1000000+VLOOKUP(B11,Choices!$A$3:$C$18,3,FALSE)) -> 3110611 | D11: 39739 | E11: Downtown Seafood | F11: Food for PD Event | H11: 38.67 | J11: =IF(H11=0,"",IF(C11="","Error",""))
A12: 2 | B12: Postage & Shipping | C12: =IF(B12="Enter Account Title","",$C$5*1000000+VLOOKUP(B12,Choices!$A$3:$C$18,3,FALSE)) -> 3240535 | D12: 39744 | E12: Certified Mail | F12: Package to State Ed | H12: 3.4 | J12: =IF(H12=0,"",IF(C12="","Error",""))
A13: 3 | B13: Student Recruiting & Parent Involvement | C13: =IF(B13="Enter Account Title","",$C$5*1000000+VLOOKUP(B13,Choices!$A$3:$C$18,3,FALSE)) -> 3240540 | D13: 39746 | E13: My Pizza | F13: Pizza for event at library for 1st year parents | H13: 68.08 | J13: =IF(H13=0,"",IF(C13="","Error",""))
A14: 4 | B14: Travel | C14: =IF(B14="Enter Account Title","",$C$5*1000000+VLOOKUP(B14,Choices!$A$3:$C$18,3,FALSE)) -> 3223580 | D14: 39755 | E14: Taxi | F14: Taxi from School 1 to School 2 for PD | H14: 8.6 | J14: =IF(H14=0,"",IF(C14="","Error",""))
A15: 5 | B15: Maintenance & Repairs | C15: =IF(B15="Enter Account Title","",$C$5*1000000+VLOOKUP(B15,Choices!$A$3:$C$18,3,FALSE)) -> 3262430 | D15: 39762 | E15: Jake's Hardware | F15: Screwdriver | H15: 10.99 | J15: =IF(H15=0,"",IF(C15="","Error",""))
A16: 6 | B16: Professional Development OTPS | C16: =IF(B16="Enter Account Title","",$C$5*1000000+VLOOKUP(B16,Choices!$A$3:$C$18,3,FALSE)) -> 3223325 | D16: 39767 | E16: Binding Shop | F16: Binding for PD books | H16: 23.87 | J16: =IF(H16=0,"",IF(C16="","Error",""))
A17: 7 | B17: Field Lessons | C17: =IF(B17="Enter Account Title","",$C$5*1000000+VLOOKUP(B17,Choices!$A$3:$C$18,3,FALSE)) -> 3110617 | D17: 39777 | E17: IHOP | F17: Food after museum trip for students | H17: 68.25 | J17: =IF(H17=0,"",IF(C17="","Error",""))
A18: 8 | B18: Technology Supplies | C18: =IF(B18="Enter Account Title","",$C$5*1000000+VLOOKUP(B18,Choices!$A$3:$C$18,3,FALSE)) -> 3284611 | D18: 39785 | E18: Circuit City | F18: Replacement battery charger | H18: 29.99 | J18: =IF(H18=0,"",IF(C18="","Error",""))
A19: 9 | B19: Office Supplies | C19: =IF(B19="Enter Account Title","",$C$5*1000000+VLOOKUP(B19,Choices!$A$3:$C$18,3,FALSE)) -> 3240611 | D19: 39787 | E19: Office Depot | F19: Emergency box of paper | H19: 34.99 | J19: =IF(H19=0,"",IF(C19="","Error",""))
A20: 10 | B20: Enter Account Title | C20: =IF(B20="Enter Account Title","",$C$5*1000000+VLOOKUP(B20,Choices!$A$3:$C$18,3,FALSE)) | J20: =IF(H20=0,"",IF(C20="","Error",""))
A21: 11 | B21: Enter Account Title | C21: =IF(B21="Enter Account Title","",$C$5*1000000+VLOOKUP(B21,Choices!$A$3:$C$18,3,FALSE)) | J21: =IF(H21=0,"",IF(C21="","Error",""))
A22: 12 | B22: Enter Account Title | C22: =IF(B22="Enter Account Title","",$C$5*1000000+VLOOKUP(B22,Choices!$A$3:$C$18,3,FALSE)) | J22: =IF(H22=0,"",IF(C22="","Error",""))
A23: 13 | B23: Enter Account Title | C23: =IF(B23="Enter Account Title","",$C$5*1000000+VLOOKUP(B23,Choices!$A$3:$C$18,3,FALSE)) | J23: =IF(H23=0,"",IF(C23="","Error",""))
A24: 14 | B24: Enter Account Title | C24: =IF(B24="Enter Account Title","",$C$5*1000000+VLOOKUP(B24,Choices!$A$3:$C$18,3,FALSE)) | J24: =IF(H24=0,"",IF(C24="","Error",""))
A25: 15 | B25: Enter Account Title | C25: =IF(B25="Enter Account Title","",$C$5*1000000+VLOOKUP(B25,Choices!$A$3:$C$18,3,FALSE)) | J25: =IF(H25=0,"",IF(C25="","Error",""))
A26: 16 | B26: Enter Account Title | C26: =IF(B26="Enter Account Title","",$C$5*1000000+VLOOKUP(B26,Choices!$A$3:$C$18,3,FALSE)) | J26: =IF(H26=0,"",IF(C26="","Error",""))
A27: 17 | B27: Enter Account Title | C27: =IF(B27="Enter Account Title","",$C$5*1000000+VLOOKUP(B27,Choices!$A$3:$C$18,3,FALSE)) | J27: =IF(H27=0,"",IF(C27="","Error",""))
A28: 18 | B28: Enter Account Title | C28: =IF(B28="Enter Account Title","",$C$5*1000000+VLOOKUP(B28,Choices!$A$3:$C$18,3,FALSE)) | J28: =IF(H28=0,"",IF(C28="","Error",""))
A29: 19 | B29: Enter Account Title | C29: =IF(B29="Enter Account Title","",$C$5*1000000+VLOOKUP(B29,Choices!$A$3:$C$18,3,FALSE)) | J29: =IF(H29=0,"",IF(C29="","Error",""))
A30: 20 | B30: Enter Account Title | C30: =IF(B30="Enter Account Title","",$C$5*1000000+VLOOKUP(B30,Choices!$A$3:$C$18,3,FALSE)) | J30: =IF(H30=0,"",IF(C30="","Error",""))
A31: 21 | B31: Enter Account Title | C31: =IF(B31="Enter Account Title","",$C$5*1000000+VLOOKUP(B31,Choices!$A$3:$C$18,3,FALSE)) | J31: =IF(H31=0,"",IF(C31="","Error",""))
... A60: 50 | B60: Enter Account Title | C60: =IF(B60="Enter Account Title","",$C$5*1000000+VLOOKUP(B60,Choices!$A$3:$C$18,3,FALSE)) | J60: =IF(H60=0,"",IF(C60="","Error",""))
B61: Total Expensed | H61: =SUM(H11:H60) -> 286.84
B62: Implied Ending Balance | H62: =H8+H9-H61 -> 212.8
B63: Actual Cash On Hand (Counted from the petty cash box) | H63: 213.2
B64: Difference | H64: =H62-H63 -> -0.4
B65: Explanation of Any Difference | F65: Didn't have change for 10/23 postage, teacher accepted $3
B67: Amount Requested | H67: =ROUND(H61,0) -> 287
B69: All expenses Require Receipts
B70: Descriptions for travel are required to include city & state going to as well as purpose
B71: Descriptions for meals are required to include the names of all people eating | F71: =IF(COUNTIF(J11:J60,"ERROR")>0,"ERROR - NOT READY TO SEND IN",IF(J3="","OK TO SEND","ERROR - NOT READY TO SEND IN")) -> OK TO SEND
B72: Descriptions for client entertainment are required to include date, purpose and client (donor) names
B77: Requester's Signature | E77: Approver's Name | G77: Approver's Signature
B80: Date | G80: Date
...

Sheet Choices
A1: School's Chart of Accounts | F1: School Entity
A2: Enter Account Title | B2: Description | C2: Acct # | F2: Enter Entity
A3: Classroom Supplies | B3: Supplies used in the classroom, whether by students or teachers. This should be used as the default supply code unless specific information identifies a more appropriate account. | C3: 110611 | F3: School Name 1 | G3: 3
A4: Field Lessons | B4: Costs related to field trips including trips to local businesses, colleges and museums. | C4: 110617 | F4: School Name 2 | G4: 5
A5: Food for Special Events | B5: Food for school events including parent events, special occasion parties or student rewards. Food service program shortfalls (such as lunch) should be coded under food service management. Food for in-house professional development meetings should be coded under professional development. | C5: 110618 | F5: School Name 3 | G5: 4
A6: Durables Curriculum (Non-Capital) | B6: Textbooks, reading books and other curriculum materials that last more than a year but do not qualify for capitalization. | C6: 110642 | F6: School Name 4 | G6: 7
A7: Consumables | B7: Workbooks, textbooks or manipulatives that last less than one year related to any subject | C7: 110643 | F7: School Name 5 | G7: 6
A8: Professional Development OTPS | B8: Costs related to the training of principals, teachers or any other employees. Food at staff meetings, staff gifts, conference costs, space rental costs for training or any other professional development related cost other than travel would be coded here. | C8: 223325
A9: Travel | B9: Costs related to the training of principals, teachers or any other employees. Food at staff meetings, staff gifts, conference costs, space rental costs for training or any other professional development related cost other than travel would be coded here. | C9: 223580
A10: Postage & Shipping | B10: Costs associated with mailing or shipping goods including couriers. Typical vendors for this include Federal Express and the United States Postal Service. Postage machine and online postage service costs would also be coded here. | C10: 240535
A11: Student Recruiting & Parent Involvement | B11: Costs incurred to attract and retain students such as advertising. Also includes costs associated with parent involvement and community development such as parent committee costs, parent mailings, non-recruiting parent information sessions, community information sessions or community sponsorships. | C11: 240540
A12: Non-Instructional Travel & Food | B12: Travel, food and other costs not associated with professional development. Such costs would include taxi costs at night, travel costs between entities, or costs associated with meetings with the district. | C12: 240580
A13: Office Supplies | B13: Supplies used primarily in the administrative offices such as folders, binders, pens, pencils and paper clips. The majority of supplies are used within the classroom or by teachers and should be coded to the classroom supplies account. | C13: 240611
A14: Non-Instructional Equipment & Furniture | B14: Equipment and furniture used outside of the classroom such as file cabinets, office fax machine or printer and office furniture. | C14: 240730
A15: Custodial Services & Supplies | B15: Costs associated with cleaning the facilities including cleaning/maintenance companies, cleaning supplies and bathroom supplies. | C15: 262420
A16: Maintenance & Repairs | B16: Ongoing facility & grounds related maintenance and repair costs including things like repairs to air conditioners and water fountains. Also includes minor improvements that do not qualify for capitalization but represent improvements to the facilities such as painting, student art boards and other temporary improvements. | C16: 262430
A17: Teacher Recruiting & Orientation | B17: Costs associated with recruiting new staff to any of the entities including advertising, job postings, job fairs, travel for potential recruits, and recruiting meals. | C17: 283540
A18: Technology Supplies | B18: Supplies and small items associated with the technology infrastructure including replacement keyboards, routers, and cables | C18: 284611
