Workbook

Sheet männlich
A1: Jugend B / männlich | G1: KABU | H1: 11.1 | I1: GEW 1 | J1: 10.6 | K1: GEW 2 | L1: 15.7 | M1: GEW 3 | N1: 15 | O1: VARI | P1: 40 | Q1: MINI | R1: 10 | S1: SPR.BO | T1: 10 | U1: SPR.SE | V1: 5 | W1: BODT | X1: 10 | Y1: ZSTO | Z1: 10 | AA1: 30m | AB1: 3.8 | AC1: 60m | AD1: 8.6 | AE1: 800 m | AF1: 160 | AG1: 2000m | AH1: 500 | AI1: 3000m | AJ1: 790 | AK1: JAP | AL1: 15 | AM1: SKA | AN1: 4 | AO1: LST | AP1: 33 | AQ1: KLZ | AR1: 17 | AS1: RB | AT1: 27 | AU1: ABK | AV1: 10 Wdh. in 3,7 sek | AW1: MED vw | AX1: 10.1 | AY1: MED rw | AZ1: 11.9 | BA1: KHK | BB1: 45 | BC1: JANDA | BD1: 26 | BE1: RAR | BF1: 35 | BG1: RD | BH1: 36 | BI1: HKR | BJ1: 45 | BK1: SWS | BL1: 2.4 | BM1: SEIL | BN1: 100 Wdh in 28 sek | BO1: HBK | BP1: 28 | BQ1: FSF | BR1: 5 | BS1: STT | BT1: 1 | BU1: FLG | BV1: 1 | BW1: FLG | BX1: 1 | BY1: FSP | BZ1: 0 | CA1: FSP | CB1: 0 | CC1: Punkte AT1 Gewandtheit | CE1: Punkte AT2 Ausdauer | CG1: Punkte AT2 Kraft | CI1: Punkte AT3 | CK1: Punkte Technik | CM1: Gesamtpunkte | CN1: Gsamtplatzierung
A2: Reihenf. | B2: Datum: 09.10.2011 | F2: 20
B3: Name | C3: Verein | D3: Gewicht | E3: Größe | F3: Geburtsdat. | G3: Zeit | H3: Pkt. | I3: Zeit | J3: Pkt. | K3: Zeit | L3: Pkt. | M3: Zeit | N3: Pkt. | O3: Zeit | P3: Pkt. | Q3: Note | R3: Pkt. | S3: Note | T3: Pkt. | U3: Note | V3: Pkt. | W3: Note | X3: Pkt. | Y3: Seg. | Z3: Pkt. | AA3: Zeit | AB3: Pkt. | AC3: Zeit | AD3: Pkt. | AE3: Zeit | AF3: Pkt. | AG3: Zeit | AH3: Pkt. | AI3: Zeit | AJ3: Pkt | AK3: Zeit | AL3: Pkt. | AM3: Zeit | AN3: Pkt. | AO3: Anz. | AP3: Pkt. | AQ3: Anz. | AR3: Pkt. | AS3: Anz. | AT3: Pkt. | AU3: Zeit | AV3: Pkt. | AW3: Weite | AX3: Pkt. | AY3: Weite | AZ3: Pkt. | BA3: Zeit | BB3: Pkt. | BC3: Anz. | BD3: Pkt. | BE3: Anz. | BF3: Pkt. | BG3: Anz. | BH3: Pkt. | BI3: Zeit | BJ3: Pkt. | BK3: Weite | BL3: Pkt. | BM3: Zeit | BN3: Pkt. | BO3: cm | BP3: Pkt. | BQ3: grd | BR3: Pkt. | BS3: Note | BT3: Pkt. | BU3: Note | BV3: Pkt. | BW3: Note | BX3: Pkt. | BY3: cm | BZ3: Pkt. | CA3: cm | CB3: Pkt. | CC3: Pkt. | CD3: Platz | CE3: Pkt. | CF3: Platz | CG3: Pkt | CH3: Platz | CI3: Pkt. | CJ3: Platz | CK3: Pkt. | CL3: Platz | CM3: Pkt. | CN3: Platz
A4: 1 | B4: Heider, Paul-Lukas | C4: RCI | D4: 60.7 | E4: 168 | F4: 35836 | H4: =IF(G4="",0,IF(G4<$H$1,50,IF(G4>18.7,0,VLOOKUP(G4,Liste_AT1!$A$3:$B$79,2,0)))) -> 0 | J4: =IF(I4="",0,IF(I4<$J$1,50,IF(I4>22.8,0,VLOOKUP(I4,Liste_AT1!$C$3:$D$125,2,0)))) -> 0 | L4: =IF(K4="",0,IF(K4<$L$1,50,IF(K4>29.2,0,VLOOKUP(K4,Liste_AT1!$E$3:$F$138,2,0)))) -> 0 | M4: 23.2 | N4: =IF(M4="",0,IF(M4<15,50,IF(M4>39.5,0,VLOOKUP(M4,Liste_AT1!$G$3:$H$248,2,0)))) -> 33 | P4: =IF(O4="",0,IF(O4<40,50,IF(O4>108,0,VLOOKUP(O4,Liste_AT1!$I$3:$J$71,2,0)))) -> 0 | R4: =IF(Q4>10,50,IF(Q4<1,0,IF(Q4="",0,VLOOKUP(Q4,Liste_AT1!$K$3:$L$21,2,0)))) -> 0 | T4: =IF(S4>10,50,IF(S4<1,0,VLOOKUP(S4,Liste_AT1!$M$3:$N$21,2,0))) -> 0 | V4: =IF(U4>5,35,IF(U4<1,0,VLOOKUP(U4,Liste_AT1!$O$3:$P$19,2))) -> 0 | W4: 9.6 | X4: =IF(W4>10,50,IF(W4<1,0,VLOOKUP(W4,Liste_AT1!$Q$3:$R$21,2))) -> 48 | Z4: =IF(Y4>10,50,IF(Y4<1,0,VLOOKUP(Y4,Liste_AT1!$S$3:$T$12,2))) -> 0 | AB4: =IF(AA4="",0,IF(AA4<3.8,50,IF(AA4>6.9,0,VLOOKUP(AA4,Liste_AT2!$A$3:$B$34,2)))) -> 0 | AD4: =IF(AC4="",0,IF(AC4<8.6,50,IF(AC4>12.1,0,VLOOKUP(AC4,Liste_AT2!$C$3:$D$38,2)))) -> 0 | AF4: =IF(AE4="",0,IF(AE4<160,50,IF(AE4>231,0,VLOOKUP(AE4,Liste_AT2!$F$3:$G$74,2)))) -> 0 | AG4: 488 | AH4: =IF(AG4="",0,IF(AG4<500,50,IF(AG4>626,0,VLOOKUP(AG4,Liste_AT2!$AU$3:$AW$66,3)))) -> 50 | AJ4: =IF(AI4="",0,IF(AI4<822,50,IF(AI4>948,0,VLOOKUP(AI4,Liste_AT2!$I$3:$J$66,2)))) -> 0 | AK4: 16.4 | AL4: =IF(AK4="",0,IF(AK4<15,50,IF(AK4>22.5,0,VLOOKUP(AK4,Liste_AT2!$K$3:$L$78,2)))) -> 36 | AN4: =IF(AM4="",0,IF(AM4<4,50,IF(AM4>9.4,0,VLOOKUP(AM4,Liste_AT2!$M$3:$N$57,2)))) -> 0 | AP4: =IF(AO4="",0,IF(AO4>33,50,IF(AO4<7,0,VLOOKUP(AO4,Liste_AT2!$Q$3:$R$29,2)))) -> 0 | AR4: =IF(AQ4="",0,IF(AQ4>17,50,IF(AQ4<1,0,VLOOKUP(AQ4,Liste_AT2!$U$3:$V$19,2)))) -> 0 | AT4: =IF(AS4="",0,IF(AS4>27,50,IF(AS4<6,0,VLOOKUP(AS4,Liste_AT2!$W$3:$X$24,2)))) -> 0 | AV4: =IF(AU4="",0,IF(AU4<3.7,50,IF(AU4>8,0,VLOOKUP(AU4,Liste_AT2!$AA$3:$AB$46,2)))) -> 0 | AX4: =IF(AW4="",0,IF(AW4<4,0,IF(AW4>10.1,50,VLOOKUP(AW4,Liste_AT2!$AC$3:$AD$62,2)))) -> 0 | AY4: 11 | AZ4: =IF(AY4="",0,IF(AY4>11.9,50,IF(AY4<5,0,VLOOKUP(AY4,Liste_AT2!$AE$3:$AF$72,2)))) -> 47 | BB4: =IF(BA4="",0,IF(BA4>45,50,IF(BA4<2,0,VLOOKUP(BA4,Liste_AT2!$AG$3:$AH$61,2)))) -> 0 | BD4: =IF(BC4="",0,IF(BC4>26,50,IF(BC4<4,0,VLOOKUP(BC4,Liste_AT2!$AI$3:$AJ$25,2)))) -> 0 | BE4: 21 | BF4: =IF(BE4="",0,IF(BE4>35,50,IF(BE4<14,0,VLOOKUP(BE4,Liste_AT2!$AK$3:$AL$24,2)))) -> 14 | BH4: =IF(BG4="",0,IF(BG4>36,50,IF(BG4<7,0,VLOOKUP(BG4,Liste_AT2!$AM$3:$AN$32,2)))) -> 0 | BJ4: =IF(BI4="",0,IF(BI4>45,50,IF(BI4<6,0,VLOOKUP(BI4,Liste_AT2!$AO$3:$AP$52,2)))) -> 0 | BK4: 1.99 | BL4: =IF(BK4="",0,IF(BK4>2.4,50,IF(BK4<1.15,0,VLOOKUP(BK4,Liste_AT2!$AQ$3:$AR$52,2)))) -> 29 | BM4: 34.8 | BN4: =IF(BM4="",0,IF(BM4<28,50,IF(BM4>62,0,VLOOKUP(BM4,Liste_AT2!$AS$3:$AT$343,2,0)))) -> 43 | BO4: 17 | BP4: =IF(BO4="",0,IF(BO4<1,0,IF(BO4>28,50,VLOOKUP(BO4,Liste_AT3!$A$3:$B$30,2)))) -> 30 | BR4: =IF(BQ4="",0,IF(BQ4<5,50,IF(BQ4>40,0,VLOOKUP(BQ4,Liste_AT3!$C$3:$D$38,2)))) -> 0 | BS4: 1.5 | BT4: =IF(BS4="",0,IF(BS4<1,50,IF(BS4>4.75,0,VLOOKUP(BS4,Liste_AT3!$E$3:$F$18,2)))) -> 42 | BV4: =IF(BU4="",0,IF(BU4<1,50,IF(BU4>4.75,0,VLOOKUP(BU4,Liste_AT3!$G$3:$H$18,2)))) -> 0 | BX4: =IF(BW4="",0,IF(BW4<1,50,IF(BW4>4.75,0,VLOOKUP(BW4,Liste_AT3!$G$3:$H$18,2)))) -> 0 | BZ4: =IF(BY4="",0,IF(BY4>40,0,VLOOKUP(BY4,Liste_AT3!$I$3:$J$43,2,2))) -> 0 | CB4: =IF(CA4="",0,IF(CA4>40,0,VLOOKUP(CA4,Liste_AT3!$I$3:$J$43,2,2))) -> 0 | CC4: =SUM(H4,J4,L4,N4,P4,R4,T4,V4,X4,Z4) -> 81 | CD4: =IF(CC4=0,"",RANK(CC4,$CC$4:$CC$19)) -> 3 | CE4: =SUM(AB4,AD4,AF4,AJ4,AL4,AN4,AH4) -> 86 | CF4: =IF(CE4=0,"",RANK(CE4,$CE$4:$CE$19)) -> 1 | CG4: =SUM(AP4,AR4,AT4,AV4,AX4,AZ4,BB4,BD4,BF4,BH4,BJ4,BL4,BN4) -> 133 | CH4: =IF(CG4=0,"",RANK(CG4,$CG$4:$CG$19)) -> 1 | CI4: =SUM(BP4,BR4) -> 30 | CJ4: =IF(CI4=0,"",RANK(CI4,$CI$4:$CI$19)) -> 2 | CK4: =SUM(BT4,BV4,BX4,BZ4,CB4) -> 42 | CL4: =IF(CK4=0,"",RANK(CK4,$CK$4:$CK$19)) -> 1 | CM4: =SUM(CC4,CE4,CG4,CI4,CK4) -> 372 | CN4: =IF(CM4=0,"",RANK(CM4,$CM$4:$CM$19)) -> 1
A5: 3 | B5: Jannusch, Jonas | C5: SON | D5: 65 | E5: 171 | F5: 35892 | H5: =IF(G5="",0,IF(G5<$H$1,50,IF(G5>18.7,0,VLOOKUP(G5,Liste_AT1!$A$3:$B$79,2,0)))) -> 0 | J5: =IF(I5="",0,IF(I5<$J$1,50,IF(I5>22.8,0,VLOOKUP(I5,Liste_AT1!$C$3:$D$125,2,0)))) -> 0 | L5: =IF(K5="",0,IF(K5<$L$1,50,IF(K5>29.2,0,VLOOKUP(K5,Liste_AT1!$E$3:$F$138,2,0)))) -> 0 | M5: 22.7 | N5: =IF(M5="",0,IF(M5<15,50,IF(M5>39.5,0,VLOOKUP(M5,Liste_AT1!$G$3:$H$248,2,0)))) -> 34 | P5: =IF(O5="",0,IF(O5<40,50,IF(O5>108,0,VLOOKUP(O5,Liste_AT1!$I$3:$J$71,2,0)))) -> 0 | R5: =IF(Q5>10,50,IF(Q5<1,0,IF(Q5="",0,VLOOKUP(Q5,Liste_AT1!$K$3:$L$21,2,0)))) -> 0 | T5: =IF(S5>10,50,IF(S5<1,0,VLOOKUP(S5,Liste_AT1!$M$3:$N$21,2,0))) -> 0 | V5: =IF(U5>5,35,IF(U5<1,0,VLOOKUP(U5,Liste_AT1!$O$3:$P$19,2))) -> 0 | W5: 9.3 | X5: =IF(W5>10,50,IF(W5<1,0,VLOOKUP(W5,Liste_AT1!$Q$3:$R$21,2))) -> 46 | Z5: =IF(Y5>10,50,IF(Y5<1,0,VLOOKUP(Y5,Liste_AT1!$S$3:$T$12,2))) -> 0 | AB5: =IF(AA5="",0,IF(AA5<3.8,50,IF(AA5>6.9,0,VLOOKUP(AA5,Liste_AT2!$A$3:$B$34,2)))) -> 0 | AD5: =IF(AC5="",0,IF(AC5<8.6,50,IF(AC5>12.1,0,VLOOKUP(AC5,Liste_AT2!$C$3:$D$38,2)))) -> 0 | AF5: =IF(AE5="",0,IF(AE5<160,50,IF(AE5>231,0,VLOOKUP(AE5,Liste_AT2!$F$3:$G$74,2)))) -> 0 | AG5: 504 | AH5: =IF(AG5="",0,IF(AG5<500,50,IF(AG5>626,0,VLOOKUP(AG5,Liste_AT2!$AU$3:$AW$66,3)))) -> 48 | AJ5: =IF(AI5="",0,IF(AI5<822,50,IF(AI5>948,0,VLOOKUP(AI5,Liste_AT2!$I$3:$J$66,2)))) -> 0 | AK5: 16.4 | AL5: =IF(AK5="",0,IF(AK5<15,50,IF(AK5>22.5,0,VLOOKUP(AK5,Liste_AT2!$K$3:$L$78,2)))) -> 36 | AN5: =IF(AM5="",0,IF(AM5<4,50,IF(AM5>9.4,0,VLOOKUP(AM5,Liste_AT2!$M$3:$N$57,2)))) -> 0 | AP5: =IF(AO5="",0,IF(AO5>33,50,IF(AO5<7,0,VLOOKUP(AO5,Liste_AT2!$Q$3:$R$29,2)))) -> 0 | AR5: =IF(AQ5="",0,IF(AQ5>17,50,IF(AQ5<1,0,VLOOKUP(AQ5,Liste_AT2!$U$3:$V$19,2)))) -> 0 | AT5: =IF(AS5="",0,IF(AS5>27,50,IF(AS5<6,0,VLOOKUP(AS5,Liste_AT2!$W$3:$X$24,2)))) -> 0 | AV5: =IF(AU5="",0,IF(AU5<3.7,50,IF(AU5>8,0,VLOOKUP(AU5,Liste_AT2!$AA$3:$AB$46,2)))) -> 0 | AX5: =IF(AW5="",0,IF(AW5<4,0,IF(AW5>10.1,50,VLOOKUP(AW5,Liste_AT2!$AC$3:$AD$62,2)))) -> 0 | AY5: 11.3 | AZ5: =IF(AY5="",0,IF(AY5>11.9,50,IF(AY5<5,0,VLOOKUP(AY5,Liste_AT2!$AE$3:$AF$72,2)))) -> 48 | BB5: =IF(BA5="",0,IF(BA5>45,50,IF(BA5<2,0,VLOOKUP(BA5,Liste_AT2!$AG$3:$AH$61,2)))) -> 0 | BD5: =IF(BC5="",0,IF(BC5>26,50,IF(BC5<4,0,VLOOKUP(BC5,Liste_AT2!$AI$3:$AJ$25,2)))) -> 0 | BE5: 16 | BF5: =IF(BE5="",0,IF(BE5>35,50,IF(BE5<14,0,VLOOKUP(BE5,Liste_AT2!$AK$3:$AL$24,2)))) -> 4 | BH5: =IF(BG5="",0,IF(BG5>36,50,IF(BG5<7,0,VLOOKUP(BG5,Liste_AT2!$AM$3:$AN$32,2)))) -> 0 | BJ5: =IF(BI5="",0,IF(BI5>45,50,IF(BI5<6,0,VLOOKUP(BI5,Liste_AT2!$AO$3:$AP$52,2)))) -> 0 | BK5: 2.15 | BL5: =IF(BK5="",0,IF(BK5>2.4,50,IF(BK5<1.15,0,VLOOKUP(BK5,Liste_AT2!$AQ$3:$AR$52,2)))) -> 37 | BM5: 44.4 | BN5: =IF(BM5="",0,IF(BM5<28,50,IF(BM5>62,0,VLOOKUP(BM5,Liste_AT2!$AS$3:$AT$343,2,0)))) -> 28 | BO5: 13.3 | BP5: =IF(BO5="",0,IF(BO5<1,0,IF(BO5>28,50,VLOOKUP(BO5,Liste_AT3!$A$3:$B$30,2)))) -> 22 | BR5: =IF(BQ5="",0,IF(BQ5<5,50,IF(BQ5>40,0,VLOOKUP(BQ5,Liste_AT3!$C$3:$D$38,2)))) -> 0 | BS5: 2.25 | BT5: =IF(BS5="",0,IF(BS5<1,50,IF(BS5>4.75,0,VLOOKUP(BS5,Liste_AT3!$E$3:$F$18,2)))) -> 29 | BV5: =IF(BU5="",0,IF(BU5<1,50,IF(BU5>4.75,0,VLOOKUP(BU5,Liste_AT3!$G$3:$H$18,2)))) -> 0 | BX5: =IF(BW5="",0,IF(BW5<1,50,IF(BW5>4.75,0,VLOOKUP(BW5,Liste_AT3!$G$3:$H$18,2)))) -> 0 | BZ5: =IF(BY5="",0,IF(BY5>40,0,VLOOKUP(BY5,Liste_AT3!$I$3:$J$43,2,2))) -> 0 | CB5: =IF(CA5="",0,IF(CA5>40,0,VLOOKUP(CA5,Liste_AT3!$I$3:$J$43,2,2))) -> 0 | CC5: =SUM(H5,J5,L5,N5,P5,R5,T5,V5,X5,Z5) -> 80 | CD5: =IF(CC5=0,"",RANK(CC5,$CC$4:$CC$19)) -> 5 | CE5: =SUM(AB5,AD5,AF5,AJ5,AL5,AN5,AH5) -> 84 | CF5: =IF(CE5=0,"",RANK(CE5,$CE$4:$CE$19)) -> 2 | CG5: =SUM(AP5,AR5,AT5,AV5,AX5,AZ5,BB5,BD5,BF5,BH5,BJ5,BL5,BN5) -> 117 | CH5: =IF(CG5=0,"",RANK(CG5,$CG$4:$CG$19)) -> 2 | CI5: =SUM(BP5,BR5) -> 22 | CJ5: =IF(CI5=0,"",RANK(CI5,$CI$4:$CI$19)) -> 8 | CK5: =SUM(BT5,BV5,BX5,BZ5,CB5) -> 29 | CL5: =IF(CK5=0,"",RANK(CK5,$CK$4:$CK$19)) -> 7 | CM5: =SUM(CC5,CE5,CG5,CI5,CK5) -> 332 | CN5: =IF(CM5=0,"",RANK(CM5,$CM$4:$CM$19)) -> 2
A6: 2 | B6: Langenhan, Max | C6: FRO | D6: 48.7 | E6: 156 | F6: 36212 | H6: =IF(G6="",0,IF(G6<$H$1,50,IF(G6>18.7,0,VLOOKUP(G6,Liste_AT1!$A$3:$B$79,2,0)))) -> 0 | J6: =IF(I6="",0,IF(I6<$J$1,50,IF(I6>22.8,0,VLOOKUP(I6,Liste_AT1!$C$3:$D$125,2,0)))) -> 0 | L6: =IF(K6="",0,IF(K6<$L$1,50,IF(K6>29.2,0,VLOOKUP(K6,Liste_AT1!$E$3:$F$138,2,0)))) -> 0 | M6: 21.5 | N6: =IF(M6="",0,IF(M6<15,50,IF(M6>39.5,0,VLOOKUP(M6,Liste_AT1!$G$3:$H$248,2,0)))) -> 37 | P6: =IF(O6="",0,IF(O6<40,50,IF(O6>108,0,VLOOKUP(O6,Liste_AT1!$I$3:$J$71,2,0)))) -> 0 | R6: =IF(Q6>10,50,IF(Q6<1,0,IF(Q6="",0,VLOOKUP(Q6,Liste_AT1!$K$3:$L$21,2,0)))) -> 0 | T6: =IF(S6>10,50,IF(S6<1,0,VLOOKUP(S6,Liste_AT1!$M$3:$N$21,2,0))) -> 0 | V6: =IF(U6>5,35,IF(U6<1,0,VLOOKUP(U6,Liste_AT1!$O$3:$P$19,2))) -> 0 | W6: 9.5 | X6: =IF(W6>10,50,IF(W6<1,0,VLOOKUP(W6,Liste_AT1!$Q$3:$R$21,2))) -> 48 | Z6: =IF(Y6>10,50,IF(Y6<1,0,VLOOKUP(Y6,Liste_AT1!$S$3:$T$12,2))) -> 0 | AB6: =IF(AA6="",0,IF(AA6<3.8,50,IF(AA6>6.9,0,VLOOKUP(AA6,Liste_AT2!$A$3:$B$34,2)))) -> 0 | AD6: =IF(AC6="",0,IF(AC6<8.6,50,IF(AC6>12.1,0,VLOOKUP(AC6,Liste_AT2!$C$3:$D$38,2)))) -> 0 | AF6: =IF(AE6="",0,IF(AE6<160,50,IF(AE6>231,0,VLOOKUP(AE6,Liste_AT2!$F$3:$G$74,2)))) -> 0 | AG6: 548 | AH6: =IF(AG6="",0,IF(AG6<500,50,IF(AG6>626,0,VLOOKUP(AG6,Liste_AT2!$AU$3:$AW$66,3)))) -> 26 | AJ6: =IF(AI6="",0,IF(AI6<822,50,IF(AI6>948,0,VLOOKUP(AI6,Liste_AT2!$I$3:$J$66,2)))) -> 0 | AK6: 16.6 | AL6: =IF(AK6="",0,IF(AK6<15,50,IF(AK6>22.5,0,VLOOKUP(AK6,Liste_AT2!$K$3:$L$78,2)))) -> 34 | AN6: =IF(AM6="",0,IF(AM6<4,50,IF(AM6>9.4,0,VLOOKUP(AM6,Liste_AT2!$M$3:$N$57,2)))) -> 0 | AP6: =IF(AO6="",0,IF(AO6>33,50,IF(AO6<7,0,VLOOKUP(AO6,Liste_AT2!$Q$3:$R$29,2)))) -> 0 | AR6: =IF(AQ6="",0,IF(AQ6>17,50,IF(AQ6<1,0,VLOOKUP(AQ6,Liste_AT2!$U$3:$V$19,2)))) -> 0 | AT6: =IF(AS6="",0,IF(AS6>27,50,IF(AS6<6,0,VLOOKUP(AS6,Liste_AT2!$W$3:$X$24,2)))) -> 0 | AV6: =IF(AU6="",0,IF(AU6<3.7,50,IF(AU6>8,0,VLOOKUP(AU6,Liste_AT2!$AA$3:$AB$46,2)))) -> 0 | AX6: =IF(AW6="",0,IF(AW6<4,0,IF(AW6>10.1,50,VLOOKUP(AW6,Liste_AT2!$AC$3:$AD$62,2)))) -> 0 | AY6: 8.8 | AZ6: =IF(AY6="",0,IF(AY6>11.9,50,IF(AY6<5,0,VLOOKUP(AY6,Liste_AT2!$AE$3:$AF$72,2)))) -> 29 | BB6: =IF(BA6="",0,IF(BA6>45,50,IF(BA6<2,0,VLOOKUP(BA6,Liste_AT2!$AG$3:$AH$61,2)))) -> 0 | BD6: =IF(BC6="",0,IF(BC6>26,50,IF(BC6<4,0,VLOOKUP(BC6,Liste_AT2!$AI$3:$AJ$25,2)))) -> 0 | BE6: 20 | BF6: =IF(BE6="",0,IF(BE6>35,50,IF(BE6<14,0,VLOOKUP(BE6,Liste_AT2!$AK$3:$AL$24,2)))) -> 12 | BH6: =IF(BG6="",0,IF(BG6>36,50,IF(BG6<7,0,VLOOKUP(BG6,Liste_AT2!$AM$3:$AN$32,2)))) -> 0 | BJ6: =IF(BI6="",0,IF(BI6>45,50,IF(BI6<6,0,VLOOKUP(BI6,Liste_AT2!$AO$3:$AP$52,2)))) -> 0 | BK6: 1.95 | BL6: =IF(BK6="",0,IF(BK6>2.4,50,IF(BK6<1.15,0,VLOOKUP(BK6,Liste_AT2!$AQ$3:$AR$52,2)))) -> 27 | BM6: 38.4 | BN6: =IF(BM6="",0,IF(BM6<28,50,IF(BM6>62,0,VLOOKUP(BM6,Liste_AT2!$AS$3:$AT$343,2,0)))) -> 39 | BO6: 19.8 | BP6: =IF(BO6="",0,IF(BO6<1,0,IF(BO6>28,50,VLOOKUP(BO6,Liste_AT3!$A$3:$B$30,2)))) -> 34 | BR6: =IF(BQ6="",0,IF(BQ6<5,50,IF(BQ6>40,0,VLOOKUP(BQ6,Liste_AT3!$C$3:$D$38,2)))) -> 0 | BS6: 2 | BT6: =IF(BS6="",0,IF(BS6<1,50,IF(BS6>4.75,0,VLOOKUP(BS6,Liste_AT3!$E$3:$F$18,2)))) -> 34 | BV6: =IF(BU6="",0,IF(BU6<1,50,IF(BU6>4.75,0,VLOOKUP(BU6,Liste_AT3!$G$3:$H$18,2)))) -> 0 | BX6: =IF(BW6="",0,IF(BW6<1,50,IF(BW6>4.75,0,VLOOKUP(BW6,Liste_AT3!$G$3:$H$18,2)))) -> 0 | BZ6: =IF(BY6="",0,IF(BY6>40,0,VLOOKUP(BY6,Liste_AT3!$I$3:$J$43,2,2))) -> 0 | CB6: =IF(CA6="",0,IF(CA6>40,0,VLOOKUP(CA6,Liste_AT3!$I$3:$J$43,2,2))) -> 0 | CC6: =SUM(H6,J6,L6,N6,P6,R6,T6,V6,X6,Z6) -> 85 | CD6: =IF(CC6=0,"",RANK(CC6,$CC$4:$CC$19)) -> 2 | CE6: =SUM(AB6,AD6,AF6,AJ6,AL6,AN6,AH6) -> 60 | CF6: =IF(CE6=0,"",RANK(CE6,$CE$4:$CE$19)) -> 4 | CG6: =SUM(AP6,AR6,AT6,AV6,AX6,AZ6,BB6,BD6,BF6,BH6,BJ6,BL6,BN6) -> 107 | CH6: =IF(CG6=0,"",RANK(CG6,$CG$4:$CG$19)) -> 5 | CI6: =SUM(BP6,BR6) -> 34 | CJ6: =IF(CI6=0,"",RANK(CI6,$CI$4:$CI$19)) -> 1 | CK6: =SUM(BT6,BV6,BX6,BZ6,CB6) -> 34 | CL6: =IF(CK6=0,"",RANK(CK6,$CK$4:$CK$19)) -> 3 | CM6: =SUM(CC6,CE6,CG6,CI6,CK6) -> 320 | CN6: =IF(CM6=0,"",RANK(CM6,$CM$4:$CM$19)) -> 3
A7: 4 | B7: Hoffmann, Lukas | C7: RTS | D7: 59.7 | E7: 168 | F7: 36348 | H7: =IF(G7="",0,IF(G7<$H$1,50,IF(G7>18.7,0,VLOOKUP(G7,Liste_AT1!$A$3:$B$79,2,0)))) -> 0 | J7: =IF(I7="",0,IF(I7<$J$1,50,IF(I7>22.8,0,VLOOKUP(I7,Liste_AT1!$C$3:$D$125,2,0)))) -> 0 | L7: =IF(K7="",0,IF(K7<$L$1,50,IF(K7>29.2,0,VLOOKUP(K7,Liste_AT1!$E$3:$F$138,2,0)))) -> 0 | M7: 19.2 | N7: =IF(M7="",0,IF(M7<15,50,IF(M7>39.5,0,VLOOKUP(M7,Liste_AT1!$G$3:$H$248,2,0)))) -> 41 | P7: =IF(O7="",0,IF(O7<40,50,IF(O7>108,0,VLOOKUP(O7,Liste_AT1!$I$3:$J$71,2,0)))) -> 0 | R7: =IF(Q7>10,50,IF(Q7<1,0,IF(Q7="",0,VLOOKUP(Q7,Liste_AT1!$K$3:$L$21,2,0)))) -> 0 | T7: =IF(S7>10,50,IF(S7<1,0,VLOOKUP(S7,Liste_AT1!$M$3:$N$21,2,0))) -> 0 | V7: =IF(U7>5,35,IF(U7<1,0,VLOOKUP(U7,Liste_AT1!$O$3:$P$19,2))) -> 0 | W7: 9.2 | X7: =IF(W7>10,50,IF(W7<1,0,VLOOKUP(W7,Liste_AT1!$Q$3:$R$21,2))) -> 46 | Z7: =IF(Y7>10,50,IF(Y7<1,0,VLOOKUP(Y7,Liste_AT1!$S$3:$T$12,2))) -> 0 | AB7: =IF(AA7="",0,IF(AA7<3.8,50,IF(AA7>6.9,0,VLOOKUP(AA7,Liste_AT2!$A$3:$B$34,2)))) -> 0 | AD7: =IF(AC7="",0,IF(AC7<8.6,50,IF(AC7>12.1,0,VLOOKUP(AC7,Liste_AT2!$C$3:$D$38,2)))) -> 0 | AF7: =IF(AE7="",0,IF(AE7<160,50,IF(AE7>231,0,VLOOKUP(AE7,Liste_AT2!$F$3:$G$74,2)))) -> 0 | AG7: 601 | AH7: =IF(AG7="",0,IF(AG7<500,50,IF(AG7>626,0,VLOOKUP(AG7,Liste_AT2!$AU$3:$AW$66,3)))) -> 7 | AJ7: =IF(AI7="",0,IF(AI7<822,50,IF(AI7>948,0,VLOOKUP(AI7,Liste_AT2!$I$3:$J$66,2)))) -> 0 | AK7: 16.9 | AL7: =IF(AK7="",0,IF(AK7<15,50,IF(AK7>22.5,0,VLOOKUP(AK7,Liste_AT2!$K$3:$L$78,2)))) -> 31 | AN7: =IF(AM7="",0,IF(AM7<4,50,IF(AM7>9.4,0,VLOOKUP(AM7,Liste_AT2!$M$3:$N$57,2)))) -> 0 | AP7: =IF(AO7="",0,IF(AO7>33,50,IF(AO7<7,0,VLOOKUP(AO7,Liste_AT2!$Q$3:$R$29,2)))) -> 0 | AR7: =IF(AQ7="",0,IF(AQ7>17,50,IF(AQ7<1,0,VLOOKUP(AQ7,Liste_AT2!$U$3:$V$19,2)))) -> 0 | AT7: =IF(AS7="",0,IF(AS7>27,50,IF(AS7<6,0,VLOOKUP(AS7,Liste_AT2!$W$3:$X$24,2)))) -> 0 | AV7: =IF(AU7="",0,IF(AU7<3.7,50,IF(AU7>8,0,VLOOKUP(AU7,Liste_AT2!$AA$3:$AB$46,2)))) -> 0 | AX7: =IF(AW7="",0,IF(AW7<4,0,IF(AW7>10.1,50,VLOOKUP(AW7,Liste_AT2!$AC$3:$AD$62,2)))) -> 0 | AY7: 9.6 | AZ7: =IF(AY7="",0,IF(AY7>11.9,50,IF(AY7<5,0,VLOOKUP(AY7,Liste_AT2!$AE$3:$AF$72,2)))) -> 37 | BB7: =IF(BA7="",0,IF(BA7>45,50,IF(BA7<2,0,VLOOKUP(BA7,Liste_AT2!$AG$3:$AH$61,2)))) -> 0 | BD7: =IF(BC7="",0,IF(BC7>26,50,IF(BC7<4,0,VLOOKUP(BC7,Liste_AT2!$AI$3:$AJ$25,2)))) -> 0 | BE7: 18 | BF7: =IF(BE7="",0,IF(BE7>35,50,IF(BE7<14,0,VLOOKUP(BE7,Liste_AT2!$AK$3:$AL$24,2)))) -> 8 | BH7: =IF(BG7="",0,IF(BG7>36,50,IF(BG7<7,0,VLOOKUP(BG7,Liste_AT2!$AM$3:$AN$32,2)))) -> 0 | BJ7: =IF(BI7="",0,IF(BI7>45,50,IF(BI7<6,0,VLOOKUP(BI7,Liste_AT2!$AO$3:$AP$52,2)))) -> 0 | BK7: 1.84 | BL7: =IF(BK7="",0,IF(BK7>2.4,50,IF(BK7<1.15,0,VLOOKUP(BK7,Liste_AT2!$AQ$3:$AR$52,2)))) -> 22 | BM7: 33.6 | BN7: =IF(BM7="",0,IF(BM7<28,50,IF(BM7>62,0,VLOOKUP(BM7,Liste_AT2!$AS$3:$AT$343,2,0)))) -> 44 | BO7: 16.4 | BP7: =IF(BO7="",0,IF(BO7<1,0,IF(BO7>28,50,VLOOKUP(BO7,Liste_AT3!$A$3:$B$30,2)))) -> 28 | BR7: =IF(BQ7="",0,IF(BQ7<5,50,IF(BQ7>40,0,VLOOKUP(BQ7,Liste_AT3!$C$3:$D$38,2)))) -> 0 | BS7: 2 | BT7: =IF(BS7="",0,IF(BS7<1,50,IF(BS7>4.75,0,VLOOKUP(BS7,Liste_AT3!$E$3:$F$18,2)))) -> 34 | BV7: =IF(BU7="",0,IF(BU7<1,50,IF(BU7>4.75,0,VLOOKUP(BU7,Liste_AT3!$G$3:$H$18,2)))) -> 0 | BX7: =IF(BW7="",0,IF(BW7<1,50,IF(BW7>4.75,0,VLOOKUP(BW7,Liste_AT3!$G$3:$H$18,2)))) -> 0 | BZ7: =IF(BY7="",0,IF(BY7>40,0,VLOOKUP(BY7,Liste_AT3!$I$3:$J$43,2,2))) -> 0 | CB7: =IF(CA7="",0,IF(CA7>40,0,VLOOKUP(CA7,Liste_AT3!$I$3:$J$43,2,2))) -> 0 | CC7: =SUM(H7,J7,L7,N7,P7,R7,T7,V7,X7,Z7) -> 87 | CD7: =IF(CC7=0,"",RANK(CC7,$CC$4:$CC$19)) -> 1 | CE7: =SUM(AB7,AD7,AF7,AJ7,AL7,AN7,AH7) -> 38 | CF7: =IF(CE7=0,"",RANK(CE7,$CE$4:$CE$19)) -> 7 | CG7: =SUM(AP7,AR7,AT7,AV7,AX7,AZ7,BB7,BD7,BF7,BH7,BJ7,BL7,BN7) -> 111 | CH7: =IF(CG7=0,"",RANK(CG7,$CG$4:$CG$19)) -> 4 | CI7: =SUM(BP7,BR7) -> 28 | CJ7: =IF(CI7=0,"",RANK(CI7,$CI$4:$CI$19)) -> 4 | CK7: =SUM(BT7,BV7,BX7,BZ7,CB7) -> 34 | CL7: =IF(CK7=0,"",RANK(CK7,$CK$4:$CK$19)) -> 3 | CM7: =SUM(CC7,CE7,CG7,CI7,CK7) -> 298 | CN7: =IF(CM7=0,"",RANK(CM7,$CM$4:$CM$19)) -> 4
A8: 5 | B8: Gubitz, Paul | C8: TSV ZM | D8: 54.5 | E8: 151 | F8: 36303 | H8: =IF(G8="",0,IF(G8<$H$1,50,IF(G8>18.7,0,VLOOKUP(G8,Liste_AT1!$A$3:$B$79,2,0)))) -> 0 | J8: =IF(I8="",0,IF(I8<$J$1,50,IF(I8>22.8,0,VLOOKUP(I8,Liste_AT1!$C$3:$D$125,2,0)))) -> 0 | L8: =IF(K8="",0,IF(K8<$L$1,50,IF(K8>29.2,0,VLOOKUP(K8,Liste_AT1!$E$3:$F$138,2,0)))) -> 0 | M8: 23.9 | N8: =IF(M8="",0,IF(M8<15,50,IF(M8>39.5,0,VLOOKUP(M8,Liste_AT1!$G$3:$H$248,2,0)))) -> 32 | P8: =IF(O8="",0,IF(O8<40,50,IF(O8>108,0,VLOOKUP(O8,Liste_AT1!$I$3:$J$71,2,0)))) -> 0 | R8: =IF(Q8>10,50,IF(Q8<1,0,IF(Q8="",0,VLOOKUP(Q8,Liste_AT1!$K$3:$L$21,2,0)))) -> 0 | T8: =IF(S8>10,50,IF(S8<1,0,VLOOKUP(S8,Liste_AT1!$M$3:$N$21,2,0))) -> 0 | V8: =IF(U8>5,35,IF(U8<1,0,VLOOKUP(U8,Liste_AT1!$O$3:$P$19,2))) -> 0 | W8: 9.3 | X8: =IF(W8>10,50,IF(W8<1,0,VLOOKUP(W8,Liste_AT1!$Q$3:$R$21,2))) -> 46 | Z8: =IF(Y8>10,50,IF(Y8<1,0,VLOOKUP(Y8,Liste_AT1!$S$3:$T$12,2))) -> 0 | AB8: =IF(AA8="",0,IF(AA8<3.8,50,IF(AA8>6.9,0,VLOOKUP(AA8,Liste_AT2!$A$3:$B$34,2)))) -> 0 | AD8: =IF(AC8="",0,IF(AC8<8.6,50,IF(AC8>12.1,0,VLOOKUP(AC8,Liste_AT2!$C$3:$D$38,2)))) -> 0 | AF8: =IF(AE8="",0,IF(AE8<160,50,IF(AE8>231,0,VLOOKUP(AE8,Liste_AT2!$F$3:$G$74,2)))) -> 0 | AG8: - | AH8: =IF(AG8="",0,IF(AG8<500,50,IF(AG8>626,0,VLOOKUP(AG8,Liste_AT2!$AU$3:$AW$66,3)))) -> 0 | AJ8: =IF(AI8="",0,IF(AI8<822,50,IF(AI8>948,0,VLOOKUP(AI8,Liste_AT2!$I$3:$J$66,2)))) -> 0 | AK8: 16.9 | AL8: =IF(AK8="",0,IF(AK8<15,50,IF(AK8>22.5,0,VLOOKUP(AK8,Liste_AT2!$K$3:$L$78,2)))) -> 31 | AN8: =IF(AM8="",0,IF(AM8<4,50,IF(AM8>9.4,0,VLOOKUP(AM8,Liste_AT2!$M$3:$N$57,2)))) -> 0 | AP8: =IF(AO8="",0,IF(AO8>33,50,IF(AO8<7,0,VLOOKUP(AO8,Liste_AT2!$Q$3:$R$29,2)))) -> 0 | AR8: =IF(AQ8="",0,IF(AQ8>17,50,IF(AQ8<1,0,VLOOKUP(AQ8,Liste_AT2!$U$3:$V$19,2)))) -> 0 | AT8: =IF(AS8="",0,IF(AS8>27,50,IF(AS8<6,0,VLOOKUP(AS8,Liste_AT2!$W$3:$X$24,2)))) -> 0 | AV8: =IF(AU8="",0,IF(AU8<3.7,50,IF(AU8>8,0,VLOOKUP(AU8,Liste_AT2!$AA$3:$AB$46,2)))) -> 0 | AX8: =IF(AW8="",0,IF(AW8<4,0,IF(AW8>10.1,50,VLOOKUP(AW8,Liste_AT2!$AC$3:$AD$62,2)))) -> 0 | AY8: 9.4 | AZ8: =IF(AY8="",0,IF(AY8>11.9,50,IF(AY8<5,0,VLOOKUP(AY8,Liste_AT2!$AE$3:$AF$72,2)))) -> 35 | BB8: =IF(BA8="",0,IF(BA8>45,50,IF(BA8<2,0,VLOOKUP(BA8,Liste_AT2!$AG$3:$AH$61,2)))) -> 0 | BD8: =IF(BC8="",0,IF(BC8>26,50,IF(BC8<4,0,VLOOKUP(BC8,Liste_AT2!$AI$3:$AJ$25,2)))) -> 0 | BE8: 22 | BF8: =IF(BE8="",0,IF(BE8>35,50,IF(BE8<14,0,VLOOKUP(BE8,Liste_AT2!$AK$3:$AL$24,2)))) -> 16 | BH8: =IF(BG8="",0,IF(BG8>36,50,IF(BG8<7,0,VLOOKUP(BG8,Liste_AT2!$AM$3:$AN$32,2)))) -> 0 | BJ8: =IF(BI8="",0,IF(BI8>45,50,IF(BI8<6,0,VLOOKUP(BI8,Liste_AT2!$AO$3:$AP$52,2)))) -> 0 | BK8: 1.77 | BL8: =IF(BK8="",0,IF(BK8>2.4,50,IF(BK8<1.15,0,VLOOKUP(BK8,Liste_AT2!$AQ$3:$AR$52,2)))) -> 18 | BM8: 32 | BN8: =IF(BM8="",0,IF(BM8<28,50,IF(BM8>62,0,VLOOKUP(BM8,Liste_AT2!$AS$3:$AT$343,2,0)))) -> 46 | BO8: 14.5 | BP8: =IF(BO8="",0,IF(BO8<1,0,IF(BO8>28,50,VLOOKUP(BO8,Liste_AT3!$A$3:$B$30,2)))) -> 24 | BR8: =IF(BQ8="",0,IF(BQ8<5,50,IF(BQ8>40,0,VLOOKUP(BQ8,Liste_AT3!$C$3:$D$38,2)))) -> 0 | BS8: 2 | BT8: =IF(BS8="",0,IF(BS8<1,50,IF(BS8>4.75,0,VLOOKUP(BS8,Liste_AT3!$E$3:$F$18,2)))) -> 34 | BV8: =IF(BU8="",0,IF(BU8<1,50,IF(BU8>4.75,0,VLOOKUP(BU8,Liste_AT3!$G$3:$H$18,2)))) -> 0 | BX8: =IF(BW8="",0,IF(BW8<1,50,IF(BW8>4.75,0,VLOOKUP(BW8,Liste_AT3!$G$3:$H$18,2)))) -> 0 | BZ8: =IF(BY8="",0,IF(BY8>40,0,VLOOKUP(BY8,Liste_AT3!$I$3:$J$43,2,2))) -> 0 | CB8: =IF(CA8="",0,IF(CA8>40,0,VLOOKUP(CA8,Liste_AT3!$I$3:$J$43,2,2))) -> 0 | CC8: =SUM(H8,J8,L8,N8,P8,R8,T8,V8,X8,Z8) -> 78 | CD8: =IF(CC8=0,"",RANK(CC8,$CC$4:$CC$19)) -> 6 | CE8: =SUM(AB8,AD8,AF8,AJ8,AL8,AN8,AH8) -> 31 | CF8: =IF(CE8=0,"",RANK(CE8,$CE$4:$CE$19)) -> 8 | CG8: =SUM(AP8,AR8,AT8,AV8,AX8,AZ8,BB8,BD8,BF8,BH8,BJ8,BL8,BN8) -> 115 | CH8: =IF(CG8=0,"",RANK(CG8,$CG$4:$CG$19)) -> 3 | CI8: =SUM(BP8,BR8) -> 24 | CJ8: =IF(CI8=0,"",RANK(CI8,$CI$4:$CI$19)) -> 7 | CK8: =SUM(BT8,BV8,BX8,BZ8,CB8) -> 34 | CL8: =IF(CK8=0,"",RANK(CK8,$CK$4:$CK$19)) -> 3 | CM8: =SUM(CC8,CE8,CG8,CI8,CK8) -> 282 | CN8: =IF(CM8=0,"",RANK(CM8,$CM$4:$CM$19)) -> 5
A9: 6 | B9: Schneider, Robin | C9: RCI | D9: 39.8 | E9: 151 | F9: 36513 | H9: =IF(G9="",0,IF(G9<$H$1,50,IF(G9>18.7,0,VLOOKUP(G9,Liste_AT1!$A$3:$B$79,2,0)))) -> 0 | J9: =IF(I9="",0,IF(I9<$J$1,50,IF(I9>22.8,0,VLOOKUP(I9,Liste_AT1!$C$3:$D$125,2,0)))) -> 0 | L9: =IF(K9="",0,IF(K9<$L$1,50,IF(K9>29.2,0,VLOOKUP(K9,Liste_AT1!$E$3:$F$138,2,0)))) -> 0 | M9: 28.2 | N9: =IF(M9="",0,IF(M9<15,50,IF(M9>39.5,0,VLOOKUP(M9,Liste_AT1!$G$3:$H$248,2,0)))) -> 23 | P9: =IF(O9="",0,IF(O9<40,50,IF(O9>108,0,VLOOKUP(O9,Liste_AT1!$I$3:$J$71,2,0)))) -> 0 | R9: =IF(Q9>10,50,IF(Q9<1,0,IF(Q9="",0,VLOOKUP(Q9,Liste_AT1!$K$3:$L$21,2,0)))) -> 0 | T9: =IF(S9>10,50,IF(S9<1,0,VLOOKUP(S9,Liste_AT1!$M$3:$N$21,2,0))) -> 0 | V9: =IF(U9>5,35,IF(U9<1,0,VLOOKUP(U9,Liste_AT1!$O$3:$P$19,2))) -> 0 | W9: 9.3 | X9: =IF(W9>10,50,IF(W9<1,0,VLOOKUP(W9,Liste_AT1!$Q$3:$R$21,2))) -> 46 | Z9: =IF(Y9>10,50,IF(Y9<1,0,VLOOKUP(Y9,Liste_AT1!$S$3:$T$12,2))) -> 0 | AB9: =IF(AA9="",0,IF(AA9<3.8,50,IF(AA9>6.9,0,VLOOKUP(AA9,Liste_AT2!$A$3:$B$34,2)))) -> 0 | AD9: =IF(AC9="",0,IF(AC9<8.6,50,IF(AC9>12.1,0,VLOOKUP(AC9,Liste_AT2!$C$3:$D$38,2)))) -> 0 | AF9: =IF(AE9="",0,IF(AE9<160,50,IF(AE9>231,0,VLOOKUP(AE9,Liste_AT2!$F$3:$G$74,2)))) -> 0 | AG9: 513 | AH9: =IF(AG9="",0,IF(AG9<500,50,IF(AG9>626,0,VLOOKUP(AG9,Liste_AT2!$AU$3:$AW$66,3)))) -> 44 | AJ9: =IF(AI9="",0,IF(AI9<822,50,IF(AI9>948,0,VLOOKUP(AI9,Liste_AT2!$I$3:$J$66,2)))) -> 0 | AK9: 17 | AL9: =IF(AK9="",0,IF(AK9<15,50,IF(AK9>22.5,0,VLOOKUP(AK9,Liste_AT2!$K$3:$L$78,2)))) -> 30 | AN9: =IF(AM9="",0,IF(AM9<4,50,IF(AM9>9.4,0,VLOOKUP(AM9,Liste_AT2!$M$3:$N$57,2)))) -> 0 | AP9: =IF(AO9="",0,IF(AO9>33,50,IF(AO9<7,0,VLOOKUP(AO9,Liste_AT2!$Q$3:$R$29,2)))) -> 0 | AR9: =IF(AQ9="",0,IF(AQ9>17,50,IF(AQ9<1,0,VLOOKUP(AQ9,Liste_AT2!$U$3:$V$19,2)))) -> 0 | AT9: =IF(AS9="",0,IF(AS9>27,50,IF(AS9<6,0,VLOOKUP(AS9,Liste_AT2!$W$3:$X$24,2)))) -> 0 | AV9: =IF(AU9="",0,IF(AU9<3.7,50,IF(AU9>8,0,VLOOKUP(AU9,Liste_AT2!$AA$3:$AB$46,2)))) -> 0 | AX9: =IF(AW9="",0,IF(AW9<4,0,IF(AW9>10.1,50,VLOOKUP(AW9,Liste_AT2!$AC$3:$AD$62,2)))) -> 0 | AY9: 6.7 | AZ9: =IF(AY9="",0,IF(AY9>11.9,50,IF(AY9<5,0,VLOOKUP(AY9,Liste_AT2!$AE$3:$AF$72,2)))) -> 9 | BB9: =IF(BA9="",0,IF(BA9>45,50,IF(BA9<2,0,VLOOKUP(BA9,Liste_AT2!$AG$3:$AH$61,2)))) -> 0 | BD9: =IF(BC9="",0,IF(BC9>26,50,IF(BC9<4,0,VLOOKUP(BC9,Liste_AT2!$AI$3:$AJ$25,2)))) -> 0 | BE9: 19 | BF9: =IF(BE9="",0,IF(BE9>35,50,IF(BE9<14,0,VLOOKUP(BE9,Liste_AT2!$AK$3:$AL$24,2)))) -> 10 | BH9: =IF(BG9="",0,IF(BG9>36,50,IF(BG9<7,0,VLOOKUP(BG9,Liste_AT2!$AM$3:$AN$32,2)))) -> 0 | BJ9: =IF(BI9="",0,IF(BI9>45,50,IF(BI9<6,0,VLOOKUP(BI9,Liste_AT2!$AO$3:$AP$52,2)))) -> 0 | BK9: 1.72 | BL9: =IF(BK9="",0,IF(BK9>2.4,50,IF(BK9<1.15,0,VLOOKUP(BK9,Liste_AT2!$AQ$3:$AR$52,2)))) -> 16 | BM9: 39.3 | BN9: =IF(BM9="",0,IF(BM9<28,50,IF(BM9>62,0,VLOOKUP(BM9,Liste_AT2!$AS$3:$AT$343,2,0)))) -> 38 | BO9: 9 | BP9: =IF(BO9="",0,IF(BO9<1,0,IF(BO9>28,50,VLOOKUP(BO9,Liste_AT3!$A$3:$B$30,2)))) -> 14 | BR9: =IF(BQ9="",0,IF(BQ9<5,50,IF(BQ9>40,0,VLOOKUP(BQ9,Liste_AT3!$C$3:$D$38,2)))) -> 0 | BS9: 2 | BT9: =IF(BS9="",0,IF(BS9<1,50,IF(BS9>4.75,0,VLOOKUP(BS9,Liste_AT3!$E$3:$F$18,2)))) -> 34 | BV9: =IF(BU9="",0,IF(BU9<1,50,IF(BU9>4.75,0,VLOOKUP(BU9,Liste_AT3!$G$3:$H$18,2)))) -> 0 | BX9: =IF(BW9="",0,IF(BW9<1,50,IF(BW9>4.75,0,VLOOKUP(BW9,Liste_AT3!$G$3:$H$18,2)))) -> 0 | BZ9: =IF(BY9="",0,IF(BY9>40,0,VLOOKUP(BY9,Liste_AT3!$I$3:$J$43,2,2))) -> 0 | CB9: =IF(CA9="",0,IF(CA9>40,0,VLOOKUP(CA9,Liste_AT3!$I$3:$J$43,2,2))) -> 0 | CC9: =SUM(H9,J9,L9,N9,P9,R9,T9,V9,X9,Z9) -> 69 | CD9: =IF(CC9=0,"",RANK(CC9,$CC$4:$CC$19)) -> 9 | CE9: =SUM(AB9,AD9,AF9,AJ9,AL9,AN9,AH9) -> 74 | CF9: =IF(CE9=0,"",RANK(CE9,$CE$4:$CE$19)) -> 3 | CG9: =SUM(AP9,AR9,AT9,AV9,AX9,AZ9,BB9,BD9,BF9,BH9,BJ9,BL9,BN9) -> 73 | CH9: =IF(CG9=0,"",RANK(CG9,$CG$4:$CG$19)) -> 9 | CI9: =SUM(BP9,BR9) -> 14 | CJ9: =IF(CI9=0,"",RANK(CI9,$CI$4:$CI$19)) -> 10 | CK9: =SUM(BT9,BV9,BX9,BZ9,CB9) -> 34 | CL9: =IF(CK9=0,"",RANK(CK9,$CK$4:$CK$19)) -> 3 | CM9: =SUM(CC9,CE9,CG9,CI9,CK9) -> 264 | CN9: =IF(CM9=0,"",RANK(CM9,$CM$4:$CM$19)) -> 6
A10: 16 | B10: Jaensch, Thomas | C10: RRC ZM | D10: 46.2 | E10: 164 | F10: 36539 | H10: =IF(G10="",0,IF(G10<$H$1,50,IF(G10>18.7,0,VLOOKUP(G10,Liste_AT1!$A$3:$B$79,2,0)))) -> 0 | J10: =IF(I10="",0,IF(I10<$J$1,50,IF(I10>22.8,0,VLOOKUP(I10,Liste_AT1!$C$3:$D$125,2,0)))) -> 0 | L10: =IF(K10="",0,IF(K10<$L$1,50,IF(K10>29.2,0,VLOOKUP(K10,Liste_AT1!$E$3:$F$138,2,0)))) -> 0 | M10: 28.9 | N10: =IF(M10="",0,IF(M10<15,50,IF(M10>39.5,0,VLOOKUP(M10,Liste_AT1!$G$3:$H$248,2,0)))) -> 22 | P10: =IF(O10="",0,IF(O10<40,50,IF(O10>108,0,VLOOKUP(O10,Liste_AT1!$I$3:$J$71,2,0)))) -> 0 | R10: =IF(Q10>10,50,IF(Q10<1,0,IF(Q10="",0,VLOOKUP(Q10,Liste_AT1!$K$3:$L$21,2,0)))) -> 0 | T10: =IF(S10>10,50,IF(S10<1,0,VLOOKUP(S10,Liste_AT1!$M$3:$N$21,2,0))) -> 0 | V10: =IF(U10>5,35,IF(U10<1,0,VLOOKUP(U10,Liste_AT1!$O$3:$P$19,2))) -> 0 | W10: 9.2 | X10: =IF(W10>10,50,IF(W10<1,0,VLOOKUP(W10,Liste_AT1!$Q$3:$R$21,2))) -> 46 | Z10: =IF(Y10>10,50,IF(Y10<1,0,VLOOKUP(Y10,Liste_AT1!$S$3:$T$12,2))) -> 0 | AB10: =IF(AA10="",0,IF(AA10<3.8,50,IF(AA10>6.9,0,VLOOKUP(AA10,Liste_AT2!$A$3:$B$34,2)))) -> 0 | AD10: =IF(AC10="",0,IF(AC10<8.6,50,IF(AC10>12.1,0,VLOOKUP(AC10,Liste_AT2!$C$3:$D$38,2)))) -> 0 | AF10: =IF(AE10="",0,IF(AE10<160,50,IF(AE10>231,0,VLOOKUP(AE10,Liste_AT2!$F$3:$G$74,2)))) -> 0 | AG10: 549 | AH10: =IF(AG10="",0,IF(AG10<500,50,IF(AG10>626,0,VLOOKUP(AG10,Liste_AT2!$AU$3:$AW$66,3)))) -> 26 | AJ10: =IF(AI10="",0,IF(AI10<822,50,IF(AI10>948,0,VLOOKUP(AI10,Liste_AT2!$I$3:$J$66,2)))) -> 0 | AK10: 18.3 | AL10: =IF(AK10="",0,IF(AK10<15,50,IF(AK10>22.5,0,VLOOKUP(AK10,Liste_AT2!$K$3:$L$78,2)))) -> 17 | AN10: =IF(AM10="",0,IF(AM10<4,50,IF(AM10>9.4,0,VLOOKUP(AM10,Liste_AT2!$M$3:$N$57,2)))) -> 0 | AP10: =IF(AO10="",0,IF(AO10>33,50,IF(AO10<7,0,VLOOKUP(AO10,Liste_AT2!$Q$3:$R$29,2)))) -> 0 | AR10: =IF(AQ10="",0,IF(AQ10>17,50,IF(AQ10<1,0,VLOOKUP(AQ10,Liste_AT2!$U$3:$V$19,2)))) -> 0 | AT10: =IF(AS10="",0,IF(AS10>27,50,IF(AS10<6,0,VLOOKUP(AS10,Liste_AT2!$W$3:$X$24,2)))) -> 0 | AV10: =IF(AU10="",0,IF(AU10<3.7,50,IF(AU10>8,0,VLOOKUP(AU10,Liste_AT2!$AA$3:$AB$46,2)))) -> 0 | AX10: =IF(AW10="",0,IF(AW10<4,0,IF(AW10>10.1,50,VLOOKUP(AW10,Liste_AT2!$AC$3:$AD$62,2)))) -> 0 | AY10: 8 | AZ10: =IF(AY10="",0,IF(AY10>11.9,50,IF(AY10<5,0,VLOOKUP(AY10,Liste_AT2!$AE$3:$AF$72,2)))) -> 21 | BB10: =IF(BA10="",0,IF(BA10>45,50,IF(BA10<2,0,VLOOKUP(BA10,Liste_AT2!$AG$3:$AH$61,2)))) -> 0 | BD10: =IF(BC10="",0,IF(BC10>26,50,IF(BC10<4,0,VLOOKUP(BC10,Liste_AT2!$AI$3:$AJ$25,2)))) -> 0 | BE10: 17 | BF10: =IF(BE10="",0,IF(BE10>35,50,IF(BE10<14,0,VLOOKUP(BE10,Liste_AT2!$AK$3:$AL$24,2)))) -> 6 | BH10: =IF(BG10="",0,IF(BG10>36,50,IF(BG10<7,0,VLOOKUP(BG10,Liste_AT2!$AM$3:$AN$32,2)))) -> 0 | BJ10: =IF(BI10="",0,IF(BI10>45,50,IF(BI10<6,0,VLOOKUP(BI10,Liste_AT2!$AO$3:$AP$52,2)))) -> 0 | BK10: 1.63 | BL10: =IF(BK10="",0,IF(BK10>2.4,50,IF(BK10<1.15,0,VLOOKUP(BK10,Liste_AT2!$AQ$3:$AR$52,2)))) -> 11 | BM10: 39.9 | BN10: =IF(BM10="",0,IF(BM10<28,50,IF(BM10>62,0,VLOOKUP(BM10,Liste_AT2!$AS$3:$AT$343,2,0)))) -> 37 | BO10: 15 | BP10: =IF(BO10="",0,IF(BO10<1,0,IF(BO10>28,50,VLOOKUP(BO10,Liste_AT3!$A$3:$B$30,2)))) -> 26 | BR10: =IF(BQ10="",0,IF(BQ10<5,50,IF(BQ10>40,0,VLOOKUP(BQ10,Liste_AT3!$C$3:$D$38,2)))) -> 0 | BS10: 1.75 | BT10: =IF(BS10="",0,IF(BS10<1,50,IF(BS10>4.75,0,VLOOKUP(BS10,Liste_AT3!$E$3:$F$18,2)))) -> 38 | BV10: =IF(BU10="",0,IF(BU10<1,50,IF(BU10>4.75,0,VLOOKUP(BU10,Liste_AT3!$G$3:$H$18,2)))) -> 0 | BX10: =IF(BW10="",0,IF(BW10<1,50,IF(BW10>4.75,0,VLOOKUP(BW10,Liste_AT3!$G$3:$H$18,2)))) -> 0 | BZ10: =IF(BY10="",0,IF(BY10>40,0,VLOOKUP(BY10,Liste_AT3!$I$3:$J$43,2,2))) -> 0 | CB10: =IF(CA10="",0,IF(CA10>40,0,VLOOKUP(CA10,Liste_AT3!$I$3:$J$43,2,2))) -> 0 | CC10: =SUM(H10,J10,L10,N10,P10,R10,T10,V10,X10,Z10) -> 68 | CD10: =IF(CC10=0,"",RANK(CC10,$CC$4:$CC$19)) -> 10 | CE10: =SUM(AB10,AD10,AF10,AJ10,AL10,AN10,AH10) -> 43 | CF10: =IF(CE10=0,"",RANK(CE10,$CE$4:$CE$19)) -> 6 | CG10: =SUM(AP10,AR10,AT10,AV10,AX10,AZ10,BB10,BD10,BF10,BH10,BJ10,BL10,BN10) -> 75 | CH10: =IF(CG10=0,"",RANK(CG10,$CG$4:$CG$19)) -> 8 | CI10: =SUM(BP10,BR10) -> 26 | CJ10: =IF(CI10=0,"",RANK(CI10,$CI$4:$CI$19)) -> 5 | CK10: =SUM(BT10,BV10,BX10,BZ10,CB10) -> 38 | CL10: =IF(CK10=0,"",RANK(CK10,$CK$4:$CK$19)) -> 2 | CM10: =SUM(CC10,CE10,CG10,CI10,CK10) -> 250 | CN10: =IF(CM10=0,"",RANK(CM10,$CM$4:$CM$19)) -> 7
A11: 9 | B11: Orlamünder, Hannes | C11: RRC ZM | D11: 51.7 | E11: 165 | F11: 36365 | H11: =IF(G11="",0,IF(G11<$H$1,50,IF(G11>18.7,0,VLOOKUP(G11,Liste_AT1!$A$3:$B$79,2,0)))) -> 0 | J11: =IF(I11="",0,IF(I11<$J$1,50,IF(I11>22.8,0,VLOOKUP(I11,Liste_AT1!$C$3:$D$125,2,0)))) -> 0 | L11: =IF(K11="",0,IF(K11<$L$1,50,IF(K11>29.2,0,VLOOKUP(K11,Liste_AT1!$E$3:$F$138,2,0)))) -> 0 | M11: 31.9 | N11: =IF(M11="",0,IF(M11<15,50,IF(M11>39.5,0,VLOOKUP(M11,Liste_AT1!$G$3:$H$248,2,0)))) -> 16 | P11: =IF(O11="",0,IF(O11<40,50,IF(O11>108,0,VLOOKUP(O11,Liste_AT1!$I$3:$J$71,2,0)))) -> 0 | R11: =IF(Q11>10,50,IF(Q11<1,0,IF(Q11="",0,VLOOKUP(Q11,Liste_AT1!$K$3:$L$21,2,0)))) -> 0 | T11: =IF(S11>10,50,IF(S11<1,0,VLOOKUP(S11,Liste_AT1!$M$3:$N$21,2,0))) -> 0 | V11: =IF(U11>5,35,IF(U11<1,0,VLOOKUP(U11,Liste_AT1!$O$3:$P$19,2))) -> 0 | W11: 9.3 | X11: =IF(W11>10,50,IF(W11<1,0,VLOOKUP(W11,Liste_AT1!$Q$3:$R$21,2))) -> 46 | Z11: =IF(Y11>10,50,IF(Y11<1,0,VLOOKUP(Y11,Liste_AT1!$S$3:$T$12,2))) -> 0 | AB11: =IF(AA11="",0,IF(AA11<3.8,50,IF(AA11>6.9,0,VLOOKUP(AA11,Liste_AT2!$A$3:$B$34,2)))) -> 0 | AD11: =IF(AC11="",0,IF(AC11<8.6,50,IF(AC11>12.1,0,VLOOKUP(AC11,Liste_AT2!$C$3:$D$38,2)))) -> 0 | AF11: =IF(AE11="",0,IF(AE11<160,50,IF(AE11>231,0,VLOOKUP(AE11,Liste_AT2!$F$3:$G$74,2)))) -> 0 | AG11: 602 | AH11: =IF(AG11="",0,IF(AG11<500,50,IF(AG11>626,0,VLOOKUP(AG11,Liste_AT2!$AU$3:$AW$66,3)))) -> 7 | AJ11: =IF(AI11="",0,IF(AI11<822,50,IF(AI11>948,0,VLOOKUP(AI11,Liste_AT2!$I$3:$J$66,2)))) -> 0 | AK11: 17.9 | AL11: =IF(AK11="",0,IF(AK11<15,50,IF(AK11>22.5,0,VLOOKUP(AK11,Liste_AT2!$K$3:$L$78,2)))) -> 21 | AN11: =IF(AM11="",0,IF(AM11<4,50,IF(AM11>9.4,0,VLOOKUP(AM11,Liste_AT2!$M$3:$N$57,2)))) -> 0 | AP11: =IF(AO11="",0,IF(AO11>33,50,IF(AO11<7,0,VLOOKUP(AO11,Liste_AT2!$Q$3:$R$29,2)))) -> 0 | AR11: =IF(AQ11="",0,IF(AQ11>17,50,IF(AQ11<1,0,VLOOKUP(AQ11,Liste_AT2!$U$3:$V$19,2)))) -> 0 | AT11: =IF(AS11="",0,IF(AS11>27,50,IF(AS11<6,0,VLOOKUP(AS11,Liste_AT2!$W$3:$X$24,2)))) -> 0 | AV11: =IF(AU11="",0,IF(AU11<3.7,50,IF(AU11>8,0,VLOOKUP(AU11,Liste_AT2!$AA$3:$AB$46,2)))) -> 0 | AX11: =IF(AW11="",0,IF(AW11<4,0,IF(AW11>10.1,50,VLOOKUP(AW11,Liste_AT2!$AC$3:$AD$62,2)))) -> 0 | AY11: 9.1 | AZ11: =IF(AY11="",0,IF(AY11>11.9,50,IF(AY11<5,0,VLOOKUP(AY11,Liste_AT2!$AE$3:$AF$72,2)))) -> 32 | BB11: =IF(BA11="",0,IF(BA11>45,50,IF(BA11<2,0,VLOOKUP(BA11,Liste_AT2!$AG$3:$AH$61,2)))) -> 0 | BD11: =IF(BC11="",0,IF(BC11>26,50,IF(BC11<4,0,VLOOKUP(BC11,Liste_AT2!$AI$3:$AJ$25,2)))) -> 0 | BE11: 13 | BF11: =IF(BE11="",0,IF(BE11>35,50,IF(BE11<14,0,VLOOKUP(BE11,Liste_AT2!$AK$3:$AL$24,2)))) -> 0 | BH11: =IF(BG11="",0,IF(BG11>36,50,IF(BG11<7,0,VLOOKUP(BG11,Liste_AT2!$AM$3:$AN$32,2)))) -> 0 | BJ11: =IF(BI11="",0,IF(BI11>45,50,IF(BI11<6,0,VLOOKUP(BI11,Liste_AT2!$AO$3:$AP$52,2)))) -> 0 | BK11: 1.91 | BL11: =IF(BK11="",0,IF(BK11>2.4,50,IF(BK11<1.15,0,VLOOKUP(BK11,Liste_AT2!$AQ$3:$AR$52,2)))) -> 25 | BM11: 41 | BN11: =IF(BM11="",0,IF(BM11<28,50,IF(BM11>62,0,VLOOKUP(BM11,Liste_AT2!$AS$3:$AT$343,2,0)))) -> 35 | BO11: 17.5 | BP11: =IF(BO11="",0,IF(BO11<1,0,IF(BO11>28,50,VLOOKUP(BO11,Liste_AT3!$A$3:$B$30,2)))) -> 30 | BR11: =IF(BQ11="",0,IF(BQ11<5,50,IF(BQ11>40,0,VLOOKUP(BQ11,Liste_AT3!$C$3:$D$38,2)))) -> 0 | BS11: 2.25 | BT11: =IF(BS11="",0,IF(BS11<1,50,IF(BS11>4.75,0,VLOOKUP(BS11,Liste_AT3!$E$3:$F$18,2)))) -> 29 | BV11: =IF(BU11="",0,IF(BU11<1,50,IF(BU11>4.75,0,VLOOKUP(BU11,Liste_AT3!$G$3:$H$18,2)))) -> 0 | BX11: =IF(BW11="",0,IF(BW11<1,50,IF(BW11>4.75,0,VLOOKUP(BW11,Liste_AT3!$G$3:$H$18,2)))) -> 0 | BZ11: =IF(BY11="",0,IF(BY11>40,0,VLOOKUP(BY11,Liste_AT3!$I$3:$J$43,2,2))) -> 0 | CB11: =IF(CA11="",0,IF(CA11>40,0,VLOOKUP(CA11,Liste_AT3!$I$3:$J$43,2,2))) -> 0 | CC11: =SUM(H11,J11,L11,N11,P11,R11,T11,V11,X11,Z11) -> 62 | CD11: =IF(CC11=0,"",RANK(CC11,$CC$4:$CC$19)) -> 12 | CE11: =SUM(AB11,AD11,AF11,AJ11,AL11,AN11,AH11) -> 28 | CF11: =IF(CE11=0,"",RANK(CE11,$CE$4:$CE$19)) -> 10 | CG11: =SUM(AP11,AR11,AT11,AV11,AX11,AZ11,BB11,BD11,BF11,BH11,BJ11,BL11,BN11) -> 92 | CH11: =IF(CG11=0,"",RANK(CG11,$CG$4:$CG$19)) -> 6 | CI11: =SUM(BP11,BR11) -> 30 | CJ11: =IF(CI11=0,"",RANK(CI11,$CI$4:$CI$19)) -> 2 | CK11: =SUM(BT11,BV11,BX11,BZ11,CB11) -> 29 | CL11: =IF(CK11=0,"",RANK(CK11,$CK$4:$CK$19)) -> 7 | CM11: =SUM(CC11,CE11,CG11,CI11,CK11) -> 241 | CN11: =IF(CM11=0,"",RANK(CM11,$CM$4:$CM$19)) -> 8
A12: 11 | B12: Juchheim, Leon | C12: RCI | D12: 39.4 | E12: 152 | F12: 36329 | H12: =IF(G12="",0,IF(G12<$H$1,50,IF(G12>18.7,0,VLOOKUP(G12,Liste_AT1!$A$3:$B$79,2,0)))) -> 0 | J12: =IF(I12="",0,IF(I12<$J$1,50,IF(I12>22.8,0,VLOOKUP(I12,Liste_AT1!$C$3:$D$125,2,0)))) -> 0 | L12: =IF(K12="",0,IF(K12<$L$1,50,IF(K12>29.2,0,VLOOKUP(K12,Liste_AT1!$E$3:$F$138,2,0)))) -> 0 | M12: 22.2 | N12: =IF(M12="",0,IF(M12<15,50,IF(M12>39.5,0,VLOOKUP(M12,Liste_AT1!$G$3:$H$248,2,0)))) -> 35 | P12: =IF(O12="",0,IF(O12<40,50,IF(O12>108,0,VLOOKUP(O12,Liste_AT1!$I$3:$J$71,2,0)))) -> 0 | R12: =IF(Q12>10,50,IF(Q12<1,0,IF(Q12="",0,VLOOKUP(Q12,Liste_AT1!$K$3:$L$21,2,0)))) -> 0 | T12: =IF(S12>10,50,IF(S12<1,0,VLOOKUP(S12,Liste_AT1!$M$3:$N$21,2,0))) -> 0 | V12: =IF(U12>5,35,IF(U12<1,0,VLOOKUP(U12,Liste_AT1!$O$3:$P$19,2))) -> 0 | W12: 9 | X12: =IF(W12>10,50,IF(W12<1,0,VLOOKUP(W12,Liste_AT1!$Q$3:$R$21,2))) -> 46 | Z12: =IF(Y12>10,50,IF(Y12<1,0,VLOOKUP(Y12,Liste_AT1!$S$3:$T$12,2))) -> 0 | AB12: =IF(AA12="",0,IF(AA12<3.8,50,IF(AA12>6.9,0,VLOOKUP(AA12,Liste_AT2!$A$3:$B$34,2)))) -> 0 | AD12: =IF(AC12="",0,IF(AC12<8.6,50,IF(AC12>12.1,0,VLOOKUP(AC12,Liste_AT2!$C$3:$D$38,2)))) -> 0 | AF12: =IF(AE12="",0,IF(AE12<160,50,IF(AE12>231,0,VLOOKUP(AE12,Liste_AT2!$F$3:$G$74,2)))) -> 0 | AG12: 544 | AH12: =IF(AG12="",0,IF(AG12<500,50,IF(AG12>626,0,VLOOKUP(AG12,Liste_AT2!$AU$3:$AW$66,3)))) -> 28 | AJ12: =IF(AI12="",0,IF(AI12<822,50,IF(AI12>948,0,VLOOKUP(AI12,Liste_AT2!$I$3:$J$66,2)))) -> 0 | AK12: 18.2 | AL12: =IF(AK12="",0,IF(AK12<15,50,IF(AK12>22.5,0,VLOOKUP(AK12,Liste_AT2!$K$3:$L$78,2)))) -> 18 | AN12: =IF(AM12="",0,IF(AM12<4,50,IF(AM12>9.4,0,VLOOKUP(AM12,Liste_AT2!$M$3:$N$57,2)))) -> 0 | AP12: =IF(AO12="",0,IF(AO12>33,50,IF(AO12<7,0,VLOOKUP(AO12,Liste_AT2!$Q$3:$R$29,2)))) -> 0 | AR12: =IF(AQ12="",0,IF(AQ12>17,50,IF(AQ12<1,0,VLOOKUP(AQ12,Liste_AT2!$U$3:$V$19,2)))) -> 0 | AT12: =IF(AS12="",0,IF(AS12>27,50,IF(AS12<6,0,VLOOKUP(AS12,Liste_AT2!$W$3:$X$24,2)))) -> 0 | AV12: =IF(AU12="",0,IF(AU12<3.7,50,IF(AU12>8,0,VLOOKUP(AU12,Liste_AT2!$AA$3:$AB$46,2)))) -> 0 | AX12: =IF(AW12="",0,IF(AW12<4,0,IF(AW12>10.1,50,VLOOKUP(AW12,Liste_AT2!$AC$3:$AD$62,2)))) -> 0 | AY12: 4.8 | AZ12: =IF(AY12="",0,IF(AY12>11.9,50,IF(AY12<5,0,VLOOKUP(AY12,Liste_AT2!$AE$3:$AF$72,2)))) -> 0 | BB12: =IF(BA12="",0,IF(BA12>45,50,IF(BA12<2,0,VLOOKUP(BA12,Liste_AT2!$AG$3:$AH$61,2)))) -> 0 | BD12: =IF(BC12="",0,IF(BC12>26,50,IF(BC12<4,0,VLOOKUP(BC12,Liste_AT2!$AI$3:$AJ$25,2)))) -> 0 | BE12: 19 | BF12: =IF(BE12="",0,IF(BE12>35,50,IF(BE12<14,0,VLOOKUP(BE12,Liste_AT2!$AK$3:$AL$24,2)))) -> 10 | BH12: =IF(BG12="",0,IF(BG12>36,50,IF(BG12<7,0,VLOOKUP(BG12,Liste_AT2!$AM$3:$AN$32,2)))) -> 0 | BJ12: =IF(BI12="",0,IF(BI12>45,50,IF(BI12<6,0,VLOOKUP(BI12,Liste_AT2!$AO$3:$AP$52,2)))) -> 0 | BK12: 1.49 | BL12: =IF(BK12="",0,IF(BK12>2.4,50,IF(BK12<1.15,0,VLOOKUP(BK12,Liste_AT2!$AQ$3:$AR$52,2)))) -> 7 | BM12: 38.6 | BN12: =IF(BM12="",0,IF(BM12<28,50,IF(BM12>62,0,VLOOKUP(BM12,Liste_AT2!$AS$3:$AT$343,2,0)))) -> 39 | BO12: 8.7 | BP12: =IF(BO12="",0,IF(BO12<1,0,IF(BO12>28,50,VLOOKUP(BO12,Liste_AT3!$A$3:$B$30,2)))) -> 12 | BR12: =IF(BQ12="",0,IF(BQ12<5,50,IF(BQ12>40,0,VLOOKUP(BQ12,Liste_AT3!$C$3:$D$38,2)))) -> 0 | BS12: 2.5 | BT12: =IF(BS12="",0,IF(BS12<1,50,IF(BS12>4.75,0,VLOOKUP(BS12,Liste_AT3!$E$3:$F$18,2)))) -> 25 | BV12: =IF(BU12="",0,IF(BU12<1,50,IF(BU12>4.75,0,VLOOKUP(BU12,Liste_AT3!$G$3:$H$18,2)))) -> 0 | BX12: =IF(BW12="",0,IF(BW12<1,50,IF(BW12>4.75,0,VLOOKUP(BW12,Liste_AT3!$G$3:$H$18,2)))) -> 0 | BZ12: =IF(BY12="",0,IF(BY12>40,0,VLOOKUP(BY12,Liste_AT3!$I$3:$J$43,2,2))) -> 0 | CB12: =IF(CA12="",0,IF(CA12>40,0,VLOOKUP(CA12,Liste_AT3!$I$3:$J$43,2,2))) -> 0 | CC12: =SUM(H12,J12,L12,N12,P12,R12,T12,V12,X12,Z12) -> 81 | CD12: =IF(CC12=0,"",RANK(CC12,$CC$4:$CC$19)) -> 3 | CE12: =SUM(AB12,AD12,AF12,AJ12,AL12,AN12,AH12) -> 46 | CF12: =IF(CE12=0,"",RANK(CE12,$CE$4:$CE$19)) -> 5 | CG12: =SUM(AP12,AR12,AT12,AV12,AX12,AZ12,BB12,BD12,BF12,BH12,BJ12,BL12,BN12) -> 56 | CH12: =IF(CG12=0,"",RANK(CG12,$CG$4:$CG$19)) -> 15 | CI12: =SUM(BP12,BR12) -> 12 | CJ12: =IF(CI12=0,"",RANK(CI12,$CI$4:$CI$19)) -> 12 | CK12: =SUM(BT12,BV12,BX12,BZ12,CB12) -> 25 | CL12: =IF(CK12=0,"",RANK(CK12,$CK$4:$CK$19)) -> 10 | CM12: =SUM(CC12,CE12,CG12,CI12,CK12) -> 220 | CN12: =IF(CM12=0,"",RANK(CM12,$CM$4:$CM$19)) -> 9
A13: 12 | B13: Kluczenski, Sascha | C13: FRO | D13: 46.7 | E13: 148 | F13: 36509 | H13: =IF(G13="",0,IF(G13<$H$1,50,IF(G13>18.7,0,VLOOKUP(G13,Liste_AT1!$A$3:$B$79,2,0)))) -> 0 | J13: =IF(I13="",0,IF(I13<$J$1,50,IF(I13>22.8,0,VLOOKUP(I13,Liste_AT1!$C$3:$D$125,2,0)))) -> 0 | L13: =IF(K13="",0,IF(K13<$L$1,50,IF(K13>29.2,0,VLOOKUP(K13,Liste_AT1!$E$3:$F$138,2,0)))) -> 0 | M13: 23.2 | N13: =IF(M13="",0,IF(M13<15,50,IF(M13>39.5,0,VLOOKUP(M13,Liste_AT1!$G$3:$H$248,2,0)))) -> 33 | P13: =IF(O13="",0,IF(O13<40,50,IF(O13>108,0,VLOOKUP(O13,Liste_AT1!$I$3:$J$71,2,0)))) -> 0 | R13: =IF(Q13>10,50,IF(Q13<1,0,IF(Q13="",0,VLOOKUP(Q13,Liste_AT1!$K$3:$L$21,2,0)))) -> 0 | T13: =IF(S13>10,50,IF(S13<1,0,VLOOKUP(S13,Liste_AT1!$M$3:$N$21,2,0))) -> 0 | V13: =IF(U13>5,35,IF(U13<1,0,VLOOKUP(U13,Liste_AT1!$O$3:$P$19,2))) -> 0 | W13: 8.9 | X13: =IF(W13>10,50,IF(W13<1,0,VLOOKUP(W13,Liste_AT1!$Q$3:$R$21,2))) -> 43 | Z13: =IF(Y13>10,50,IF(Y13<1,0,VLOOKUP(Y13,Liste_AT1!$S$3:$T$12,2))) -> 0 | AB13: =IF(AA13="",0,IF(AA13<3.8,50,IF(AA13>6.9,0,VLOOKUP(AA13,Liste_AT2!$A$3:$B$34,2)))) -> 0 | AD13: =IF(AC13="",0,IF(AC13<8.6,50,IF(AC13>12.1,0,VLOOKUP(AC13,Liste_AT2!$C$3:$D$38,2)))) -> 0 | AF13: =IF(AE13="",0,IF(AE13<160,50,IF(AE13>231,0,VLOOKUP(AE13,Liste_AT2!$F$3:$G$74,2)))) -> 0 | AG13: 603 | AH13: =IF(AG13="",0,IF(AG13<500,50,IF(AG13>626,0,VLOOKUP(AG13,Liste_AT2!$AU$3:$AW$66,3)))) -> 7 | AJ13: =IF(AI13="",0,IF(AI13<822,50,IF(AI13>948,0,VLOOKUP(AI13,Liste_AT2!$I$3:$J$66,2)))) -> 0 | AK13: 17.8 | AL13: =IF(AK13="",0,IF(AK13<15,50,IF(AK13>22.5,0,VLOOKUP(AK13,Liste_AT2!$K$3:$L$78,2)))) -> 22 | AN13: =IF(AM13="",0,IF(AM13<4,50,IF(AM13>9.4,0,VLOOKUP(AM13,Liste_AT2!$M$3:$N$57,2)))) -> 0 | AP13: =IF(AO13="",0,IF(AO13>33,50,IF(AO13<7,0,VLOOKUP(AO13,Liste_AT2!$Q$3:$R$29,2)))) -> 0 | AR13: =IF(AQ13="",0,IF(AQ13>17,50,IF(AQ13<1,0,VLOOKUP(AQ13,Liste_AT2!$U$3:$V$19,2)))) -> 0 | AT13: =IF(AS13="",0,IF(AS13>27,50,IF(AS13<6,0,VLOOKUP(AS13,Liste_AT2!$W$3:$X$24,2)))) -> 0 | AV13: =IF(AU13="",0,IF(AU13<3.7,50,IF(AU13>8,0,VLOOKUP(AU13,Liste_AT2!$AA$3:$AB$46,2)))) -> 0 | AX13: =IF(AW13="",0,IF(AW13<4,0,IF(AW13>10.1,50,VLOOKUP(AW13,Liste_AT2!$AC$3:$AD$62,2)))) -> 0 | AY13: 6.1 | AZ13: =IF(AY13="",0,IF(AY13>11.9,50,IF(AY13<5,0,VLOOKUP(AY13,Liste_AT2!$AE$3:$AF$72,2)))) -> 6 | BB13: =IF(BA13="",0,IF(BA13>45,50,IF(BA13<2,0,VLOOKUP(BA13,Liste_AT2!$AG$3:$AH$61,2)))) -> 0 | BD13: =IF(BC13="",0,IF(BC13>26,50,IF(BC13<4,0,VLOOKUP(BC13,Liste_AT2!$AI$3:$AJ$25,2)))) -> 0 | BE13: 19 | BF13: =IF(BE13="",0,IF(BE13>35,50,IF(BE13<14,0,VLOOKUP(BE13,Liste_AT2!$AK$3:$AL$24,2)))) -> 10 | BH13: =IF(BG13="",0,IF(BG13>36,50,IF(BG13<7,0,VLOOKUP(BG13,Liste_AT2!$AM$3:$AN$32,2)))) -> 0 | BJ13: =IF(BI13="",0,IF(BI13>45,50,IF(BI13<6,0,VLOOKUP(BI13,Liste_AT2!$AO$3:$AP$52,2)))) -> 0 | BK13: 1.6 | BL13: =IF(BK13="",0,IF(BK13>2.4,50,IF(BK13<1.15,0,VLOOKUP(BK13,Liste_AT2!$AQ$3:$AR$52,2)))) -> 10 | BM13: 40.3 | BN13: =IF(BM13="",0,IF(BM13<28,50,IF(BM13>62,0,VLOOKUP(BM13,Liste_AT2!$AS$3:$AT$343,2,0)))) -> 36 | BO13: 15 | BP13: =IF(BO13="",0,IF(BO13<1,0,IF(BO13>28,50,VLOOKUP(BO13,Liste_AT3!$A$3:$B$30,2)))) -> 26 | BR13: =IF(BQ13="",0,IF(BQ13<5,50,IF(BQ13>40,0,VLOOKUP(BQ13,Liste_AT3!$C$3:$D$38,2)))) -> 0 | BS13: 2.75 | BT13: =IF(BS13="",0,IF(BS13<1,50,IF(BS13>4.75,0,VLOOKUP(BS13,Liste_AT3!$E$3:$F$18,2)))) -> 22 | BV13: =IF(BU13="",0,IF(BU13<1,50,IF(BU13>4.75,0,VLOOKUP(BU13,Liste_AT3!$G$3:$H$18,2)))) -> 0 | BX13: =IF(BW13="",0,IF(BW13<1,50,IF(BW13>4.75,0,VLOOKUP(BW13,Liste_AT3!$G$3:$H$18,2)))) -> 0 | BZ13: =IF(BY13="",0,IF(BY13>40,0,VLOOKUP(BY13,Liste_AT3!$I$3:$J$43,2,2))) -> 0 | CB13: =IF(CA13="",0,IF(CA13>40,0,VLOOKUP(CA13,Liste_AT3!$I$3:$J$43,2,2))) -> 0 | CC13: =SUM(H13,J13,L13,N13,P13,R13,T13,V13,X13,Z13) -> 76 | CD13: =IF(CC13=0,"",RANK(CC13,$CC$4:$CC$19)) -> 7 | CE13: =SUM(AB13,AD13,AF13,AJ13,AL13,AN13,AH13) -> 29 | CF13: =IF(CE13=0,"",RANK(CE13,$CE$4:$CE$19)) -> 9 | CG13: =SUM(AP13,AR13,AT13,AV13,AX13,AZ13,BB13,BD13,BF13,BH13,BJ13,BL13,BN13) -> 62 | CH13: =IF(CG13=0,"",RANK(CG13,$CG$4:$CG$19)) -> 11 | CI13: =SUM(BP13,BR13) -> 26 | CJ13: =IF(CI13=0,"",RANK(CI13,$CI$4:$CI$19)) -> 5 | CK13: =SUM(BT13,BV13,BX13,BZ13,CB13) -> 22 | CL13: =IF(CK13=0,"",RANK(CK13,$CK$4:$CK$19)) -> 14 | CM13: =SUM(CC13,CE13,CG13,CI13,CK13) -> 215 | CN13: =IF(CM13=0,"",RANK(CM13,$CM$4:$CM$19)) -> 10
A14: 10 | B14: Dietsch, Pascal | C14: WAL | D14: 42.1 | E14: 151 | F14: 36347 | H14: =IF(G14="",0,IF(G14<$H$1,50,IF(G14>18.7,0,VLOOKUP(G14,Liste_AT1!$A$3:$B$79,2,0)))) -> 0 | J14: =IF(I14="",0,IF(I14<$J$1,50,IF(I14>22.8,0,VLOOKUP(I14,Liste_AT1!$C$3:$D$125,2,0)))) -> 0 | L14: =IF(K14="",0,IF(K14<$L$1,50,IF(K14>29.2,0,VLOOKUP(K14,Liste_AT1!$E$3:$F$138,2,0)))) -> 0 | M14: 25.4 | N14: =IF(M14="",0,IF(M14<15,50,IF(M14>39.5,0,VLOOKUP(M14,Liste_AT1!$G$3:$H$248,2,0)))) -> 29 | P14: =IF(O14="",0,IF(O14<40,50,IF(O14>108,0,VLOOKUP(O14,Liste_AT1!$I$3:$J$71,2,0)))) -> 0 | R14: =IF(Q14>10,50,IF(Q14<1,0,IF(Q14="",0,VLOOKUP(Q14,Liste_AT1!$K$3:$L$21,2,0)))) -> 0 | T14: =IF(S14>10,50,IF(S14<1,0,VLOOKUP(S14,Liste_AT1!$M$3:$N$21,2,0))) -> 0 | V14: =IF(U14>5,35,IF(U14<1,0,VLOOKUP(U14,Liste_AT1!$O$3:$P$19,2))) -> 0 | W14: 8.9 | X14: =IF(W14>10,50,IF(W14<1,0,VLOOKUP(W14,Liste_AT1!$Q$3:$R$21,2))) -> 43 | Z14: =IF(Y14>10,50,IF(Y14<1,0,VLOOKUP(Y14,Liste_AT1!$S$3:$T$12,2))) -> 0 | AB14: =IF(AA14="",0,IF(AA14<3.8,50,IF(AA14>6.9,0,VLOOKUP(AA14,Liste_AT2!$A$3:$B$34,2)))) -> 0 | AD14: =IF(AC14="",0,IF(AC14<8.6,50,IF(AC14>12.1,0,VLOOKUP(AC14,Liste_AT2!$C$3:$D$38,2)))) -> 0 | AF14: =IF(AE14="",0,IF(AE14<160,50,IF(AE14>231,0,VLOOKUP(AE14,Liste_AT2!$F$3:$G$74,2)))) -> 0 | AG14: 668 | AH14: =IF(AG14="",0,IF(AG14<500,50,IF(AG14>626,0,VLOOKUP(AG14,Liste_AT2!$AU$3:$AW$66,3)))) -> 0 | AJ14: =IF(AI14="",0,IF(AI14<822,50,IF(AI14>948,0,VLOOKUP(AI14,Liste_AT2!$I$3:$J$66,2)))) -> 0 | AK14: 18.4 | AL14: =IF(AK14="",0,IF(AK14<15,50,IF(AK14>22.5,0,VLOOKUP(AK14,Liste_AT2!$K$3:$L$78,2)))) -> 16 | AN14: =IF(AM14="",0,IF(AM14<4,50,IF(AM14>9.4,0,VLOOKUP(AM14,Liste_AT2!$M$3:$N$57,2)))) -> 0 | AP14: =IF(AO14="",0,IF(AO14>33,50,IF(AO14<7,0,VLOOKUP(AO14,Liste_AT2!$Q$3:$R$29,2)))) -> 0 | AR14: =IF(AQ14="",0,IF(AQ14>17,50,IF(AQ14<1,0,VLOOKUP(AQ14,Liste_AT2!$U$3:$V$19,2)))) -> 0 | AT14: =IF(AS14="",0,IF(AS14>27,50,IF(AS14<6,0,VLOOKUP(AS14,Liste_AT2!$W$3:$X$24,2)))) -> 0 | AV14: =IF(AU14="",0,IF(AU14<3.7,50,IF(AU14>8,0,VLOOKUP(AU14,Liste_AT2!$AA$3:$AB$46,2)))) -> 0 | AX14: =IF(AW14="",0,IF(AW14<4,0,IF(AW14>10.1,50,VLOOKUP(AW14,Liste_AT2!$AC$3:$AD$62,2)))) -> 0 | AY14: 7.3 | AZ14: =IF(AY14="",0,IF(AY14>11.9,50,IF(AY14<5,0,VLOOKUP(AY14,Liste_AT2!$AE$3:$AF$72,2)))) -> 14 | BB14: =IF(BA14="",0,IF(BA14>45,50,IF(BA14<2,0,VLOOKUP(BA14,Liste_AT2!$AG$3:$AH$61,2)))) -> 0 | BD14: =IF(BC14="",0,IF(BC14>26,50,IF(BC14<4,0,VLOOKUP(BC14,Liste_AT2!$AI$3:$AJ$25,2)))) -> 0 | BE14: 19 | BF14: =IF(BE14="",0,IF(BE14>35,50,IF(BE14<14,0,VLOOKUP(BE14,Liste_AT2!$AK$3:$AL$24,2)))) -> 10 | BH14: =IF(BG14="",0,IF(BG14>36,50,IF(BG14<7,0,VLOOKUP(BG14,Liste_AT2!$AM$3:$AN$32,2)))) -> 0 | BJ14: =IF(BI14="",0,IF(BI14>45,50,IF(BI14<6,0,VLOOKUP(BI14,Liste_AT2!$AO$3:$AP$52,2)))) -> 0 | BK14: 1.61 | BL14: =IF(BK14="",0,IF(BK14>2.4,50,IF(BK14<1.15,0,VLOOKUP(BK14,Liste_AT2!$AQ$3:$AR$52,2)))) -> 10 | BM14: 34 | BN14: =IF(BM14="",0,IF(BM14<28,50,IF(BM14>62,0,VLOOKUP(BM14,Liste_AT2!$AS$3:$AT$343,2,0)))) -> 44 | BO14: 3.8 | BP14: =IF(BO14="",0,IF(BO14<1,0,IF(BO14>28,50,VLOOKUP(BO14,Liste_AT3!$A$3:$B$30,2)))) -> 2 | BR14: =IF(BQ14="",0,IF(BQ14<5,50,IF(BQ14>40,0,VLOOKUP(BQ14,Liste_AT3!$C$3:$D$38,2)))) -> 0 | BS14: 2.25 | BT14: =IF(BS14="",0,IF(BS14<1,50,IF(BS14>4.75,0,VLOOKUP(BS14,Liste_AT3!$E$3:$F$18,2)))) -> 29 | BV14: =IF(BU14="",0,IF(BU14<1,50,IF(BU14>4.75,0,VLOOKUP(BU14,Liste_AT3!$G$3:$H$18,2)))) -> 0 | BX14: =IF(BW14="",0,IF(BW14<1,50,IF(BW14>4.75,0,VLOOKUP(BW14,Liste_AT3!$G$3:$H$18,2)))) -> 0 | BZ14: =IF(BY14="",0,IF(BY14>40,0,VLOOKUP(BY14,Liste_AT3!$I$3:$J$43,2,2))) -> 0 | CB14: =IF(CA14="",0,IF(CA14>40,0,VLOOKUP(CA14,Liste_AT3!$I$3:$J$43,2,2))) -> 0 | CC14: =SUM(H14,J14,L14,N14,P14,R14,T14,V14,X14,Z14) -> 72 | CD14: =IF(CC14=0,"",RANK(CC14,$CC$4:$CC$19)) -> 8 | CE14: =SUM(AB14,AD14,AF14,AJ14,AL14,AN14,AH14) -> 16 | CF14: =IF(CE14=0,"",RANK(CE14,$CE$4:$CE$19)) -> 11 | CG14: =SUM(AP14,AR14,AT14,AV14,AX14,AZ14,BB14,BD14,BF14,BH14,BJ14,BL14,BN14) -> 78 | CH14: =IF(CG14=0,"",RANK(CG14,$CG$4:$CG$19)) -> 7 | CI14: =SUM(BP14,BR14) -> 2 | CJ14: =IF(CI14=0,"",RANK(CI14,$CI$4:$CI$19)) -> 15 | CK14: =SUM(BT14,BV14,BX14,BZ14,CB14) -> 29 | CL14: =IF(CK14=0,"",RANK(CK14,$CK$4:$CK$19)) -> 7 | CM14: =SUM(CC14,CE14,CG14,CI14,CK14) -> 197 | CN14: =IF(CM14=0,"",RANK(CM14,$CM$4:$CM$19)) -> 11
A15: 8 | B15: Berkes, Michael | C15: RTS | D15: 59.1 | E15: 165 | F15: 36368 | H15: =IF(G15="",0,IF(G15<$H$1,50,IF(G15>18.7,0,VLOOKUP(G15,Liste_AT1!$A$3:$B$79,2,0)))) -> 0 | J15: =IF(I15="",0,IF(I15<$J$1,50,IF(I15>22.8,0,VLOOKUP(I15,Liste_AT1!$C$3:$D$125,2,0)))) -> 0 | L15: =IF(K15="",0,IF(K15<$L$1,50,IF(K15>29.2,0,VLOOKUP(K15,Liste_AT1!$E$3:$F$138,2,0)))) -> 0 | M15: 25.8 | N15: =IF(M15="",0,IF(M15<15,50,IF(M15>39.5,0,VLOOKUP(M15,Liste_AT1!$G$3:$H$248,2,0)))) -> 28 | P15: =IF(O15="",0,IF(O15<40,50,IF(O15>108,0,VLOOKUP(O15,Liste_AT1!$I$3:$J$71,2,0)))) -> 0 | R15: =IF(Q15>10,50,IF(Q15<1,0,IF(Q15="",0,VLOOKUP(Q15,Liste_AT1!$K$3:$L$21,2,0)))) -> 0 | T15: =IF(S15>10,50,IF(S15<1,0,VLOOKUP(S15,Liste_AT1!$M$3:$N$21,2,0))) -> 0 | V15: =IF(U15>5,35,IF(U15<1,0,VLOOKUP(U15,Liste_AT1!$O$3:$P$19,2))) -> 0 | W15: 7.1 | X15: =IF(W15>10,50,IF(W15<1,0,VLOOKUP(W15,Liste_AT1!$Q$3:$R$21,2))) -> 34 | Z15: =IF(Y15>10,50,IF(Y15<1,0,VLOOKUP(Y15,Liste_AT1!$S$3:$T$12,2))) -> 0 | AB15: =IF(AA15="",0,IF(AA15<3.8,50,IF(AA15>6.9,0,VLOOKUP(AA15,Liste_AT2!$A$3:$B$34,2)))) -> 0 | AD15: =IF(AC15="",0,IF(AC15<8.6,50,IF(AC15>12.1,0,VLOOKUP(AC15,Liste_AT2!$C$3:$D$38,2)))) -> 0 | AF15: =IF(AE15="",0,IF(AE15<160,50,IF(AE15>231,0,VLOOKUP(AE15,Liste_AT2!$F$3:$G$74,2)))) -> 0 | AG15: 726 | AH15: =IF(AG15="",0,IF(AG15<500,50,IF(AG15>626,0,VLOOKUP(AG15,Liste_AT2!$AU$3:$AW$66,3)))) -> 0 | AJ15: =IF(AI15="",0,IF(AI15<822,50,IF(AI15>948,0,VLOOKUP(AI15,Liste_AT2!$I$3:$J$66,2)))) -> 0 | AK15: 19.3 | AL15: =IF(AK15="",0,IF(AK15<15,50,IF(AK15>22.5,0,VLOOKUP(AK15,Liste_AT2!$K$3:$L$78,2)))) -> 11 | AN15: =IF(AM15="",0,IF(AM15<4,50,IF(AM15>9.4,0,VLOOKUP(AM15,Liste_AT2!$M$3:$N$57,2)))) -> 0 | AP15: =IF(AO15="",0,IF(AO15>33,50,IF(AO15<7,0,VLOOKUP(AO15,Liste_AT2!$Q$3:$R$29,2)))) -> 0 | AR15: =IF(AQ15="",0,IF(AQ15>17,50,IF(AQ15<1,0,VLOOKUP(AQ15,Liste_AT2!$U$3:$V$19,2)))) -> 0 | AT15: =IF(AS15="",0,IF(AS15>27,50,IF(AS15<6,0,VLOOKUP(AS15,Liste_AT2!$W$3:$X$24,2)))) -> 0 | AV15: =IF(AU15="",0,IF(AU15<3.7,50,IF(AU15>8,0,VLOOKUP(AU15,Liste_AT2!$AA$3:$AB$46,2)))) -> 0 | AX15: =IF(AW15="",0,IF(AW15<4,0,IF(AW15>10.1,50,VLOOKUP(AW15,Liste_AT2!$AC$3:$AD$62,2)))) -> 0 | AY15: 7.8 | AZ15: =IF(AY15="",0,IF(AY15>11.9,50,IF(AY15<5,0,VLOOKUP(AY15,Liste_AT2!$AE$3:$AF$72,2)))) -> 19 | BB15: =IF(BA15="",0,IF(BA15>45,50,IF(BA15<2,0,VLOOKUP(BA15,Liste_AT2!$AG$3:$AH$61,2)))) -> 0 | BD15: =IF(BC15="",0,IF(BC15>26,50,IF(BC15<4,0,VLOOKUP(BC15,Liste_AT2!$AI$3:$AJ$25,2)))) -> 0 | BE15: 10 | BF15: =IF(BE15="",0,IF(BE15>35,50,IF(BE15<14,0,VLOOKUP(BE15,Liste_AT2!$AK$3:$AL$24,2)))) -> 0 | BH15: =IF(BG15="",0,IF(BG15>36,50,IF(BG15<7,0,VLOOKUP(BG15,Liste_AT2!$AM$3:$AN$32,2)))) -> 0 | BJ15: =IF(BI15="",0,IF(BI15>45,50,IF(BI15<6,0,VLOOKUP(BI15,Liste_AT2!$AO$3:$AP$52,2)))) -> 0 | BK15: 1.65 | BL15: =IF(BK15="",0,IF(BK15>2.4,50,IF(BK15<1.15,0,VLOOKUP(BK15,Liste_AT2!$AQ$3:$AR$52,2)))) -> 12 | BM15: 37 | BN15: =IF(BM15="",0,IF(BM15<28,50,IF(BM15>62,0,VLOOKUP(BM15,Liste_AT2!$AS$3:$AT$343,2,0)))) -> 41 | BO15: 7 | BP15: =IF(BO15="",0,IF(BO15<1,0,IF(BO15>28,50,VLOOKUP(BO15,Liste_AT3!$A$3:$B$30,2)))) -> 10 | BR15: =IF(BQ15="",0,IF(BQ15<5,50,IF(BQ15>40,0,VLOOKUP(BQ15,Liste_AT3!$C$3:$D$38,2)))) -> 0 | BS15: 2.5 | BT15: =IF(BS15="",0,IF(BS15<1,50,IF(BS15>4.75,0,VLOOKUP(BS15,Liste_AT3!$E$3:$F$18,2)))) -> 25 | BV15: =IF(BU15="",0,IF(BU15<1,50,IF(BU15>4.75,0,VLOOKUP(BU15,Liste_AT3!$G$3:$H$18,2)))) -> 0 | BX15: =IF(BW15="",0,IF(BW15<1,50,IF(BW15>4.75,0,VLOOKUP(BW15,Liste_AT3!$G$3:$H$18,2)))) -> 0 | BZ15: =IF(BY15="",0,IF(BY15>40,0,VLOOKUP(BY15,Liste_AT3!$I$3:$J$43,2,2))) -> 0 | CB15: =IF(CA15="",0,IF(CA15>40,0,VLOOKUP(CA15,Liste_AT3!$I$3:$J$43,2,2))) -> 0 | CC15: =SUM(H15,J15,L15,N15,P15,R15,T15,V15,X15,Z15) -> 62 | CD15: =IF(CC15=0,"",RANK(CC15,$CC$4:$CC$19)) -> 12 | CE15: =SUM(AB15,AD15,AF15,AJ15,AL15,AN15,AH15) -> 11 | CF15: =IF(CE15=0,"",RANK(CE15,$CE$4:$CE$19)) -> 12 | CG15: =SUM(AP15,AR15,AT15,AV15,AX15,AZ15,BB15,BD15,BF15,BH15,BJ15,BL15,BN15) -> 72 | CH15: =IF(CG15=0,"",RANK(CG15,$CG$4:$CG$19)) -> 10 | CI15: =SUM(BP15,BR15) -> 10 | CJ15: =IF(CI15=0,"",RANK(CI15,$CI$4:$CI$19)) -> 13 | CK15: =SUM(BT15,BV15,BX15,BZ15,CB15) -> 25 | CL15: =IF(CK15=0,"",RANK(CK15,$CK$4:$CK$19)) -> 10 | CM15: =SUM(CC15,CE15,CG15,CI15,CK15) -> 180 | CN15: =IF(CM15=0,"",RANK(CM15,$CM$4:$CM$19)) -> 12
A16: 14 | B16: Brendel, Fabian | C16: RCI | D16: 45 | E16: 152 | F16: 36492 | H16: =IF(G16="",0,IF(G16<$H$1,50,IF(G16>18.7,0,VLOOKUP(G16,Liste_AT1!$A$3:$B$79,2,0)))) -> 0 | J16: =IF(I16="",0,IF(I16<$J$1,50,IF(I16>22.8,0,VLOOKUP(I16,Liste_AT1!$C$3:$D$125,2,0)))) -> 0 | L16: =IF(K16="",0,IF(K16<$L$1,50,IF(K16>29.2,0,VLOOKUP(K16,Liste_AT1!$E$3:$F$138,2,0)))) -> 0 | M16: 34.5 | N16: =IF(M16="",0,IF(M16<15,50,IF(M16>39.5,0,VLOOKUP(M16,Liste_AT1!$G$3:$H$248,2,0)))) -> 11 | P16: =IF(O16="",0,IF(O16<40,50,IF(O16>108,0,VLOOKUP(O16,Liste_AT1!$I$3:$J$71,2,0)))) -> 0 | R16: =IF(Q16>10,50,IF(Q16<1,0,IF(Q16="",0,VLOOKUP(Q16,Liste_AT1!$K$3:$L$21,2,0)))) -> 0 | T16: =IF(S16>10,50,IF(S16<1,0,VLOOKUP(S16,Liste_AT1!$M$3:$N$21,2,0))) -> 0 | V16: =IF(U16>5,35,IF(U16<1,0,VLOOKUP(U16,Liste_AT1!$O$3:$P$19,2))) -> 0 | W16: 9.1 | X16: =IF(W16>10,50,IF(W16<1,0,VLOOKUP(W16,Liste_AT1!$Q$3:$R$21,2))) -> 46 | Z16: =IF(Y16>10,50,IF(Y16<1,0,VLOOKUP(Y16,Liste_AT1!$S$3:$T$12,2))) -> 0 | AB16: =IF(AA16="",0,IF(AA16<3.8,50,IF(AA16>6.9,0,VLOOKUP(AA16,Liste_AT2!$A$3:$B$34,2)))) -> 0 | AD16: =IF(AC16="",0,IF(AC16<8.6,50,IF(AC16>12.1,0,VLOOKUP(AC16,Liste_AT2!$C$3:$D$38,2)))) -> 0 | AF16: =IF(AE16="",0,IF(AE16<160,50,IF(AE16>231,0,VLOOKUP(AE16,Liste_AT2!$F$3:$G$74,2)))) -> 0 | AG16: 628 | AH16: =IF(AG16="",0,IF(AG16<500,50,IF(AG16>626,0,VLOOKUP(AG16,Liste_AT2!$AU$3:$AW$66,3)))) -> 0 | AJ16: =IF(AI16="",0,IF(AI16<822,50,IF(AI16>948,0,VLOOKUP(AI16,Liste_AT2!$I$3:$J$66,2)))) -> 0 | AK16: 19.3 | AL16: =IF(AK16="",0,IF(AK16<15,50,IF(AK16>22.5,0,VLOOKUP(AK16,Liste_AT2!$K$3:$L$78,2)))) -> 11 | AN16: =IF(AM16="",0,IF(AM16<4,50,IF(AM16>9.4,0,VLOOKUP(AM16,Liste_AT2!$M$3:$N$57,2)))) -> 0 | AP16: =IF(AO16="",0,IF(AO16>33,50,IF(AO16<7,0,VLOOKUP(AO16,Liste_AT2!$Q$3:$R$29,2)))) -> 0 | AR16: =IF(AQ16="",0,IF(AQ16>17,50,IF(AQ16<1,0,VLOOKUP(AQ16,Liste_AT2!$U$3:$V$19,2)))) -> 0 | AT16: =IF(AS16="",0,IF(AS16>27,50,IF(AS16<6,0,VLOOKUP(AS16,Liste_AT2!$W$3:$X$24,2)))) -> 0 | AV16: =IF(AU16="",0,IF(AU16<3.7,50,IF(AU16>8,0,VLOOKUP(AU16,Liste_AT2!$AA$3:$AB$46,2)))) -> 0 | AX16: =IF(AW16="",0,IF(AW16<4,0,IF(AW16>10.1,50,VLOOKUP(AW16,Liste_AT2!$AC$3:$AD$62,2)))) -> 0 | AY16: 5.7 | AZ16: =IF(AY16="",0,IF(AY16>11.9,50,IF(AY16<5,0,VLOOKUP(AY16,Liste_AT2!$AE$3:$AF$72,2)))) -> 4 | BB16: =IF(BA16="",0,IF(BA16>45,50,IF(BA16<2,0,VLOOKUP(BA16,Liste_AT2!$AG$3:$AH$61,2)))) -> 0 | BD16: =IF(BC16="",0,IF(BC16>26,50,IF(BC16<4,0,VLOOKUP(BC16,Liste_AT2!$AI$3:$AJ$25,2)))) -> 0 | BE16: 17 | BF16: =IF(BE16="",0,IF(BE16>35,50,IF(BE16<14,0,VLOOKUP(BE16,Liste_AT2!$AK$3:$AL$24,2)))) -> 6 | BH16: =IF(BG16="",0,IF(BG16>36,50,IF(BG16<7,0,VLOOKUP(BG16,Liste_AT2!$AM$3:$AN$32,2)))) -> 0 | BJ16: =IF(BI16="",0,IF(BI16>45,50,IF(BI16<6,0,VLOOKUP(BI16,Liste_AT2!$AO$3:$AP$52,2)))) -> 0 | BK16: 1.64 | BL16: =IF(BK16="",0,IF(BK16>2.4,50,IF(BK16<1.15,0,VLOOKUP(BK16,Liste_AT2!$AQ$3:$AR$52,2)))) -> 12 | BM16: 39.3 | BN16: =IF(BM16="",0,IF(BM16<28,50,IF(BM16>62,0,VLOOKUP(BM16,Liste_AT2!$AS$3:$AT$343,2,0)))) -> 38 | BO16: 9.3 | BP16: =IF(BO16="",0,IF(BO16<1,0,IF(BO16>28,50,VLOOKUP(BO16,Liste_AT3!$A$3:$B$30,2)))) -> 14 | BR16: =IF(BQ16="",0,IF(BQ16<5,50,IF(BQ16>40,0,VLOOKUP(BQ16,Liste_AT3!$C$3:$D$38,2)))) -> 0 | BS16: 2.5 | BT16: =IF(BS16="",0,IF(BS16<1,50,IF(BS16>4.75,0,VLOOKUP(BS16,Liste_AT3!$E$3:$F$18,2)))) -> 25 | BV16: =IF(BU16="",0,IF(BU16<1,50,IF(BU16>4.75,0,VLOOKUP(BU16,Liste_AT3!$G$3:$H$18,2)))) -> 0 | BX16: =IF(BW16="",0,IF(BW16<1,50,IF(BW16>4.75,0,VLOOKUP(BW16,Liste_AT3!$G$3:$H$18,2)))) -> 0 | BZ16: =IF(BY16="",0,IF(BY16>40,0,VLOOKUP(BY16,Liste_AT3!$I$3:$J$43,2,2))) -> 0 | CB16: =IF(CA16="",0,IF(CA16>40,0,VLOOKUP(CA16,Liste_AT3!$I$3:$J$43,2,2))) -> 0 | CC16: =SUM(H16,J16,L16,N16,P16,R16,T16,V16,X16,Z16) -> 57 | CD16: =IF(CC16=0,"",RANK(CC16,$CC$4:$CC$19)) -> 15 | CE16: =SUM(AB16,AD16,AF16,AJ16,AL16,AN16,AH16) -> 11 | CF16: =IF(CE16=0,"",RANK(CE16,$CE$4:$CE$19)) -> 12 | CG16: =SUM(AP16,AR16,AT16,AV16,AX16,AZ16,BB16,BD16,BF16,BH16,BJ16,BL16,BN16) -> 60 | CH16: =IF(CG16=0,"",RANK(CG16,$CG$4:$CG$19)) -> 13 | CI16: =SUM(BP16,BR16) -> 14 | CJ16: =IF(CI16=0,"",RANK(CI16,$CI$4:$CI$19)) -> 10 | CK16: =SUM(BT16,BV16,BX16,BZ16,CB16) -> 25 | CL16: =IF(CK16=0,"",RANK(CK16,$CK$4:$CK$19)) -> 10 | CM16: =SUM(CC16,CE16,CG16,CI16,CK16) -> 167 | CN16: =IF(CM16=0,"",RANK(CM16,$CM$4:$CM$19)) -> 13
