Workbook
Name Deficit__Surplus: [2]LABOR!$B$25
Name Deficit__Surplus: [1]LABOR!$B$25
Name depre_98_99: [2]DEPREC!$AC$55
Name depre_98_99: [1]DEPREC!$AC$55
Name time_period: [2]LABOR!$A$36
Name time_period: [1]LABOR!$A$36

Sheet Lab Tests
A1: RATE CALCULATION BASED ON PRODUCTS OR SERVICES
A3: NOTE: Excel workbook contains formulas and links to the other worksheets; PLEASE DO NOT CHANGE FORMULAS
A5: Scenario: Lab Tests Sold for a Year
A6: Instructions
A7: 1. At the Recharge Facility cell, fill out the name of the Recharge Facility and if applicable, include Fund Number.
A8: 2. At the Rate Caculation cell, put in type of rate calculation (e.g., senior consultation, consulation)
A9: 3. Fill out the worksheet as row titles indicate.
A10: 4. Fill out % Effort based on the percentage effort of each person that will work on this rate. Put in 0% for the other personnel not included in this rate.
A11: 6. Fill out the Current Salary based on the full annual salary of each individual at the university.
A12: 7. Recharge Salary Expense is a formula. It multiplies % effort by the current salary to get the recharge salary expense.
A13: 8. Fill out % Benefits based on full benefits percentage of each individual at the university. It should be based on historical, actual data, if available.
A14: If not available, contact HR for the standard current rate for benefits (currently, the standard benefits rate is 23%).
... A35: Cost of Operation:
A36: Staff | B36: Role | C36: % Effort | D36: Current Salary | E36: Salary Expense | F36: % Benefits | G36: Benefit Expense | H36: Total Recharge Expense
C37: A | D37: B | E37: C | F37: D | G37: E | H37: F
E38: A * B | G38: C * D | H38: C + E
A39: Name | B39: Director | C39: 0.05 | D39: 101000 | E39: =C39*D39 -> 5050 | F39: 0.22 | G39: =E39*F39 -> 1111 | H39: =E39+G39 -> 6161
A40: Name | B40: Senior SRA | C40: 0.15 | D40: 75000 | E40: =C40*D40 -> 11250 | F40: 0.19 | G40: =E40*F40 -> 2137.5 | H40: =E40+G40 -> 13387.5
A41: Name | B41: SRA | C41: 0.5 | D41: 50000 | E41: =C41*D41 -> 25000 | F41: 0.23 | G41: =E41*F41 -> 5750 | H41: =E41+G41 -> 30750
A42: Name | B42: SRA | C42: 0.5 | D42: 50000 | E42: =C42*D42 -> 25000 | F42: 0.25 | G42: =E42*F42 -> 6250 | H42: =E42+G42 -> 31250
A43: Total Personnel | C43: =SUM(C39:C42) -> 1.2 | E43: =SUM(E39:E42) -> 66300 | G43: =SUM(G39:G42) -> 15248.5 | H43: =SUM(H39:H42) -> 81548.5
A45: NGN | H45: 600
A46: Office Supplies | H46: =500*C43 -> 600
A47: Lab Supplies | H47: 2500
A48: Equipment Depreciation | H48: =depreciation!M14 -> 19166.667
A50: Total S&E | H50: =SUM(H45:H49) -> 22866.667
A52: Adjustment for Prior Year Deficit or (Surplus) | H52: -1000
A54: Total projected expenses to be recovered | H54: =SUM(H43,H50,H52) -> 103415.17
A56: Billable Units: # of Lab Tests | H56: 2000
A58: Proposed Rate (UC Users) | H58: =H54/H56 -> 51.707583
A60: Proposed Rate (Non-UC Users) | H60: =H58*1.45 -> 74.975996

Sheet Consultation
A1: RATE CALCULATION BASED ON PRODUCTIVE HOURS AND DIFFERENT CLASSIFICATIONS (Pay groups)
A3: NOTE: Excel workbook contains formulas and links to the other worksheets; PLEASE DO NOT CHANGE FORMULAS
A5: Scenario: Productive Hours with Substantial Pay Differences
A6: Instructions
A7: 1. At the Recharge Facility cell, fill out the name of the Recharge Facility and if applicable, include Fund Number.
A8: 2. At the Rate Caculation cell, put in type of rate calculation (e.g., senior consultation, consulation)
A9: 3. Fill out the worksheet as row titles indicate.
A10: 4. Group employees of similar pay rates/functions, for the rate that is being calculated.
A11: 5. Fill out % Effort based on the percentage effort of each person that will work on this rate. Put in 0% for the other personnel not included in this rate.
A12: 6. Fill out the Current Salary based on the full annual salary of each individual at the university.
A13: 7. Recharge Salary Expense is a formula. It multiplies % effort by the current salary to get the recharge salary expense.
A14: 8. Fill out % Benefits based on full benefits percentage of each individual at the university. It should be based on historical, actual data, if available.
... A45: Cost of Operation:
A46: Staff | B46: Role | C46: % Effort | D46: Current Salary | E46: Salary Expense | F46: % Benefits | G46: Benefit Expense | H46: Total Recharge Expense | I46: Total Working Hours | J46: Less Holiday | K46: Less Vacation | L46: Less Sick Leave | M46: Less Non-ProductiveHours | N46: Total Productive Hours
C47: A | D47: B | E47: C | F47: D | G47: E | H47: F
E48: A * B | G48: C * D | H48: C + E
A49: ='Lab Tests'!A39 -> Name | B49: ='Lab Tests'!B39 -> Director | C49: 0.05 | D49: 85000 | E49: =C49*D49 -> 4250 | F49: 0.22 | G49: =E49*F49 -> 935 | H49: =E49+G49 -> 5185 | I49: =2088*C49 -> 104.4 | J49: =104*C49 -> 5.2 | K49: =192*C49 -> 9.6 | L49: =96*C49 -> 4.8 | M49: =I49-J49-K49-L49 -> 84.8 | N49: =I49-J49-K49-L49-M49 -> 0
A50: ='Lab Tests'!A40 -> Name | B50: ='Lab Tests'!B40 -> Senior SRA | C50: 0 | D50: 75000 | E50: =C50*D50 -> 0 | F50: 0.19 | G50: =E50*F50 -> 0 | H50: =E50+G50 -> 0 | I50: =2088*C50 -> 0 | J50: =104*C50 -> 0 | K50: =192*C50 -> 0 | L50: =96*C50 -> 0 | M50: =0.1*I50 -> 0 | N50: =SUM(N46:N46) -> 0
A51: ='Lab Tests'!A41 -> Name | B51: ='Lab Tests'!B41 -> SRA | C51: 0.5 | D51: 50000 | E51: =C51*D51 -> 25000 | F51: 0.23 | G51: =E51*F51 -> 5750 | H51: =E51+G51 -> 30750 | I51: =2088*C51 -> 1044 | J51: =104*C51 -> 52 | K51: =120*C51 -> 60 | L51: =96*C51 -> 48 | M51: =0.1*I51 -> 104.4 | N51: =I51-J51-K51-L51-M51 -> 779.6
A52: ='Lab Tests'!A42 -> Name | B52: ='Lab Tests'!B42 -> SRA | C52: 0.5 | D52: 50000 | E52: =C52*D52 -> 25000 | F52: 0.25 | G52: =E52*F52 -> 6250 | H52: =E52+G52 -> 31250 | I52: =2088*C52 -> 1044 | J52: =104*C52 -> 52 | K52: =120*C52 -> 60 | L52: =96*C52 -> 48 | M52: =0.1*I52 -> 104.4 | N52: =I52-J52-K52-L52-M52 -> 779.6
A53: Total Personnel | C53: =SUM(C49:C52) -> 1.05 | E53: =SUM(E49:E49) -> 4250 | G53: =SUM(G49:G49) -> 935 | H53: =SUM(H49:H52) -> 67185 | N53: =SUM(N49:N52) -> 1559.2
A55: ='Lab Tests'!A45 -> NGN | H55: 525
A56: ='Lab Tests'!A46 -> Office Supplies | H56: =500*C53 -> 525
A57: ='Lab Tests'!A47 -> Lab Supplies | H57: 0
A58: ='Lab Tests'!A48 -> Equipment Depreciation | H58: 0
A60: Total S&E | H60: =SUM(H55:H59) -> 1050
A62: Adjustment for Prior Year Deficit or Surplus | H62: 750
A64: Total projected expenses to be recovered | H64: =SUM(H53,H60,H62) -> 68985
A66: Billable Units: # of Productive Hours | H66: =N53 -> 1559.2
A68: Proposed Rate (UC Users) | H68: =H64/H66 -> 44.243843
A70: Proposed Rate (Non-UC Users) | H70: =H68*1.45 -> 64.153572

Sheet depreciation
B1: UCSD Dept
B2: XX Recharge Facility
B3: Equipment Depreciation
B4: Fiscal Year 20XX/XX
G7: Custody | H7: Acquisition | I7: Depreciation | J7: Useful | L7: 1 | M7: 2 | N7: 3 | O7: 4 | P7: 5 | Q7: 6 | R7: 7 | S7: 8 | T7: 9 | U7: 10 | V7: 11 | W7: 12 | X7: 13 | Y7: 14 | Z7: 15 | AA7: 16 | AB7: 17 | AC7: 18 | AD7: 19 | AE7: 20 | AF7: 21
B8: Description | C8: UCID | D8: Price | E8: P.O | F8: Fund | G8: Code | H8: Date | I8: Amount | J8: Life | K8: dep/yr | L8: 08/09 | M8: 09/10 | N8: 10/11 | O8: 11/12 | P8: 12/13 | Q8: 13/14 | R8: 14/15 | S8: 15/16 | T8: 16/17 | U8: 17/18 | V8: 18/19 | W8: 19/20 | X8: 20/21 | Y8: 21/22 | Z8: 22/23 | AA8: 23/24 | AB8: 24/25 | AC8: 25/26 | AD8: 26/27 | AE8: 27/28 | AF8: 28/29 | AG8: Total | AJ8: VENDORS | AK8: location | AL8: note
A10: 1 | B10: machine a | C10: 1234567 | D10: 250000 | E10: 10xxxxxx | F10: 19900A | G10: 1234 | H10: Jul-09 | I10: =D10 -> 250000 | J10: 20 | K10: =I10/J10 -> 12500 | L10: N/A | M10: =K10 -> 12500 | N10: =K10 -> 12500 | O10: =K10 -> 12500 | P10: =K10 -> 12500 | Q10: =K10 -> 12500 | R10: =K10 -> 12500 | S10: =K10 -> 12500 | T10: =K10 -> 12500 | U10: =K10 -> 12500 | V10: =K10 -> 12500 | W10: =K10 -> 12500 | X10: =K10 -> 12500 | Y10: =K10 -> 12500 | Z10: =K10 -> 12500 | AA10: =K10 -> 12500 | AB10: =K10 -> 12500 | AC10: =K10 -> 12500 | AD10: =K10 -> 12500 | AE10: =K10 -> 12500 | AF10: =K10 -> 12500 | AG10: =SUM(M10:AF10) -> 250000 | AH10: =AG10-I10 -> 0 | AJ10: Name | AL10: info as per Jan's spreadsheet
A11: 2 | B11: machine b | C11: 2234567 | D11: 100000 | E11: 10xxxxxx | F11: 56789A | G11: 1234 | H11: Jul-08 | I11: =D11 -> 100000 | J11: 15 | K11: =I11/J11 -> 6666.6667 | L11: =K11 -> 6666.6667 | M11: =K11 -> 6666.6667 | N11: =K11 -> 6666.6667 | O11: =K11 -> 6666.6667 | P11: =K11 -> 6666.6667 | Q11: =K11 -> 6666.6667 | R11: =K11 -> 6666.6667 | S11: =K11 -> 6666.6667 | T11: =K11 -> 6666.6667 | U11: =K11 -> 6666.6667 | V11: =K11 -> 6666.6667 | W11: =K11 -> 6666.6667 | X11: =K11 -> 6666.6667 | Y11: =K11 -> 6666.6667 | Z11: =K11 -> 6666.6667 | AA11: =L11 -> 6666.6667 | AB11: N/A | AC11: N/A | AD11: N/A | AE11: N/A | AF11: N/A | AG11: =SUM(M11:AF11) -> 100000 | AJ11: Name
B14: Total | D14: =SUM(D10:D12) -> 350000 | I14: =SUM(I10:I12) -> 350000 | K14: =SUM(K10:K10) -> 12500 | M14: =SUM(M10:M12) -> 19166.667 | N14: =SUM(N10:N12) -> 19166.667 | O14: =SUM(O10:O12) -> 19166.667 | P14: =SUM(P10:P12) -> 19166.667 | Q14: =SUM(Q10:Q12) -> 19166.667 | R14: =SUM(R10:R12) -> 19166.667 | S14: =SUM(S10:S12) -> 19166.667 | T14: =SUM(T10:T12) -> 19166.667 | ... AG14: =SUM(AG10:AG12) -> 350000
B17: If an equipment was allotted to different rates, please provide rationale

Sheet Statement of Operations
A1: STATEMENT OF OPERATIONS
A3: NOTE: Excel workbook contains formulas and links to the other worksheets; PLEASE DO NOT CHANGE FORMULAS
A4: Scenario: Profit and Loss Statement for Lab Tests and Consultation Produtive Hours
A5: Instructions
A6: 1. Find out the percentage of UC users and non-UC users for each rate. The total percentage for both types of users in each
A7: rate should equal 100%(e.g., 90% UC users and 10% non-UC users for Lab Tests). The 90% UC users and 10% will
A8: be used as an example for the Lab Tests and Consultation rates below.
A9: 2. Estimated No. Billable Units-UC User for Lab Tests is a formula. It multiplies the percentage of UC Users
A10: by the Total No. of Billable Units for the rate, Lab Tests. To get the Total No. of Billable Units, please reference
A11: the number from the Lab Tests Calculation Worksheet.
A12: 3. Estimated No. Billable Units-Non UC User for Lab Tests is a formula. It multiplies the percentage of Non UC Users
A13: by the Total No. of Billable Units for the rate, Lab Tests. To get the Total No. of Billable Units, please reference
... A47: Proposed Pricing
C48: Services
C49: Lab Test | D49: Consultation
A50: Estimated No. Billable Units- UC User | C50: ='Lab Tests'!H56*0.9 -> 1800 | D50: =Consultation!H66*0.9 -> 1403.28
A51: Estimated No. Billable Units- Non UC User | C51: ='Lab Tests'!H56*0.1 -> 200 | D51: =Consultation!H66*0.1 -> 155.92
A52: Proposed Rate (UC Users) | C52: ='Lab Tests'!H58 -> 51.707583 | D52: =Consultation!H68 -> 44.243843
A53: Proposed Rate (Non-UC Users)* | C53: ='Lab Tests'!H60 -> 74.975996 | D53: =Consultation!H70 -> 64.153572
A54: *Non-UC Users Hourly Rate includes the current approved
A55: differential income transfer percentage
A57: Distribution of Effort
C59: Services
A60: Acad/Staff | B60: Role | C60: =C49 -> Lab Test | D60: =D49 -> Consultation | E60: Total
A61: ='Lab Tests'!A39 -> Name | B61: ='Lab Tests'!B39 -> Director | C61: ='Lab Tests'!C39 -> 0.05 | D61: =Consultation!C49 -> 0.05 | E61: =SUM(C61:D61) -> 0.1
A62: ='Lab Tests'!A40 -> Name | B62: ='Lab Tests'!B40 -> Senior SRA | C62: ='Lab Tests'!C40 -> 0.15 | D62: =Consultation!C50 -> 0 | E62: =SUM(C62:D62) -> 0.15
A63: ='Lab Tests'!A41 -> Name | B63: ='Lab Tests'!B41 -> SRA | C63: ='Lab Tests'!C41 -> 0.5 | D63: =Consultation!C51 -> 0.5 | E63: =SUM(C63:D63) -> 1
A64: ='Lab Tests'!A42 -> Name | B64: ='Lab Tests'!B42 -> SRA | C64: ='Lab Tests'!C42 -> 0.5 | D64: =Consultation!C52 -> 0.5 | E64: =SUM(C64:D64) -> 1
A66: Summary
C68: Services
C69: =C49 -> Lab Test | D69: =D49 -> Consultation | E69: Total
A70: Income
A71: Recharge Income-UC User | C71: =C50*C52 -> 93073.65 | D71: =D50*D52 -> 62086.5 | E71: =SUM(C71:D71) -> 155160.15
A72: Revenue- Non-UC User | C72: =C51*C53 -> 14995.199 | D72: =D51*D53 -> 10002.825 | E72: =SUM(C72:D72) -> 24998.024
A73: Total Income | C73: =SUM(C71:C72) -> 108068.85 | D73: =SUM(D71:D72) -> 72089.325 | E73: =SUM(E71:E72) -> 180158.17
A75: Salaries & Benefits
A76: ='Lab Tests'!A39 -> Name | B76: ='Lab Tests'!B39 -> Director | C76: ='Lab Tests'!H39 -> 6161 | D76: =Consultation!H49 -> 5185 | E76: =SUM(C76:D76) -> 11346
A77: ='Lab Tests'!A40 -> Name | B77: ='Lab Tests'!B40 -> Senior SRA | C77: ='Lab Tests'!H40 -> 13387.5 | D77: =Consultation!H50 -> 0 | E77: =SUM(C77:D77) -> 13387.5
A78: ='Lab Tests'!A41 -> Name | B78: ='Lab Tests'!B41 -> SRA | C78: ='Lab Tests'!H41 -> 30750 | D78: =Consultation!H51 -> 30750 | E78: =SUM(C78:D78) -> 61500
A79: ='Lab Tests'!A42 -> Name | B79: ='Lab Tests'!B42 -> SRA | C79: ='Lab Tests'!H42 -> 31250 | D79: =Consultation!H52 -> 31250 | E79: =SUM(C79:D79) -> 62500
...
