Workbook
Name _10POS_BY_CAT: '[1]Summ Atty Agt'!#REF!
Name _11POS_BY_CAT: #REF!
Name _1ATTORNEY_SUPP: #REF!
Name _2ATTORNEY_SUPP: #REF!
Name _3GA_ROLLUP: 'B. Summary of Requirements '!#REF!
Name _4GA_ROLLUP: #REF!
Name _6GA_ROLLUP: '[1]Sum of Req'!#REF!
Name _7GA_ROLLUP: #REF!
Name _8POS_BY_CAT: #REF!
Name _9POS_BY_CAT: #REF!
Name DL: 'B. Summary of Requirements '!$A$3:$X$55
Name DL: #REF!
Name EXECSUPP: 'B. Summary of Requirements '!#REF!
Name EXECSUPP: #REF!
Name EXECSUPP: '[1]Sum of Req'!#REF!
Name EXECSUPP: #REF!
Name FY0711.1: #REF!
Name FY0711.5: #REF!
Name FY0712.1: #REF!
Name FY0721.0: #REF!
Name FY0722.0: #REF!
Name FY0723.1: #REF!
Name FY0723.2: #REF!
Name FY0723.3: #REF!
Name FY0724.0: #REF!
Name FY0725.2: #REF!
Name FY0725.3: #REF!
Name FY0725.6: #REF!
Name FY0726.0: #REF!
Name FY0731.0: #REF!
Name FY0732.0: #REF!
Name FY07Ling: #REF!
Name FY07Mult: #REF!
Name FY07PEPI: #REF!
Name FY07Tot: #REF!
Name FY07Train: #REF!
Name FY0811.1: #REF!
Name FY0811.5: #REF!
Name FY0812.1: #REF!
Name FY0821.0: #REF!
Name FY0822.0: #REF!
Name FY0823.1: #REF!
Name FY0823.2: #REF!
Name FY0823.3: #REF!
Name FY0824.0: #REF!
Name FY0825.2: #REF!
Name FY0825.3: #REF!
Name FY0825.6: #REF!
Name FY0826.0: #REF!
Name FY0831.0: #REF!
Name FY0832.0: #REF!
Name FY08Ling: #REF!
Name FY08Mult: #REF!
Name FY08PEPI: #REF!
Name FY08Tot: #REF!
Name FY08Train: #REF!
Name FY0911.1: #REF!
Name FY0911.5: #REF!
Name FY0912.1: #REF!
Name FY0921.0: #REF!

Sheet A. Organization Chart
A1: A: Organizational Chart | N1: end of line
N2: end of line
N3: end of line
N4: end of line
N5: end of line
N6: end of line
N7: end of line
N8: end of line
N9: end of line
N10: end of line
N11: end of line
N12: end of line
N13: end of line
... N29: end of sheet
A200: 2012 template
A256: FY 2011 CJ Submission

Sheet B. Summary of Requirements 
A1: B: Summary of Requirements | Y1: end of line
Y2: end of line
Y3: end of line
A4: Summary of Requirements | Y4: end of line
A5: National Security Division | Y5: end of line
A6: Salaries and Expenses | Y6: end of line
A7: (Dollars in Thousands) | Y7: end of line
Y8: end of line
Y9: end of line
Y10: end of line
V11: FY 2013 Request | Y11: end of line
V12: Perm. Pos. | W12: FTE | X12: Amount | Y12: end of line
Y13: end of line
A14: 2011 Enacted | V14: 346 | W14: 346 | X14: 87762 | Y14: end of line
A15: 2012 Enacted | V15: 359 | W15: 353 | X15: 87000 | Y15: end of line
A16: Adjustments to Base | Y16: end of line
A17: Transfers: | Y17: end of line
A18: [list all - if applicable] | B18: JCON and JCON S/TS | V18: 0 | W18: 0 | X18: 1182 | Y18: end of line
A19: [list all - if applicable] | B19: Office of Information Policy (OIP) | V19: 0 | W19: 0 | X19: -16 | Y19: end of line
A20: [list all - if applicable] | B20: Professional Responsibility Advisory Office (PRAO) | V20: 0 | W20: 0 | X20: -74 | Y20: end of line
A21: Subtotal Transfers | V21: =SUM(V17:V20) -> 0 | W21: =SUM(W17:W20) -> 0 | X21: =SUM(X17:X20) -> 1092 | Y21: end of line
A22: Increases: | Y22: end of line
A23: Pay and Benefits | V23: 0 | W23: 6 | X23: 802 | Y23: end of line
A24: Domestic Rent and Facilities | V24: 0 | W24: 0 | X24: 1337 | Y24: end of line
A25: Subtotal Increases | V25: =SUM(V23:V24) -> 0 | W25: =SUM(W23:W24) -> 6 | X25: =SUM(X23:X24) -> 2139 | Y25: end of line
A26: Total Adjustments to Base | V26: =V25 -> 0 | W26: =W25 -> 6 | X26: =+X25+X21 -> 3231 | Y26: end of line
A27: 2013 Current Services | V27: =+V26+V15 -> 359 | W27: =+W26+W15 -> 359 | X27: =+X26+X15 -> 90231 | Y27: end of line
A28: Program Changes | Y28: end of line
A29: Offsets: | Y29: end of line
A30: IT Savings | V30: 0 | W30: 0 | X30: -192 | Y30: end of line
A31: Subtotal Offsets | V31: =SUM(V30:V30) -> 0 | W31: =SUM(W30:W30) -> 0 | X31: =SUM(X30:X30) -> -192 | Y31: end of line
A32: Total Program Changes | V32: =V31 -> 0 | W32: =W31 -> 0 | X32: =X31 -> -192 | Y32: end of line
A33: 2013 Total Request | V33: =V27+V32 -> 359 | W33: =W27+W32 -> 359 | X33: =X27+X32 -> 90039 | Y33: end of line
A34: 2012 - 2013 Total Change | V34: =+V33-V15 -> 0 | W34: =+W33-W15 -> 6 | X34: =+X33-X15 -> 3039 | Y34: end of line
Y35: end of line
A36: NOTE: All FTE numbers in this table reflect authorized FTE, which is the total number of FTE available to a component. Because the FY 2013 President’s Budget Appendix builds the FTE request using actual FTE rather than authorized, it may not match the FY 2012 FTE enacted and FY 2013 FTE request reflected in this table. | Y36: end of line
Y37: end of line
Y38: end of line
Y39: end of line
Y40: end of line
...

Sheet C. Increases Offsets
A1: C: Program Increases/Offsets By Decision Unit | H1: end of line
H2: end of line
H3: end of line
A4: FY 2013 Program Increases/Offsets By Decision Unit | H4: end of line
A5: National Security Division | H5: end of line
A6: (Dollars in Thousands) | H6: end of line
H7: end of line
H8: end of line
A9: Program Offsets | B9: Location of Description by Decision Unit | C9: National Security Division | G9: Total Offsets | H9: end of line
C10: Pos. | D10: Agt./Atty. | E10: FTE | F10: Amount | H10: end of line
H11: end of line
A12: Program Offset - IT Savings | B12: National Security Division | C12: 0 | D12: 0 | E12: 0 | F12: -192 | G12: =+F12 -> -192 | H12: end of line
A13: Total Offsets | C13: =SUM(C11:C12) -> 0 | D13: =SUM(D11:D12) -> 0 | E13: =SUM(E11:E12) -> 0 | F13: =SUM(F11:F12) -> -192 | G13: =SUM(G11:G12) -> -192 | H13: end of line
H14: end of line

Sheet D. Strategic Goals & Objectives
A1: D: Resources by DOJ Strategic Goal and Strategic Objective | Q1: end of line
Q2: end of line
A3: Resources by Department of Justice Strategic Goal/Objective | Q3: end of line
A4: National Security Division | Q4: end of line
A5: (Dollars in Thousands) | Q5: end of line
Q6: end of line
Q7: end of line
C8: 2011 Appropriation Enacted | F8: 2012 Enacted | I8: 2013 Current Services | K8: 2013 | O8: 2013 Request | Q8: end of line
K9: Increases | M9: Offsets | Q9: end of line
A10: Strategic Goal and Strategic Objective | Q10: end of line
C11: Direct, Reimb. Other FTE | D11: Direct Amount $000s | F11: Direct, Reimb. Other FTE | G11: Direct Amount $000s | I11: Direct, Reimb. Other FTE | J11: Direct Amount $000s | K11: Direct, Reimb. Other FTE | L11: Direct Amount $000s | M11: Direct, Reimb. Other FTE | N11: Direct Amount $000s | O11: Direct, Reimb. Other FTE | P11: Direct Amount $000s | Q11: end of line
Q12: end of line
A13: Goal 1: Prevent Terrorism and Promote the Nation's Security Consistent with the Rule of Law | Q13: end of line
A14: 1.1 Prevent, disrupt, and defeat terrorist operations before they occur | C14: 220 | D14: 62282 | F14: 226 | G14: 61123 | I14: 230 | J14: 63393 | N14: -135 | O14: =+I14+K14+M14 -> 230 | P14: =+J14+L14+N14 -> 63258 | Q14: end of line
A15: 1.2 Prosecute those involved in terrorist acts | C15: 86 | D15: 17228 | F15: 87 | G15: 17498 | I15: 88 | J15: 18148 | N15: -39 | O15: =+I15+K15+M15 -> 88 | P15: =+J15+L15+N15 -> 18109 | Q15: end of line
A16: 1.3 Combat espionage against the United States | C16: 40 | D16: 8252 | F16: 40 | G16: 8379 | I16: 41 | J16: 8690 | N16: -18 | O16: =+I16+K16+M16 -> 41 | P16: =+J16+L16+N16 -> 8672 | Q16: end of line
A17: Subtotal, Goal 1 | C17: =SUM(C14:C16) -> 346 | D17: =SUM(D14:D16) -> 87762 | F17: =SUM(F14:F16) -> 353 | G17: =SUM(G14:G16) -> 87000 | I17: =SUM(I14:I16) -> 359 | J17: =SUM(J14:J16) -> 90231 | K17: =SUM(K14:K16) -> 0 | L17: =SUM(L14:L16) -> 0 | M17: =SUM(M14:M16) -> 0 | N17: =SUM(N14:N16) -> -192 | O17: =SUM(O14:O16) -> 359 | P17: =SUM(P14:P16) -> 90039 | Q17: end of line
A18: GRAND TOTAL | C18: =C17 -> 346 | D18: =D17 -> 87762 | F18: =F17 -> 353 | G18: =G17 -> 87000 | I18: =+I17 -> 359 | J18: =J17 -> 90231 | K18: =K17 -> 0 | L18: =L17 -> 0 | M18: =M17 -> 0 | N18: =N17 -> -192 | O18: =O17 -> 359 | P18: =P17 -> 90039 | Q18: end of sheet

Sheet E. ATB Justification
A1: E. Justification for Base Adjustments | E1: end of line
E2: end of line
A3: Justification for Base Adjustments | E3: end of line
A4: National Security Division | E4: end of line
E5: end of line
E6: end of line
B7: POS | C7: FTE | D7: Amount | E7: end of line
A8: Transfers | E8: end of line
E9: end of line
A10: JCON and JCON S/TS. A transfer of $1,182,000 is included in support of the Department's Justice Consolidated Office Network (JCON) and JCON S/TS programs which will be moved to the Working Capital Fund and provided as a billable service in FY 2013. | D10: 1182000 | E10: end of line
A12: Office of Information Policy. The National Security Division transfers for the Office of Information Policy (OIP) into the General Administration appropriation will centralize appropriated funding and eliminate the current reimbursable financing process. The centralization of the funding is administratively advantageous because it eliminates the paper-intensive reimbursement process. | D12: -16000 | E12: end of line
A14: Professional Responsibility Advisory Office. The National Security Division transfers for the Professional Responsibility Advisory Office (PRAO) into the General Administration appropriation will centralize appropriated funding and eliminate the current reimbursable financing process. The centralization of the funding is administratively advantageous because it eliminates the paper-intensive reimbursement process. | D14: -74000 | E14: end of line
A16: Increases | E16: end of line
A18: 2013 Pay Raise. This request provides for a proposed 0.5 percent pay raise to be effective in January of 2013. This increase only includes the general pay raise. The amount requested, $204,000, represents the pay amounts for 3/4 of the fiscal year plus appropriate benefits ($149,000 for pay and $55,000 for benefits). | D18: 204000 | E18: end of line
E19: end of line
A20: Retirement. Agency retirement contributions increase as employees under CSRS retire and are replaced by FERS employees. Based on OPM government-wide estimates, we project that the DOJ workforce will convert from CSRS to FERS at a rate of 1.3 percent per year. The requested increase of $85,000 is necessary to meet our increased retirement obligations as a result of this conversion. | D20: 85000 | E20: end of line
E21: end of line
A22: Employees Compensation Fund. The $1,000 increase reflects payments to the Department of Labor for injury benefits paid in the past year under the Federal Employee Compensation Act. This estimate is based on the first quarter of prior year billing and current year estimates. | D22: 1000 | E22: end of line
E23: end of line
A24: Health Insurance. Effective January 2013, the National Security Division's contribution to Federal employees' health insurance premiums increased by 7.9 percent. Applied against the 2011 estimate of $2,685,000, the additional amount required is $213,000. | D24: 213000 | E24: end of line
E25: end of line
A26: FERS Regular/Law Enforcement Retirement Contribution. On June 11, 2010, the Board of Actuaries of the Civil Service Retirement System recommended a new set of economic assumptions for the Civil Service Retirement System (CSRS) and the Federal Employees Retirement System (FERS). In accordance with this change, effective October 1, 2011 (FY 2012), the total normal cost of regular retirement under FERS will increase from the current level of 12.5 percent of pay to 12.7 percent. The total FERS contribution for Law Enforcement retirement will increase from 27.0 percent to 27.6 percent. This will result in new agency contribution rates of 11.9 percent for normal costsl (up from the current 11.7 percent) and 26.3 percent for law enforcement personnel (up from the current 25.7 percent). The amount requested, 87,000, represents the funds needed to cover this increase. | D26: 87000 | E26: end of line
A28: Changes in Compensable Days. The increase cost for one more compensable day in FY 2013 compared to FY 2012 is calculated by dividing the FY 2012 estimated personnel compensation $174,000 and applicable benefits $38,000 by 260 compensable days. | D28: 212000 | E28: end of line
E29: end of line
E32: end of line
B33: POS | C33: FTE | D33: Amount
A34: General Services Administration (GSA) Rent. GSA will continue to charge rental rates that approximate those charged to commercial tenants for equivalent space and related services. The requested increase of $310,000 is required to meet our commitment to GSA. The costs associated with GSA rent were derived through the use of an automated system, which uses the latest inventory data, including rate increases to be effective in FY 2013 for each building currently occupied by Department of Justice components, as well as the costs of new space to be occupied. GSA provided data on the rate increases. | D34: 310000 | E34: end of line
A36: Non-GSA. The requested increase of $1,000,000 is required to meet our commitment for locations which are not provided by GSA. | D36: 1000000 | E36: end of line
E37: end of line
A38: Security Charges. Guard Service includes those costs paid directly by DOJ and those paid to Department of Homeland Security (DHS). The requested increase of $27,000 is required to meet our commitment to DHS and other security costs. | D38: 27000 | E38: end of line
E40: end of line
A41: Total Increase: | B41: 0 | C41: 0 | D41: 3231000 | E41: end of line
A42: Total ATB: | B42: 0 | C42: 0 | D42: 3231000 | E42: end of line
E43: end of line
E44: end of sheet

Sheet F. 2011 Crosswalk
A1: F: Crosswalk of 2011 Availability | P1: end of line
P2: end of line
A3: Crosswalk of 2011 Availability | P3: end of line
A4: =+'B. Summary of Requirements '!A5 -> National Security Division | P4: end of line
A5: =+'B. Summary of Requirements '!A6 -> Salaries and Expenses | P5: end of line
A6: (Dollars in Thousands) | P6: end of line
P7: end of line
P8: end of line
A9: Decision Unit | B9: FY 2011 Without Balance Rescissions | E9: Balance Rescissions | H9: Reprogrammings / Transfers | K9: Carryover | L9: Recoveries | M9: 2011 Availability | P9: end of line
P10: end of line
B11: Pos. | C11: FTE | D11: Amount | E11: Pos. | F11: FTE | G11: Amount | H11: Pos. | I11: FTE | J11: Amount | K11: Amount | L11: Amount | M11: Pos. | N11: FTE | O11: Amount | P11: end of line
A12: National Security Division | B12: 346 | C12: 346 | D12: 87762 | E12: 0 | F12: 0 | G12: 0 | H12: 0 | I12: 0 | J12: 5000 | K12: 1981 | L12: 841 | M12: =B12+E12+H12 -> 346 | N12: =C12+F12+I12 -> 346 | O12: =D12+G12+J12+K12+L12 -> 95584 | P12: end of line
A13: TOTAL | B13: =SUM(B12) -> 346 | C13: =SUM(C12) -> 346 | D13: =SUM(D12) -> 87762 | E13: =SUM(E12) -> 0 | F13: =SUM(F12) -> 0 | G13: =SUM(G12) -> 0 | H13: =SUM(H12) -> 0 | I13: =SUM(I12) -> 0 | ... O13: =SUM(O12) -> 95584 | P13: end of line
A14: Reimbursable FTE | N14: =C14+F14+I14 -> 0 | P14: end of line
A15: Total FTE | C15: =SUM(C13:C14) -> 346 | F15: =+F13+F14 -> 0 | I15: =+I13+I14 -> 0 | N15: =SUM(N13:N14) -> 346 | P15: end of line
A16: Other FTE | P16: end of line
A17: LEAP | N17: =C17+F17+I17 -> 0 | P17: end of line
A18: Overtime | N18: =C18+F18+I18 -> 0 | P18: end of line
A19: Total Compensable FTE | C19: =C18+C17+C15 -> 346 | F19: =F18+F17+F15 -> 0 | I19: =I18+I17+I15 -> 0 | N19: =N18+N17+N15 -> 346 | P19: end of line
A21: Transfer/Carryover/Recovery: FY 2011 funds totaling $7,822,000 represents a $5,000,000 transfer and $1,981,000 carryover for IT related projects and $841,000 in recoveries.
P27: end of sheet

Sheet G. 2012 Crosswalk
A1: G: Crosswalk of 2012 Availability | S1: end of line
S2: end of line
A3: Crosswalk of 2012 Availability | S3: end of line
A4: =+'B. Summary of Requirements '!A5 -> National Security Division | S4: end of line
A5: =+'B. Summary of Requirements '!A6 -> Salaries and Expenses | S5: end of line
A6: (Dollars in Thousands) | S6: end of line
S7: end of line
S8: end of line
A9: Decision Unit | B9: FY 2012 Enacted Without Rescissions | E9: Rescissions | H9: Supplementals | K9: Reprogrammings / Transfers | N9: Carryover | O9: Recoveries | P9: 2012 Availability | S9: end of line
S10: end of line
B11: Pos. | C11: FTE | D11: Amount | E11: Pos. | F11: FTE | G11: Amount | H11: Pos. | I11: FTE | J11: Amount | K11: Pos. | L11: FTE | M11: Amount | N11: Amount | O11: Amount | P11: Pos. | Q11: FTE | R11: Amount | S11: end of line
A12: National Security Division | B12: 359 | C12: 353 | D12: 87000 | E12: 0 | F12: 0 | G12: 0 | M12: 0 | N12: 7659 | O12: 85 | P12: =B12+E12+H12+K12 -> 359 | Q12: =C12+F12+I12+L12 -> 353 | R12: =D12+G12+J12+M12+N12+O12 -> 94744 | S12: end of line
A13: TOTAL | B13: =SUM(B12) -> 359 | C13: =SUM(C12) -> 353 | D13: =SUM(D12) -> 87000 | E13: =SUM(E12) -> 0 | F13: =SUM(F12) -> 0 | G13: =SUM(G12) -> 0 | H13: =SUM(H12:H12) -> 0 | I13: =SUM(I12:I12) -> 0 | J13: =SUM(J12:J12) -> 0 | K13: =SUM(K12) -> 0 | L13: =SUM(L12) -> 0 | M13: =SUM(M12) -> 0 | N13: =SUM(N12) -> 7659 | O13: =SUM(O12) -> 85 | P13: =SUM(P12) -> 359 | Q13: =SUM(Q12) -> 353 | R13: =SUM(R12) -> 94744 | S13: end of line
A14: Reimbursable FTE | Q14: =C14+F14+I14+L14 -> 0 | S14: end of line
A15: Total FTE | C15: =SUM(C13:C14) -> 353 | F15: =+F13+F14 -> 0 | I15: =+I13+I14 -> 0 | L15: =+L13+L14 -> 0 | Q15: =SUM(Q13:Q14) -> 353 | S15: end of line
A16: Other FTE | S16: end of line
A17: LEAP | C17: 0 | F17: 0 | I17: 0 | L17: 0 | Q17: =C17+F17+I17+L17 -> 0 | S17: end of line
A18: Overtime | C18: 0 | F18: 0 | I18: 0 | L18: 0 | Q18: =C18+F18+I18+L18 -> 0 | S18: end of line
A19: Total Compensable FTE | C19: =C18+C17+C15 -> 353 | F19: =F18+F17+F15 -> 0 | I19: =I18+I17+I15 -> 0 | L19: =L18+L17+L15 -> 0 | Q19: =Q18+Q17+Q15 -> 353 | S19: end of line
S20: end of sheet
A22: Carryover/Recovery: FY 2012 funds totaling $7,744,000 represents a $7,659,000 carryover for IT related projects and $85,000 in recoveries.

Sheet I. Permanent Positions
A1: I: Detail of Permanent Positions by Category | L1: end of line
L2: end of line
L3: end of line
A4: Detail of Permanent Positions by Category | L4: end of line
A5: =+'B. Summary of Requirements '!A5 -> National Security Division | L5: end of line
A6: =+'B. Summary of Requirements '!A6 -> Salaries and Expenses | L6: end of line
L7: end of line
L8: end of line
A9: Category | B9: 2011 Enacted | D9: 2012 Enacted | F9: 2013 Request | L9: end of line
B10: Total Authorized | C10: Total Reimbursable | D10: Total Authorized | E10: Total Reimbursable | F10: ATBs | G10: Program Increases | H10: Program Decreases | I10: Total Pr. Changes | J10: Total Authorized | K10: Total Reimbursable | L10: end of line
L11: end of line
A12: Intelligence Series (132) | B12: 11 | D12: 11 | J12: 11 | L12: end of line
A13: Clerical and Office Services (300-399) | B13: 67 | D13: 79 | J13: 79 | L13: end of line
A14: Accounting and Budget (500-599) | B14: 7 | D14: 7 | J14: 7 | L14: end of line
A15: Attorneys (905) | B15: 236 | D15: 236 | J15: 236 | L15: end of line
A16: Paralegals / Other Law (900-998) | B16: 13 | D16: 13 | J16: 13 | L16: end of line
A17: Business & Industry (1100-1199) | B17: 1 | D17: 1 | J17: 1 | L17: end of line
A18: Information Technology Mgmt (2210) | B18: 8 | D18: 8 | J18: 8 | L18: end of line
A19: Security Specialists (080) | B19: 3 | D19: 4 | J19: 4 | L19: end of line
A20: Total | B20: =SUM(B12:B19) -> 346 | C20: =SUM(C12:C19) -> 0 | D20: =SUM(D12:D19) -> 359 | E20: =SUM(E12:E19) -> 0 | F20: =SUM(F12:F19) -> 0 | G20: =SUM(G12:G19) -> 0 | H20: =SUM(H12:H19) -> 0 | I20: =SUM(I12:I19) -> 0 | ... K20: =SUM(K12:K19) -> 0 | L20: end of line
A21: Headquarters (Washington, D.C.) | B21: 345 | D21: 358 | I21: =G21+H21 -> 0 | J21: 358 | K21: =SUM(K13:K20) -> 0 | L21: end of line
A22: U.S. Field | B22: 1 | D22: 1 | J22: 1 | L22: end of line
A23: Total | B23: =SUM(B21:B22) -> 346 | C23: =SUM(C21:C22) -> 0 | D23: =SUM(D21:D22) -> 359 | E23: =SUM(E21:E22) -> 0 | F23: =SUM(F21:F22) -> 0 | G23: =SUM(G21:G22) -> 0 | H23: =SUM(H21:H22) -> 0 | I23: =SUM(I21:I22) -> 0 | ... K23: =SUM(K21:K22) -> 0 | L23: end of sheet

Sheet J. Financial Analysis
A1: J: Financial Analysis of Program Changes | F1: end of line
F2: end of line
A3: Financial Analysis of Program Changes | F3: end of line
A4: National Security Division | F4: end of line
A5: =+'B. Summary of Requirements '!A6 -> Salaries and Expenses | F5: end of line
A6: (Dollars in Thousands) | F6: end of line
F7: end of line
A8: Grades: | D8: Program Changes | F8: end of line
B9: National Security Division IT Savings Offset | F9: end of line
B10: Pos. | C10: Amount | D10: Pos. | E10: Amount | F10: end of line
A11: Personnel benefits | B11: 0 | C11: 0 | D11: =SUM(B11) -> 0 | E11: =SUM(C11) -> 0 | F11: end of line
A12: Travel and transportation of persons | B12: 0 | C12: 0 | D12: =SUM(B12) -> 0 | E12: =SUM(C12) -> 0 | F12: end of line
A13: Transportation of things | B13: 0 | C13: 0 | D13: =SUM(B13) -> 0 | E13: =SUM(C13) -> 0 | F13: end of line
A14: GSA rent | B14: 0 | C14: 0 | D14: =SUM(B14) -> 0 | E14: =SUM(C14) -> 0 | F14: end of line
A15: Communication, rents, and utilities | B15: 0 | C15: 0 | D15: =SUM(B15) -> 0 | E15: =SUM(C15) -> 0 | F15: end of line
A16: Printing | B16: 0 | C16: 0 | D16: =SUM(B16) -> 0 | E16: =SUM(C16) -> 0 | F16: end of line
A17: Advisory and assistance services | B17: 0 | C17: 0 | D17: =SUM(B17) -> 0 | E17: =SUM(C17) -> 0 | F17: end of line
A18: Other services | B18: 0 | C18: -192 | D18: =SUM(B18) -> 0 | E18: =SUM(C18) -> -192 | F18: end of line
A19: Purchases of goods & services from Government accounts | B19: 0 | C19: 0 | D19: =SUM(B19) -> 0 | E19: =SUM(C19) -> 0 | F19: end of line
A20: Research and development contracts | B20: 0 | C20: 0 | D20: =SUM(B20) -> 0 | E20: =SUM(C20) -> 0 | F20: end of line
A21: Operation and maintenance of equipment | B21: 0 | C21: 0 | D21: =SUM(B21) -> 0 | E21: =SUM(C21) -> 0 | F21: end of line
A22: Supplies and materials | B22: 0 | C22: 0 | D22: =SUM(B22) -> 0 | E22: =SUM(C22) -> 0 | F22: end of line
A23: Equipment | B23: 0 | C23: 0 | D23: =SUM(B23) -> 0 | E23: =SUM(C23) -> 0 | F23: end of line
A24: Total, 2013 Program Changes Requested | B24: =SUM(B11:B23) -> 0 | C24: =SUM(C11:C23) -> -192 | D24: =SUM(D11:D23) -> 0 | E24: =SUM(E11:E23) -> -192 | F24: end of sheet

Sheet K. Summary by Grade
A1: K: Summary of Requirements by Grade | J1: end of line
J2: end of line
J3: end of line
A4: Summary of Requirements by Grade | J4: end of line
A5: National Security Division | J5: end of line
A6: =+'B. Summary of Requirements '!A6 -> Salaries and Expenses | J6: end of line
J7: end of line
J8: end of line
A9: Grades and Salary Ranges | B9: 2011 Enacted w/Rescissions | D9: 2012 Enacted | F9: 2013 Request | H9: Increase/Decrease | J9: end of line
J10: end of line
B11: Pos. | C11: Amount | D11: Pos. | E11: Amount | F11: Pos. | G11: Amount | H11: Pos. | I11: Amount | J11: end of line
A12: SES, $119,554 - 179,700 | B12: 19 | D12: 19 | F12: 19 | H12: =F12-D12 -> 0 | J12: end of line
A13: GS-15, $123,758 - 155,500 | B13: 218 | D13: 218 | F13: 218 | H13: =F13-D13 -> 0 | J13: end of line
A14: GS-14, $105,211 - 136,771 | B14: 24 | D14: 25 | F14: 25 | H14: =F14-D14 -> 0 | J14: end of line
A15: GS-13, $89,033 - 115,742 | B15: 30 | D15: 30 | F15: 30 | H15: =F15-D15 -> 0 | J15: end of line
A16: GS-12, $74,872 - 97,333 | B16: 13 | D16: 13 | F16: 13 | H16: =F16-D16 -> 0 | J16: end of line
A17: GS-11, $62,467 - 81,204 | B17: 24 | D17: 29 | F17: 29 | H17: =F17-D17 -> 0 | J17: end of line
A18: GS-10, $56,857 - 73,917 | B18: 0 | D18: 0 | F18: 0 | H18: =F18-D18 -> 0 | J18: end of line
A19: GS-9, $51,630 - 67,114 | B19: 6 | D19: 13 | F19: 13 | H19: =F19-D19 -> 0 | J19: end of line
A20: GS-8, $46,745 - 60,765 | B20: 6 | D20: 6 | F20: 6 | H20: =F20-D20 -> 0 | J20: end of line
A21: GS-7, $42,209 - 54,875 | B21: 6 | D21: 6 | F21: 6 | H21: =F21-D21 -> 0 | J21: end of line
A22: Total, Appropriated Positions | B22: =SUM(B12:B21) -> 346 | D22: =SUM(D12:D21) -> 359 | F22: =SUM(F12:F21) -> 359 | H22: =SUM(H12:H21) -> 0 | J22: end of line
A23: Average SES Salary | C23: 174273 | E23: 174273 | G23: 174273 | J23: end of line
A24: Average GS Salary | C24: 123007 | E24: 120901 | G24: 120901 | J24: end of line
A25: Average GS Grade | C25: 14 | E25: 14 | G25: 14 | J25: end of sheet

Sheet L. Summary by Object Class
A1: L: Summary of Requirements by Object Class | M1: end of line
M2: end of line
A3: Summary of Requirements by Object Class | M3: end of line
A4: =+'B. Summary of Requirements '!A5 -> National Security Division | M4: end of line
A5: =+'B. Summary of Requirements '!A6 -> Salaries and Expenses | M5: end of line
A6: (Dollars in Thousands) | M6: end of line
M7: end of line
A8: Object Classes | B8: 2011 Actuals | D8: 2012 Availability | F8: 2013 Request | H8: Increase/Decrease | M8: end of line
B9: FTE | C9: Amount | D9: FTE | E9: Amount | F9: FTE | G9: Amount | H9: FTE | I9: Amount | M9: end of line
A10: 11.1 Direct FTE & personnel compensation | B10: 346 | C10: 38284 | D10: 353 | E10: 41465 | F10: 359 | G10: 43495 | H10: =F10-D10 -> 6 | I10: =G10-E10 -> 2030 | M10: end of line
A11: 11.3 Other than full-time permanent | C11: 648 | E11: 705 | G11: 705 | H11: =F11-D11 -> 0 | I11: =G11-E11 -> 0 | J11: atb | K11: enhance | M11: end of line
A12: 11.5 Total, Other personnel compensation | B12: =B13+B14 -> 0 | C12: 793 | D12: =D13+D14 -> 0 | E12: 793 | F12: =F13+F14 -> 0 | G12: 793 | H12: =F12-D12 -> 0 | I12: =G12-E12 -> 0 | J12: 93 | M12: end of line
A13: Overtime | H13: =F13-D13 -> 0 | I13: =G13-E13 -> 0 | M13: end of line
A14: Other Compensation | H14: =F14-D14 -> 0 | I14: =G14-E14 -> 0 | M14: end of line
A15: 11.8 Special personal services payments | H15: =F15-D15 -> 0 | I15: =G15-E15 -> 0 | M15: end of line
A16: Total | B16: =+B10+B11+B12+B15 -> 346 | C16: =+C10+C11+C12+C15 -> 39725 | D16: =+D10+D11+D12+D15 -> 353 | E16: =+E10+E11+E12+E15 -> 42963 | F16: =+F10+F11+F12+F15 -> 359 | G16: =+G10+G11+G12+G15 -> 44993 | H16: =+H10+H11+H12+H15 -> 6 | I16: =+I10+I11+I12+I15 -> 2030 | J16: =697+630+957+2333 -> 4617 | K16: =2451-93 -> 2358 | L16: =+E16-G16 -> -2030 | M16: end of line
A17: Other Object Classes: | M17: end of line
A18: 12.0 Personnel benefits | C18: 10963 | E18: 11814 | G18: 12373 | I18: =G18-E18 -> 559 | J18: 359 | K18: =1171+93 -> 1264 | L18: =+E18-G18 -> -559 | M18: end of line
A19: 21.0 Travel and transportation of persons | C19: 1428 | E19: 1428 | G19: 1428 | I19: =G19-E19 -> 0 | K19: 110 | L19: =+E19-G19 -> 0 | M19: end of line
A20: 22.0 Transportation of things | C20: 657 | E20: 728 | G20: 728 | I20: =G20-E20 -> 0 | K20: 0 | L20: =+E20-G20 -> 0 | M20: end of line
A21: 23.1 GSA rent | C21: 9547 | E21: 9462 | G21: 9490 | I21: =G21-E21 -> 28 | J21: =4220-576 -> 3644 | L21: =+E21-G21 -> -28 | M21: end of line
A22: 23.2 Moving/Lease Expirations/Contract Parking | C22: 174 | E22: 205 | G22: 213 | I22: =G22-E22 -> 8 | L22: =+E22-G22 -> -8 | M22: end of line
A23: 23.3 Comm., util., & other misc. charges | C23: 3758 | E23: 3758 | G23: 6240 | I23: =G23-E23 -> 2482 | J23: 332 | K23: 175 | L23: =+E23-G23 -> -2482 | M23: end of line
A24: 24.0 Printing and reproduction | C24: 1 | E24: 1 | G24: 1 | I24: =G24-E24 -> 0 | L24: =+E24-G24 -> 0 | M24: end of line
A25: 25.1 Advisory and assistance services | C25: 1499 | E25: 1150 | G25: 1150 | I25: =G25-E25 -> 0 | K25: 14918 | L25: =+E25-G25 -> 0 | M25: end of line
A26: 25.2 Other services | C26: 9128 | E26: =17752-7659 -> 10093 | G26: 9095 | I26: =G26-E26 -> -998 | J26: 276 | K26: 14853 | L26: =+E26-G26 -> 998 | M26: end of line
A27: 25.3 Purchases of goods & services from Government accounts (Antennas, DHS Sec. Etc.) | C27: 2529 | E27: 2939 | G27: 1789 | I27: =G27-E27 -> -1150 | K27: 135 | L27: =+E27-G27 -> 1150 | M27: end of line
A28: 25.4 Operation and maintenance of facilities | C28: 5 | E28: 5 | G28: 5 | I28: =G28-E28 -> 0 | L28: =+E28-G28 -> 0 | M28: end of line
A29: 25.5 Research and development contracts | C29: 0 | E29: 0 | G29: 0 | I29: =G29-E29 -> 0 | L29: =+E29-G29 -> 0 | M29: end of line
A30: 25.6 Medical care | C30: 23 | E30: 23 | G30: 23 | I30: =G30-E30 -> 0 | L30: =+E30-G30 -> 0 | M30: end of line
A31: 25.7 Operation and maintenance of equipment | C31: 195 | E31: 195 | G31: 195 | I31: =G31-E31 -> 0 | K31: 10 | L31: =+E31-G31 -> 0 | M31: end of line
A32: 26.0 Supplies and materials | C32: 257 | E32: 221 | G32: 221 | I32: =G32-E32 -> 0 | K32: 85 | L32: =+E32-G32 -> 0 | M32: end of line
A33: 31.0 Equipment | C33: 2499 | E33: 2015 | G33: 2095 | I33: =G33-E33 -> 80 | K33: 37758 | L33: =+E33-G33 -> -80 | M33: end of line
A34: Total obligations | C34: =SUM(C16:C33) -> 82388 | E34: =SUM(E16:E33) -> 87000 | G34: =SUM(G16:G33) -> 90039 | I34: =SUM(I16:I33) -> 3039 | J34: =SUM(J12:J33) -> 9321 | K34: =SUM(K16:K33) -> 71666 | L34: =+E34-G34 -> -3039 | M34: end of line
A35: Unobligated balance, start of year | C35: -1981 | E35: -7659 | M35: end of line
A36: Unobligated balance, end of year | C36: 13196 | M36: end of line
A37: Recoveries of prior year obligations | C37: -5841 | M37: end of line
A38: Total DIRECT requirements | C38: =SUM(C34:C37) -> 87762 | E38: =SUM(E34:E37) -> 79341 | G38: =SUM(G34:G37) -> 90039 | M38: end of line
A40: Reimbursable FTE: | M40: end of line
A41: Full-time permanent | B41: 0 | C41: 0 | D41: 0 | E41: 0 | F41: 0 | G41: 0 | M41: end of line
...
