Workbook
Name BEAvsCLL: alignement!#REF!
Name BEAvsLIM: alignement!#REF!
Name BEAvsRDL: alignement!#REF!
Name BEAvsRIM: alignement!#REF!
Name CLLvsFXG: alignement!#REF!
Name CLLvsLIM: alignement!#REF!
Name CLLvsRIM: alignement!#REF!
Name CSFvsBEA: alignement!#REF!
Name CSFvsCLL: alignement!#REF!
Name CSFvsRIM: alignement!#REF!
Name FXGvsBEA: alignement!#REF!
Name FXGvsCSF: alignement!#REF!
Name FXGvsLIM: alignement!#REF!
Name FXGvsRDL: alignement!#REF!
Name LIMvsCSF: alignement!#REF!
Name LIMvsRDL: alignement!#REF!
Name RDLvsCLL: alignement!#REF!
Name RDLvsCSF: alignement!#REF!
Name RDLvsRIM: alignement!#REF!
Name RIMvsFXG: alignement!#REF!
Name RIMvsLIM: alignement!#REF!

Sheet alignement
K2: Badminton «AA» (Équipe)
K3: Feuille de pointage | U3: 1.GARNEAU
U4: 2.SAINTE-FOY
A5: Date: 24 NOVEMBRE 2012 | C5: Endroit : Lévis-Lauzon | M5: Équipe # 2 | Q5: =joueurs!C3 -> BEA SYLVAIN LALIBERTÉ 1 | S5: =joueurs!H3 -> BEA JOSIANE LANGLOIS 1 | U5: 3.LÉVIS-LAUZON
Q6: =joueurs!C4 -> BEA ALEXANDRE POULIN 2 | S6: =joueurs!H4 -> BEA ALEX LECLERC 2 | U6: 4.RIMOUSKI
A7: VISITEUR | F7: HEURE | I7: TERRAIN | L7: RECEVEUR | Q7: =joueurs!C5 -> BEA ALEX DUCLOS 3 | S7: =joueurs!H5 -> 0 | U7: 5.RIVIÈRE-DU-LOUP
A8: 1.GARNEAU | F8: 09h30 | I8: 1-2-3 | L8: 7.BEAUCE-APPALACHES | Q8: =joueurs!C6 -> BEA CALVIN CHEN 4 | S8: =joueurs!H6 -> BEA MARIE-ÈVE MATHIEU 4 | U8: 6.LIMOILOU
Q9: =joueurs!C7 -> BEA ROMAIN LEMIEUX 5 | S9: =joueurs!H7 -> BEAU LANY FORTIN 5 | U9: 7.BEAUCE-APPALACHES
D10: SIMPLE MASCULIN 2/3 21pts | Q10: =joueurs!C8 -> BEA PIER-ALEXANDRE BOUCHER 6
A12: No. | B12: Nom | D12: Pts | F12: Résultats | L12: No. | M12: Nom | O12: Pts | Q12: =joueurs!C10 -> CLL WILLIAM BROUARD 1 | S12: =joueurs!H10 -> CLL MARILOU HAMEL 1
A13: 1 | B13: FXG PHILIPPE RENY 3 | D13: 5 | F13: 15-21 | H13: 21-23 | M13: BEA SYLVAIN LALIBERTÉ 1 | O13: 12 | Q13: =joueurs!C11 -> CLL PASCAL BOURGAULT 2 | S13: =joueurs!H11 -> CLL VALÉRIE DESRUISSEAUX 2
Q14: =joueurs!C12 -> CLL SAMUEL GUAY 3 | S14: =joueurs!H12 -> CLL AUDREY GAGNÉ 3
Q15: =joueurs!C13 -> CLL ALEXANDRE HAMEL 4 | S15: =joueurs!H13 -> CLL CHLOÉ BRETON 4
Q16: =joueurs!C14 -> CLL MAXIME GAUDET 5 | S16: =joueurs!H14 -> CLL JULIE MÉTHOT 5
D17: SIMPLE FÉMININ 2/3 21pts | Q17: =joueurs!C15 -> CLL OLIVIER BARRETTE 6 | S17: =joueurs!H15 -> CLL CATHERINE GUIMONT 6
Q18: =joueurs!C16 -> CLL ESTÉBAN JOMPHE 7
A19: 1 | B19: FXG VANESSA GENDRON 1 | D19: 10 | F19: 12-21 | H19: 21-11 | J19: 11-21 | M19: BEA JOSIANE LANGLOIS 1 | O19: 12 | Q19: =joueurs!C17 -> 0
Q20: =joueurs!C18 -> CLL SAMUEL BEAULIEU 9
D21: DOUBLE FÉMININ 2/3 21pts | Q21: =joueurs!C19 -> CLL ANTHONY CAREY 10
Q22: =joueurs!C20 -> CLL ÉTIENNE THIBAULT 11
A23: 1 | B23: FXG EMMANUELLE DUNN 2 | D23: 12 | F23: 21-9 | H23: 21-10 | M23: BEA ALEX LECLERC 2 | O23: 4
B24: FXG JOSIANNE BOULANGER 3 | M24: BEAU LANY FORTIN 5 | Q24: =joueurs!C22 -> 0 | S24: =joueurs!H22 -> 0
Q25: =joueurs!C23 -> CSF SIMON JEAN-PINEAULT 2 | S25: =joueurs!H23 -> CSF VIRGINIE SAVARD 2
D26: DOUBLE MASCULIN 2/3 21pts | Q26: =joueurs!C24 -> CSF ALEXANDRE MAZIADE 3 | S26: =joueurs!H24 -> 0
Q27: =joueurs!C25 -> CSF MARC-ANTOINE GENEST 4 | S27: =joueurs!H25 -> CSF CATHERINE SAVARD 4
A28: 1 | B28: FXG GABRIEL GOULET-MAILHOT 5 | D28: 12 | F28: 18-21 | H28: 21-19 | J28: 21-17 | M28: BEA ALEXANDRE POULIN 2 | O28: 10 | Q28: =joueurs!C26 -> CSF MATHIEU GENEST 5 | S28: =joueurs!H26 -> CSF STÉPHANIE BELISLE 5
B29: FXG MAXIME SIROIS 4 | M29: BEA ROMAIN LEMIEUX 5 | Q29: =joueurs!C27 -> CSF WILLIAM BARRY 6 | S29: =joueurs!H27 -> CSF CHRISTINE MALTAIS 6
Q30: =joueurs!C28 -> CSF SHANNON CYR-KIRK 7 | S30: =joueurs!H28 -> CSF CAROLINE LAVOIE-MOORE 7
Q31: =joueurs!C29 -> CSF DANIEL GUÉRIN 8 | S31: =joueurs!H29 -> CSF KAYALA RITCHIE 8
Q32: =joueurs!C30 -> CSF WILLIAM ARBOUR 9 | S32: =joueurs!H30 -> CSF LAURIE ASPIRAULT 9
D33: DOUBLE MIXTE 2/3 21pts | Q33: =joueurs!C31 -> CSF NICOLAS GUÉRETTE 10 | S33: =joueurs!H31 -> CSF SABRINA BERGERON 10
Q34: =joueurs!C32 -> CSF FÉLIX BERNIER-TREMBLAY 11 | S34: =joueurs!H32 -> CSF MAUDE CANTIN 11
A35: 1 | B35: FXG DOMINIQUE PITRE 4 | D35: 12 | F35: 21-11 | H35: 23-25 | J35: 21-14 | M35: BEA MARIE-ÈVE MATHIEU 4 | O35: 10 | Q35: =joueurs!C33 -> CSF ALEXANDRE GAUDRY 12
B36: FXG SÉBASTIEN DROUIN LEMIEUX 2 | M36: BEA ALEX DUCLOS 3
Q37: =joueurs!C35 -> FXG MARC-OLIVIER BÉLIVEAU 1 | S37: =joueurs!H35 -> FXG VANESSA GENDRON 1
D38: =SUM(D13:D35) -> 51 | F38: SUBSTITUTS | J38: COLL | M38: Total de points | O38: =SUM(O13:O35) -> 48 | Q38: =joueurs!C36 -> FXG SÉBASTIEN DROUIN LEMIEUX 2 | S38: =joueurs!H36 -> FXG EMMANUELLE DUNN 2
Q39: =joueurs!C37 -> FXG PHILIPPE RENY 3 | S39: =joueurs!H37 -> FXG JOSIANNE BOULANGER 3
Q40: =joueurs!C38 -> FXG MAXIME SIROIS 4 | S40: =joueurs!H38 -> FXG DOMINIQUE PITRE 4
B41: Signature de l'entraîneur | M41: Signature de l'entraîneur | Q41: =joueurs!C39 -> FXG GABRIEL GOULET-MAILHOT 5 | S41: =joueurs!H39 -> FXG ÉLISE GRANDGUILLOT 5
Q42: =joueurs!C40 -> FXG ANTOINE BABY BOUCHARD 6 | S42: =joueurs!H40 -> 0
...

Sheet joueurs
A1: CLASSEMENT MASCULIN | F1: CLASSEMENT FÉMININ
A2: ÉQUIPE #2 | D2: présent | F2: ÉQUIPE #2 | I2: présent
B3: =MID(C3,1,3) -> BEA | C3: BEA SYLVAIN LALIBERTÉ 1 | D3: X | G3: =MID(H3,1,3) -> BEA | H3: BEA JOSIANE LANGLOIS 1 | I3: X
B4: =MID(C4,1,3) -> BEA | C4: BEA ALEXANDRE POULIN 2 | D4: X | G4: =MID(H4,1,3) -> BEA | H4: BEA ALEX LECLERC 2 | I4: X
B5: =MID(C5,1,3) -> BEA | C5: BEA ALEX DUCLOS 3 | D5: X | G5: =MID(H5,1,3)
B6: =MID(C6,1,3) -> BEA | C6: BEA CALVIN CHEN 4 | D6: X | G6: =MID(H6,1,3) -> BEA | H6: BEA MARIE-ÈVE MATHIEU 4 | I6: X
B7: =MID(C7,1,3) -> BEA | C7: BEA ROMAIN LEMIEUX 5 | D7: X | G7: =MID(H7,1,3) -> BEA | H7: BEAU LANY FORTIN 5 | I7: X
B8: =MID(C8,1,3) -> BEA | C8: BEA PIER-ALEXANDRE BOUCHER 6
B10: =MID(C10,1,3) -> CLL | C10: CLL WILLIAM BROUARD 1 | D10: X | G10: =MID(H10,1,3) -> CLL | H10: CLL MARILOU HAMEL 1 | I10: X
B11: =MID(C11,1,3) -> CLL | C11: CLL PASCAL BOURGAULT 2 | D11: X | G11: =MID(H11,1,3) -> CLL | H11: CLL VALÉRIE DESRUISSEAUX 2 | I11: X
B12: =MID(C12,1,3) -> CLL | C12: CLL SAMUEL GUAY 3 | D12: X | G12: =MID(H12,1,3) -> CLL | H12: CLL AUDREY GAGNÉ 3 | I12: X
B13: =MID(C13,1,3) -> CLL | C13: CLL ALEXANDRE HAMEL 4 | D13: X | G13: =MID(H13,1,3) -> CLL | H13: CLL CHLOÉ BRETON 4 | I13: X
B14: =MID(C14,1,3) -> CLL | C14: CLL MAXIME GAUDET 5 | D14: X | G14: =MID(H14,1,3) -> CLL | H14: CLL JULIE MÉTHOT 5 | I14: X
B15: =MID(C15,1,3) -> CLL | C15: CLL OLIVIER BARRETTE 6 | D15: X | G15: =MID(H15,1,3) -> CLL | H15: CLL CATHERINE GUIMONT 6 | I15: X
B16: =MID(C16,1,3) -> CLL | C16: CLL ESTÉBAN JOMPHE 7 | D16: X
B17: =MID(C17,1,3)
B18: =MID(C18,1,3) -> CLL | C18: CLL SAMUEL BEAULIEU 9 | D18: X
B19: =MID(C19,1,3) -> CLL | C19: CLL ANTHONY CAREY 10 | D19: X
B20: =MID(C20,1,3) -> CLL | C20: CLL ÉTIENNE THIBAULT 11 | D20: X
B22: =MID(C22,1,3) | G22: =MID(H22,1,3)
B23: =MID(C23,1,3) -> CSF | C23: CSF SIMON JEAN-PINEAULT 2 | D23: X | G23: =MID(H23,1,3) -> CSF | H23: CSF VIRGINIE SAVARD 2 | I23: X
B24: =MID(C24,1,3) -> CSF | C24: CSF ALEXANDRE MAZIADE 3 | D24: X | G24: =MID(H24,1,3)
B25: =MID(C25,1,3) -> CSF | C25: CSF MARC-ANTOINE GENEST 4 | D25: X | G25: =MID(H25,1,3) -> CSF | H25: CSF CATHERINE SAVARD 4 | I25: X
B26: =MID(C26,1,3) -> CSF | C26: CSF MATHIEU GENEST 5 | D26: X | G26: =MID(H26,1,3) -> CSF | H26: CSF STÉPHANIE BELISLE 5 | I26: X
B27: =MID(C27,1,3) -> CSF | C27: CSF WILLIAM BARRY 6 | D27: X | G27: =MID(H27,1,3) -> CSF | H27: CSF CHRISTINE MALTAIS 6 | I27: X
B28: =MID(C28,1,3) -> CSF | C28: CSF SHANNON CYR-KIRK 7 | D28: X | G28: =MID(H28,1,3) -> CSF | H28: CSF CAROLINE LAVOIE-MOORE 7 | I28: X
B29: =MID(C29,1,3) -> CSF | C29: CSF DANIEL GUÉRIN 8 | D29: X | G29: =MID(H29,1,3) -> CSF | H29: CSF KAYALA RITCHIE 8 | I29: X
B30: =MID(C30,1,3) -> CSF | C30: CSF WILLIAM ARBOUR 9 | D30: X | G30: =MID(H30,1,3) -> CSF | H30: CSF LAURIE ASPIRAULT 9 | I30: X
B31: =MID(C31,1,3) -> CSF | C31: CSF NICOLAS GUÉRETTE 10 | D31: X | G31: =MID(H31,1,3) -> CSF | H31: CSF SABRINA BERGERON 10 | I31: X
B32: =MID(C32,1,3) -> CSF | C32: CSF FÉLIX BERNIER-TREMBLAY 11 | D32: X | G32: =MID(H32,1,3) -> CSF | H32: CSF MAUDE CANTIN 11 | I32: X
B33: =MID(C33,1,3) -> CSF | C33: CSF ALEXANDRE GAUDRY 12 | D33: X
B35: =MID(C35,1,3) -> FXG | C35: FXG MARC-OLIVIER BÉLIVEAU 1 | D35: X | G35: =MID(H35,1,3) -> FXG | H35: FXG VANESSA GENDRON 1 | I35: X
B36: =MID(C36,1,3) -> FXG | C36: FXG SÉBASTIEN DROUIN LEMIEUX 2 | D36: X | G36: =MID(H36,1,3) -> FXG | H36: FXG EMMANUELLE DUNN 2 | I36: X
B37: =MID(C37,1,3) -> FXG | C37: FXG PHILIPPE RENY 3 | D37: X | G37: =MID(H37,1,3) -> FXG | H37: FXG JOSIANNE BOULANGER 3 | I37: X
B38: =MID(C38,1,3) -> FXG | C38: FXG MAXIME SIROIS 4 | D38: X | G38: =MID(H38,1,3) -> FXG | H38: FXG DOMINIQUE PITRE 4 | I38: X
B39: =MID(C39,1,3) -> FXG | C39: FXG GABRIEL GOULET-MAILHOT 5 | D39: X | G39: =MID(H39,1,3) -> FXG | H39: FXG ÉLISE GRANDGUILLOT 5 | I39: X
B40: =MID(C40,1,3) -> FXG | C40: FXG ANTOINE BABY BOUCHARD 6 | D40: X | G40: =MID(H40,1,3)
B41: =MID(C41,1,3) -> FXG | C41: FXG MARC-ANTHONY BLACKBURN 7 | D41: X
B42: =MID(C42,1,3) -> FXG | C42: FXG CHARLES-ANDRÉ BEAUDRY 8 | D42: X
B43: =MID(C43,1,3) -> FXG | C43: FXG PHILIPPE GOBEIL BOUCHARD 9 | D43: X
...

Sheet RÉSULTATS
AA7: 5
A8: Ligue de badminton mixte division 1
A9: Résultats du tournoi par équipe du 24 novembre 2012
A10: tenu à Lévis-Lauzon
A13: Équipe | B13: GAR | E13: CSF | H13: CLL | K13: RIM | N13: RDL | Q13: LIM | T13: BAP | W13: Vic. | X13: Déf. | Y13: Pts p. | Z13: Pts c. | AA13: Points
A14: 1.GARNEAU | E14: =D15 -> 26 | F14: 19 | G14: =B15 -> 54 | H14: =D16 -> 37 | I14: 18 | J14: =B16 -> 45 | K14: =D17 -> 40 | L14: 13 | M14: =B17 -> 50 | N14: =D18 -> 58 | O14: 8 | P14: =B18 -> 34 | Q14: =D19 -> 41 | R14: 6 | S14: =B19 -> 37 | T14: =D20 -> 51 | U14: 1 | V14: =B20 -> 48 | W14: 3 | X14: 3 | Y14: =E14+H14+K14+N14+Q14+T14 -> 253 | Z14: =G14+J14+M14+P14+S14+V14 -> 268 | AA14: =+Y14 -> 253
A15: 2.SAINTE-FOY | B15: =alignement!$O$902 -> 54 | C15: 19 | D15: =alignement!$D$902 -> 26 | H15: =G16 -> 58 | I15: 14 | J15: =E16 -> 33 | K15: =G17 -> 52 | L15: 9 | M15: =E17 -> 36 | N15: =G18 -> 60 | O15: 4 | P15: =E18 -> 18 | Q15: =G19 -> 60 | R15: 3 | S15: =E19 -> 22 | T15: =G20 -> 53 | U15: 11 | V15: =E20 -> 26 | W15: 6 | X15: 0 | Y15: =B15+H15+K15+N15+Q15+T15 -> 337 | Z15: =D15+J15+M15+P15+S15+V15 -> 161 | AA15: =+Y15 -> 337
A16: 3.LÉVIS-LAUZON | B16: =alignement!$D$854 -> 45 | C16: 18 | D16: =alignement!$O$854 -> 37 | E16: =alignement!$O$662 -> 33 | F16: 14 | G16: =alignement!$D$662 -> 58 | K16: =J17 -> 34 | L16: 5 | M16: =H17 -> 52 | N16: =J18 -> 52 | O16: 2 | P16: =H18 -> 28 | Q16: =J19 -> 43 | R16: 10 | S16: =H19 -> 35 | T16: =J20 -> 50 | U16: 21 | V16: =H20 -> 35 | W16: 4 | X16: 2 | Y16: =B16+E16+K16+N16+Q16+T16 -> 257 | Z16: =D16+G16+M16+P16+S16+V16 -> 245 | AA16: =+Y16 -> 257
A17: 4 RIMOUSKI | B17: =alignement!$O$614 -> 50 | C17: 13 | D17: =alignement!$D$614 -> 40 | E17: =alignement!$D$422 -> 36 | F17: 9 | G17: =alignement!$O$422 -> 52 | H17: =alignement!$O$230 -> 52 | I17: 5 | J17: =alignement!$D$230 -> 34 | N17: =M18 -> 52 | O17: 12 | P17: =K18 -> 43 | Q17: =M19 -> 50 | R17: 20 | S17: =K19 -> 35 | T17: =M20 -> 43 | U17: 17 | V17: =K20 -> 39 | W17: 5 | X17: 1 | Y17: =B17+E17+H17+N17+Q17+T17 -> 283 | Z17: =D17+G17+J17+P17+S17+V17 -> 243 | AA17: =+Y17 -> 283
A18: 5.RIVIÈRE-DU-LOUP | B18: =alignement!$D$374 -> 34 | C18: 8 | D18: =alignement!$O$374 -> 58 | E18: =alignement!$O$182 -> 18 | F18: 4 | G18: =alignement!$D$182 -> 60 | H18: =alignement!$D$86 -> 28 | I18: 2 | J18: =alignement!$O$86 -> 52 | K18: =alignement!$D$566 -> 43 | L18: 12 | M18: =alignement!$O$566 -> 52 | Q18: =P19 -> 41 | R18: 16 | S18: =N19 -> 42 | T18: =P20 -> 32 | U18: 15 | V18: =N20 -> 58 | W18: 0 | X18: 6 | Y18: =B18+E18+H18+K18+Q18+T18 -> 196 | Z18: =D18+G18+J18+M18+S18+V18 -> 322 | AA18: =+Y18 -> 196
A19: 6.LIMOILOU | B19: =alignement!$D$278 -> 37 | C19: 6 | D19: =alignement!$O$278 -> 41 | E19: =alignement!$D$134 -> 22 | F19: 3 | G19: =alignement!$O$134 -> 60 | H19: =alignement!$O$470 -> 35 | I19: 10 | J19: =alignement!$D$470 -> 43 | K19: =alignement!$D$950 -> 35 | L19: 20 | M19: =alignement!$O$950 -> 50 | N19: =alignement!$D$758 -> 42 | O19: 16 | P19: =alignement!$O$758 -> 41 | T19: =S20 -> 42 | U19: 7 | V19: =Q20 -> 43 | W19: 1 | X19: 5 | Y19: =B19+E19+H19+K19+N19+T19 -> 213 | Z19: =D19+G19+J19+M19+P19+V19 -> 278 | AA19: =+Y19 -> 213
A20: 7.BEAUCE-APPALACHES | B20: =alignement!$O$38 -> 48 | C20: 1 | D20: =alignement!$D$38 -> 51 | E20: =alignement!$D$518 -> 26 | F20: 11 | G20: =alignement!$O$518 -> 53 | H20: =alignement!$D$998 -> 35 | I20: 21 | J20: =alignement!$O$998 -> 50 | K20: =alignement!$O$806 -> 39 | L20: 17 | M20: =alignement!$D$806 -> 43 | N20: =alignement!$D$710 -> 58 | O20: 15 | P20: =alignement!$O$710 -> 32 | Q20: =alignement!$D$326 -> 43 | R20: 7 | S20: =alignement!$O$326 -> 42 | W20: 2 | X20: 4 | Y20: =B20+E20+H20+K20+N20+Q20 -> 249 | Z20: =D20+G20+J20+M20+P20+S20 -> 271 | AA20: =+Y20 -> 249
B23: Équipe #1 | E23: Équipe #2 | H23: Équipe #3 | K23: TOTAL | M23: écart | N23: #
A24: SAINTE-FOY | B24: 327 | C24: 1 | E24: 337 | F24: 1 | K24: =B24+E24 -> 664 | M24: ------ | N24: 1
A25: RIMOUSKI | B25: 299 | C25: 2 | E25: 283 | F25: 2 | K25: =B25+E25 -> 582 | M25: =K24-K25 -> 82 | N25: 2
A26: GARNEAU | B26: 261 | C26: 3 | E26: 253 | F26: 4 | K26: =B26+E26 -> 514 | M26: =K25-K26 -> 68 | N26: 3
A27: BEAUCE-APPALACHES | B27: 258 | C27: 4 | E27: 249 | F27: 5 | K27: =B27+E27 -> 507 | M27: =K26-K27 -> 7 | N27: 4
A28: LÉVIS-LAUZON | B28: 206 | C28: 7 | E28: 257 | F28: 3 | K28: =B28+E28 -> 463 | M28: =K27-K28 -> 44 | N28: 5
A29: LIMOILOU | B29: 234 | C29: 5 | E29: 213 | F29: 6 | K29: =B29+E29 -> 447 | M29: =K28-K29 -> 16 | N29: 6
A30: RIVIÈRE-DU-LOUP | B30: 215 | C30: 6 | E30: 196 | F30: 7 | K30: =B30+E30 -> 411 | M30: =K29-K30 -> 36 | N30: 7
